<?xml version="1.0" ?>
<!--This file contains the SDF model of a KUKA iiwa robot with a wsg50 gripper.
    It has been produced from the varients in //third_party/robotics/models.
    Note:  This file is temporary, and should be deleted once Bullet supports
    importing models in SDF.  Also, this file has been specialized for Bullet,
    because the mass of the base link has been set to 0, as needed by Bullet.
    Note:  All of the gripper link poses have been adjusted in the z direction
    to achieve a reasonable position of the gripper relative to the arm.
    Note: The joint names for the KUKA have been changed to J0, J1, etc. -->
    <!--There is problem with the kuka mesh and everytime i use it gazebo crashes so I am gonna comment that part-->
    

<sdf version='1.6'>
  <model name="kuka_handlit">
    <!--KUKA-->
    <link name = "world">
        <pose frame=''>0 0 0 0 0 0</pose>
        <inertial>
            <pose frame=''>0 0 0.0 0 0 0</pose>
            <mass>0.0</mass>
            <inertia>
                <ixx>0.</ixx>
                <ixy>0</ixy>
                <ixz>0</ixz>
                <iyy>0.</iyy>
                <iyz>0</iyz>
                <izz>0.</izz>
            </inertia>
        </inertial>
    </link>
    <joint name="world" type="fixed">
        <child>lbr_iiwa_link_0</child>
        <parent>world</parent>
    </joint>
    
      <link name="lbr_iiwa_link_0">
        <pose frame=''>0 0 0 0 0 0</pose>
        <inertial>
            <pose frame=''>-0.1 0 0.07 0 0 0</pose>
            <mass>5</mass>
            <inertia>
                <ixx>0.05</ixx>
                <ixy>0</ixy>
                <ixz>0</ixz>
                <iyy>0.06</iyy>
                <iyz>0</iyz>
                <izz>0.03</izz>
            </inertia>
        </inertial>
        <collision name='lbr_iiwa_link_0_collision'>
          <pose frame=''>0 0 0 0 -0 0</pose>
          <geometry>
            <mesh>
              
              <scale>1 1 1</scale>
              <uri>model://kuka_handlit/meshes/link_0.stl</uri>
              
            </mesh>
          </geometry>
        </collision>
        <visual name='lbr_iiwa_link_0_visual'>
          <pose frame=''>0 0 0 0 -0 0</pose>
          <geometry>
            <mesh>
              <scale>1 1 1</scale>
              <uri>model://kuka_handlit/meshes/link_0.stl</uri>
            </mesh>
          </geometry>
          <material>
            <ambient>0.01622888870580208 0.938424277289672 0.19248718478133697 1</ambient>
            <diffuse>0.6313055359033773 0.8131593517265105 0.8563135158975596 1</diffuse>
            <specular>0.2199948898979689 0.09841433426177082 0.7236841789933751 1</specular>
            <emissive>0 0 0 0</emissive>
          </material>
        </visual>
      </link>
    
      <link name="lbr_iiwa_link_1">
        <pose frame=''>0 0 0.1575 0 0 0</pose>
        <inertial>
            <pose frame=''>0 0.03 0.12 0 0 0</pose>
            <mass>3.4525</mass>
            <inertia>
                <ixx>0.1</ixx>
                <ixy>0</ixy>
                <ixz>0</ixz>
                <iyy>0.09</iyy>
                <iyz>0</iyz>
                <izz>0.02</izz>
            </inertia>
        </inertial>
        <collision name='lbr_iiwa_link_1_collision'>
          <pose frame=''>0 0 0 0 -0 0</pose>
          <geometry>
            <mesh>
              
              <scale>1 1 1</scale>
              <uri>model://kuka_handlit/meshes/link_1.stl</uri>
              
            </mesh>
          </geometry>
        </collision>
        <visual name='lbr_iiwa_link_1_visual'>
          <pose frame=''>0 0 0 0 -0 0</pose>
          <geometry>
            <mesh>
              <scale>1 1 1</scale>
              <uri>model://kuka_handlit/meshes/link_1.stl</uri>
            </mesh>
          </geometry>
          <material>
            <ambient>0.5506733762356296 0.589769737381622 0.41627662818067934 1</ambient>
            <diffuse>0.7295810664062102 0.7973384820867022 0.7016626246147856 1</diffuse>
            <specular>0.40233801711775596 0.08196698652548096 0.46274888154402993 1</specular>
            <emissive>0 0 0 0</emissive>
          </material>
        </visual>
      </link>
    
      <link name="lbr_iiwa_link_2">
        <pose frame=''>0 0 0.36 1.5708 0 -3.14159</pose>
        <inertial>
            <pose frame=''>0.0003 0.059 0.042 0 0 0</pose>
            <mass>3.4821</mass>
            <inertia>
                <ixx>0.05</ixx>
                <ixy>0</ixy>
                <ixz>0</ixz>
                <iyy>0.018</iyy>
                <iyz>0</iyz>
                <izz>36</izz>
            </inertia>
        </inertial>
        <collision name='lbr_iiwa_link_2_collision'>
          <pose frame=''>0 0 0 0 -0 0</pose>
          <geometry>
            <mesh>
              
              <scale>1 1 1</scale>
              <uri>model://kuka_handlit/meshes/link_2.stl</uri>
              
            </mesh>
          </geometry>
        </collision>
        <visual name='lbr_iiwa_link_2_visual'>
          <pose frame=''>0 0 0 0 -0 0</pose>
          <geometry>
            <mesh>
              <scale>1 1 1</scale>
              <uri>model://kuka_handlit/meshes/link_2.stl</uri>
            </mesh>
          </geometry>
          <material>
            <ambient>0.5087378910164088 0.2861264851598311 0.21353000471130368 1</ambient>
            <diffuse>0.01929485194550984 0.40252259653282974 0.7924799850119537 1</diffuse>
            <specular>0.10864917320950418 4.15055565727851e-06 0.8135388614403252 1</specular>
            <emissive>0 0 0 0</emissive>
          </material>
        </visual>
      </link>
    
      <link name="lbr_iiwa_link_3">
        <pose frame=''>0 0 0.5645 0 0 0</pose>
        <inertial>
            <pose frame=''>0 0.03 0.13 0 0 0</pose>
            <mass>4.05623</mass>
            <inertia>
                <ixx>0.08</ixx>
                <ixy>0</ixy>
                <ixz>0</ixz>
                <iyy>0.075</iyy>
                <iyz>0</iyz>
                <izz>0.01</izz>
            </inertia>
        </inertial>
        <collision name='lbr_iiwa_link_3_collision'>
          <pose frame=''>0 0 0 0 -0 0</pose>
          <geometry>
            <mesh>
              
              <scale>1 1 1</scale>
              <uri>model://kuka_handlit/meshes/link_3.stl</uri>
              
            </mesh>
          </geometry>
        </collision>
        <visual name='lbr_iiwa_link_3_visual'>
          <pose frame=''>0 0 0 0 -0 0</pose>
          <geometry>
            <mesh>
              <scale>1 1 1</scale>
              <uri>model://kuka_handlit/meshes/link_3.stl</uri>
            </mesh>
          </geometry>
          <material>
            <ambient>0.30568473056202283 0.744902041243869 0.4864136586908886 1</ambient>
            <diffuse>0.841339680340139 0.24373620148673014 0.9267492413489717 1</diffuse>
            <specular>0.2952228370273805 0.008199126286506542 0.2714264127962922 1</specular>
            <emissive>0 0 0 0</emissive>
          </material>
        </visual>
      </link>
    
      <link name="lbr_iiwa_link_4">
        <pose frame=''>0 0 0.78 1.5708 0 0</pose>
        <inertial>
            <pose frame=''>0 0.067 0 0.034 0 0</pose>
            <mass>3.4822</mass>
            <inertia>
                <ixx>0.03</ixx>
                <ixy>0</ixy>
                <ixz>0</ixz>
                <iyy>0.01</iyy>
                <iyz>0</iyz>
                <izz>0.029</izz>
            </inertia>
        </inertial>
        <collision name='lbr_iiwa_link_4_collision'>
          <pose frame=''>0 0 0 0 -0 0</pose>
          <geometry>
            <mesh>
              
              <scale>1 1 1</scale>
              <uri>model://kuka_handlit/meshes/link_4.stl</uri>
              
            </mesh>
          </geometry>
        </collision>
        <visual name='lbr_iiwa_link_4_visual'>
          <pose frame=''>0 0 0 0 -0 0</pose>
          <geometry>
            <mesh>
              <scale>1 1 1</scale>
              <uri>model://kuka_handlit/meshes/link_4.stl</uri>
            </mesh>
          </geometry>
          <material>
            <ambient>0.3477094608994915 0.9408969088617155 0.5872052657017574 1</ambient>
            <diffuse>0.08747190259688231 0.23255976060646488 0.8560882867533901 1</diffuse>
            <specular>0.6902635473204011 0.8066301609734473 0.3412727666864308 1</specular>
            <emissive>0 0 0 0</emissive>
          </material>
        </visual>
      </link>
    
      <link name="lbr_iiwa_link_5">
        <pose frame=''>0 0 0.9645 0 0 -3.14159</pose>
        <inertial>
            <pose frame=''>0.0001 0.021 0.076 0 0 0</pose>
            <mass>2.1633</mass>
            <inertia>
                <ixx>0.02</ixx>
                <ixy>0</ixy>
                <ixz>0</ixz>
                <iyy>0.018</iyy>
                <iyz>0</iyz>
                <izz>0.005</izz>
            </inertia>
        </inertial>
        <collision name='lbr_iiwa_link_5_collision'>
          <pose frame=''>0 0 0 0 -0 0</pose>
          <geometry>
            <mesh>
              
              <scale>1 1 1</scale>
              <uri>model://kuka_handlit/meshes/link_5.stl</uri>
              
            </mesh>
          </geometry>
        </collision>
        <visual name='lbr_iiwa_link_5_visual'>
          <pose frame=''>0 0 0 0 -0 0</pose>
          <geometry>
            <mesh>
              <scale>1 1 1</scale>
              <uri>model://kuka_handlit/meshes/link_5.stl</uri>
            </mesh>
          </geometry>
          <material>
            <ambient>0.11142663062606972 0.9390664840931227 0.6147174351049896 1</ambient>
            <diffuse>0.09259379686644698 0.07319616125276629 0.45976546239453786 1</diffuse>
            <specular>0.6539587226351409 0.4011222128022437 0.9287916057096447 1</specular>
            <emissive>0 0 0 0</emissive>
          </material>
        </visual>
      </link>
    
      <link name="lbr_iiwa_link_6">
        <pose frame=''>0 0 1.18 1.5708 0 -3.14159</pose>
        <inertial>
            <pose frame=''>0 0.0006 0.0004 0 0 0</pose>
            <mass>2.3466</mass>
            <inertia>
                <ixx>0.005</ixx>
                <ixy>0</ixy>
                <ixz>0</ixz>
                <iyy>0.0036</iyy>
                <iyz>0</iyz>
                <izz>0.0047</izz>
            </inertia>
        </inertial>
        <collision name='lbr_iiwa_link_6_collision'>
          <pose frame=''>0 0 0 0 -0 0</pose>
          <geometry>
            <mesh>
              
              <scale>1 1 1</scale>
              <uri>model://kuka_handlit/meshes/link_6.stl</uri>
              
            </mesh>
          </geometry>
        </collision>
        <visual name='lbr_iiwa_link_6_visual'>
          <pose frame=''>0 0 0 0 -0 0</pose>
          <geometry>
            <mesh>
              <scale>1 1 1</scale>
              <uri>model://kuka_handlit/meshes/link_6.stl</uri>
            </mesh>
          </geometry>
          <material>
            <ambient>0.3624047522591979 0.26453523178941163 0.4935582153660113 1</ambient>
            <diffuse>0.3548598136657142 0.1419793917412424 0.5912374225055672 1</diffuse>
            <specular>0.4796417555483845 0.9785842174452328 0.9538036657945589 1</specular>
            <emissive>0 0 0 0</emissive>
          </material>
        </visual>
      </link>
    
      <link name="lbr_iiwa_link_7">
        <pose frame=''>0 0 1.261 0 0 0</pose>
        <inertial>
            <pose frame=''>0 0 0.02 0 0 0</pose>
            <mass>3.129</mass>
            <inertia>
                <ixx>0.001</ixx>
                <ixy>0</ixy>
                <ixz>0</ixz>
                <iyy>0.001</iyy>
                <iyz>0</iyz>
                <izz>0.001</izz>
            </inertia>
        </inertial>
        <collision name='lbr_iiwa_link_7_collision'>
          <pose frame=''>0 0 0 0 -0 0</pose>
          <geometry>
            <mesh>
              
              <scale>1 1 1</scale>
              <uri>model://kuka_handlit/meshes/link_7.stl</uri>
              
            </mesh>
          </geometry>
        </collision>
        <visual name='lbr_iiwa_link_7_visual'>
          <pose frame=''>0 0 0 0 -0 0</pose>
          <geometry>
            <mesh>
              <scale>1 1 1</scale>
              <uri>model://kuka_handlit/meshes/link_7.stl</uri>
            </mesh>
          </geometry>
          <material>
            <ambient>0.5567315539683272 0.3821879342958292 0.24251646807922533 1</ambient>
            <diffuse>0.2076455810058001 0.859008191105435 0.3994032252246471 1</diffuse>
            <specular>0.9797364307434482 0.8335717256796691 0.2674743892480961 1</specular>
            <emissive>0 0 0 0</emissive>
          </material>
        </visual>
      </link>
    
   
    
      <joint name="J0" type="revolute">
        <child>lbr_iiwa_link_1</child>
        <parent>lbr_iiwa_link_0</parent>
        <axis>
          <xyz>0 0 1</xyz>
          <limit>
            <lower>-2.96706</lower>
            <upper>2.96706</upper>
            <effort>300</effort>
            <velocity>10</velocity>
          </limit>
          <dynamics>
            <damping>0.5</damping>
            <friction>0</friction>
            <spring_reference>0</spring_reference>
            <spring_stiffness>0</spring_stiffness>
          </dynamics>
        </axis>
      </joint>
    
      <joint name="J1" type="revolute">
        <child>lbr_iiwa_link_2</child>
        <parent>lbr_iiwa_link_1</parent>
        <axis>
          <xyz>0 0 1</xyz>
          <limit>
            <lower>-2.0944</lower>
            <upper>2.0944</upper>
            <effort>300</effort>
            <velocity>10</velocity>
          </limit>
          <dynamics>
            <damping>0.5</damping>
            <friction>0</friction>
            <spring_reference>0</spring_reference>
            <spring_stiffness>0</spring_stiffness>
          </dynamics>
        </axis>
      </joint>
    
      <joint name="J2" type="revolute">
        <child>lbr_iiwa_link_3</child>
        <parent>lbr_iiwa_link_2</parent>
        <axis>
          <xyz>0 0 1</xyz>
          <limit>
            <lower>-2.96706</lower>
            <upper>2.96706</upper>
            <effort>300</effort>
            <velocity>10</velocity>
          </limit>
          <dynamics>
            <damping>0.5</damping>
            <friction>0</friction>
            <spring_reference>0</spring_reference>
            <spring_stiffness>0</spring_stiffness>
          </dynamics>
        </axis>
      </joint>
    
      <joint name="J3" type="revolute">
        <child>lbr_iiwa_link_4</child>
        <parent>lbr_iiwa_link_3</parent>
        <axis>
          <xyz>0 0 1</xyz>
          <limit>
            <lower>-2.0944</lower>
            <upper>2.0944</upper>
            <effort>300</effort>
            <velocity>10</velocity>
          </limit>
          <dynamics>
            <damping>0.5</damping>
            <friction>0</friction>
            <spring_reference>0</spring_reference>
            <spring_stiffness>0</spring_stiffness>
          </dynamics>
        </axis>
      </joint>
    
      <joint name="J4" type="revolute">
        <child>lbr_iiwa_link_5</child>
        <parent>lbr_iiwa_link_4</parent>
        <axis>
          <xyz>0 0 1</xyz>
          <limit>
            <lower>-2.96706</lower>
            <upper>2.96706</upper>
            <effort>300</effort>
            <velocity>10</velocity>
          </limit>
          <dynamics>
            <damping>0.5</damping>
            <friction>0</friction>
            <spring_reference>0</spring_reference>
            <spring_stiffness>0</spring_stiffness>
          </dynamics>
        </axis>
      </joint>
    
      <joint name="J5" type="revolute">
        <child>lbr_iiwa_link_6</child>
        <parent>lbr_iiwa_link_5</parent>
        <axis>
          <xyz>0 0 1</xyz>
          <limit>
            <lower>-2.0944</lower>
            <upper>2.0944</upper>
            <effort>300</effort>
            <velocity>10</velocity>
          </limit>
          <dynamics>
            <damping>0.5</damping>
            <friction>0</friction>
            <spring_reference>0</spring_reference>
            <spring_stiffness>0</spring_stiffness>
          </dynamics>
        </axis>
      </joint>
    
      <joint name="J6" type="revolute">
        <child>lbr_iiwa_link_7</child>
        <parent>lbr_iiwa_link_6</parent>
        <axis>
          <xyz>0 0 1</xyz>
          <limit>
            <lower>-3.05433</lower>
            <upper>3.05433</upper>
            <effort>300</effort>
            <velocity>10</velocity>
          </limit>
          <dynamics>
            <damping>0.5</damping>
            <friction>0</friction>
            <spring_reference>0</spring_reference>
            <spring_stiffness>0</spring_stiffness>
          </dynamics>
        </axis>
      </joint>
    

    <!--Hand-->

    <joint name="forearm_world" type="fixed">
        <child>forearm</child>
        <parent>lbr_iiwa_link_7</parent>
    </joint>

    <link name ="forearm" >
        <pose frame=''>0 0 1.261 0 0 1.5707963267948966</pose>
        <inertial>
            <pose frame=''>0 0 0.09 0 0 0</pose>
            <mass>1.8</mass>
            <inertia>
                <ixx>0.108</ixx>
                <ixy>0</ixy>
                <ixz>0</ixz>
                <iyy>0.108</iyy>
                <iyz>0</iyz>
                <izz>0.054</izz>
            </inertia>
        </inertial>

        <visual name='visual_forearm_link'>

            <geometry>
                <mesh>
                    <scale>1 1 1</scale>
                    <uri>model://kuka_handlit/meshes/forearm_lite.dae</uri>
                </mesh>
            </geometry>
            <material>
                <ambient>0.12178073323694738 0.4429989282317658 0.8799001636092991 1</ambient>
                <diffuse>0.7072375494271524 0.6178534061439171 0.9965010465493614 1</diffuse>
                <specular>0.26945150915388616 0.8103328943436096 0.07281537933669291 1</specular>
                <emissive>0 0 0 0</emissive>
            </material>
        </visual>
        <collision name='collision_forearm_link'>
        
            <geometry>
                <mesh>
                    <scale>1 1 1</scale>
                    <uri>model://kuka_handlit/meshes/forearm_lite.dae</uri>
                </mesh>
            </geometry>
        </collision>
    </link>

    <link name = "palm">
        <pose frame=''>0 -0.015 1.41 -0.6981317007977318 0 0</pose>
        <inertial>
            <pose frame=''>0 0 0.035 0 0 0</pose>
            <mass>0.3</mass>
            <inertia>
                <ixx>0.0003581</ixx>
                <ixy>0</ixy>
                <ixz>0</ixz>
                <iyy>0.0005287</iyy>
                <iyz>0</iyz>
                <izz>0.000191</izz>
            </inertia>
        </inertial>
        
        <visual name='visual_palm_link'>

            <geometry>
                <mesh>
                    <scale>-0.001 0.001 0.001</scale>
                    <uri>model://kuka_handlit/meshes/palm2.dae</uri>
                </mesh>
            </geometry>
            <material>
                <ambient>0.7399675499571181 0.5549741433279864 0.8896384730825428 1</ambient>
                <diffuse>0.7818565484553653 0.3109879136515653 0.3563059010358891 1</diffuse>
                <specular>0.5398310156781706 0.7218027586373332 0.28653543600562037 1</specular>
                <emissive>0 0 0 0</emissive>
            </material>
        </visual>
        <collision name="collision_palm_link">

            <geometry>
                <mesh>
                    <scale>-0.001 0.001 0.001</scale>
                <uri>model://kuka_handlit/meshes/palm2_c.dae</uri>
            </mesh>
            </geometry>
        </collision>


        
    </link>
    <joint name="palm_forearm" type="fixed">
        <child>palm</child>
        <parent>forearm</parent>
        <axis>

            <xyz>0 -1 0</xyz>
         </axis>
    </joint>  

    
    <link name = "palm_fake">

    <pose frame=''>-0.01 0.020909000000000004 1.4499 -0.6981317007977318 0 0</pose>
    <inertial>
        <pose frame=''>0 0 0.0 0 0 0</pose>
        <mass>0.0</mass>
        <inertia>
            <ixx>0.0</ixx>
            <ixy>0</ixy>
            <ixz>0</ixz>
            <iyy>0.0</iyy>
            <iyz>0</iyz>
            <izz>0.0</izz>
        </inertia>
    </inertial>
        <visual name='visual_palm_fake'>
            <geometry>
                <sphere>
                <radius>0.01</radius>
                </sphere>
            </geometry>
            <material>
                <ambient>0.5672216218105076 0.531815859282997 0.5801439037594547 1</ambient>
                <diffuse>0.5464167892541046 0.6932951350253517 0.22253023363722557 1</diffuse>
                <specular>0.9022550019258972 0.9029306286118689 0.5969458319897258 1</specular>
                <emissive>0 0 0 0</emissive>
            </material>
        </visual>
    </link>

    <joint name="palm_palm_fake" type="fixed">
        <child>palm_fake</child>
        <parent>palm</parent>
        <axis>

            <xyz>0 -1 0</xyz>
         </axis>
    </joint>  

    

        <link name = "knuckle_FF">

            <pose frame=''>-0.033 0.0461 1.48277 -0.698132 0 0</pose>
            <inertial>
                <pose frame=''>0 0 0 0 0 0</pose>
                <mass>0.008</mass>
                <inertia>
                    <ixx>2.6e-07</ixx>
                    <ixy>0</ixy>
                    <ixz>0</ixz>
                    <iyy>2.6e-07</iyy>
                    <iyz>0</iyz>
                    <izz>3.2e-07</izz>
                </inertia>
            </inertial>

            <visual name='visual_knuckle_link_FF'>

                <geometry>
                    <mesh>
                        <scale>0.001 0.001 0.001</scale>
                        <uri>model://kuka_handlit/meshes/knuckle.dae</uri>
                    </mesh>
                </geometry>
                <material>
                    <ambient>0.024435061518930157 0.8176270742530305 0.8006841171561675 1</ambient>
                    <diffuse>0.6967698441827654 0.9297400111043262 0.665095191422718 1</diffuse>
                    <specular>0.7788449629172959 0.8225103581886268 0.7038417067602275 1</specular>
                    <emissive>0 0 0 0</emissive>
                </material>
            </visual>
            <collision name='collision_knuckle_link_FF'>
                <geometry>
                <mesh>
                    <scale>0.001 0.001 0.001</scale>
                    <uri>model://kuka_handlit/meshes/knuckle.dae</uri>
                </mesh>
            </geometry>
            </collision>
        </link>
        <link name = "proximal_FF">
            <pose frame=''>-0.033 0.0461 1.48277 -0.698132 0 0</pose>
            <inertial>
                <pose frame=''>0 0 0.0225 0 0 0</pose>
                <mass>0.03</mass>
                <inertia>
                    <ixx>9.8e-06</ixx>
                    <ixy>0</ixy>
                    <ixz>0</ixz>
                    <iyy>1.0e-05</iyy>
                    <iyz>0</iyz>
                    <izz>1.8e-06</izz>
                </inertia>
            </inertial>

            <visual name='visual_proximal_link_FF'>

                <geometry>
                    <mesh>
                        <scale>0.001 0.001 0.001</scale>
                        <uri>model://kuka_handlit/meshes/F3.dae</uri>
                    </mesh>
                </geometry>
                <material>
                    <ambient>0.9258076295973215 0.5895426614017267 0.970594684487352 1</ambient>
                    <diffuse>0.26514614840683215 0.4724177184202313 0.8013269131385258 1</diffuse>
                    <specular>0.2856039438106889 0.6913963270422931 0.14106260629572587 1</specular>
                    <emissive>0 0 0 0</emissive>
                </material>
            </visual>
            <collision name='collision_proximal_link_FF'>
                <geometry>
                <mesh>
                    <scale>0.001 0.001 0.001</scale>
                    <uri>model://kuka_handlit/meshes/F3_c.dae</uri>
                </mesh>
            </geometry>
            </collision>
        </link>
        <link name = "middle_FF">
            <pose frame=''>-0.033 0.07499 1.5172459999999999 -0.698132 0 0</pose>
            <inertial>
                <pose frame=''>0 0 0.0125 0 0 0</pose>
                <mass>0.017</mass>
                <inertia>
                    <ixx>2.6e-06</ixx>
                    <ixy>0</ixy>
                    <ixz>0</ixz>
                    <iyy>2.7e-06</iyy>
                    <iyz>0</iyz>
                    <izz>8.7e-07</izz>
                </inertia>
            </inertial>

            <visual name='visual_middle_link_FF'>

                <geometry>
                    <mesh>
                        <scale>0.001 0.001 0.001</scale>
                        <uri>model://kuka_handlit/meshes/F2.dae</uri>
                    </mesh>
                </geometry>
                <material>
                    <ambient>0.04415330530651507 0.03821738479182679 0.7569776363841049 1</ambient>
                    <diffuse>0.13623274793880125 0.6632334631039335 0.8930617130247858 1</diffuse>
                    <specular>0.44782801962234864 0.18065813485382864 0.6469910210641037 1</specular>
                    <emissive>0 0 0 0</emissive>
                </material>
            </visual>
            <collision name='collision_middle_link_FF'>
                <geometry>
                    <mesh>
                        <scale>0.001 0.001 0.001</scale>
                        <uri>model://kuka_handlit/meshes/F2_c.dae</uri>
                    </mesh>
                </geometry>
            </collision>
        </link>
        <link name =  "distal_FF">
            <pose frame=''>-0.033 0.09106 1.5363969999999998 -0.698132 0 0</pose>
            <inertial>
                <pose frame=''>0 0 0.012 0 0 0</pose>
                <mass>0.012</mass>
                <inertia>
                    <ixx>9.4e-07</ixx>
                    <ixy>0</ixy>
                    <ixz>0</ixz>
                    <iyy>1.1e-06</iyy>
                    <iyz>0</iyz>
                    <izz>5.3e-07</izz>
                </inertia>
            </inertial>

            <visual name='visual_distal_link_FF'>

                <geometry>
                    <mesh>
                        <scale>0.001 0.001 0.001</scale>
                        <uri>model://kuka_handlit/meshes/F1.dae</uri>
                    </mesh>
                </geometry>
                <material>
                    <ambient>0.8483947637168335 0.637669015169105 0.038800416293140016 1</ambient>
                    <diffuse>0.9579457360385237 0.23418845187632586 0.500963546605977 1</diffuse>
                    <specular>0.5387115369178558 0.3178862916775681 0.029689768559384877 1</specular>
                    <emissive>0 0 0 0</emissive>
                </material>
            </visual>
            <collision name='collision_distal_link_FF'>
                <geometry>
                    <mesh>
                        <scale>0.001 0.001 0.001</scale>
                        <uri>model://kuka_handlit/meshes/F1.dae</uri>
                    </mesh>
                </geometry>
            </collision>
        </link>

        
            
            <joint name="J3_FF" type="revolute">
                <child>proximal_FF</child>
                <parent>knuckle_FF</parent>

                <axis>
                    <xyz>1 0 0</xyz>
                    <limit>
                        <lower>0 </lower>
                        <upper>1.5708 </upper>
                        <effort>2.0 </effort>
                        <velocity>2.0 </velocity>
                    </limit>
                    <dynamics>
                        <damping>0.1</damping>
                        <friction>0</friction>
                        <spring_reference>0</spring_reference>
                        <spring_stiffness>0</spring_stiffness>
                    </dynamics>
                </axis>
            </joint>
        
            
            <joint name="J2_FF" type="revolute">
                <child>middle_FF</child>
                <parent>proximal_FF</parent>

                <axis>
                    <xyz>1 0 0</xyz>
                    <limit>
                        <lower>0 </lower>
                        <upper>1.5708 </upper>
                        <effort>2.0 </effort>
                        <velocity>2.0 </velocity>
                    </limit>
                    <dynamics>
                        <damping>0.1</damping>
                        <friction>0</friction>
                        <spring_reference>0</spring_reference>
                        <spring_stiffness>0</spring_stiffness>
                    </dynamics>
                </axis>
            </joint>
        
            
            <joint name="J1_FF" type="revolute">
                <child>distal_FF</child>
                <parent>middle_FF</parent>

                <axis>
                    <xyz>1 0 0</xyz>
                    <limit>
                        <lower>0 </lower>
                        <upper>1.5708 </upper>
                        <effort>2.0 </effort>
                        <velocity>2.0 </velocity>
                    </limit>
                    <dynamics>
                        <damping>0.1</damping>
                        <friction>0</friction>
                        <spring_reference>0</spring_reference>
                        <spring_stiffness>0</spring_stiffness>
                    </dynamics>
                </axis>
            </joint>
        
        <joint name='J4_FF' type="revolute">
            <child>knuckle_FF</child>
            <parent>palm</parent>

            <axis>
                <xyz>0 0.766044 -0.642788</xyz>
                <limit>
                    <lower>-0.349066 </lower>
                    <upper>0.349066 </upper>
                    <effort>2.0 </effort>
                    <velocity>2.0 </velocity>
                </limit>
                <dynamics>
                    <damping>0.1</damping>
                    <friction>0</friction>
                    <spring_reference>0</spring_reference>
                    <spring_stiffness>0</spring_stiffness>
                </dynamics>
            </axis>
        </joint>

    

        <link name = "knuckle_MF">

            <pose frame=''>-0.011000000000000003 0.048636 1.485838 -0.698132 0 0</pose>
            <inertial>
                <pose frame=''>0 0 0 0 0 0</pose>
                <mass>0.008</mass>
                <inertia>
                    <ixx>2.6e-07</ixx>
                    <ixy>0</ixy>
                    <ixz>0</ixz>
                    <iyy>2.6e-07</iyy>
                    <iyz>0</iyz>
                    <izz>3.2e-07</izz>
                </inertia>
            </inertial>

            <visual name='visual_knuckle_link_MF'>

                <geometry>
                    <mesh>
                        <scale>0.001 0.001 0.001</scale>
                        <uri>model://kuka_handlit/meshes/knuckle.dae</uri>
                    </mesh>
                </geometry>
                <material>
                    <ambient>0.32832188218459923 0.8684875833374706 0.15184607959892238 1</ambient>
                    <diffuse>0.7751912177395486 0.8590212019957674 0.21469903273472613 1</diffuse>
                    <specular>0.07026218563821496 0.9391981537420439 0.09842208091993865 1</specular>
                    <emissive>0 0 0 0</emissive>
                </material>
            </visual>
            <collision name='collision_knuckle_link_MF'>
                <geometry>
                <mesh>
                    <scale>0.001 0.001 0.001</scale>
                    <uri>model://kuka_handlit/meshes/knuckle.dae</uri>
                </mesh>
            </geometry>
            </collision>
        </link>
        <link name = "proximal_MF">
            <pose frame=''>-0.011000000000000003 0.048636 1.485838 -0.698132 0 0</pose>
            <inertial>
                <pose frame=''>0 0 0.0225 0 0 0</pose>
                <mass>0.03</mass>
                <inertia>
                    <ixx>9.8e-06</ixx>
                    <ixy>0</ixy>
                    <ixz>0</ixz>
                    <iyy>1.0e-05</iyy>
                    <iyz>0</iyz>
                    <izz>1.8e-06</izz>
                </inertia>
            </inertial>

            <visual name='visual_proximal_link_MF'>

                <geometry>
                    <mesh>
                        <scale>0.001 0.001 0.001</scale>
                        <uri>model://kuka_handlit/meshes/F3.dae</uri>
                    </mesh>
                </geometry>
                <material>
                    <ambient>0.8514597334017195 0.9413721352995671 0.08994362194429562 1</ambient>
                    <diffuse>0.19556852064731123 0.44456573005902644 0.20127162557912315 1</diffuse>
                    <specular>0.9179066008756507 0.19280498268150414 0.5866910001032776 1</specular>
                    <emissive>0 0 0 0</emissive>
                </material>
            </visual>
            <collision name='collision_proximal_link_MF'>
                <geometry>
                <mesh>
                    <scale>0.001 0.001 0.001</scale>
                    <uri>model://kuka_handlit/meshes/F3_c.dae</uri>
                </mesh>
            </geometry>
            </collision>
        </link>
        <link name = "middle_MF">
            <pose frame=''>-0.011000000000000003 0.077526 1.520314 -0.698132 0 0</pose>
            <inertial>
                <pose frame=''>0 0 0.0125 0 0 0</pose>
                <mass>0.017</mass>
                <inertia>
                    <ixx>2.6e-06</ixx>
                    <ixy>0</ixy>
                    <ixz>0</ixz>
                    <iyy>2.7e-06</iyy>
                    <iyz>0</iyz>
                    <izz>8.7e-07</izz>
                </inertia>
            </inertial>

            <visual name='visual_middle_link_MF'>

                <geometry>
                    <mesh>
                        <scale>0.001 0.001 0.001</scale>
                        <uri>model://kuka_handlit/meshes/F2.dae</uri>
                    </mesh>
                </geometry>
                <material>
                    <ambient>0.24274074937167534 0.5359270006593431 0.9729789688588469 1</ambient>
                    <diffuse>0.5143940968495552 0.5473504116417314 0.43495663058856504 1</diffuse>
                    <specular>0.8750635405515448 0.9600799296148403 0.33222910504150815 1</specular>
                    <emissive>0 0 0 0</emissive>
                </material>
            </visual>
            <collision name='collision_middle_link_MF'>
                <geometry>
                    <mesh>
                        <scale>0.001 0.001 0.001</scale>
                        <uri>model://kuka_handlit/meshes/F2_c.dae</uri>
                    </mesh>
                </geometry>
            </collision>
        </link>
        <link name =  "distal_MF">
            <pose frame=''>-0.011000000000000003 0.093596 1.5394649999999999 -0.698132 0 0</pose>
            <inertial>
                <pose frame=''>0 0 0.012 0 0 0</pose>
                <mass>0.012</mass>
                <inertia>
                    <ixx>9.4e-07</ixx>
                    <ixy>0</ixy>
                    <ixz>0</ixz>
                    <iyy>1.1e-06</iyy>
                    <iyz>0</iyz>
                    <izz>5.3e-07</izz>
                </inertia>
            </inertial>

            <visual name='visual_distal_link_MF'>

                <geometry>
                    <mesh>
                        <scale>0.001 0.001 0.001</scale>
                        <uri>model://kuka_handlit/meshes/F1.dae</uri>
                    </mesh>
                </geometry>
                <material>
                    <ambient>0.26879354602754657 0.6954275686516838 0.7983920445238204 1</ambient>
                    <diffuse>0.9390553891330621 0.7449674937333317 0.031952188666983905 1</diffuse>
                    <specular>0.3986551989574538 0.19970972454971447 0.2634123967038272 1</specular>
                    <emissive>0 0 0 0</emissive>
                </material>
            </visual>
            <collision name='collision_distal_link_MF'>
                <geometry>
                    <mesh>
                        <scale>0.001 0.001 0.001</scale>
                        <uri>model://kuka_handlit/meshes/F1.dae</uri>
                    </mesh>
                </geometry>
            </collision>
        </link>

        
            
            <joint name="J3_MF" type="revolute">
                <child>proximal_MF</child>
                <parent>knuckle_MF</parent>

                <axis>
                    <xyz>1 0 0</xyz>
                    <limit>
                        <lower>0 </lower>
                        <upper>1.5708 </upper>
                        <effort>2.0 </effort>
                        <velocity>2.0 </velocity>
                    </limit>
                    <dynamics>
                        <damping>0.1</damping>
                        <friction>0</friction>
                        <spring_reference>0</spring_reference>
                        <spring_stiffness>0</spring_stiffness>
                    </dynamics>
                </axis>
            </joint>
        
            
            <joint name="J2_MF" type="revolute">
                <child>middle_MF</child>
                <parent>proximal_MF</parent>

                <axis>
                    <xyz>1 0 0</xyz>
                    <limit>
                        <lower>0 </lower>
                        <upper>1.5708 </upper>
                        <effort>2.0 </effort>
                        <velocity>2.0 </velocity>
                    </limit>
                    <dynamics>
                        <damping>0.1</damping>
                        <friction>0</friction>
                        <spring_reference>0</spring_reference>
                        <spring_stiffness>0</spring_stiffness>
                    </dynamics>
                </axis>
            </joint>
        
            
            <joint name="J1_MF" type="revolute">
                <child>distal_MF</child>
                <parent>middle_MF</parent>

                <axis>
                    <xyz>1 0 0</xyz>
                    <limit>
                        <lower>0 </lower>
                        <upper>1.5708 </upper>
                        <effort>2.0 </effort>
                        <velocity>2.0 </velocity>
                    </limit>
                    <dynamics>
                        <damping>0.1</damping>
                        <friction>0</friction>
                        <spring_reference>0</spring_reference>
                        <spring_stiffness>0</spring_stiffness>
                    </dynamics>
                </axis>
            </joint>
        
        <joint name='J4_MF' type="revolute">
            <child>knuckle_MF</child>
            <parent>palm</parent>

            <axis>
                <xyz>0 0.766044 -0.642788</xyz>
                <limit>
                    <lower>-0.349066 </lower>
                    <upper>0.349066 </upper>
                    <effort>2.0 </effort>
                    <velocity>2.0 </velocity>
                </limit>
                <dynamics>
                    <damping>0.1</damping>
                    <friction>0</friction>
                    <spring_reference>0</spring_reference>
                    <spring_stiffness>0</spring_stiffness>
                </dynamics>
            </axis>
        </joint>

    

        <link name = "knuckle_RF">

            <pose frame=''>0.010999999999999996 0.0461 1.48277 -0.698132 0 0</pose>
            <inertial>
                <pose frame=''>0 0 0 0 0 0</pose>
                <mass>0.008</mass>
                <inertia>
                    <ixx>2.6e-07</ixx>
                    <ixy>0</ixy>
                    <ixz>0</ixz>
                    <iyy>2.6e-07</iyy>
                    <iyz>0</iyz>
                    <izz>3.2e-07</izz>
                </inertia>
            </inertial>

            <visual name='visual_knuckle_link_RF'>

                <geometry>
                    <mesh>
                        <scale>0.001 0.001 0.001</scale>
                        <uri>model://kuka_handlit/meshes/knuckle.dae</uri>
                    </mesh>
                </geometry>
                <material>
                    <ambient>0.6996327493005227 0.33794539540288593 0.8369380417873546 1</ambient>
                    <diffuse>0.43802441021012084 0.3410924622081867 0.5681417519615644 1</diffuse>
                    <specular>0.36273809220092446 0.15027394800236338 0.261741413503112 1</specular>
                    <emissive>0 0 0 0</emissive>
                </material>
            </visual>
            <collision name='collision_knuckle_link_RF'>
                <geometry>
                <mesh>
                    <scale>0.001 0.001 0.001</scale>
                    <uri>model://kuka_handlit/meshes/knuckle.dae</uri>
                </mesh>
            </geometry>
            </collision>
        </link>
        <link name = "proximal_RF">
            <pose frame=''>0.010999999999999996 0.0461 1.48277 -0.698132 0 0</pose>
            <inertial>
                <pose frame=''>0 0 0.0225 0 0 0</pose>
                <mass>0.03</mass>
                <inertia>
                    <ixx>9.8e-06</ixx>
                    <ixy>0</ixy>
                    <ixz>0</ixz>
                    <iyy>1.0e-05</iyy>
                    <iyz>0</iyz>
                    <izz>1.8e-06</izz>
                </inertia>
            </inertial>

            <visual name='visual_proximal_link_RF'>

                <geometry>
                    <mesh>
                        <scale>0.001 0.001 0.001</scale>
                        <uri>model://kuka_handlit/meshes/F3.dae</uri>
                    </mesh>
                </geometry>
                <material>
                    <ambient>0.2011113630725736 0.4716752660343909 0.10582904653873892 1</ambient>
                    <diffuse>0.709510260253819 0.9826679656579393 0.6971163698573098 1</diffuse>
                    <specular>0.12394437772429356 0.7595812208488011 0.512683967017382 1</specular>
                    <emissive>0 0 0 0</emissive>
                </material>
            </visual>
            <collision name='collision_proximal_link_RF'>
                <geometry>
                <mesh>
                    <scale>0.001 0.001 0.001</scale>
                    <uri>model://kuka_handlit/meshes/F3_c.dae</uri>
                </mesh>
            </geometry>
            </collision>
        </link>
        <link name = "middle_RF">
            <pose frame=''>0.010999999999999996 0.07499 1.5172459999999999 -0.698132 0 0</pose>
            <inertial>
                <pose frame=''>0 0 0.0125 0 0 0</pose>
                <mass>0.017</mass>
                <inertia>
                    <ixx>2.6e-06</ixx>
                    <ixy>0</ixy>
                    <ixz>0</ixz>
                    <iyy>2.7e-06</iyy>
                    <iyz>0</iyz>
                    <izz>8.7e-07</izz>
                </inertia>
            </inertial>

            <visual name='visual_middle_link_RF'>

                <geometry>
                    <mesh>
                        <scale>0.001 0.001 0.001</scale>
                        <uri>model://kuka_handlit/meshes/F2.dae</uri>
                    </mesh>
                </geometry>
                <material>
                    <ambient>0.18021091145247603 0.8105457059195863 0.07137988878601609 1</ambient>
                    <diffuse>0.11267175775309601 0.3350615610848482 0.806080036805263 1</diffuse>
                    <specular>0.879294423490857 0.6326933383809674 0.2680753253138255 1</specular>
                    <emissive>0 0 0 0</emissive>
                </material>
            </visual>
            <collision name='collision_middle_link_RF'>
                <geometry>
                    <mesh>
                        <scale>0.001 0.001 0.001</scale>
                        <uri>model://kuka_handlit/meshes/F2_c.dae</uri>
                    </mesh>
                </geometry>
            </collision>
        </link>
        <link name =  "distal_RF">
            <pose frame=''>0.010999999999999996 0.09106 1.5363969999999998 -0.698132 0 0</pose>
            <inertial>
                <pose frame=''>0 0 0.012 0 0 0</pose>
                <mass>0.012</mass>
                <inertia>
                    <ixx>9.4e-07</ixx>
                    <ixy>0</ixy>
                    <ixz>0</ixz>
                    <iyy>1.1e-06</iyy>
                    <iyz>0</iyz>
                    <izz>5.3e-07</izz>
                </inertia>
            </inertial>

            <visual name='visual_distal_link_RF'>

                <geometry>
                    <mesh>
                        <scale>0.001 0.001 0.001</scale>
                        <uri>model://kuka_handlit/meshes/F1.dae</uri>
                    </mesh>
                </geometry>
                <material>
                    <ambient>0.8552281155392998 0.48488911071897434 0.6591241515099736 1</ambient>
                    <diffuse>0.05712956790321677 0.43571350570723666 0.18314883266111948 1</diffuse>
                    <specular>0.7761439493616845 0.2715453432681173 0.5713412914820473 1</specular>
                    <emissive>0 0 0 0</emissive>
                </material>
            </visual>
            <collision name='collision_distal_link_RF'>
                <geometry>
                    <mesh>
                        <scale>0.001 0.001 0.001</scale>
                        <uri>model://kuka_handlit/meshes/F1.dae</uri>
                    </mesh>
                </geometry>
            </collision>
        </link>

        
            
            <joint name="J3_RF" type="revolute">
                <child>proximal_RF</child>
                <parent>knuckle_RF</parent>

                <axis>
                    <xyz>1 0 0</xyz>
                    <limit>
                        <lower>0 </lower>
                        <upper>1.5708 </upper>
                        <effort>2.0 </effort>
                        <velocity>2.0 </velocity>
                    </limit>
                    <dynamics>
                        <damping>0.1</damping>
                        <friction>0</friction>
                        <spring_reference>0</spring_reference>
                        <spring_stiffness>0</spring_stiffness>
                    </dynamics>
                </axis>
            </joint>
        
            
            <joint name="J2_RF" type="revolute">
                <child>middle_RF</child>
                <parent>proximal_RF</parent>

                <axis>
                    <xyz>1 0 0</xyz>
                    <limit>
                        <lower>0 </lower>
                        <upper>1.5708 </upper>
                        <effort>2.0 </effort>
                        <velocity>2.0 </velocity>
                    </limit>
                    <dynamics>
                        <damping>0.1</damping>
                        <friction>0</friction>
                        <spring_reference>0</spring_reference>
                        <spring_stiffness>0</spring_stiffness>
                    </dynamics>
                </axis>
            </joint>
        
            
            <joint name="J1_RF" type="revolute">
                <child>distal_RF</child>
                <parent>middle_RF</parent>

                <axis>
                    <xyz>1 0 0</xyz>
                    <limit>
                        <lower>0 </lower>
                        <upper>1.5708 </upper>
                        <effort>2.0 </effort>
                        <velocity>2.0 </velocity>
                    </limit>
                    <dynamics>
                        <damping>0.1</damping>
                        <friction>0</friction>
                        <spring_reference>0</spring_reference>
                        <spring_stiffness>0</spring_stiffness>
                    </dynamics>
                </axis>
            </joint>
        
        <joint name='J4_RF' type="revolute">
            <child>knuckle_RF</child>
            <parent>palm</parent>

            <axis>
                <xyz>0 0.766044 -0.642788</xyz>
                <limit>
                    <lower>-0.349066 </lower>
                    <upper>0.349066 </upper>
                    <effort>2.0 </effort>
                    <velocity>2.0 </velocity>
                </limit>
                <dynamics>
                    <damping>0.1</damping>
                    <friction>0</friction>
                    <spring_reference>0</spring_reference>
                    <spring_stiffness>0</spring_stiffness>
                </dynamics>
            </axis>
        </joint>

    


    <link name = "thbase">
        <pose frame=''>-0.034 -0.0028710000000000003 1.437679 0.870557 0.572429 -2.5703</pose>
        <inertial>
            <pose frame=''>0 0 0 0 0 0</pose>
            <mass>0.01</mass>
            <inertia>
                <ixx>1.6e-07</ixx>
                <ixy>0</ixy>
                <ixz>0</ixz>
                <iyy>1.6e-07</iyy>
                <iyz>0</iyz>
                <izz>1.6e-07</izz>
            </inertia>
        </inertial>
        <visual name='visual_thbase_link'>
            
            <geometry>
                <box>
                    <size>0.001 0.001 0.001</size>
                </box>
            </geometry>
            <material>
                <ambient>0.9233161954941578 0.19255435149772182 0.43698304271869526 1</ambient>
                <diffuse>0.08640551464812352 0.6136688565300998 0.4091863885306588 1</diffuse>
                <specular>0.2455490593133215 0.5318489990990981 0.7088420217836128 1</specular>
                <emissive>0 0 0 0</emissive>
            </material>
        </visual>
        <collision name='collision_thbase_link'>
            <pose frame=''>0 0 0 0 0 0</pose>
            <geometry>

                <sphere>
                    <radius>0.011</radius>
                </sphere>
            
            </geometry>
        </collision>
    </link>
    <link name = "thproximal">
            
        <pose frame=''>-0.034 -0.0028710000000000003 1.437679 0.870557 0.572429 -2.5703</pose>
        <inertial>
            <pose frame=''>0 0 0.021111 0 0 0</pose>
            <mass>0.04</mass>
            <inertia>
                <ixx>1.36e-05</ixx>
                <ixy>0</ixy>
                <ixz>0</ixz>
                <iyy>1.36e-05</iyy>
                <iyz>0</iyz>
                <izz>3.13e-06</izz>
            </inertia>
        </inertial>

        <visual name='visual_thproximal_link'>
            
            <geometry>
                <mesh>
                    <scale>0.001 0.001 0.001</scale>
                    <uri>model://kuka_handlit/meshes/TH3_z.dae</uri>
                </mesh>
            </geometry>
            <material>
                <ambient>0.9885875819664195 0.19347181247001333 0.5470571334644431 1</ambient>
                <diffuse>0.6411548296998965 0.9104824461693585 0.5135078025133158 1</diffuse>
                <specular>0.19604058018715487 0.5304961406430565 0.12298241091509621 1</specular>
                <emissive>0 0 0 0</emissive>
            </material>
        </visual>
        <collision name='collision_thproximal_link'>
            <geometry>
                <mesh>
                    <scale>0.001 0.001 0.001</scale>
                    <uri>model://kuka_handlit/meshes/TH3_z_c.dae</uri>
                </mesh>
            </geometry>
        </collision>
    </link>
    <link name = "thhub">
        <pose frame=''>-0.06087000000000001 0.014400999999999999 1.4582629999999999 0.870557 0.572429 -2.5703</pose>
        <inertial>
            <pose frame=''>0 0 0 0 0 0</pose>
            <mass>0.005</mass>
            <inertia>
                <ixx>1.0e-06</ixx>
                <ixy>0</ixy>
                <ixz>0</ixz>
                <iyy>1.0e-06</iyy>
                <iyz>0</iyz>
                <izz>3.0e-07</izz>
            </inertia>
        </inertial>
        <visual name='visual_thhub_link'>
            
            <geometry>
                <box>
                    <size>0.001 0.001 0.001</size>
                </box>
            </geometry>
            <material>

            </material>
        </visual>
        <collision name='collision_thhub_link'>
            <geometry>
                <box>
                    <size>0.001 0.001 0.001</size>
                </box>
            </geometry>
        </collision>
    </link>
    <link name = "thmiddle">
            
        <pose frame=''>-0.06087000000000001 0.014400999999999999 1.4582629999999999 0.870557 0.572429 -2.5703</pose>
        <inertial>
            <pose frame=''>0 0 0.16 0 0 0</pose>
            <mass>0.02</mass>
            <inertia>
                <ixx>5.1e-06</ixx>
                <ixy>0</ixy>
                <ixz>0</ixz>
                <iyy>5.1e-06</iyy>
                <iyz>0</iyz>
                <izz>1.21e-06</izz>
            </inertia>
        </inertial>

        <visual name='visual_thmiddle_link'>
            
            <geometry>
                <mesh>
                    <scale>0.001 0.001 0.001</scale>
                    <uri>model://kuka_handlit/meshes/TH2_z.dae</uri>
                </mesh>
            </geometry>
            <material>
                <ambient>0.4870884715045316 0.5025621237804445 0.4889831247770795 1</ambient>
                <diffuse>0.10668218066130908 0.10450688031217514 0.34028534665345556 1</diffuse>
                <specular>0.9903214934573421 0.2138545146300811 0.9461785581314955 1</specular>
                <emissive>0 0 0 0</emissive>
            </material>
        </visual>

        <collision name='collision_thmiddle_link'>
            <geometry>
                <mesh>
                    <scale>0.001 0.001 0.001</scale>
                    <uri>model://kuka_handlit/meshes/TH2_z_c.dae</uri>
                </mesh>
            </geometry>
        </collision>
    </link>
    <link name = "thdistal">
            
        <pose frame=''>-0.083498 0.028946 1.475596 -0.785398 0.698132 1.5707999999999998</pose>
        <inertial>
            <pose frame=''>0 0 0.014559 0 0 0</pose>
            <mass>0.016</mass>
            <inertia>
                <ixx>2.1e-06</ixx>
                <ixy>0</ixy>
                <ixz>0</ixz>
                <iyy>2.2e-06</iyy>
                <iyz>0</iyz>
                <izz>1.0e-06</izz>
            </inertia>
        </inertial>

        <visual name='visual_thdistal_link'>
            
            <geometry>
                <mesh>
                    <scale>0.001 0.001 0.001</scale>
                    <uri>model://kuka_handlit/meshes/TH1_z.dae</uri>
                </mesh>
            </geometry>
            <material>
                <ambient>0.0030119421578879146 0.5027280366880262 0.03767026437181653 1</ambient>
                <diffuse>0.6607950277180347 0.7968537151200282 0.9028552695291555 1</diffuse>
                <specular>0.9420831271640815 0.6423097928201842 0.4098024872078537 1</specular>
                <emissive>0 0 0 0</emissive>
            </material>
        </visual>
        <collision name='collision_thdistal_link'>
            <geometry>
                <mesh>
                    <scale>0.001 0.001 0.001</scale>
                    <uri>model://kuka_handlit/meshes/TH1_z.dae</uri>
                </mesh>
            </geometry>
        </collision>
    </link>

    
        <joint name ="THJ5"  type ="revolute">
            <child>thbase</child>
            <parent>palm</parent>
            <axis>
                <xyz>0 0 0.541675</xyz>
                <limit>
                    <lower>-1.0472 </lower>
                    <upper>1.0472 </upper>
                    <effort>5.0 </effort>
                    <velocity>4.0 </velocity>
                </limit>
                <dynamics>
                    <damping>0.2</damping>
                    <friction>0</friction>
                </dynamics>
            </axis>
        </joint>
    
        <joint name ="THJ4"  type ="revolute">
            <child>thproximal</child>
            <parent>thbase</parent>
            <axis>
                <xyz>-0.707107 -0.454519 -0.541675</xyz>
                <limit>
                    <lower>0 </lower>
                    <upper>1.22173 </upper>
                    <effort>3.0 </effort>
                    <velocity>4.0 </velocity>
                </limit>
                <dynamics>
                    <damping>0.2</damping>
                    <friction>0</friction>
                </dynamics>
            </axis>
        </joint>
    
        <joint name ="THJ2"  type ="revolute">
            <child>thmiddle</child>
            <parent>thhub</parent>
            <axis>
                <xyz>0 -0.766044 0.642788</xyz>
                <limit>
                    <lower>-0.698132 </lower>
                    <upper>0.698132 </upper>
                    <effort>2.0 </effort>
                    <velocity>2.0 </velocity>
                </limit>
                <dynamics>
                    <damping>0.1</damping>
                    <friction>0</friction>
                </dynamics>
            </axis>
        </joint>
    
        <joint name ="THJ1"  type ="revolute">
            <child>thdistal</child>
            <parent>thmiddle</parent>
            <axis>
                <xyz>0 -0.766044 0.642788</xyz>
                <limit>
                    <lower>0 </lower>
                    <upper>1.5708 </upper>
                    <effort>1.0 </effort>
                    <velocity>4.0 </velocity>
                </limit>
                <dynamics>
                    <damping>0.2</damping>
                    <friction>0</friction>
                </dynamics>
            </axis>
        </joint>
    
    <joint name ="THJ3"  type ="fixed">
        <child>thhub</child>
        <parent>thproximal</parent>
        <axis>
            <xyz>1 0 0</xyz>
        </axis>
    </joint>






 
   
  </model>

</sdf>