<?xml version="1.0" ?>



<sdf version='1.6'>
  <model name="handlit">
    <!--KUKA-->
    <link name = "world">
        <pose frame=''>0 0 0 0 0 0</pose>
        <inertial>
            <pose frame=''>0 0 0.0 0 0 0</pose>
            <mass>0.0</mass>
            <inertia>
                <ixx>0.</ixx>
                <ixy>0</ixy>
                <ixz>0</ixz>
                <iyy>0.</iyy>
                <iyz>0</iyz>
                <izz>0.</izz>
            </inertia>
        </inertial>
    </link>


    <joint name="forearm_world" type="fixed">
        <child>forearm</child>
        <parent>world</parent>
    </joint>

    <link name ="forearm" >
        <pose frame=''>0 0 0 0 0 1.5707963267948966</pose>
        <inertial>
            <pose frame=''>0 0 0.09 0 0 0</pose>
            <mass>1.8</mass>
            <inertia>
                <ixx>0.108</ixx>
                <ixy>0</ixy>
                <ixz>0</ixz>
                <iyy>0.108</iyy>
                <iyz>0</iyz>
                <izz>0.054</izz>
            </inertia>
        </inertial>

        <visual name='visual_forearm_link'>

            <geometry>
                <mesh>
                    <scale>1 1 1</scale>
                    <uri>./meshes/forearm_lite.dae</uri>
                </mesh>
            </geometry>
            <material>
                <ambient>0.7262728352470186 0.9630018479128702 0.5550995273483169 1</ambient>
                <diffuse>0.7285081224474094 0.0489147894388845 0.9172236295886759 1</diffuse>
                <specular>0.9874888870209391 0.050483865732168565 0.7597486349641824 1</specular>
                <emissive>0 0 0 0</emissive>
            </material>
        </visual>

    </link>

    <link name = "palm">
        <pose frame=''>0 -0.015 0.149 -0.6981317007977318 0 0</pose>
        <inertial>
            <pose frame=''>0 0 0.035 0 0 0</pose>
            <mass>0.3</mass>
            <inertia>
                <ixx>0.0003581</ixx>
                <ixy>0</ixy>
                <ixz>0</ixz>
                <iyy>0.0005287</iyy>
                <iyz>0</iyz>
                <izz>0.000191</izz>
            </inertia>
        </inertial>
        
        <visual name='visual_palm_link'>

            <geometry>
                <mesh>
                    <scale>-0.001 0.001 0.001</scale>
                    <uri>./meshes/palm2.dae</uri>
                </mesh>
            </geometry>
            <material>
                <ambient>0.756992461430815 0.6963768967082823 0.6315675635941309 1</ambient>
                <diffuse>0.3012094192880974 0.8175141738638875 0.2895638741375065 1</diffuse>
                <specular>0.9621979076843282 0.2545013848063594 0.7049418110603994 1</specular>
                <emissive>0 0 0 0</emissive>
            </material>
        </visual>
 


        
    </link>
    <joint name="palm_forearm" type="fixed">
        <child>palm</child>
        <parent>forearm</parent>
        <axis>

            <xyz>0 -1 0</xyz>
         </axis>
    </joint>  

    
    <link name = "palm_fake">

        <pose frame=''>-0.01 0.020909000000000004 0.1889 -0.6981317007977318 0 0</pose>
        <inertial>
            <pose frame=''>0 0 0.0 0 0 0</pose>
            <mass>0.0</mass>
            <inertia>
                <ixx>0.0</ixx>
                <ixy>0</ixy>
                <ixz>0</ixz>
                <iyy>0.0</iyy>
                <iyz>0</iyz>
                <izz>0.0</izz>
            </inertia>
        </inertial>
            <visual name='visual_palm_fake'>
                <geometry>
                    <sphere>
                    <radius>0.01</radius>
                    </sphere>
                </geometry>
                <material>
                    <ambient>0.5672216218105076 0.531815859282997 0.5801439037594547 1</ambient>
                    <diffuse>0.5464167892541046 0.6932951350253517 0.22253023363722557 1</diffuse>
                    <specular>0.9022550019258972 0.9029306286118689 0.5969458319897258 1</specular>
                    <emissive>0 0 0 0</emissive>
                </material>
            </visual>
    </link>

    <joint name="palm_palm_fake" type="fixed">
        <child>palm_fake</child>
        <parent>palm</parent>
        <axis>

            <xyz>0 -1 0</xyz>
         </axis>
    </joint>  
    

    
    

        <link name = "knuckle_FF">

            <pose frame=''>-0.033 0.0461 0.22177 -0.698132 0 0</pose>
            <inertial>
                <pose frame=''>0 0 0 0 0 0</pose>
                <mass>0.008</mass>
                <inertia>
                    <ixx>2.6e-07</ixx>
                    <ixy>0</ixy>
                    <ixz>0</ixz>
                    <iyy>2.6e-07</iyy>
                    <iyz>0</iyz>
                    <izz>3.2e-07</izz>
                </inertia>
            </inertial>

            <visual name='visual_knuckle_link_FF'>

                <geometry>
                    <mesh>
                        <scale>0.001 0.001 0.001</scale>
                        <uri>./meshes/knuckle.dae</uri>
                    </mesh>
                </geometry>
                <material>
                    <ambient>0.09407520250441792 0.12965760398002069 0.9394012346218648 1</ambient>
                    <diffuse>0.16768404289197747 0.3405418254873156 0.8785487303636916 1</diffuse>
                    <specular>0.9191282335906747 0.7468205272225454 0.4435948623083946 1</specular>
                    <emissive>0 0 0 0</emissive>
                </material>
            </visual>
            <collision name='collision_knuckle_link_FF'>
                <geometry>
                <mesh>
                    <scale>0.00050 0.00050 0.00050</scale>
                    <uri>./meshes/knuckle.dae</uri>
                </mesh>
            </geometry>
            </collision>
        </link>
        <link name = "proximal_FF">
            <pose frame=''>-0.033 0.0461 0.22177 -0.698132 0 0</pose>
            <inertial>
                <pose frame=''>0 0 0.0225 0 0 0</pose>
                <mass>0.03</mass>
                <inertia>
                    <ixx>9.8e-06</ixx>
                    <ixy>0</ixy>
                    <ixz>0</ixz>
                    <iyy>1.0e-05</iyy>
                    <iyz>0</iyz>
                    <izz>1.8e-06</izz>
                </inertia>
            </inertial>

            <visual name='visual_proximal_link_FF'>

                <geometry>
                    <mesh>
                        <scale>0.001 0.001 0.001</scale>
                        <uri>./meshes/F3.dae</uri>
                    </mesh>
                </geometry>
                <material>
                    <ambient>0.5580302989348269 0.4149394261623952 0.2901549919536418 1</ambient>
                    <diffuse>0.949367562297506 0.5273284567253377 0.8379829134045444 1</diffuse>
                    <specular>0.3961561409073694 0.6658423273807648 0.4215118362594732 1</specular>
                    <emissive>0 0 0 0</emissive>
                </material>
            </visual>
            <collision name='collision_proximal_link_FF'>
                <geometry>
                <mesh>
                    <scale>0.001 0.001 0.001</scale>
                    <uri>./meshes/F3_c.dae</uri>
                </mesh>
            </geometry>
            </collision>
        </link>
        <link name = "middle_FF">
            <pose frame=''>-0.033 0.07499 0.256246 -0.698132 0 0</pose>
            <inertial>
                <pose frame=''>0 0 0.0125 0 0 0</pose>
                <mass>0.017</mass>
                <inertia>
                    <ixx>2.6e-06</ixx>
                    <ixy>0</ixy>
                    <ixz>0</ixz>
                    <iyy>2.7e-06</iyy>
                    <iyz>0</iyz>
                    <izz>8.7e-07</izz>
                </inertia>
            </inertial>

            <visual name='visual_middle_link_FF'>

                <geometry>
                    <mesh>
                        <scale>0.001 0.001 0.001</scale>
                        <uri>./meshes/F2.dae</uri>
                    </mesh>
                </geometry>
                <material>
                    <ambient>0.5196700265517784 0.47529252526511 0.2853952377173713 1</ambient>
                    <diffuse>0.7344088914894362 0.08144753246258374 0.8889698403929757 1</diffuse>
                    <specular>0.6588770772391106 0.4764735692768408 0.20281260684941238 1</specular>
                    <emissive>0 0 0 0</emissive>
                </material>
            </visual>
            <collision name='collision_middle_link_FF'>
                <geometry>
                    <mesh>
                        <scale>0.001 0.001 0.001</scale>
                        <uri>./meshes/F2_c.dae</uri>
                    </mesh>
                </geometry>
            </collision>
        </link>
        <link name =  "distal_FF">
            <pose frame=''>-0.033 0.09106 0.275397 -0.698132 0 0</pose>
            <inertial>
                <pose frame=''>0 0 0.012 0 0 0</pose>
                <mass>0.012</mass>
                <inertia>
                    <ixx>9.4e-07</ixx>
                    <ixy>0</ixy>
                    <ixz>0</ixz>
                    <iyy>1.1e-06</iyy>
                    <iyz>0</iyz>
                    <izz>5.3e-07</izz>
                </inertia>
            </inertial>

            <visual name='visual_distal_link_FF'>

                <geometry>
                    <mesh>
                        <scale>0.001 0.001 0.001</scale>
                        <uri>./meshes/F1.dae</uri>
                    </mesh>
                </geometry>
                <material>
                    <ambient>0.6478272464434638 0.43749567448934223 0.2811406469865171 1</ambient>
                    <diffuse>0.8855197474415111 0.14586890855418722 0.7173680513785259 1</diffuse>
                    <specular>0.2644720153818466 0.5434917154478641 0.7328010810322433 1</specular>
                    <emissive>0 0 0 0</emissive>
                </material>
            </visual>
            <collision name='collision_distal_link_FF'>
                <geometry>
                    <mesh>
                        <scale>0.001 0.001 0.001</scale>
                        <uri>./meshes/F1.dae</uri>
                    </mesh>
                </geometry>
            </collision>
        </link>

        
            
            <joint name="J3_FF" type="revolute">
                <child>proximal_FF</child>
                <parent>knuckle_FF</parent>

                <axis>
                    <xyz>1 0 0</xyz>
                    <limit>
                        <lower>0 </lower>
                        <upper>1.5708 </upper>
                        <effort>6.0 </effort>
                        <velocity>0.8 </velocity>
                    </limit>
                    <dynamics>
                        <damping>0.1</damping>
                        <friction>0</friction>
                        <spring_reference>0</spring_reference>
                        <spring_stiffness>0</spring_stiffness>
                    </dynamics>
                </axis>
            </joint>
        
            
            <joint name="J2_FF" type="revolute">
                <child>middle_FF</child>
                <parent>proximal_FF</parent>

                <axis>
                    <xyz>1 0 0</xyz>
                    <limit>
                        <lower>0 </lower>
                        <upper>1.5708 </upper>
                        <effort>6.0 </effort>
                        <velocity>0.8 </velocity>
                    </limit>
                    <dynamics>
                        <damping>0.1</damping>
                        <friction>0</friction>
                        <spring_reference>0</spring_reference>
                        <spring_stiffness>0</spring_stiffness>
                    </dynamics>
                </axis>
            </joint>
        
            
            <joint name="J1_FF" type="revolute">
                <child>distal_FF</child>
                <parent>middle_FF</parent>

                <axis>
                    <xyz>1 0 0</xyz>
                    <limit>
                        <lower>0 </lower>
                        <upper>1.5708 </upper>
                        <effort>6.0 </effort>
                        <velocity>0.8 </velocity>
                    </limit>
                    <dynamics>
                        <damping>0.1</damping>
                        <friction>0</friction>
                        <spring_reference>0</spring_reference>
                        <spring_stiffness>0</spring_stiffness>
                    </dynamics>
                </axis>
            </joint>
        
        <joint name='J4_FF' type="revolute">
            <child>knuckle_FF</child>
            <parent>palm</parent>

            <axis>
                <xyz>0 0.766044 -0.642788</xyz>
                <limit>
                    <lower>-0.349066 </lower>
                    <upper>0.349066 </upper>
                    <effort>6.0 </effort>
                    <velocity>0.8 </velocity>
                </limit>
                <dynamics>
                    <damping>0.1</damping>
                    <friction>0</friction>
                    <spring_reference>0</spring_reference>
                    <spring_stiffness>0</spring_stiffness>
                </dynamics>
            </axis>
        </joint>

    

        <link name = "knuckle_MF">

            <pose frame=''>-0.011000000000000003 0.048636 0.22483799999999998 -0.698132 0 0</pose>
            <inertial>
                <pose frame=''>0 0 0 0 0 0</pose>
                <mass>0.008</mass>
                <inertia>
                    <ixx>2.6e-07</ixx>
                    <ixy>0</ixy>
                    <ixz>0</ixz>
                    <iyy>2.6e-07</iyy>
                    <iyz>0</iyz>
                    <izz>3.2e-07</izz>
                </inertia>
            </inertial>

            <visual name='visual_knuckle_link_MF'>

                <geometry>
                    <mesh>
                        <scale>0.001 0.001 0.001</scale>
                        <uri>./meshes/knuckle.dae</uri>
                    </mesh>
                </geometry>
                <material>
                    <ambient>0.7125130886006963 0.18710431020304097 0.2846148290382795 1</ambient>
                    <diffuse>0.768627251939468 0.9596376211332945 0.7125451051644497 1</diffuse>
                    <specular>0.17576998478385641 0.34933913811230355 0.29454558782556584 1</specular>
                    <emissive>0 0 0 0</emissive>
                </material>
            </visual>
            <collision name='collision_knuckle_link_MF'>
                <geometry>
                <mesh>
                    <scale>0.00050 0.00050 0.00050</scale>
                    <uri>./meshes/knuckle.dae</uri>
                </mesh>
            </geometry>
            </collision>
        </link>
        <link name = "proximal_MF">
            <pose frame=''>-0.011000000000000003 0.048636 0.22483799999999998 -0.698132 0 0</pose>
            <inertial>
                <pose frame=''>0 0 0.0225 0 0 0</pose>
                <mass>0.03</mass>
                <inertia>
                    <ixx>9.8e-06</ixx>
                    <ixy>0</ixy>
                    <ixz>0</ixz>
                    <iyy>1.0e-05</iyy>
                    <iyz>0</iyz>
                    <izz>1.8e-06</izz>
                </inertia>
            </inertial>

            <visual name='visual_proximal_link_MF'>

                <geometry>
                    <mesh>
                        <scale>0.001 0.001 0.001</scale>
                        <uri>./meshes/F3.dae</uri>
                    </mesh>
                </geometry>
                <material>
                    <ambient>0.19820436975125366 0.25920801970608354 0.5879243872337925 1</ambient>
                    <diffuse>0.18413144283958716 0.967770569288885 0.38687176685086977 1</diffuse>
                    <specular>0.4198032553763873 0.7067362772243273 0.6496441471600752 1</specular>
                    <emissive>0 0 0 0</emissive>
                </material>
            </visual>
            <collision name='collision_proximal_link_MF'>
                <geometry>
                <mesh>
                    <scale>0.001 0.001 0.001</scale>
                    <uri>./meshes/F3_c.dae</uri>
                </mesh>
            </geometry>
            </collision>
        </link>
        <link name = "middle_MF">
            <pose frame=''>-0.011000000000000003 0.077526 0.259314 -0.698132 0 0</pose>
            <inertial>
                <pose frame=''>0 0 0.0125 0 0 0</pose>
                <mass>0.017</mass>
                <inertia>
                    <ixx>2.6e-06</ixx>
                    <ixy>0</ixy>
                    <ixz>0</ixz>
                    <iyy>2.7e-06</iyy>
                    <iyz>0</iyz>
                    <izz>8.7e-07</izz>
                </inertia>
            </inertial>

            <visual name='visual_middle_link_MF'>

                <geometry>
                    <mesh>
                        <scale>0.001 0.001 0.001</scale>
                        <uri>./meshes/F2.dae</uri>
                    </mesh>
                </geometry>
                <material>
                    <ambient>0.7010262206638123 0.18515605669661606 0.11193464518181806 1</ambient>
                    <diffuse>0.9338915669426122 0.9520148070710004 0.2935727249902498 1</diffuse>
                    <specular>0.8001825267735424 0.01220977706039772 0.7117158600673533 1</specular>
                    <emissive>0 0 0 0</emissive>
                </material>
            </visual>
            <collision name='collision_middle_link_MF'>
                <geometry>
                    <mesh>
                        <scale>0.001 0.001 0.001</scale>
                        <uri>./meshes/F2_c.dae</uri>
                    </mesh>
                </geometry>
            </collision>
        </link>
        <link name =  "distal_MF">
            <pose frame=''>-0.011000000000000003 0.093596 0.27846499999999996 -0.698132 0 0</pose>
            <inertial>
                <pose frame=''>0 0 0.012 0 0 0</pose>
                <mass>0.012</mass>
                <inertia>
                    <ixx>9.4e-07</ixx>
                    <ixy>0</ixy>
                    <ixz>0</ixz>
                    <iyy>1.1e-06</iyy>
                    <iyz>0</iyz>
                    <izz>5.3e-07</izz>
                </inertia>
            </inertial>

            <visual name='visual_distal_link_MF'>

                <geometry>
                    <mesh>
                        <scale>0.001 0.001 0.001</scale>
                        <uri>./meshes/F1.dae</uri>
                    </mesh>
                </geometry>
                <material>
                    <ambient>0.5675894914568435 0.9702765601542112 0.8559400630124562 1</ambient>
                    <diffuse>0.4333880611289851 0.8894486920056953 0.42083751125393 1</diffuse>
                    <specular>0.45420380758093826 0.09926853880580144 0.42808096203631907 1</specular>
                    <emissive>0 0 0 0</emissive>
                </material>
            </visual>
            <collision name='collision_distal_link_MF'>
                <geometry>
                    <mesh>
                        <scale>0.001 0.001 0.001</scale>
                        <uri>./meshes/F1.dae</uri>
                    </mesh>
                </geometry>
            </collision>
        </link>

        
            
            <joint name="J3_MF" type="revolute">
                <child>proximal_MF</child>
                <parent>knuckle_MF</parent>

                <axis>
                    <xyz>1 0 0</xyz>
                    <limit>
                        <lower>0 </lower>
                        <upper>1.5708 </upper>
                        <effort>6.0 </effort>
                        <velocity>0.8 </velocity>
                    </limit>
                    <dynamics>
                        <damping>0.1</damping>
                        <friction>0</friction>
                        <spring_reference>0</spring_reference>
                        <spring_stiffness>0</spring_stiffness>
                    </dynamics>
                </axis>
            </joint>
        
            
            <joint name="J2_MF" type="revolute">
                <child>middle_MF</child>
                <parent>proximal_MF</parent>

                <axis>
                    <xyz>1 0 0</xyz>
                    <limit>
                        <lower>0 </lower>
                        <upper>1.5708 </upper>
                        <effort>6.0 </effort>
                        <velocity>0.8 </velocity>
                    </limit>
                    <dynamics>
                        <damping>0.1</damping>
                        <friction>0</friction>
                        <spring_reference>0</spring_reference>
                        <spring_stiffness>0</spring_stiffness>
                    </dynamics>
                </axis>
            </joint>
        
            
            <joint name="J1_MF" type="revolute">
                <child>distal_MF</child>
                <parent>middle_MF</parent>

                <axis>
                    <xyz>1 0 0</xyz>
                    <limit>
                        <lower>0 </lower>
                        <upper>1.5708 </upper>
                        <effort>6.0 </effort>
                        <velocity>0.8 </velocity>
                    </limit>
                    <dynamics>
                        <damping>0.1</damping>
                        <friction>0</friction>
                        <spring_reference>0</spring_reference>
                        <spring_stiffness>0</spring_stiffness>
                    </dynamics>
                </axis>
            </joint>
        
        <joint name='J4_MF' type="revolute">
            <child>knuckle_MF</child>
            <parent>palm</parent>

            <axis>
                <xyz>0 0.766044 -0.642788</xyz>
                <limit>
                    <lower>-0.349066 </lower>
                    <upper>0.349066 </upper>
                    <effort>6.0 </effort>
                    <velocity>0.8 </velocity>
                </limit>
                <dynamics>
                    <damping>0.1</damping>
                    <friction>0</friction>
                    <spring_reference>0</spring_reference>
                    <spring_stiffness>0</spring_stiffness>
                </dynamics>
            </axis>
        </joint>

    

        <link name = "knuckle_RF">

            <pose frame=''>0.010999999999999996 0.0461 0.22177 -0.698132 0 0</pose>
            <inertial>
                <pose frame=''>0 0 0 0 0 0</pose>
                <mass>0.008</mass>
                <inertia>
                    <ixx>2.6e-07</ixx>
                    <ixy>0</ixy>
                    <ixz>0</ixz>
                    <iyy>2.6e-07</iyy>
                    <iyz>0</iyz>
                    <izz>3.2e-07</izz>
                </inertia>
            </inertial>

            <visual name='visual_knuckle_link_RF'>

                <geometry>
                    <mesh>
                        <scale>0.001 0.001 0.001</scale>
                        <uri>./meshes/knuckle.dae</uri>
                    </mesh>
                </geometry>
                <material>
                    <ambient>0.6546371129198457 0.5922894211874774 0.46932250228523764 1</ambient>
                    <diffuse>0.6735854053894114 0.10874267438645235 0.9374857244389729 1</diffuse>
                    <specular>0.9321411833879993 0.6199429211355926 0.22768291885163905 1</specular>
                    <emissive>0 0 0 0</emissive>
                </material>
            </visual>
            <collision name='collision_knuckle_link_RF'>
                <geometry>
                <mesh>
                    <scale>0.00050 0.00050 0.00050</scale>
                    <uri>./meshes/knuckle.dae</uri>
                </mesh>
            </geometry>
            </collision>
        </link>
        <link name = "proximal_RF">
            <pose frame=''>0.010999999999999996 0.0461 0.22177 -0.698132 0 0</pose>
            <inertial>
                <pose frame=''>0 0 0.0225 0 0 0</pose>
                <mass>0.03</mass>
                <inertia>
                    <ixx>9.8e-06</ixx>
                    <ixy>0</ixy>
                    <ixz>0</ixz>
                    <iyy>1.0e-05</iyy>
                    <iyz>0</iyz>
                    <izz>1.8e-06</izz>
                </inertia>
            </inertial>

            <visual name='visual_proximal_link_RF'>

                <geometry>
                    <mesh>
                        <scale>0.001 0.001 0.001</scale>
                        <uri>./meshes/F3.dae</uri>
                    </mesh>
                </geometry>
                <material>
                    <ambient>0.038718560132853685 0.4516718117053674 0.26376615813353566 1</ambient>
                    <diffuse>0.5282705587745641 0.5550300787074559 0.16115307100362608 1</diffuse>
                    <specular>0.9254967837250535 0.6971193153762737 0.7964461509815661 1</specular>
                    <emissive>0 0 0 0</emissive>
                </material>
            </visual>
            <collision name='collision_proximal_link_RF'>
                <geometry>
                <mesh>
                    <scale>0.001 0.001 0.001</scale>
                    <uri>./meshes/F3_c.dae</uri>
                </mesh>
            </geometry>
            </collision>
        </link>
        <link name = "middle_RF">
            <pose frame=''>0.010999999999999996 0.07499 0.256246 -0.698132 0 0</pose>
            <inertial>
                <pose frame=''>0 0 0.0125 0 0 0</pose>
                <mass>0.017</mass>
                <inertia>
                    <ixx>2.6e-06</ixx>
                    <ixy>0</ixy>
                    <ixz>0</ixz>
                    <iyy>2.7e-06</iyy>
                    <iyz>0</iyz>
                    <izz>8.7e-07</izz>
                </inertia>
            </inertial>

            <visual name='visual_middle_link_RF'>

                <geometry>
                    <mesh>
                        <scale>0.001 0.001 0.001</scale>
                        <uri>./meshes/F2.dae</uri>
                    </mesh>
                </geometry>
                <material>
                    <ambient>0.3825057879339182 0.5302707537090202 0.8633236655143327 1</ambient>
                    <diffuse>0.5625728623553131 0.62632601843645 0.6245928926384579 1</diffuse>
                    <specular>0.7445335243262422 0.6351341425981256 0.46766122611218774 1</specular>
                    <emissive>0 0 0 0</emissive>
                </material>
            </visual>
            <collision name='collision_middle_link_RF'>
                <geometry>
                    <mesh>
                        <scale>0.001 0.001 0.001</scale>
                        <uri>./meshes/F2_c.dae</uri>
                    </mesh>
                </geometry>
            </collision>
        </link>
        <link name =  "distal_RF">
            <pose frame=''>0.010999999999999996 0.09106 0.275397 -0.698132 0 0</pose>
            <inertial>
                <pose frame=''>0 0 0.012 0 0 0</pose>
                <mass>0.012</mass>
                <inertia>
                    <ixx>9.4e-07</ixx>
                    <ixy>0</ixy>
                    <ixz>0</ixz>
                    <iyy>1.1e-06</iyy>
                    <iyz>0</iyz>
                    <izz>5.3e-07</izz>
                </inertia>
            </inertial>

            <visual name='visual_distal_link_RF'>

                <geometry>
                    <mesh>
                        <scale>0.001 0.001 0.001</scale>
                        <uri>./meshes/F1.dae</uri>
                    </mesh>
                </geometry>
                <material>
                    <ambient>0.10102733200888314 0.2150814576086253 0.47645806238095356 1</ambient>
                    <diffuse>0.4866697724249588 0.6164264182250547 0.34993478191921124 1</diffuse>
                    <specular>0.7228935174028022 0.16618556076996593 0.09492684187547984 1</specular>
                    <emissive>0 0 0 0</emissive>
                </material>
            </visual>
            <collision name='collision_distal_link_RF'>
                <geometry>
                    <mesh>
                        <scale>0.001 0.001 0.001</scale>
                        <uri>./meshes/F1.dae</uri>
                    </mesh>
                </geometry>
            </collision>
        </link>

        
            
            <joint name="J3_RF" type="revolute">
                <child>proximal_RF</child>
                <parent>knuckle_RF</parent>

                <axis>
                    <xyz>1 0 0</xyz>
                    <limit>
                        <lower>0 </lower>
                        <upper>1.5708 </upper>
                        <effort>6.0 </effort>
                        <velocity>0.8 </velocity>
                    </limit>
                    <dynamics>
                        <damping>0.1</damping>
                        <friction>0</friction>
                        <spring_reference>0</spring_reference>
                        <spring_stiffness>0</spring_stiffness>
                    </dynamics>
                </axis>
            </joint>
        
            
            <joint name="J2_RF" type="revolute">
                <child>middle_RF</child>
                <parent>proximal_RF</parent>

                <axis>
                    <xyz>1 0 0</xyz>
                    <limit>
                        <lower>0 </lower>
                        <upper>1.5708 </upper>
                        <effort>6.0 </effort>
                        <velocity>0.8 </velocity>
                    </limit>
                    <dynamics>
                        <damping>0.1</damping>
                        <friction>0</friction>
                        <spring_reference>0</spring_reference>
                        <spring_stiffness>0</spring_stiffness>
                    </dynamics>
                </axis>
            </joint>
        
            
            <joint name="J1_RF" type="revolute">
                <child>distal_RF</child>
                <parent>middle_RF</parent>

                <axis>
                    <xyz>1 0 0</xyz>
                    <limit>
                        <lower>0 </lower>
                        <upper>1.5708 </upper>
                        <effort>6.0 </effort>
                        <velocity>0.8 </velocity>
                    </limit>
                    <dynamics>
                        <damping>0.1</damping>
                        <friction>0</friction>
                        <spring_reference>0</spring_reference>
                        <spring_stiffness>0</spring_stiffness>
                    </dynamics>
                </axis>
            </joint>
        
        <joint name='J4_RF' type="revolute">
            <child>knuckle_RF</child>
            <parent>palm</parent>

            <axis>
                <xyz>0 0.766044 -0.642788</xyz>
                <limit>
                    <lower>-0.349066 </lower>
                    <upper>0.349066 </upper>
                    <effort>6.0 </effort>
                    <velocity>0.8 </velocity>
                </limit>
                <dynamics>
                    <damping>0.1</damping>
                    <friction>0</friction>
                    <spring_reference>0</spring_reference>
                    <spring_stiffness>0</spring_stiffness>
                </dynamics>
            </axis>
        </joint>

    
    

    
    <link name = "thbase">
        <pose frame=''>-0.034 -0.0028710000000000003 0.176679 0.870557 0.572429 -2.5703</pose>
        <inertial>
            <pose frame=''>0 0 0 0 0 0</pose>
            <mass>0.01</mass>
            <inertia>
                <ixx>1.6e-07</ixx>
                <ixy>0</ixy>
                <ixz>0</ixz>
                <iyy>1.6e-07</iyy>
                <iyz>0</iyz>
                <izz>1.6e-07</izz>
            </inertia>
        </inertial>
        <visual name='visual_thbase_link'>
            
            <geometry>
                <box>
                    <size>0.001 0.001 0.001</size>
                </box>
            </geometry>
            <material>
                <ambient>0.793491202336701 0.580557275366707 0.28798606304488483 1</ambient>
                <diffuse>0.20531503076304203 0.11633773671804948 0.28193600055013646 1</diffuse>
                <specular>0.558825455347443 0.13759114593982258 0.27113584108993627 1</specular>
                <emissive>0 0 0 0</emissive>
            </material>
        </visual>
        <collision name='collision_thbase_link'>
            <pose frame=''>0 0 0 0 0 0</pose>
            <geometry>

                <sphere>
                    <radius>0.005</radius>
                </sphere>
            
            </geometry>
        </collision>
    </link>
    <link name = "thproximal">
            
        <pose frame=''>-0.034 -0.0028710000000000003 0.176679 0.870557 0.572429 -2.5703</pose>
        <inertial>
            <pose frame=''>0 0 0.021111 0 0 0</pose>
            <mass>0.04</mass>
            <inertia>
                <ixx>1.36e-05</ixx>
                <ixy>0</ixy>
                <ixz>0</ixz>
                <iyy>1.36e-05</iyy>
                <iyz>0</iyz>
                <izz>3.13e-06</izz>
            </inertia>
        </inertial>

        <visual name='visual_thproximal_link'>
            
            <geometry>
                <mesh>
                    <scale>0.001 0.001 0.001</scale>
                    <uri>./meshes/TH3_z.dae</uri>
                </mesh>
            </geometry>
            <material>
                <ambient>0.8053871441016514 0.962230265734726 0.7628837761330564 1</ambient>
                <diffuse>0.22881937643649986 0.1874127739907837 0.8144038867570642 1</diffuse>
                <specular>0.9705428793384492 0.1490773948824936 0.41075697764179786 1</specular>
                <emissive>0 0 0 0</emissive>
            </material>
        </visual>
        <collision name='collision_thproximal_link'>
            <geometry>
                <mesh>
                    <scale>0.001 0.001 0.001</scale>
                    <uri>./meshes/TH3_z_c.dae</uri>
                </mesh>
            </geometry>
        </collision>
    </link>
    <link name = "thhub">
        <pose frame=''>-0.06087000000000001 0.014400999999999999 0.197263 0.870557 0.572429 -2.5703</pose>
        <inertial>
            <pose frame=''>0 0 0 0 0 0</pose>
            <mass>0.005</mass>
            <inertia>
                <ixx>1.0e-06</ixx>
                <ixy>0</ixy>
                <ixz>0</ixz>
                <iyy>1.0e-06</iyy>
                <iyz>0</iyz>
                <izz>3.0e-07</izz>
            </inertia>
        </inertial>
        <visual name='visual_thhub_link'>
            
            <geometry>
                <box>
                    <size>0.001 0.001 0.001</size>
                </box>
            </geometry>
            <material>

            </material>
        </visual>
        <collision name='collision_thhub_link'>
            <geometry>
                <box>
                    <size>0.001 0.001 0.001</size>
                </box>
            </geometry>
        </collision>
    </link>
    <link name = "thmiddle">
            
        <pose frame=''>-0.06087000000000001 0.014400999999999999 0.197263 0.870557 0.572429 -2.5703</pose>
        <inertial>
            <pose frame=''>0 0 0.16 0 0 0</pose>
            <mass>0.02</mass>
            <inertia>
                <ixx>5.1e-06</ixx>
                <ixy>0</ixy>
                <ixz>0</ixz>
                <iyy>5.1e-06</iyy>
                <iyz>0</iyz>
                <izz>1.21e-06</izz>
            </inertia>
        </inertial>

        <visual name='visual_thmiddle_link'>
            
            <geometry>
                <mesh>
                    <scale>0.001 0.001 0.001</scale>
                    <uri>./meshes/TH2_z.dae</uri>
                </mesh>
            </geometry>
            <material>
                <ambient>0.7650246484566191 0.6433166908392309 0.2561271106018147 1</ambient>
                <diffuse>0.31537005923216455 0.8960439497232296 0.6052545399008182 1</diffuse>
                <specular>0.25423581730844524 0.6315485098647313 0.4851678114250778 1</specular>
                <emissive>0 0 0 0</emissive>
            </material>
        </visual>

        <collision name='collision_thmiddle_link'>
            <geometry>
                <mesh>
                    <scale>0.001 0.001 0.001</scale>
                    <uri>./meshes/TH2_z_c.dae</uri>
                </mesh>
            </geometry>
        </collision>
    </link>
    <link name = "thdistal">
            
        <pose frame=''>-0.083498 0.028946 0.214596 -0.785398 0.698132 1.5707999999999998</pose>
        <inertial>
            <pose frame=''>0 0 0.014559 0 0 0</pose>
            <mass>0.016</mass>
            <inertia>
                <ixx>2.1e-06</ixx>
                <ixy>0</ixy>
                <ixz>0</ixz>
                <iyy>2.2e-06</iyy>
                <iyz>0</iyz>
                <izz>1.0e-06</izz>
            </inertia>
        </inertial>

        <visual name='visual_thdistal_link'>
            
            <geometry>
                <mesh>
                    <scale>0.001 0.001 0.001</scale>
                    <uri>./meshes/TH1_z.dae</uri>
                </mesh>
            </geometry>
            <material>
                <ambient>0.5493899248299303 0.3043574617643068 0.06709953130245372 1</ambient>
                <diffuse>0.051813100846129445 0.544536873958222 0.5897223147476931 1</diffuse>
                <specular>0.06703861519013465 0.7574730244710944 0.8922969113388742 1</specular>
                <emissive>0 0 0 0</emissive>
            </material>
        </visual>
        <collision name='collision_thdistal_link'>
            <geometry>
                <mesh>
                    <scale>0.001 0.001 0.001</scale>
                    <uri>./meshes/TH1_z.dae</uri>
                </mesh>
            </geometry>
        </collision>
    </link>

    
        <joint name ="THJ5"  type ="revolute">
            <child>thbase</child>
            <parent>palm</parent>
            <axis>
                <xyz>0 0 0.541675</xyz>
                <limit>
                    <lower>-1.0472 </lower>
                    <upper>1.0472 </upper>
                    <effort>8.0 </effort>
                    <velocity>0.7 </velocity>
                </limit>
                <dynamics>
                    <damping>0.2</damping>
                    <friction>0</friction>
                </dynamics>
            </axis>
        </joint>
    
        <joint name ="THJ4"  type ="revolute">
            <child>thproximal</child>
            <parent>thbase</parent>
            <axis>
                <xyz>-0.707107 -0.454519 -0.541675</xyz>
                <limit>
                    <lower>0 </lower>
                    <upper>1.22173 </upper>
                    <effort>8 </effort>
                    <velocity>0.7 </velocity>
                </limit>
                <dynamics>
                    <damping>0.2</damping>
                    <friction>0</friction>
                </dynamics>
            </axis>
        </joint>
    
        <joint name ="THJ2"  type ="revolute">
            <child>thmiddle</child>
            <parent>thhub</parent>
            <axis>
                <xyz>0 -0.766044 0.642788</xyz>
                <limit>
                    <lower>-0.698132 </lower>
                    <upper>0.698132 </upper>
                    <effort>8.0 </effort>
                    <velocity>0.7 </velocity>
                </limit>
                <dynamics>
                    <damping>0.1</damping>
                    <friction>0</friction>
                </dynamics>
            </axis>
        </joint>
    
        <joint name ="THJ1"  type ="revolute">
            <child>thdistal</child>
            <parent>thmiddle</parent>
            <axis>
                <xyz>1 0 0</xyz>
                <limit>
                    <lower>0 </lower>
                    <upper>1.5708 </upper>
                    <effort>8.0 </effort>
                    <velocity>0.7 </velocity>
                </limit>
                <dynamics>
                    <damping>0.2</damping>
                    <friction>0</friction>
                </dynamics>
            </axis>
        </joint>
    
    <joint name ="THJ3"  type ="fixed">
        <child>thhub</child>
        <parent>thproximal</parent>
        <axis>
            <xyz>1 0 0</xyz>
        </axis>
    </joint>
    






 
   
  </model>

</sdf>