<?xml version="1.0" ?>
<!-- =================================================================================== -->
<!-- |    This document was autogenerated by xacro from ./example_iiwa7.urdf.xacro     | -->
<!-- |    EDITING THIS FILE BY HAND IS NOT RECOMMENDED                                 | -->
<!-- =================================================================================== -->
<robot name="im_iiwa">
  <link name="world"/>
  <joint name="im_iiwa_world_joint" type="fixed">
    <parent link="world"/>
    <child link="im_iiwa_link_0"/>
    <origin rpy="0.0 0.0 1.5707963267948966" xyz="0.0 0.0 0.006"/>
  </joint>
  <link name="im_iiwa_link_0">
    <inertial>
      <!--origin xyz="-0.1 0 0.07" rpy="0 0 0"/-->
      <origin rpy="0 0 0" xyz="0 0 0"/>
      <mass value="5"/>
      <inertia ixx="0.05" ixy="0" ixz="0" iyy="0.06" iyz="0" izz="0.03"/>
    </inertial>
    <visual>
      <origin rpy="0 0 0" xyz="0 0 0"/>
      <geometry>
        <mesh filename="package://iiwa_fri_description/meshes/iiwa14/visual/link_0.stl"/>
      </geometry>
      <material name="Grey"/>
    </visual>
    <collision>
      <origin rpy="0 0 0" xyz="0 0 0"/>
      <geometry>
        <mesh filename="package://iiwa_fri_description/meshes/iiwa14/collision/link_0.stl"/>
      </geometry>
      <material name="Grey"/>
    </collision>
    <self_collision_checking>
      <origin rpy="0 0 0" xyz="0 0 0"/>
      <geometry>
        <capsule length="0.25" radius="0.15"/>
      </geometry>
    </self_collision_checking>
  </link>
  <!-- joint between link_0 and link_1 -->
  <joint name="im_iiwa_joint_1" type="revolute">
    <parent link="im_iiwa_link_0"/>
    <child link="im_iiwa_link_1"/>
    <origin rpy="0 0 0" xyz="0 0 0.1575"/>
    <axis xyz="0 0 1"/>
    <limit effort="3000" lower="-2.9670597283903604" upper="2.9670597283903604" velocity="10"/>
    <dynamics damping="0.5"/>
  </joint>
  <link name="im_iiwa_link_1">
    <inertial>
      <origin rpy="0 0 0" xyz="0 -0.03 0.12"/>
      <mass value="4"/>
      <inertia ixx="0.1" ixy="0" ixz="0" iyy="0.09" iyz="0" izz="0.02"/>
    </inertial>
    <visual>
      <origin rpy="0 0 0" xyz="0 0 0"/>
      <geometry>
        <mesh filename="package://iiwa_fri_description/meshes/iiwa14/visual/link_1.stl"/>
      </geometry>
      <material name="Orange"/>
    </visual>
    <collision>
      <origin rpy="0 0 0" xyz="0 0 0"/>
      <geometry>
        <mesh filename="package://iiwa_fri_description/meshes/iiwa14/collision/link_1.stl"/>
      </geometry>
      <material name="Orange"/>
    </collision>
  </link>
  <!-- joint between link_1 and link_2 -->
  <joint name="im_iiwa_joint_2" type="revolute">
    <parent link="im_iiwa_link_1"/>
    <child link="im_iiwa_link_2"/>
    <origin rpy="1.5707963267948966   0 3.141592653589793" xyz="0 0 0.2025"/>
    <axis xyz="0 0 1"/>
    <limit effort="3000" lower="-2.0943951023931953" upper="2.0943951023931953" velocity="10"/>
    <dynamics damping="0.5"/>
  </joint>
  <link name="im_iiwa_link_2">
    <inertial>
      <origin rpy="0 0 0" xyz="0.0003 0.059 0.042"/>
      <mass value="4"/>
      <inertia ixx="0.05" ixy="0" ixz="0" iyy="0.018" iyz="0" izz="0.044"/>
    </inertial>
    <visual>
      <origin rpy="0 0 0" xyz="0 0 0"/>
      <geometry>
        <mesh filename="package://iiwa_fri_description/meshes/iiwa14/visual/link_2.stl"/>
      </geometry>
      <material name="Orange"/>
    </visual>
    <collision>
      <origin rpy="0 0 0" xyz="0 0 0"/>
      <geometry>
        <mesh filename="package://iiwa_fri_description/meshes/iiwa14/collision/link_2.stl"/>
      </geometry>
      <material name="Orange"/>
    </collision>
  </link>
  <!-- joint between link_2 and link_3 -->
  <joint name="im_iiwa_joint_3" type="revolute">
    <parent link="im_iiwa_link_2"/>
    <child link="im_iiwa_link_3"/>
    <origin rpy="1.5707963267948966 0 3.141592653589793" xyz="0 0.2045 0"/>
    <axis xyz="0 0 1"/>
    <limit effort="3000" lower="-2.9670597283903604" upper="2.9670597283903604" velocity="10"/>
    <dynamics damping="0.5"/>
  </joint>
  <link name="im_iiwa_link_3">
    <inertial>
      <origin rpy="0 0 0" xyz="0 0.03 0.13"/>
      <mass value="3"/>
      <inertia ixx="0.08" ixy="0" ixz="0" iyy="0.075" iyz="0" izz="0.01"/>
    </inertial>
    <visual>
      <origin rpy="0 0 0" xyz="0 0 0"/>
      <geometry>
        <mesh filename="package://iiwa_fri_description/meshes/iiwa14/visual/link_3.stl"/>
      </geometry>
      <material name="Orange"/>
    </visual>
    <collision>
      <origin rpy="0 0 0" xyz="0 0 0"/>
      <geometry>
        <mesh filename="package://iiwa_fri_description/meshes/iiwa14/collision/link_3.stl"/>
      </geometry>
      <material name="Orange"/>
    </collision>
  </link>
  <!-- joint between link_3 and link_4 -->
  <joint name="im_iiwa_joint_4" type="revolute">
    <parent link="im_iiwa_link_3"/>
    <child link="im_iiwa_link_4"/>
    <origin rpy="1.5707963267948966 0 0" xyz="0 0 0.2155"/>
    <axis xyz="0 0 1"/>
    <limit effort="3000" lower="-2.0943951023931953" upper="2.0943951023931953" velocity="10"/>
    <dynamics damping="0.5"/>
  </joint>
  <link name="im_iiwa_link_4">
    <inertial>
      <origin rpy="0 0 0" xyz="0 0.067 0.034"/>
      <mass value="2.7"/>
      <inertia ixx="0.03" ixy="0" ixz="0" iyy="0.01" iyz="0" izz="0.029"/>
    </inertial>
    <visual>
      <origin rpy="0 0 0" xyz="0 0 0"/>
      <geometry>
        <mesh filename="package://iiwa_fri_description/meshes/iiwa14/visual/link_4.stl"/>
      </geometry>
      <material name="Orange"/>
    </visual>
    <collision>
      <origin rpy="0 0 0" xyz="0 0 0"/>
      <geometry>
        <mesh filename="package://iiwa_fri_description/meshes/iiwa14/collision/link_4.stl"/>
      </geometry>
      <material name="Orange"/>
    </collision>
  </link>
  <!-- joint between link_4 and link_5 -->
  <joint name="im_iiwa_joint_5" type="revolute">
    <parent link="im_iiwa_link_4"/>
    <child link="im_iiwa_link_5"/>
    <origin rpy="-1.5707963267948966 3.141592653589793 0" xyz="0 0.1845 0"/>
    <axis xyz="0 0 1"/>
    <limit effort="3000" lower="-2.9670597283903604" upper="2.9670597283903604" velocity="10"/>
    <dynamics damping="0.5"/>
  </joint>
  <link name="im_iiwa_link_5">
    <inertial>
      <origin rpy="0 0 0" xyz="0.0001 0.021 0.076"/>
      <mass value="1.7"/>
      <inertia ixx="0.02" ixy="0" ixz="0" iyy="0.018" iyz="0" izz="0.005"/>
    </inertial>
    <visual>
      <origin rpy="0 0 0" xyz="0 0 0"/>
      <geometry>
        <mesh filename="package://iiwa_fri_description/meshes/iiwa14/visual/link_5.stl"/>
      </geometry>
      <material name="Orange"/>
    </visual>
    <collision>
      <origin rpy="0 0 0" xyz="0 0 0"/>
      <geometry>
        <mesh filename="package://iiwa_fri_description/meshes/iiwa14/collision/link_5.stl"/>
      </geometry>
      <material name="Orange"/>
    </collision>
  </link>
  <!-- joint between link_5 and link_6 -->
  <joint name="im_iiwa_joint_6" type="revolute">
    <parent link="im_iiwa_link_5"/>
    <child link="im_iiwa_link_6"/>
    <origin rpy="1.5707963267948966 0 0" xyz="0 0 0.2155"/>
    <axis xyz="0 0 1"/>
    <limit effort="3000" lower="-2.0943951023931953" upper="2.0943951023931953" velocity="10"/>
    <dynamics damping="0.5"/>
  </joint>
  <link name="im_iiwa_link_6">
    <inertial>
      <origin rpy="0 0 0" xyz="0 0.0006 0.0004"/>
      <mass value="1.8"/>
      <inertia ixx="0.005" ixy="0" ixz="0" iyy="0.0036" iyz="0" izz="0.0047"/>
    </inertial>
    <visual>
      <origin rpy="0 0 0" xyz="0 0 0"/>
      <geometry>
        <mesh filename="package://iiwa_fri_description/meshes/iiwa14/visual/link_6.stl"/>
      </geometry>
      <material name="Orange"/>
    </visual>
    <collision>
      <origin rpy="0 0 0" xyz="0 0 0"/>
      <geometry>
        <mesh filename="package://iiwa_fri_description/meshes/iiwa14/collision/link_6.stl"/>
      </geometry>
      <material name="Orange"/>
    </collision>
  </link>
  <!-- joint between link_6 and link_7 -->
  <joint name="im_iiwa_joint_7" type="revolute">
    <parent link="im_iiwa_link_6"/>
    <child link="im_iiwa_link_7"/>
    <origin rpy="-1.5707963267948966 3.141592653589793 0" xyz="0 0.081 0"/>
    <axis xyz="0 0 1"/>
    <limit effort="3000" lower="-3.0543261909900763" upper="3.0543261909900763" velocity="10"/>
    <dynamics damping="0.5"/>
  </joint>
  <link name="im_iiwa_link_7">
    <inertial>
      <origin rpy="0 0 0" xyz="0 0 0.02"/>
      <mass value="0.3"/>
      <inertia ixx="0.001" ixy="0" ixz="0" iyy="0.001" iyz="0" izz="0.001"/>
    </inertial>
    <visual>
      <origin rpy="0 0 0" xyz="0 0 0"/>
      <geometry>
        <mesh filename="package://iiwa_fri_description/meshes/iiwa14/visual/link_7.stl"/>
      </geometry>
      <material name="Grey"/>
    </visual>
    <collision>
      <origin rpy="0 0 0" xyz="0 0 0"/>
      <geometry>
        <mesh filename="package://iiwa_fri_description/meshes/iiwa14/collision/link_7.stl"/>
      </geometry>
      <material name="Grey"/>
    </collision>
  </link>
  <joint name="im_iiwa_joint_ee" type="fixed">
    <parent link="im_iiwa_link_7"/>
    <child link="im_iiwa_link_ee"/>
    <origin rpy="0 0 0" xyz="0 0 0.045"/>
  </joint>
  <link name="im_iiwa_link_ee">
    </link>
  <gazebo>
    <plugin filename="libgazebo_ros_control.so" name="gazebo_ros_control">
      <robotNamespace>/im_iiwa</robotNamespace>
    </plugin>
  </gazebo>
  <!-- Link0 -->
  <gazebo reference="im_iiwa_link_0">
    <material>Gazebo/Grey</material>
    <mu1>0.2</mu1>
    <mu2>0.2</mu2>
  </gazebo>
  <!-- Link1 -->
  <gazebo reference="im_iiwa_link_1">
    <material>Gazebo/Orange</material>
    <mu1>0.2</mu1>
    <mu2>0.2</mu2>
  </gazebo>
  <!-- Link2 -->
  <gazebo reference="im_iiwa_link_2">
    <material>Gazebo/Orange</material>
    <mu1>0.2</mu1>
    <mu2>0.2</mu2>
  </gazebo>
  <!-- Link3 -->
  <gazebo reference="im_iiwa_link_3">
    <material>Gazebo/Orange</material>
    <mu1>0.2</mu1>
    <mu2>0.2</mu2>
  </gazebo>
  <!-- Link4 -->
  <gazebo reference="im_iiwa_link_4">
    <material>Gazebo/Orange</material>
    <mu1>0.2</mu1>
    <mu2>0.2</mu2>
  </gazebo>
  <!-- Link5 -->
  <gazebo reference="im_iiwa_link_5">
    <material>Gazebo/Orange</material>
    <mu1>0.2</mu1>
    <mu2>0.2</mu2>
  </gazebo>
  <!-- Link6 -->
  <gazebo reference="im_iiwa_link_6">
    <material>Gazebo/Orange</material>
    <mu1>0.2</mu1>
    <mu2>0.2</mu2>
  </gazebo>
  <!-- Link7 -->
  <gazebo reference="im_iiwa_link_7">
    <material>Gazebo/Grey</material>
    <mu1>0.2</mu1>
    <mu2>0.2</mu2>
  </gazebo>
  <transmission name="im_iiwa_tran_1">
    <type>transmission_interface/SimpleTransmission</type>
    <joint name="im_iiwa_joint_1">
      <hardwareInterface>hardware_interface/PositionJointInterface</hardwareInterface>
    </joint>
    <actuator name="im_iiwa_motor_1">
      <hardwareInterface>hardware_interface/PositionJointInterface</hardwareInterface>
      <mechanicalReduction>1</mechanicalReduction>
    </actuator>
  </transmission>
  <transmission name="im_iiwa_tran_2">
    <type>transmission_interface/SimpleTransmission</type>
    <joint name="im_iiwa_joint_2">
      <hardwareInterface>hardware_interface/PositionJointInterface</hardwareInterface>
    </joint>
    <actuator name="im_iiwa_motor_2">
      <hardwareInterface>hardware_interface/PositionJointInterface</hardwareInterface>
      <mechanicalReduction>1</mechanicalReduction>
    </actuator>
  </transmission>
  <transmission name="im_iiwa_tran_3">
    <type>transmission_interface/SimpleTransmission</type>
    <joint name="im_iiwa_joint_3">
      <hardwareInterface>hardware_interface/PositionJointInterface</hardwareInterface>
    </joint>
    <actuator name="im_iiwa_motor_3">
      <hardwareInterface>hardware_interface/PositionJointInterface</hardwareInterface>
      <mechanicalReduction>1</mechanicalReduction>
    </actuator>
  </transmission>
  <transmission name="im_iiwa_tran_4">
    <type>transmission_interface/SimpleTransmission</type>
    <joint name="im_iiwa_joint_4">
      <hardwareInterface>hardware_interface/PositionJointInterface</hardwareInterface>
    </joint>
    <actuator name="im_iiwa_motor_4">
      <hardwareInterface>hardware_interface/PositionJointInterface</hardwareInterface>
      <mechanicalReduction>1</mechanicalReduction>
    </actuator>
  </transmission>
  <transmission name="im_iiwa_tran_5">
    <type>transmission_interface/SimpleTransmission</type>
    <joint name="im_iiwa_joint_5">
      <hardwareInterface>hardware_interface/PositionJointInterface</hardwareInterface>
    </joint>
    <actuator name="im_iiwa_motor_5">
      <hardwareInterface>hardware_interface/PositionJointInterface</hardwareInterface>
      <mechanicalReduction>1</mechanicalReduction>
    </actuator>
  </transmission>
  <transmission name="im_iiwa_tran_6">
    <type>transmission_interface/SimpleTransmission</type>
    <joint name="im_iiwa_joint_6">
      <hardwareInterface>hardware_interface/PositionJointInterface</hardwareInterface>
    </joint>
    <actuator name="im_iiwa_motor_6">
      <hardwareInterface>hardware_interface/PositionJointInterface</hardwareInterface>
      <mechanicalReduction>1</mechanicalReduction>
    </actuator>
  </transmission>
  <transmission name="im_iiwa_tran_7">
    <type>transmission_interface/SimpleTransmission</type>
    <joint name="im_iiwa_joint_7">
      <hardwareInterface>hardware_interface/PositionJointInterface</hardwareInterface>
    </joint>
    <actuator name="im_iiwa_motor_7">
      <hardwareInterface>hardware_interface/PositionJointInterface</hardwareInterface>
      <mechanicalReduction>1</mechanicalReduction>
    </actuator>
  </transmission>
  <!--<xacro:iiwa_torque_transmission robot_name="${robot_name}"/>-->
  <!--
    <xacro:include filename="$(find sat_description)/sensors/kinect.urdf.xacro"/>
    
    <joint name="$(arg eye_robot_name)_ee_to_eye" type="fixed">
        <parent link="$(arg eye_robot_name)_link_ee"/>
        <child link="camera_link"/>
		<origin xyz="0.012 0.0 0.1" rpy="${0.0} ${-pi/2} ${0.0}"/>
    </joint>
    -->
</robot>

