<?xml version="1.0" ?>



<sdf version='1.6'>
  <model name="kuka_handlit">
    <!--KUKA-->
    <link name = "world">
        <pose frame=''>0 0 0 0 0 0</pose>
        <inertial>
            <pose frame=''>0 0 0.0 0 0 0</pose>
            <mass>0.0</mass>
            <inertia>
                <ixx>0.</ixx>
                <ixy>0</ixy>
                <ixz>0</ixz>
                <iyy>0.</iyy>
                <iyz>0</iyz>
                <izz>0.</izz>
            </inertia>
        </inertial>
    </link>
    <joint name="world" type="fixed">
        <child>lbr_iiwa_link_0</child>
        <parent>world</parent>
    </joint>
    
      <link name="lbr_iiwa_link_0">
        <pose frame=''>0 0 0 0 0 0</pose>
        <inertial>
            <pose frame=''>-0.1 0 0.07 0 0 0</pose>
            <mass>5</mass>
            <inertia>
                <ixx>0.05</ixx>
                <ixy>0</ixy>
                <ixz>0</ixz>
                <iyy>0.06</iyy>
                <iyz>0</iyz>
                <izz>0.03</izz>
            </inertia>
        </inertial>
        <collision name='lbr_iiwa_link_0_collision'>
          <pose frame=''>0 0 0 0 -0 0</pose>
          <geometry>
            <mesh>
              
              <scale>1 1 1</scale>
              <uri>meshes/kuka/collision/link_0.stl</uri>
              
            </mesh>
          </geometry>
        </collision>
       
      </link>
    
      <link name="lbr_iiwa_link_1">
        <pose frame=''>0 0 0.1575 0 0 0</pose>
        <inertial>
            <pose frame=''>0 -0.03 0.12 0 0 0</pose>
            <mass>3.4525</mass>
            <inertia>
                <ixx>0.02183</ixx>
                <ixy>0</ixy>
                <ixz>0</ixz>
                <iyy>0.007703</iyy>
                <iyz>-0.003887</iyz>
                <izz>0.02083</izz>
            </inertia>
        </inertial>
        <collision name='lbr_iiwa_link_1_collision'>
          <pose frame=''>0 0 0 0 -0 0</pose>
          <geometry>
            <mesh>
              
              <scale>1 1 1</scale>
              <uri>meshes/kuka/collision/link_1.stl</uri>
              
            </mesh>
          </geometry>
        </collision>
       
      </link>
    
      <link name="lbr_iiwa_link_2">
        <pose frame=''>0 0 0.34 1.5708 0 -3.14159</pose>
        <inertial>
            <pose frame=''>0.0003 0.059 0.042 0 0 0</pose>
            <mass>3.4821</mass>
            <inertia>
                <ixx>0.02076</ixx>
                <ixy>0</ixy>
                <ixz>0.003626</ixz>
                <iyy>0.02179</iyy>
                <iyz>0</iyz>
                <izz>0.00779</izz>
            </inertia>
        </inertial>
        <collision name='lbr_iiwa_link_2_collision'>
          <pose frame=''>0 0 0 0 -0 0</pose>
          <geometry>
            <mesh>
              
              <scale>1 1 1</scale>
              <uri>meshes/kuka/collision/link_2.stl</uri>
              
            </mesh>
          </geometry>
        </collision>
       
      </link>
    
      <link name="lbr_iiwa_link_3">
        <pose frame=''>0 0 0.524 0 0 0</pose>
        <inertial>
            <pose frame=''>0 0.03 0.13 0 0 0</pose>
            <mass>4.05623</mass>
            <inertia>
                <ixx>0.03204</ixx>
                <ixy>0</ixy>
                <ixz>0</ixz>
                <iyy>0.00972</iyy>
                <iyz>0.006227</iyz>
                <izz>0.03042</izz>
            </inertia>
        </inertial>
        <collision name='lbr_iiwa_link_3_collision'>
          <pose frame=''>0 0 0 0 -0 0</pose>
          <geometry>
            <mesh>
              
              <scale>1 1 1</scale>
              <uri>meshes/kuka/collision/link_3.stl</uri>
              
            </mesh>
          </geometry>
        </collision>
       
      </link>
    
      <link name="lbr_iiwa_link_4">
        <pose frame=''>0 0 0.74 1.5708 0 0</pose>
        <inertial>
            <pose frame=''>0 0.067 0.034 0 0 0</pose>
            <mass>3.4822</mass>
            <inertia>
                <ixx>0.02178</ixx>
                <ixy>0</ixy>
                <ixz>0</ixz>
                <iyy>0.02075</iyy>
                <iyz>-0.003625</iyz>
                <izz>0.007785</izz>
            </inertia>
        </inertial>
        <collision name='lbr_iiwa_link_4_collision'>
          <pose frame=''>0 0 0 0 -0 0</pose>
          <geometry>
            <mesh>
              
              <scale>1 1 1</scale>
              <uri>meshes/kuka/collision/link_4.stl</uri>
              
            </mesh>
          </geometry>
        </collision>
       
      </link>
    
      <link name="lbr_iiwa_link_5">
        <pose frame=''>0 0 0.9239999999999999 0 0 -3.14159</pose>
        <inertial>
            <pose frame=''>0.0001 0.021 0.076 0 0 0</pose>
            <mass>2.1633</mass>
            <inertia>
                <ixx>0.01287</ixx>
                <ixy>0</ixy>
                <ixz>0</ixz>
                <iyy>0.005708</iyy>
                <iyz>-0.003946</iyz>
                <izz>0.01112</izz>
            </inertia>
        </inertial>
        <collision name='lbr_iiwa_link_5_collision'>
          <pose frame=''>0 0 0 0 -0 0</pose>
          <geometry>
            <mesh>
              
              <scale>1 1 1</scale>
              <uri>meshes/kuka/collision/link_5.stl</uri>
              
            </mesh>
          </geometry>
        </collision>
       
      </link>
    
      <link name="lbr_iiwa_link_6">
        <pose frame=''>0 -0.0607 1.14 1.5708 0 -3.14159</pose>
        <inertial>
            <pose frame=''>0 0.0006 0.0004 0 0 0</pose>
            <mass>2.3466</mass>
            <inertia>
                <ixx>0.006509</ixx>
                <ixy>0</ixy>
                <ixz>0</ixz>
                <iyy>0.006259</iyy>
                <iyz>0.00031891</iyz>
                <izz>0.004527</izz>
            </inertia>
        </inertial>
        <collision name='lbr_iiwa_link_6_collision'>
          <pose frame=''>0 0 0 0 -0 0</pose>
          <geometry>
            <mesh>
              
              <scale>1 1 1</scale>
              <uri>meshes/kuka/collision/link_6.stl</uri>
              
            </mesh>
          </geometry>
        </collision>
       
      </link>
    
      <link name="lbr_iiwa_link_7">
        <pose frame=''>0 0 1.2205000000000001 0 0 0</pose>
        <inertial>
            <pose frame=''>0 0.00043 0.071108 0 0 0</pose>
            <mass>3.129</mass>
            <inertia>
                <ixx>0.145258</ixx>
                <ixy>0.0005912</ixy>
                <ixz>0</ixz>
                <iyy>0.145283</iyy>
                <iyz>-0.000503009</iyz>
                <izz>0.0572184</izz>
            </inertia>
        </inertial>
        <collision name='lbr_iiwa_link_7_collision'>
          <pose frame=''>0 0 0 0 -0 0</pose>
          <geometry>
            <mesh>
              
              <scale>1 1 1</scale>
              <uri>meshes/kuka/collision/link_7.stl</uri>
              
            </mesh>
          </geometry>
        </collision>
       
      </link>
    
   
    
      <joint name="J0" type="revolute">
        <child>lbr_iiwa_link_1</child>
        <parent>lbr_iiwa_link_0</parent>
        <axis>
          <xyz>0 0 1</xyz>
          <limit>
            <lower>-2.96706</lower>
            <upper>2.96706</upper>
            <effort>300</effort>
            <velocity>10</velocity>
          </limit>
          <dynamics>
            <damping>0.5</damping>
            <friction>0</friction>
            <spring_reference>0</spring_reference>
            <spring_stiffness>0</spring_stiffness>
          </dynamics>
        </axis>
      </joint>
    
      <joint name="J1" type="revolute">
        <child>lbr_iiwa_link_2</child>
        <parent>lbr_iiwa_link_1</parent>
        <axis>
          <xyz>0 0 1</xyz>
          <limit>
            <lower>-2.0944</lower>
            <upper>2.0944</upper>
            <effort>300</effort>
            <velocity>10</velocity>
          </limit>
          <dynamics>
            <damping>0.5</damping>
            <friction>0</friction>
            <spring_reference>0</spring_reference>
            <spring_stiffness>0</spring_stiffness>
          </dynamics>
        </axis>
      </joint>
    
      <joint name="J2" type="revolute">
        <child>lbr_iiwa_link_3</child>
        <parent>lbr_iiwa_link_2</parent>
        <axis>
          <xyz>0 0 1</xyz>
          <limit>
            <lower>-2.96706</lower>
            <upper>2.96706</upper>
            <effort>300</effort>
            <velocity>10</velocity>
          </limit>
          <dynamics>
            <damping>0.5</damping>
            <friction>0</friction>
            <spring_reference>0</spring_reference>
            <spring_stiffness>0</spring_stiffness>
          </dynamics>
        </axis>
      </joint>
    
      <joint name="J3" type="revolute">
        <child>lbr_iiwa_link_4</child>
        <parent>lbr_iiwa_link_3</parent>
        <axis>
          <xyz>0 0 1</xyz>
          <limit>
            <lower>-2.0944</lower>
            <upper>2.0944</upper>
            <effort>300</effort>
            <velocity>10</velocity>
          </limit>
          <dynamics>
            <damping>0.5</damping>
            <friction>0</friction>
            <spring_reference>0</spring_reference>
            <spring_stiffness>0</spring_stiffness>
          </dynamics>
        </axis>
      </joint>
    
      <joint name="J4" type="revolute">
        <child>lbr_iiwa_link_5</child>
        <parent>lbr_iiwa_link_4</parent>
        <axis>
          <xyz>0 0 1</xyz>
          <limit>
            <lower>-2.96706</lower>
            <upper>2.96706</upper>
            <effort>300</effort>
            <velocity>10</velocity>
          </limit>
          <dynamics>
            <damping>0.5</damping>
            <friction>0</friction>
            <spring_reference>0</spring_reference>
            <spring_stiffness>0</spring_stiffness>
          </dynamics>
        </axis>
      </joint>
    
      <joint name="J5" type="revolute">
        <child>lbr_iiwa_link_6</child>
        <parent>lbr_iiwa_link_5</parent>
        <axis>
          <xyz>0 0 1</xyz>
          <limit>
            <lower>-2.0944</lower>
            <upper>2.0944</upper>
            <effort>300</effort>
            <velocity>10</velocity>
          </limit>
          <dynamics>
            <damping>0.5</damping>
            <friction>0</friction>
            <spring_reference>0</spring_reference>
            <spring_stiffness>0</spring_stiffness>
          </dynamics>
        </axis>
      </joint>
    
      <joint name="J6" type="revolute">
        <child>lbr_iiwa_link_7</child>
        <parent>lbr_iiwa_link_6</parent>
        <axis>
          <xyz>0 0 1</xyz>
          <limit>
            <lower>-3.05433</lower>
            <upper>3.05433</upper>
            <effort>300</effort>
            <velocity>10</velocity>
          </limit>
          <dynamics>
            <damping>0.5</damping>
            <friction>0</friction>
            <spring_reference>0</spring_reference>
            <spring_stiffness>0</spring_stiffness>
          </dynamics>
        </axis>
      </joint>
    

    <link name = "lbr_iiwa_link_ee">

        <pose frame=''>0 0 1.2655 0 0 0</pose>
        <inertial>
            <pose frame=''>0 0.00043 0.071108 0 0 0</pose>
            <mass>1.0e-22</mass>
            <inertia>
                <ixx>0.145258</ixx>
                <ixy>0.0005912</ixy>
                <ixz>0</ixz>
                <iyy>0.145283</iyy>
                <iyz>-0.000503009</iyz>
                <izz>0.0572184</izz>
            </inertia>
        </inertial>
           
    </link>
    
    <joint name="J7" type="fixed">
        <child>lbr_iiwa_link_ee</child>
        <parent>lbr_iiwa_link_7</parent>
        <axis>

            <xyz>0 -1 0</xyz>
         </axis>
    </joint>  
    <!--Hand-->

    <joint name="forearm_world" type="fixed">
        <child>forearm</child>
        <parent>lbr_iiwa_link_ee</parent>
    </joint>

    <link name ="forearm" >
        <pose frame=''>0 0 1.2655 0 0 1.5707963267948966</pose>
        <inertial>
            <pose frame=''>0 0 0.09 0 0 0</pose>
            <mass>1.8</mass>
            <inertia>
                <ixx>0.108</ixx>
                <ixy>0</ixy>
                <ixz>0</ixz>
                <iyy>0.108</iyy>
                <iyz>0</iyz>
                <izz>0.054</izz>
            </inertia>
        </inertial>

       
        <collision name='collision_forearm_link'>
        
            <geometry>
                <mesh>
                    <scale>1 1 1</scale>
                    <uri>meshes/forearm_lite.dae</uri>
                </mesh>
            </geometry>
        </collision>
    </link>

    <link name = "palm">
        <pose frame=''>0 -0.015 1.4145 -0.6981317007977318 0 0</pose>
        <inertial>
            <pose frame=''>0 0 0.035 0 0 0</pose>
            <mass>0.3</mass>
            <inertia>
                <ixx>0.0003581</ixx>
                <ixy>0</ixy>
                <ixz>0</ixz>
                <iyy>0.0005287</iyy>
                <iyz>0</iyz>
                <izz>0.000191</izz>
            </inertia>
        </inertial>
        
       
        <collision name="collision_palm_link">

            <geometry>
                <mesh>
                    <scale>-0.001 0.001 0.001</scale>
                <uri>meshes/palm5_c.dae</uri>
            </mesh>
            </geometry>
        </collision>


        
    </link>
    <joint name="palm_forearm" type="fixed">
        <child>palm</child>
        <parent>forearm</parent>
        <axis>

            <xyz>0 -1 0</xyz>
         </axis>
    </joint>  

    
    <link name = "palm_fake">

        <pose frame=''>-0.01 0.020909000000000004 1.4544000000000001 -0.6981317007977318 0 0</pose>
        <inertial>
            <pose frame=''>0 0 0.0 0 0 0</pose>
            <mass>0.0</mass>
            <inertia>
                <ixx>0.0</ixx>
                <ixy>0</ixy>
                <ixz>0</ixz>
                <iyy>0.0</iyy>
                <iyz>0</iyz>
                <izz>0.0</izz>
            </inertia>
        </inertial>
           
    </link>

    <joint name="palm_palm_fake" type="fixed">
        <child>palm_fake</child>
        <parent>palm</parent>
        <axis>

            <xyz>0 -1 0</xyz>
         </axis>
    </joint>  

    

        <link name = "knuckle_FF">

            <pose frame=''>-0.033 0.0461 1.48727 -0.698132 0 0</pose>
            <inertial>
                <pose frame=''>0 0 0 0 0 0</pose>
                <mass>0.008</mass>
                <inertia>
                    <ixx>2.6e-07</ixx>
                    <ixy>0</ixy>
                    <ixz>0</ixz>
                    <iyy>2.6e-07</iyy>
                    <iyz>0</iyz>
                    <izz>3.2e-07</izz>
                </inertia>
            </inertial>

           
            <collision name='collision_knuckle_link_FF'>
                <geometry>
                <mesh>
                    <scale>0.001 0.001 0.001</scale>
                    <uri>meshes/knuckle.dae</uri>
                </mesh>
            </geometry>
            </collision>
        </link>
        <link name = "proximal_FF">
            <pose frame=''>-0.033 0.0461 1.48727 -0.698132 0 0</pose>
            <inertial>
                <pose frame=''>0 0 0.0225 0 0 0</pose>
                <mass>0.03</mass>
                <inertia>
                    <ixx>9.8e-06</ixx>
                    <ixy>0</ixy>
                    <ixz>0</ixz>
                    <iyy>1.0e-05</iyy>
                    <iyz>0</iyz>
                    <izz>1.8e-06</izz>
                </inertia>
            </inertial>

           
            <collision name='collision_proximal_link_FF'>
                <geometry>
                <mesh>
                    <scale>0.001 0.001 0.001</scale>
                    <uri>meshes/F3_c.dae</uri>
                </mesh>
            </geometry>
            </collision>
        </link>
        <link name = "middle_FF">
            <pose frame=''>-0.033 0.07499 1.521746 -0.698132 0 0</pose>
            <inertial>
                <pose frame=''>0 0 0.0125 0 0 0</pose>
                <mass>0.017</mass>
                <inertia>
                    <ixx>2.6e-06</ixx>
                    <ixy>0</ixy>
                    <ixz>0</ixz>
                    <iyy>2.7e-06</iyy>
                    <iyz>0</iyz>
                    <izz>8.7e-07</izz>
                </inertia>
            </inertial>

           
            <collision name='collision_middle_link_FF'>
                <geometry>
                    <mesh>
                        <scale>0.001 0.001 0.001</scale>
                        <uri>meshes/F2_c.dae</uri>
                    </mesh>
                </geometry>
            </collision>
        </link>
        <link name =  "distal_FF">
            <pose frame=''>-0.033 0.09106 1.540897 -0.698132 0 0</pose>
            <inertial>
                <pose frame=''>0 0 0.012 0 0 0</pose>
                <mass>0.012</mass>
                <inertia>
                    <ixx>9.4e-07</ixx>
                    <ixy>0</ixy>
                    <ixz>0</ixz>
                    <iyy>1.1e-06</iyy>
                    <iyz>0</iyz>
                    <izz>5.3e-07</izz>
                </inertia>
            </inertial>

           
            <collision name='collision_distal_link_FF'>
                <geometry>
                    <mesh>
                        <scale>0.001 0.001 0.001</scale>
                        <uri>meshes/F1.dae</uri>
                    </mesh>
                </geometry>
            </collision>
        </link>

        
            
            <joint name="J3_FF" type="revolute">
                <child>proximal_FF</child>
                <parent>knuckle_FF</parent>

                <axis>
                    <xyz>1 0 0</xyz>
                    <limit>
                        <lower>0 </lower>
                        <upper>1.5708 </upper>
                        <effort>6.0 </effort>
                        <velocity>0.8 </velocity>
                    </limit>
                    <dynamics>
                        <damping>0.1</damping>
                        <friction>0</friction>
                        <spring_reference>0</spring_reference>
                        <spring_stiffness>0</spring_stiffness>
                    </dynamics>
                </axis>
            </joint>
        
            
            <joint name="J2_FF" type="revolute">
                <child>middle_FF</child>
                <parent>proximal_FF</parent>

                <axis>
                    <xyz>1 0 0</xyz>
                    <limit>
                        <lower>0 </lower>
                        <upper>1.5708 </upper>
                        <effort>6.0 </effort>
                        <velocity>0.8 </velocity>
                    </limit>
                    <dynamics>
                        <damping>0.1</damping>
                        <friction>0</friction>
                        <spring_reference>0</spring_reference>
                        <spring_stiffness>0</spring_stiffness>
                    </dynamics>
                </axis>
            </joint>
        
            
            <joint name="J1_FF" type="revolute">
                <child>distal_FF</child>
                <parent>middle_FF</parent>

                <axis>
                    <xyz>1 0 0</xyz>
                    <limit>
                        <lower>0 </lower>
                        <upper>1.5708 </upper>
                        <effort>6.0 </effort>
                        <velocity>0.8 </velocity>
                    </limit>
                    <dynamics>
                        <damping>0.1</damping>
                        <friction>0</friction>
                        <spring_reference>0</spring_reference>
                        <spring_stiffness>0</spring_stiffness>
                    </dynamics>
                </axis>
            </joint>
        
        <joint name='J4_FF' type="revolute">
            <child>knuckle_FF</child>
            <parent>palm</parent>

            <axis>
                <xyz>0 0.766044 -0.642788</xyz>
                <limit>
                    <lower>-0.349066 </lower>
                    <upper>0.349066 </upper>
                    <effort>6.0 </effort>
                    <velocity>0.8 </velocity>
                </limit>
                <dynamics>
                    <damping>0.1</damping>
                    <friction>0</friction>
                    <spring_reference>0</spring_reference>
                    <spring_stiffness>0</spring_stiffness>
                </dynamics>
            </axis>
        </joint>

    

        <link name = "knuckle_MF">

            <pose frame=''>-0.011000000000000003 0.048636 1.4903380000000002 -0.698132 0 0</pose>
            <inertial>
                <pose frame=''>0 0 0 0 0 0</pose>
                <mass>0.008</mass>
                <inertia>
                    <ixx>2.6e-07</ixx>
                    <ixy>0</ixy>
                    <ixz>0</ixz>
                    <iyy>2.6e-07</iyy>
                    <iyz>0</iyz>
                    <izz>3.2e-07</izz>
                </inertia>
            </inertial>

           
            <collision name='collision_knuckle_link_MF'>
                <geometry>
                <mesh>
                    <scale>0.001 0.001 0.001</scale>
                    <uri>meshes/knuckle.dae</uri>
                </mesh>
            </geometry>
            </collision>
        </link>
        <link name = "proximal_MF">
            <pose frame=''>-0.011000000000000003 0.048636 1.4903380000000002 -0.698132 0 0</pose>
            <inertial>
                <pose frame=''>0 0 0.0225 0 0 0</pose>
                <mass>0.03</mass>
                <inertia>
                    <ixx>9.8e-06</ixx>
                    <ixy>0</ixy>
                    <ixz>0</ixz>
                    <iyy>1.0e-05</iyy>
                    <iyz>0</iyz>
                    <izz>1.8e-06</izz>
                </inertia>
            </inertial>

           
            <collision name='collision_proximal_link_MF'>
                <geometry>
                <mesh>
                    <scale>0.001 0.001 0.001</scale>
                    <uri>meshes/F3_c.dae</uri>
                </mesh>
            </geometry>
            </collision>
        </link>
        <link name = "middle_MF">
            <pose frame=''>-0.011000000000000003 0.077526 1.5248140000000001 -0.698132 0 0</pose>
            <inertial>
                <pose frame=''>0 0 0.0125 0 0 0</pose>
                <mass>0.017</mass>
                <inertia>
                    <ixx>2.6e-06</ixx>
                    <ixy>0</ixy>
                    <ixz>0</ixz>
                    <iyy>2.7e-06</iyy>
                    <iyz>0</iyz>
                    <izz>8.7e-07</izz>
                </inertia>
            </inertial>

           
            <collision name='collision_middle_link_MF'>
                <geometry>
                    <mesh>
                        <scale>0.001 0.001 0.001</scale>
                        <uri>meshes/F2_c.dae</uri>
                    </mesh>
                </geometry>
            </collision>
        </link>
        <link name =  "distal_MF">
            <pose frame=''>-0.011000000000000003 0.093596 1.543965 -0.698132 0 0</pose>
            <inertial>
                <pose frame=''>0 0 0.012 0 0 0</pose>
                <mass>0.012</mass>
                <inertia>
                    <ixx>9.4e-07</ixx>
                    <ixy>0</ixy>
                    <ixz>0</ixz>
                    <iyy>1.1e-06</iyy>
                    <iyz>0</iyz>
                    <izz>5.3e-07</izz>
                </inertia>
            </inertial>

           
            <collision name='collision_distal_link_MF'>
                <geometry>
                    <mesh>
                        <scale>0.001 0.001 0.001</scale>
                        <uri>meshes/F1.dae</uri>
                    </mesh>
                </geometry>
            </collision>
        </link>

        
            
            <joint name="J3_MF" type="revolute">
                <child>proximal_MF</child>
                <parent>knuckle_MF</parent>

                <axis>
                    <xyz>1 0 0</xyz>
                    <limit>
                        <lower>0 </lower>
                        <upper>1.5708 </upper>
                        <effort>6.0 </effort>
                        <velocity>0.8 </velocity>
                    </limit>
                    <dynamics>
                        <damping>0.1</damping>
                        <friction>0</friction>
                        <spring_reference>0</spring_reference>
                        <spring_stiffness>0</spring_stiffness>
                    </dynamics>
                </axis>
            </joint>
        
            
            <joint name="J2_MF" type="revolute">
                <child>middle_MF</child>
                <parent>proximal_MF</parent>

                <axis>
                    <xyz>1 0 0</xyz>
                    <limit>
                        <lower>0 </lower>
                        <upper>1.5708 </upper>
                        <effort>6.0 </effort>
                        <velocity>0.8 </velocity>
                    </limit>
                    <dynamics>
                        <damping>0.1</damping>
                        <friction>0</friction>
                        <spring_reference>0</spring_reference>
                        <spring_stiffness>0</spring_stiffness>
                    </dynamics>
                </axis>
            </joint>
        
            
            <joint name="J1_MF" type="revolute">
                <child>distal_MF</child>
                <parent>middle_MF</parent>

                <axis>
                    <xyz>1 0 0</xyz>
                    <limit>
                        <lower>0 </lower>
                        <upper>1.5708 </upper>
                        <effort>6.0 </effort>
                        <velocity>0.8 </velocity>
                    </limit>
                    <dynamics>
                        <damping>0.1</damping>
                        <friction>0</friction>
                        <spring_reference>0</spring_reference>
                        <spring_stiffness>0</spring_stiffness>
                    </dynamics>
                </axis>
            </joint>
        
        <joint name='J4_MF' type="revolute">
            <child>knuckle_MF</child>
            <parent>palm</parent>

            <axis>
                <xyz>0 0.766044 -0.642788</xyz>
                <limit>
                    <lower>-0.349066 </lower>
                    <upper>0.349066 </upper>
                    <effort>6.0 </effort>
                    <velocity>0.8 </velocity>
                </limit>
                <dynamics>
                    <damping>0.1</damping>
                    <friction>0</friction>
                    <spring_reference>0</spring_reference>
                    <spring_stiffness>0</spring_stiffness>
                </dynamics>
            </axis>
        </joint>

    

        <link name = "knuckle_RF">

            <pose frame=''>0.010999999999999996 0.0461 1.48727 -0.698132 0 0</pose>
            <inertial>
                <pose frame=''>0 0 0 0 0 0</pose>
                <mass>0.008</mass>
                <inertia>
                    <ixx>2.6e-07</ixx>
                    <ixy>0</ixy>
                    <ixz>0</ixz>
                    <iyy>2.6e-07</iyy>
                    <iyz>0</iyz>
                    <izz>3.2e-07</izz>
                </inertia>
            </inertial>

           
            <collision name='collision_knuckle_link_RF'>
                <geometry>
                <mesh>
                    <scale>0.001 0.001 0.001</scale>
                    <uri>meshes/knuckle.dae</uri>
                </mesh>
            </geometry>
            </collision>
        </link>
        <link name = "proximal_RF">
            <pose frame=''>0.010999999999999996 0.0461 1.48727 -0.698132 0 0</pose>
            <inertial>
                <pose frame=''>0 0 0.0225 0 0 0</pose>
                <mass>0.03</mass>
                <inertia>
                    <ixx>9.8e-06</ixx>
                    <ixy>0</ixy>
                    <ixz>0</ixz>
                    <iyy>1.0e-05</iyy>
                    <iyz>0</iyz>
                    <izz>1.8e-06</izz>
                </inertia>
            </inertial>

           
            <collision name='collision_proximal_link_RF'>
                <geometry>
                <mesh>
                    <scale>0.001 0.001 0.001</scale>
                    <uri>meshes/F3_c.dae</uri>
                </mesh>
            </geometry>
            </collision>
        </link>
        <link name = "middle_RF">
            <pose frame=''>0.010999999999999996 0.07499 1.521746 -0.698132 0 0</pose>
            <inertial>
                <pose frame=''>0 0 0.0125 0 0 0</pose>
                <mass>0.017</mass>
                <inertia>
                    <ixx>2.6e-06</ixx>
                    <ixy>0</ixy>
                    <ixz>0</ixz>
                    <iyy>2.7e-06</iyy>
                    <iyz>0</iyz>
                    <izz>8.7e-07</izz>
                </inertia>
            </inertial>

           
            <collision name='collision_middle_link_RF'>
                <geometry>
                    <mesh>
                        <scale>0.001 0.001 0.001</scale>
                        <uri>meshes/F2_c.dae</uri>
                    </mesh>
                </geometry>
            </collision>
        </link>
        <link name =  "distal_RF">
            <pose frame=''>0.010999999999999996 0.09106 1.540897 -0.698132 0 0</pose>
            <inertial>
                <pose frame=''>0 0 0.012 0 0 0</pose>
                <mass>0.012</mass>
                <inertia>
                    <ixx>9.4e-07</ixx>
                    <ixy>0</ixy>
                    <ixz>0</ixz>
                    <iyy>1.1e-06</iyy>
                    <iyz>0</iyz>
                    <izz>5.3e-07</izz>
                </inertia>
            </inertial>

           
            <collision name='collision_distal_link_RF'>
                <geometry>
                    <mesh>
                        <scale>0.001 0.001 0.001</scale>
                        <uri>meshes/F1.dae</uri>
                    </mesh>
                </geometry>
            </collision>
        </link>

        
            
            <joint name="J3_RF" type="revolute">
                <child>proximal_RF</child>
                <parent>knuckle_RF</parent>

                <axis>
                    <xyz>1 0 0</xyz>
                    <limit>
                        <lower>0 </lower>
                        <upper>1.5708 </upper>
                        <effort>6.0 </effort>
                        <velocity>0.8 </velocity>
                    </limit>
                    <dynamics>
                        <damping>0.1</damping>
                        <friction>0</friction>
                        <spring_reference>0</spring_reference>
                        <spring_stiffness>0</spring_stiffness>
                    </dynamics>
                </axis>
            </joint>
        
            
            <joint name="J2_RF" type="revolute">
                <child>middle_RF</child>
                <parent>proximal_RF</parent>

                <axis>
                    <xyz>1 0 0</xyz>
                    <limit>
                        <lower>0 </lower>
                        <upper>1.5708 </upper>
                        <effort>6.0 </effort>
                        <velocity>0.8 </velocity>
                    </limit>
                    <dynamics>
                        <damping>0.1</damping>
                        <friction>0</friction>
                        <spring_reference>0</spring_reference>
                        <spring_stiffness>0</spring_stiffness>
                    </dynamics>
                </axis>
            </joint>
        
            
            <joint name="J1_RF" type="revolute">
                <child>distal_RF</child>
                <parent>middle_RF</parent>

                <axis>
                    <xyz>1 0 0</xyz>
                    <limit>
                        <lower>0 </lower>
                        <upper>1.5708 </upper>
                        <effort>6.0 </effort>
                        <velocity>0.8 </velocity>
                    </limit>
                    <dynamics>
                        <damping>0.1</damping>
                        <friction>0</friction>
                        <spring_reference>0</spring_reference>
                        <spring_stiffness>0</spring_stiffness>
                    </dynamics>
                </axis>
            </joint>
        
        <joint name='J4_RF' type="revolute">
            <child>knuckle_RF</child>
            <parent>palm</parent>

            <axis>
                <xyz>0 0.766044 -0.642788</xyz>
                <limit>
                    <lower>-0.349066 </lower>
                    <upper>0.349066 </upper>
                    <effort>6.0 </effort>
                    <velocity>0.8 </velocity>
                </limit>
                <dynamics>
                    <damping>0.1</damping>
                    <friction>0</friction>
                    <spring_reference>0</spring_reference>
                    <spring_stiffness>0</spring_stiffness>
                </dynamics>
            </axis>
        </joint>

    


    <link name = "thbase">
        <pose frame=''>-0.034 -0.0028710000000000003 1.442179 0.870557 0.572429 -2.5703</pose>
        <inertial>
            <pose frame=''>0 0 0 0 0 0</pose>
            <mass>0.01</mass>
            <inertia>
                <ixx>1.6e-07</ixx>
                <ixy>0</ixy>
                <ixz>0</ixz>
                <iyy>1.6e-07</iyy>
                <iyz>0</iyz>
                <izz>1.6e-07</izz>
            </inertia>
        </inertial>
       
        <collision name='collision_thbase_link'>
            <pose frame=''>0 0 0 0 0 0</pose>
            <geometry>

                <sphere>
                    <radius>0.005</radius>
                </sphere>
            
            </geometry>
        </collision>
    </link>
    <link name = "thproximal">
            
        <pose frame=''>-0.034 -0.0028710000000000003 1.442179 0.870557 0.572429 -2.5703</pose>
        <inertial>
            <pose frame=''>0 0 0.021111 0 0 0</pose>
            <mass>0.04</mass>
            <inertia>
                <ixx>1.36e-05</ixx>
                <ixy>0</ixy>
                <ixz>0</ixz>
                <iyy>1.36e-05</iyy>
                <iyz>0</iyz>
                <izz>3.13e-06</izz>
            </inertia>
        </inertial>

       
        <collision name='collision_thproximal_link'>
            <geometry>
                <mesh>
                    <scale>0.001 0.001 0.001</scale>
                    <uri>meshes/TH3_z_c.dae</uri>
                </mesh>
            </geometry>
        </collision>
    </link>
    <link name = "thhub">
        <pose frame=''>-0.06087000000000001 0.014400999999999999 1.462763 0.870557 0.572429 -2.5703</pose>
        <inertial>
            <pose frame=''>0 0 0 0 0 0</pose>
            <mass>0.005</mass>
            <inertia>
                <ixx>1.0e-06</ixx>
                <ixy>0</ixy>
                <ixz>0</ixz>
                <iyy>1.0e-06</iyy>
                <iyz>0</iyz>
                <izz>3.0e-07</izz>
            </inertia>
        </inertial>
       
        <collision name='collision_thhub_link'>
            <geometry>
                <box>
                    <size>0.001 0.001 0.001</size>
                </box>
            </geometry>
        </collision>
    </link>
    <link name = "thmiddle">
            
        <pose frame=''>-0.06087000000000001 0.014400999999999999 1.462763 0.870557 0.572429 -2.5703</pose>
        <inertial>
            <pose frame=''>0 0 0.16 0 0 0</pose>
            <mass>0.02</mass>
            <inertia>
                <ixx>5.1e-06</ixx>
                <ixy>0</ixy>
                <ixz>0</ixz>
                <iyy>5.1e-06</iyy>
                <iyz>0</iyz>
                <izz>1.21e-06</izz>
            </inertia>
        </inertial>

       

        <collision name='collision_thmiddle_link'>
            <geometry>
                <mesh>
                    <scale>0.001 0.001 0.001</scale>
                    <uri>meshes/TH2_z_c.dae</uri>
                </mesh>
            </geometry>
        </collision>
    </link>
    <link name = "thdistal">
            
        <pose frame=''>-0.083498 0.028946 1.480096 -0.785398 0.698132 1.5707999999999998</pose>
        <inertial>
            <pose frame=''>0 0 0.014559 0 0 0</pose>
            <mass>0.016</mass>
            <inertia>
                <ixx>2.1e-06</ixx>
                <ixy>0</ixy>
                <ixz>0</ixz>
                <iyy>2.2e-06</iyy>
                <iyz>0</iyz>
                <izz>1.0e-06</izz>
            </inertia>
        </inertial>

       
        <collision name='collision_thdistal_link'>
            <geometry>
                <mesh>
                    <scale>0.001 0.001 0.001</scale>
                    <uri>meshes/TH1_z.dae</uri>
                </mesh>
            </geometry>
        </collision>
    </link>

    
        <joint name ="THJ5"  type ="revolute">
            <child>thbase</child>
            <parent>palm</parent>
            <axis>
                <xyz>0 0 0.541675</xyz>
                <limit>
                    <lower>-1.0472 </lower>
                    <upper>1.0472 </upper>
                    <effort>8.0 </effort>
                    <velocity>0.7 </velocity>
                </limit>
                <dynamics>
                    <damping>0.1</damping>
                    <friction>0</friction>
                </dynamics>
            </axis>
        </joint>
    
        <joint name ="THJ4"  type ="revolute">
            <child>thproximal</child>
            <parent>thbase</parent>
            <axis>
                <xyz>-0.707107 -0.454519 -0.541675</xyz>
                <limit>
                    <lower>0 </lower>
                    <upper>1.22173 </upper>
                    <effort>8.0 </effort>
                    <velocity>0.7 </velocity>
                </limit>
                <dynamics>
                    <damping>0.2</damping>
                    <friction>0</friction>
                </dynamics>
            </axis>
        </joint>
    
        <joint name ="THJ2"  type ="revolute">
            <child>thmiddle</child>
            <parent>thhub</parent>
            <axis>
                <xyz>0 -0.766044 0.642788</xyz>
                <limit>
                    <lower>-0.698132 </lower>
                    <upper>0.698132 </upper>
                    <effort>8.0 </effort>
                    <velocity>0.7 </velocity>
                </limit>
                <dynamics>
                    <damping>0.1</damping>
                    <friction>0</friction>
                </dynamics>
            </axis>
        </joint>
    
        <joint name ="THJ1"  type ="revolute">
            <child>thdistal</child>
            <parent>thmiddle</parent>
            <axis>
                <xyz>1 0 0</xyz>
                <limit>
                    <lower>0 </lower>
                    <upper>1.5708 </upper>
                    <effort>8.0 </effort>
                    <velocity>0.7 </velocity>
                </limit>
                <dynamics>
                    <damping>0.2</damping>
                    <friction>0</friction>
                </dynamics>
            </axis>
        </joint>
    
    <joint name ="THJ3"  type ="fixed">
        <child>thhub</child>
        <parent>thproximal</parent>
        <axis>
            <xyz>1 0 0</xyz>
        </axis>
    </joint>






 
   
  </model>

</sdf>