<?xml version='1.0'?>
<%
# This is where ruby code goes
 # models to include
 distal = "model://finger/F1.dae"
 middle = "model://finger/F2.dae"
 proximal = "model://finger/F3.dae"
 knuckle = "model://finger/knuckle.dae"
%>
<sdf version='1.6'>
  <model name='finger'>
        <!-- knuckle -> proximal -->
        <link name = "knuckle_link">
            <pose frame=''>0 0 0 0 0 0</pose>
            <inertial>
                <pose frame=''>0 0 0 0 0 0</pose>
                <mass>0.008</mass>
                <inertia>
                    <ixx>0.00000026</ixx>
                    <ixy>0</ixy>
                    <ixz>0</ixz>
                    <iyy>0.00000026</iyy>
                    <iyz>0</iyz>
                    <izz>0.00000032</izz>
                </inertia>
            </inertial>
        
            <visual name='visual'>
                
                <geometry>
                    <mesh>
                        <scale>0.001 0.001 0.001</scale>
                        <uri><%= knuckle %></uri>
                    </mesh>
                </geometry>
                <material>

                </material>
            </visual>
            <collision name='collision'>
                <geometry>
                    <mesh>
                        <scale>0.001 0.001 0.001</scale>
                        <uri><%= knuckle %></uri>
                    </mesh>
                </geometry>
            </collision>
        </link>
        <link name = "proximal_link">
            <pose frame=''>0 0 0 0 0 0</pose>
            <inertial>
                <pose frame=''>0 0 0.0225 0 0 0</pose>
                <mass>0.030</mass>
                <inertia>
                    <ixx>0.0000098</ixx>
                    <ixy>0</ixy>
                    <ixz>0</ixz>
                    <iyy>0.00001</iyy>
                    <iyz>0</iyz>
                    <izz>0.0000018</izz>
                </inertia>
            </inertial>
        
            <visual name='visual'>
                
                <geometry>
                    <mesh>
                        <scale>0.001 0.001 0.001</scale>
                        <uri><%= proximal %></uri>
                    </mesh>
                </geometry>
                <material>

                </material>
            </visual>
            <collision name='collision'>
                <geometry>
                    <mesh>
                        <scale>0.001 0.001 0.001</scale>
                        <uri><%= proximal %></uri>
                    </mesh>
                </geometry>
            </collision>
        </link>
        
        <joint name="knuckle_proximal" type="revolute">
            <parent>knuckle_link</parent>
            <child>proximal_link</child>
             <pose frame=''>0 0 0.025 0 0 0</pose>
            <axis>
                <xyz>1 0 0</xyz>
            </axis>

        </joint>
        -->
  </model>
</sdf>