<?xml version='1.0'?>

<sdf version='1.6'>

<model name='shadow_hand'>
    <static>true</static>
    <link name = "forearm_link">
        <pose frame=''>0 0 0 0 0 0</pose>
        <inertial>
            <pose frame=''>0 0 0.09 0 0 0</pose>
            <mass>3.0</mass>
            <inertia>
                <ixx>0.0138</ixx>
                <ixy>0</ixy>
                <ixz>0</ixz>
                <iyy>0.0138</iyy>
                <iyz>0</iyz>
                <izz>0.00744</izz>
            </inertia>
        </inertial>

        <visual name='visual'>
            
            <geometry>
                <mesh>
                    <scale>0.001 0.001 0.001</scale>
                    <uri>model://shadow_hand/forearm.dae</uri>
                </mesh>
            </geometry>
            <material>

            </material>
        </visual>
        <collision name='collision'>
           
            <geometry>
                <mesh>
                    <scale>0.001 0.001 0.001</scale>
                    <uri>model://shadow_hand/forearm.dae</uri>
                </mesh>
            </geometry>
        </collision>
        <gravity>1</gravity>
        <velocity_decay/>
        <self_collide>0</self_collide>
    </link>
    <link name = "wrist_link">
        <pose frame=''>0.0 -0.01 0.213 0 0 0</pose>
        <inertial>
            <pose frame=''>0 0 0.029 0 0 0</pose>
            <mass>0.1</mass>
            <inertia>
                <ixx>3.5e-05</ixx>
                <ixy>0</ixy>
                <ixz>0</ixz>
                <iyy>6.4e-05</iyy>
                <iyz>0</iyz>
                <izz>4.38e-05</izz>
            </inertia>
        </inertial>

        <visual name='visual'>
            <geometry>
                <mesh>
                    <scale>0.001 0.001 0.001</scale>
                    <uri>model://shadow_hand/wrist.dae</uri>
                </mesh>
            </geometry>
            <material>

            </material>
        </visual>
        <collision name='collision'>
            <geometry>
                <mesh>
                    <scale>0.001 0.001 0.001</scale>
                    <uri>model://shadow_hand/wrist.dae</uri>
                </mesh>
            </geometry>
        </collision>
        <gravity>1</gravity>
        <velocity_decay/>
        <self_collide>0</self_collide>
    </link>
     <joint name='WRJ2' type='revolute'>
        <child>wrist_link</child>
        <parent>forearm_link</parent>
        <axis>
            <xyz>0 1 0</xyz>
            <limit>
                <lower>-0.523599</lower>
                <upper>0.174533</upper>
                <effort>10</effort>
                <velocity>2.0</velocity>
            </limit>
            <dynamics>
                <damping>0.1</damping>
                <friction>0.0</friction>
                <spring_reference>0.0</spring_reference>
                <spring_stiffness>0.0</spring_stiffness>
            </dynamics>
            <use_parent_model_frame>1</use_parent_model_frame>
        </axis>
        <physics>
            <provide_feedback>1</provide_feedback>
            <ode>
              <provide_feedback>1</provide_feedback>
              <implicit_spring_damper>1</implicit_spring_damper>
              <cfm_damping>1</cfm_damping>
              <limit>
                <cfm>0</cfm>
                <erp>0.2</erp>
              </limit>
            </ode>
        </physics>
    </joint>  


    <link name = "palm_link">
        <pose frame=''>0.0 -0.01 0.247 0 0 0</pose>
        <inertial>
            <pose frame=''>0 0 0.035 0 0 0</pose>
            <mass>0.3</mass>
            <inertia>
                <ixx>0.0003581</ixx>
                <ixy>0</ixy>
                <ixz>0</ixz>
                <iyy>0.0005287</iyy>
                <iyz>0</iyz>
                <izz>0.000191</izz>
            </inertia>
        </inertial>
	  
        <visual name='visual'>
            
            <geometry>
                <mesh>
                    <scale>-0.001 0.001 0.001</scale>
                    <uri>model://shadow_hand/palm_mirror.dae</uri>
                </mesh>
            </geometry>
            <material>

            </material>
        </visual>
        <collision name='collision'>
            
            <geometry>
                <mesh>
                    <scale>-0.001 0.001 0.001</scale>
                    <uri>model://shadow_hand/palm_mirror.dae</uri>
                </mesh>
            </geometry>
            <material>

            </material>
        </collision>
        <gravity>1</gravity>
        <velocity_decay/>
        <self_collide>0</self_collide>
   
    </link>
    <joint name='WRJ1' type='revolute'>
        <child>palm_link</child>
        <parent>wrist_link</parent>
        <axis>
            <xyz>1 0 0</xyz>
            <limit>
                <lower>-0.698132</lower>
                <upper>0.488692</upper>
                <effort>30</effort>
                <velocity>2.0</velocity>
            </limit>
            <dynamics>
                <damping>0.1</damping>
                <friction>0.0</friction>
                <spring_reference>0.0</spring_reference>
                <spring_stiffness>0.0</spring_stiffness>
            </dynamics>
            <use_parent_model_frame>1</use_parent_model_frame>
        </axis>
        <physics>
            <provide_feedback>1</provide_feedback>
            <ode>
              <provide_feedback>1</provide_feedback>
              <implicit_spring_damper>1</implicit_spring_damper>
              <cfm_damping>1</cfm_damping>
              <limit>
                <cfm>0</cfm>
                <erp>0.2</erp>
              </limit>
            </ode>
        </physics>
    </joint>   


   
  
    <link name = "knuckle_link_FF">
        
        <pose frame=''>0.033 -0.01 0.342 0 0 0</pose>
        <inertial>
            <pose frame=''>0 0 0 0 0 0</pose>
            <mass>0.008</mass>
            <inertia>
                <ixx>2.6e-07</ixx>
                <ixy>0</ixy>
                <ixz>0</ixz>
                <iyy>2.6e-07</iyy>
                <iyz>0</iyz>
                <izz>3.2e-07</izz>
            </inertia>
        </inertial>
      
        <visual name='visual'>
            
            <geometry>
                <mesh>
                    <scale>0.001 0.001 0.001</scale>
                    <uri>model://shadow_hand/knuckle.dae</uri>
                </mesh>
            </geometry>
            <material>

            </material>
        </visual>
        <collision name='collision'>
            <pose frame=''>0 0 0 0 1.5708 0</pose>
            <geometry>
                <cylinder>
                    <radius>0.007</radius> 
                    <length>0.014</length> 
                </cylinder> 
            </geometry>
        </collision>
        <gravity>1</gravity>
        <velocity_decay/>
        <self_collide>0</self_collide>
    </link>

    <link name = "proximal_link_FF">
        <pose frame=''>0.033 -0.01 0.342 0 0 0</pose>
        <inertial>
            <pose frame=''>0 0 0.0225 0 0 0</pose>
            <mass>0.03</mass>
            <inertia>
                <ixx>9.8e-06</ixx>
                <ixy>0</ixy>
                <ixz>0</ixz>
                <iyy>1.0e-05</iyy>
                <iyz>0</iyz>
                <izz>1.8e-06</izz>
            </inertia>
        </inertial>
        
        <visual name='visual'>
            
            <geometry>
                <mesh>
                    <scale>0.001 0.001 0.001</scale>
                    <uri>model://shadow_hand/F3.dae</uri>
                </mesh>
            </geometry>
            <material>

            </material>
        </visual>
        <collision name='collision'>
            <pose frame=''>0 0 0.025 0 0 0</pose>
            <geometry>
                <cylinder>
                    <radius>0.007</radius> 
                    <length>0.040</length> 
                </cylinder> 
            </geometry>
        </collision>
        <gravity>1</gravity>
        <velocity_decay/>
        <self_collide>0</self_collide>
    </link>
    <link name = "middle_link_FF">
        <pose frame=''>0.033 -0.01 0.387 0 0 0</pose>
        <inertial>
            <pose frame=''>0 0 0.0125 0 0 0</pose>
            <mass>0.017</mass>
            <inertia>
                <ixx>2.6e-06</ixx>
                <ixy>0</ixy>
                <ixz>0</ixz>
                <iyy>2.7e-06</iyy>
                <iyz>0</iyz>
                <izz>8.7e-07</izz>
            </inertia>
        </inertial>
      
        <visual name='visual'>
            
            <geometry>
                <mesh>
                    <scale>0.001 0.001 0.001</scale>
                    <uri>model://shadow_hand/F2.dae</uri>
                </mesh>
            </geometry>
            <material>
                <script>
                    <uri>file://media/materials/scripts/gazebo.material</uri>
                    <name>Gazebo/Blue</name>
                </script>
            </material>
        </visual>
        <collision name='collision'>
            <pose frame=''>0 0 0.0125 0 0 0</pose>
            <geometry>
                <cylinder>
                    <radius>0.007</radius> 
                    <length>0.025</length> 
                </cylinder> 
            </geometry>
        </collision>
        <gravity>1</gravity>
        <velocity_decay/>
        <self_collide>0</self_collide>
    </link>
    <link name = "distal_link_FF">
        <pose frame=''>0.033 -0.01 0.41200000000000003 0 0 0</pose>
        <inertial>
            <pose frame=''>0 0 0.012 0 0 0</pose>
            <mass>0.012</mass>
            <inertia>
                <ixx>9.4e-07</ixx>
                <ixy>0</ixy>
                <ixz>0</ixz>
                <iyy>1.1e-06</iyy>
                <iyz>0</iyz>
                <izz>5.3e-07</izz>
            </inertia>
        </inertial>
      
        <visual name='visual'>
            
            <geometry>
                <mesh>
                    <scale>0.001 0.001 0.001</scale>
                    <uri>model://shadow_hand/F1.dae</uri>
                </mesh>
            </geometry>
            <material>
                 <script>
                    <uri>file://media/materials/scripts/gazebo.material</uri>
                    <name>Gazebo/Red</name>
                </script>
            </material>
        </visual>
        <collision name='collision'>
            <geometry>
                <mesh>
                    <scale>0.001 0.001 0.001</scale>
                    <uri>model://shadow_hand/F1.dae</uri>
                </mesh>
            </geometry>
        </collision>
        <gravity>1</gravity>
        <velocity_decay/>
        <self_collide>0</self_collide>
    </link>
    
    
        <joint name="J3_FF" type="revolute">
            <child>proximal_link_FF</child>
            <parent>knuckle_link_FF</parent>
            
            <axis>
                <xyz>1 0 0</xyz>
                <limit>
                    <lower>0 </lower>
                    <upper>1.5707963267948966 </upper>
                    <effort>2.0 </effort>
                    <velocity>2.0 </velocity>
                </limit>
                <dynamics>
                    <damping>0.1</damping>
                    <friction>0.0</friction>
                    <spring_reference>0</spring_reference>
                    <spring_stiffness>0</spring_stiffness>
                </dynamics>
                <use_parent_model_frame>1</use_parent_model_frame>
            </axis>
            <physics>
                <provide_feedback>1</provide_feedback>
                <ode>
                  <provide_feedback>1</provide_feedback>
                  <implicit_spring_damper>1</implicit_spring_damper>
                  <cfm_damping>1</cfm_damping>
                  <limit>
                    <cfm>0</cfm>
                    <erp>0.2</erp>
                  </limit>
                </ode>
            </physics>
        </joint>
    
        <joint name="J2_FF" type="revolute">
            <child>middle_link_FF</child>
            <parent>proximal_link_FF</parent>
            
            <axis>
                <xyz>1 0 0</xyz>
                <limit>
                    <lower>0 </lower>
                    <upper>1.5707963267948966 </upper>
                    <effort>2.0 </effort>
                    <velocity>2.0 </velocity>
                </limit>
                <dynamics>
                    <damping>0.1</damping>
                    <friction>0.0</friction>
                    <spring_reference>0</spring_reference>
                    <spring_stiffness>0</spring_stiffness>
                </dynamics>
                <use_parent_model_frame>1</use_parent_model_frame>
            </axis>
            <physics>
                <provide_feedback>1</provide_feedback>
                <ode>
                  <provide_feedback>1</provide_feedback>
                  <implicit_spring_damper>1</implicit_spring_damper>
                  <cfm_damping>1</cfm_damping>
                  <limit>
                    <cfm>0</cfm>
                    <erp>0.2</erp>
                  </limit>
                </ode>
            </physics>
        </joint>
    
        <joint name="J1_FF" type="revolute">
            <child>distal_link_FF</child>
            <parent>middle_link_FF</parent>
            
            <axis>
                <xyz>1 0 0</xyz>
                <limit>
                    <lower>0 </lower>
                    <upper>1.5707963267948966 </upper>
                    <effort>2.0 </effort>
                    <velocity>2.0 </velocity>
                </limit>
                <dynamics>
                    <damping>0.1</damping>
                    <friction>0.0</friction>
                    <spring_reference>0</spring_reference>
                    <spring_stiffness>0</spring_stiffness>
                </dynamics>
                <use_parent_model_frame>1</use_parent_model_frame>
            </axis>
            <physics>
                <provide_feedback>1</provide_feedback>
                <ode>
                  <provide_feedback>1</provide_feedback>
                  <implicit_spring_damper>1</implicit_spring_damper>
                  <cfm_damping>1</cfm_damping>
                  <limit>
                    <cfm>0</cfm>
                    <erp>0.2</erp>
                  </limit>
                </ode>
            </physics>
        </joint>
    
    <joint name='J4_FF' type="revolute">
        <child>knuckle_link_FF</child>
        <parent>palm_link</parent>
        
        <axis>
            <xyz>0 -1 0</xyz>
            <limit>
                <lower>-3.141592653589793 </lower>
                <upper>0.0 </upper>
                <effort>2.0 </effort>
                <velocity>2.0 </velocity>
            </limit>
            <dynamics>
                <damping>0.1</damping>
                <friction>0</friction>
                <spring_reference>0</spring_reference>
                <spring_stiffness>0</spring_stiffness>
            </dynamics>
            <use_parent_model_frame>1</use_parent_model_frame>
        </axis>
        <physics>
            <provide_feedback>1</provide_feedback>
            <ode>
            <provide_feedback>1</provide_feedback>
            <implicit_spring_damper>1</implicit_spring_damper>
            <cfm_damping>1</cfm_damping>
            <limit>
                <cfm>0</cfm>
                <erp>0.2</erp>
            </limit>
            </ode>
        </physics>
    </joint>

   
  
    <link name = "knuckle_link_MF">
        
        <pose frame=''>0.011000000000000003 -0.01 0.34600000000000003 0 0 0</pose>
        <inertial>
            <pose frame=''>0 0 0 0 0 0</pose>
            <mass>0.008</mass>
            <inertia>
                <ixx>2.6e-07</ixx>
                <ixy>0</ixy>
                <ixz>0</ixz>
                <iyy>2.6e-07</iyy>
                <iyz>0</iyz>
                <izz>3.2e-07</izz>
            </inertia>
        </inertial>
      
        <visual name='visual'>
            
            <geometry>
                <mesh>
                    <scale>0.001 0.001 0.001</scale>
                    <uri>model://shadow_hand/knuckle.dae</uri>
                </mesh>
            </geometry>
            <material>

            </material>
        </visual>
        <collision name='collision'>
            <pose frame=''>0 0 0 0 1.5708 0</pose>
            <geometry>
                <cylinder>
                    <radius>0.007</radius> 
                    <length>0.014</length> 
                </cylinder> 
            </geometry>
        </collision>
        <gravity>1</gravity>
        <velocity_decay/>
        <self_collide>0</self_collide>
    </link>

    <link name = "proximal_link_MF">
        <pose frame=''>0.011000000000000003 -0.01 0.34600000000000003 0 0 0</pose>
        <inertial>
            <pose frame=''>0 0 0.0225 0 0 0</pose>
            <mass>0.03</mass>
            <inertia>
                <ixx>9.8e-06</ixx>
                <ixy>0</ixy>
                <ixz>0</ixz>
                <iyy>1.0e-05</iyy>
                <iyz>0</iyz>
                <izz>1.8e-06</izz>
            </inertia>
        </inertial>
        
        <visual name='visual'>
            
            <geometry>
                <mesh>
                    <scale>0.001 0.001 0.001</scale>
                    <uri>model://shadow_hand/F3.dae</uri>
                </mesh>
            </geometry>
            <material>

            </material>
        </visual>
        <collision name='collision'>
            <pose frame=''>0 0 0.025 0 0 0</pose>
            <geometry>
                <cylinder>
                    <radius>0.007</radius> 
                    <length>0.040</length> 
                </cylinder> 
            </geometry>
        </collision>
        <gravity>1</gravity>
        <velocity_decay/>
        <self_collide>0</self_collide>
    </link>
    <link name = "middle_link_MF">
        <pose frame=''>0.011000000000000003 -0.01 0.391 0 0 0</pose>
        <inertial>
            <pose frame=''>0 0 0.0125 0 0 0</pose>
            <mass>0.017</mass>
            <inertia>
                <ixx>2.6e-06</ixx>
                <ixy>0</ixy>
                <ixz>0</ixz>
                <iyy>2.7e-06</iyy>
                <iyz>0</iyz>
                <izz>8.7e-07</izz>
            </inertia>
        </inertial>
      
        <visual name='visual'>
            
            <geometry>
                <mesh>
                    <scale>0.001 0.001 0.001</scale>
                    <uri>model://shadow_hand/F2.dae</uri>
                </mesh>
            </geometry>
            <material>
                <script>
                    <uri>file://media/materials/scripts/gazebo.material</uri>
                    <name>Gazebo/Blue</name>
                </script>
            </material>
        </visual>
        <collision name='collision'>
            <pose frame=''>0 0 0.0125 0 0 0</pose>
            <geometry>
                <cylinder>
                    <radius>0.007</radius> 
                    <length>0.025</length> 
                </cylinder> 
            </geometry>
        </collision>
        <gravity>1</gravity>
        <velocity_decay/>
        <self_collide>0</self_collide>
    </link>
    <link name = "distal_link_MF">
        <pose frame=''>0.011000000000000003 -0.01 0.41600000000000004 0 0 0</pose>
        <inertial>
            <pose frame=''>0 0 0.012 0 0 0</pose>
            <mass>0.012</mass>
            <inertia>
                <ixx>9.4e-07</ixx>
                <ixy>0</ixy>
                <ixz>0</ixz>
                <iyy>1.1e-06</iyy>
                <iyz>0</iyz>
                <izz>5.3e-07</izz>
            </inertia>
        </inertial>
      
        <visual name='visual'>
            
            <geometry>
                <mesh>
                    <scale>0.001 0.001 0.001</scale>
                    <uri>model://shadow_hand/F1.dae</uri>
                </mesh>
            </geometry>
            <material>
                 <script>
                    <uri>file://media/materials/scripts/gazebo.material</uri>
                    <name>Gazebo/Red</name>
                </script>
            </material>
        </visual>
        <collision name='collision'>
            <geometry>
                <mesh>
                    <scale>0.001 0.001 0.001</scale>
                    <uri>model://shadow_hand/F1.dae</uri>
                </mesh>
            </geometry>
        </collision>
        <gravity>1</gravity>
        <velocity_decay/>
        <self_collide>0</self_collide>
    </link>
    
    
        <joint name="J3_MF" type="revolute">
            <child>proximal_link_MF</child>
            <parent>knuckle_link_MF</parent>
            
            <axis>
                <xyz>1 0 0</xyz>
                <limit>
                    <lower>0 </lower>
                    <upper>1.5707963267948966 </upper>
                    <effort>2.0 </effort>
                    <velocity>2.0 </velocity>
                </limit>
                <dynamics>
                    <damping>0.1</damping>
                    <friction>0.0</friction>
                    <spring_reference>0</spring_reference>
                    <spring_stiffness>0</spring_stiffness>
                </dynamics>
                <use_parent_model_frame>1</use_parent_model_frame>
            </axis>
            <physics>
                <provide_feedback>1</provide_feedback>
                <ode>
                  <provide_feedback>1</provide_feedback>
                  <implicit_spring_damper>1</implicit_spring_damper>
                  <cfm_damping>1</cfm_damping>
                  <limit>
                    <cfm>0</cfm>
                    <erp>0.2</erp>
                  </limit>
                </ode>
            </physics>
        </joint>
    
        <joint name="J2_MF" type="revolute">
            <child>middle_link_MF</child>
            <parent>proximal_link_MF</parent>
            
            <axis>
                <xyz>1 0 0</xyz>
                <limit>
                    <lower>0 </lower>
                    <upper>1.5707963267948966 </upper>
                    <effort>2.0 </effort>
                    <velocity>2.0 </velocity>
                </limit>
                <dynamics>
                    <damping>0.1</damping>
                    <friction>0.0</friction>
                    <spring_reference>0</spring_reference>
                    <spring_stiffness>0</spring_stiffness>
                </dynamics>
                <use_parent_model_frame>1</use_parent_model_frame>
            </axis>
            <physics>
                <provide_feedback>1</provide_feedback>
                <ode>
                  <provide_feedback>1</provide_feedback>
                  <implicit_spring_damper>1</implicit_spring_damper>
                  <cfm_damping>1</cfm_damping>
                  <limit>
                    <cfm>0</cfm>
                    <erp>0.2</erp>
                  </limit>
                </ode>
            </physics>
        </joint>
    
        <joint name="J1_MF" type="revolute">
            <child>distal_link_MF</child>
            <parent>middle_link_MF</parent>
            
            <axis>
                <xyz>1 0 0</xyz>
                <limit>
                    <lower>0 </lower>
                    <upper>1.5707963267948966 </upper>
                    <effort>2.0 </effort>
                    <velocity>2.0 </velocity>
                </limit>
                <dynamics>
                    <damping>0.1</damping>
                    <friction>0.0</friction>
                    <spring_reference>0</spring_reference>
                    <spring_stiffness>0</spring_stiffness>
                </dynamics>
                <use_parent_model_frame>1</use_parent_model_frame>
            </axis>
            <physics>
                <provide_feedback>1</provide_feedback>
                <ode>
                  <provide_feedback>1</provide_feedback>
                  <implicit_spring_damper>1</implicit_spring_damper>
                  <cfm_damping>1</cfm_damping>
                  <limit>
                    <cfm>0</cfm>
                    <erp>0.2</erp>
                  </limit>
                </ode>
            </physics>
        </joint>
    
    <joint name='J4_MF' type="revolute">
        <child>knuckle_link_MF</child>
        <parent>palm_link</parent>
        
        <axis>
            <xyz>0 -1 0</xyz>
            <limit>
                <lower>-3.141592653589793 </lower>
                <upper>0.0 </upper>
                <effort>2.0 </effort>
                <velocity>2.0 </velocity>
            </limit>
            <dynamics>
                <damping>0.1</damping>
                <friction>0</friction>
                <spring_reference>0</spring_reference>
                <spring_stiffness>0</spring_stiffness>
            </dynamics>
            <use_parent_model_frame>1</use_parent_model_frame>
        </axis>
        <physics>
            <provide_feedback>1</provide_feedback>
            <ode>
            <provide_feedback>1</provide_feedback>
            <implicit_spring_damper>1</implicit_spring_damper>
            <cfm_damping>1</cfm_damping>
            <limit>
                <cfm>0</cfm>
                <erp>0.2</erp>
            </limit>
            </ode>
        </physics>
    </joint>

   
  
    <link name = "knuckle_link_RF">
        
        <pose frame=''>-0.010999999999999996 -0.01 0.342 0 0 0</pose>
        <inertial>
            <pose frame=''>0 0 0 0 0 0</pose>
            <mass>0.008</mass>
            <inertia>
                <ixx>2.6e-07</ixx>
                <ixy>0</ixy>
                <ixz>0</ixz>
                <iyy>2.6e-07</iyy>
                <iyz>0</iyz>
                <izz>3.2e-07</izz>
            </inertia>
        </inertial>
      
        <visual name='visual'>
            
            <geometry>
                <mesh>
                    <scale>0.001 0.001 0.001</scale>
                    <uri>model://shadow_hand/knuckle.dae</uri>
                </mesh>
            </geometry>
            <material>

            </material>
        </visual>
        <collision name='collision'>
            <pose frame=''>0 0 0 0 1.5708 0</pose>
            <geometry>
                <cylinder>
                    <radius>0.007</radius> 
                    <length>0.014</length> 
                </cylinder> 
            </geometry>
        </collision>
        <gravity>1</gravity>
        <velocity_decay/>
        <self_collide>0</self_collide>
    </link>

    <link name = "proximal_link_RF">
        <pose frame=''>-0.010999999999999996 -0.01 0.342 0 0 0</pose>
        <inertial>
            <pose frame=''>0 0 0.0225 0 0 0</pose>
            <mass>0.03</mass>
            <inertia>
                <ixx>9.8e-06</ixx>
                <ixy>0</ixy>
                <ixz>0</ixz>
                <iyy>1.0e-05</iyy>
                <iyz>0</iyz>
                <izz>1.8e-06</izz>
            </inertia>
        </inertial>
        
        <visual name='visual'>
            
            <geometry>
                <mesh>
                    <scale>0.001 0.001 0.001</scale>
                    <uri>model://shadow_hand/F3.dae</uri>
                </mesh>
            </geometry>
            <material>

            </material>
        </visual>
        <collision name='collision'>
            <pose frame=''>0 0 0.025 0 0 0</pose>
            <geometry>
                <cylinder>
                    <radius>0.007</radius> 
                    <length>0.040</length> 
                </cylinder> 
            </geometry>
        </collision>
        <gravity>1</gravity>
        <velocity_decay/>
        <self_collide>0</self_collide>
    </link>
    <link name = "middle_link_RF">
        <pose frame=''>-0.010999999999999996 -0.01 0.387 0 0 0</pose>
        <inertial>
            <pose frame=''>0 0 0.0125 0 0 0</pose>
            <mass>0.017</mass>
            <inertia>
                <ixx>2.6e-06</ixx>
                <ixy>0</ixy>
                <ixz>0</ixz>
                <iyy>2.7e-06</iyy>
                <iyz>0</iyz>
                <izz>8.7e-07</izz>
            </inertia>
        </inertial>
      
        <visual name='visual'>
            
            <geometry>
                <mesh>
                    <scale>0.001 0.001 0.001</scale>
                    <uri>model://shadow_hand/F2.dae</uri>
                </mesh>
            </geometry>
            <material>
                <script>
                    <uri>file://media/materials/scripts/gazebo.material</uri>
                    <name>Gazebo/Blue</name>
                </script>
            </material>
        </visual>
        <collision name='collision'>
            <pose frame=''>0 0 0.0125 0 0 0</pose>
            <geometry>
                <cylinder>
                    <radius>0.007</radius> 
                    <length>0.025</length> 
                </cylinder> 
            </geometry>
        </collision>
        <gravity>1</gravity>
        <velocity_decay/>
        <self_collide>0</self_collide>
    </link>
    <link name = "distal_link_RF">
        <pose frame=''>-0.010999999999999996 -0.01 0.41200000000000003 0 0 0</pose>
        <inertial>
            <pose frame=''>0 0 0.012 0 0 0</pose>
            <mass>0.012</mass>
            <inertia>
                <ixx>9.4e-07</ixx>
                <ixy>0</ixy>
                <ixz>0</ixz>
                <iyy>1.1e-06</iyy>
                <iyz>0</iyz>
                <izz>5.3e-07</izz>
            </inertia>
        </inertial>
      
        <visual name='visual'>
            
            <geometry>
                <mesh>
                    <scale>0.001 0.001 0.001</scale>
                    <uri>model://shadow_hand/F1.dae</uri>
                </mesh>
            </geometry>
            <material>
                 <script>
                    <uri>file://media/materials/scripts/gazebo.material</uri>
                    <name>Gazebo/Red</name>
                </script>
            </material>
        </visual>
        <collision name='collision'>
            <geometry>
                <mesh>
                    <scale>0.001 0.001 0.001</scale>
                    <uri>model://shadow_hand/F1.dae</uri>
                </mesh>
            </geometry>
        </collision>
        <gravity>1</gravity>
        <velocity_decay/>
        <self_collide>0</self_collide>
    </link>
    
    
        <joint name="J3_RF" type="revolute">
            <child>proximal_link_RF</child>
            <parent>knuckle_link_RF</parent>
            
            <axis>
                <xyz>1 0 0</xyz>
                <limit>
                    <lower>0 </lower>
                    <upper>1.5707963267948966 </upper>
                    <effort>2.0 </effort>
                    <velocity>2.0 </velocity>
                </limit>
                <dynamics>
                    <damping>0.1</damping>
                    <friction>0.0</friction>
                    <spring_reference>0</spring_reference>
                    <spring_stiffness>0</spring_stiffness>
                </dynamics>
                <use_parent_model_frame>1</use_parent_model_frame>
            </axis>
            <physics>
                <provide_feedback>1</provide_feedback>
                <ode>
                  <provide_feedback>1</provide_feedback>
                  <implicit_spring_damper>1</implicit_spring_damper>
                  <cfm_damping>1</cfm_damping>
                  <limit>
                    <cfm>0</cfm>
                    <erp>0.2</erp>
                  </limit>
                </ode>
            </physics>
        </joint>
    
        <joint name="J2_RF" type="revolute">
            <child>middle_link_RF</child>
            <parent>proximal_link_RF</parent>
            
            <axis>
                <xyz>1 0 0</xyz>
                <limit>
                    <lower>0 </lower>
                    <upper>1.5707963267948966 </upper>
                    <effort>2.0 </effort>
                    <velocity>2.0 </velocity>
                </limit>
                <dynamics>
                    <damping>0.1</damping>
                    <friction>0.0</friction>
                    <spring_reference>0</spring_reference>
                    <spring_stiffness>0</spring_stiffness>
                </dynamics>
                <use_parent_model_frame>1</use_parent_model_frame>
            </axis>
            <physics>
                <provide_feedback>1</provide_feedback>
                <ode>
                  <provide_feedback>1</provide_feedback>
                  <implicit_spring_damper>1</implicit_spring_damper>
                  <cfm_damping>1</cfm_damping>
                  <limit>
                    <cfm>0</cfm>
                    <erp>0.2</erp>
                  </limit>
                </ode>
            </physics>
        </joint>
    
        <joint name="J1_RF" type="revolute">
            <child>distal_link_RF</child>
            <parent>middle_link_RF</parent>
            
            <axis>
                <xyz>1 0 0</xyz>
                <limit>
                    <lower>0 </lower>
                    <upper>1.5707963267948966 </upper>
                    <effort>2.0 </effort>
                    <velocity>2.0 </velocity>
                </limit>
                <dynamics>
                    <damping>0.1</damping>
                    <friction>0.0</friction>
                    <spring_reference>0</spring_reference>
                    <spring_stiffness>0</spring_stiffness>
                </dynamics>
                <use_parent_model_frame>1</use_parent_model_frame>
            </axis>
            <physics>
                <provide_feedback>1</provide_feedback>
                <ode>
                  <provide_feedback>1</provide_feedback>
                  <implicit_spring_damper>1</implicit_spring_damper>
                  <cfm_damping>1</cfm_damping>
                  <limit>
                    <cfm>0</cfm>
                    <erp>0.2</erp>
                  </limit>
                </ode>
            </physics>
        </joint>
    
    <joint name='J4_RF' type="revolute">
        <child>knuckle_link_RF</child>
        <parent>palm_link</parent>
        
        <axis>
            <xyz>0 -1 0</xyz>
            <limit>
                <lower>-3.141592653589793 </lower>
                <upper>0.0 </upper>
                <effort>2.0 </effort>
                <velocity>2.0 </velocity>
            </limit>
            <dynamics>
                <damping>0.1</damping>
                <friction>0</friction>
                <spring_reference>0</spring_reference>
                <spring_stiffness>0</spring_stiffness>
            </dynamics>
            <use_parent_model_frame>1</use_parent_model_frame>
        </axis>
        <physics>
            <provide_feedback>1</provide_feedback>
            <ode>
            <provide_feedback>1</provide_feedback>
            <implicit_spring_damper>1</implicit_spring_damper>
            <cfm_damping>1</cfm_damping>
            <limit>
                <cfm>0</cfm>
                <erp>0.2</erp>
            </limit>
            </ode>
        </physics>
    </joint>

   

    <link name = "metacarpal_link_lf">
        <pose frame=''>-0.031 -0.01 0.26771 0 0 0</pose>
        <inertial>
            <pose frame=''>0 0 0.04 0 0 0</pose>
            <mass>0.03</mass>
            <inertia>
                <ixx>1.45e-05</ixx>
                <ixy>0</ixy>
                <ixz>0</ixz>
                <iyy>1.638e-05</iyy>
                <iyz>0</iyz>
                <izz>4.272e-06</izz>
            </inertia>
        </inertial>
        <visual name='visual'>
            
            <geometry>
                <mesh>
                    <scale>0.001 0.001 0.001</scale>
                    <uri>model://shadow_hand/lfmetacarpal.dae</uri>
                </mesh>
            </geometry>
            <material>

            </material>
        </visual>
        <collision name='collision'>
            <pose frame=''>0 0 0 0 0 0</pose>
            <geometry>
                <mesh>
                    <scale>0.001 0.001 0.001</scale>
                    <uri>model://shadow_hand/lfmetacarpal.dae</uri>
                </mesh>
            </geometry>
        </collision>
        <gravity>1</gravity>
        <velocity_decay/>
        <self_collide>0</self_collide>
    </link>
    <link name = "knuckle_link_lf">
        
        <pose frame=''>-0.031 -0.01 0.3335 0 0 0</pose>
        <inertial>
            <pose frame=''>0 0 0 0 0 0</pose>
            <mass>0.008</mass>
            <inertia>
                <ixx>2.6e-07</ixx>
                <ixy>0</ixy>
                <ixz>0</ixz>
                <iyy>2.6e-07</iyy>
                <iyz>0</iyz>
                <izz>3.2e-07</izz>
            </inertia>
        </inertial>
      
        <visual name='visual'>
            
            <geometry>
                <mesh>
                    <scale>0.001 0.001 0.001</scale>
                    <uri>model://shadow_hand/knuckle.dae</uri>
                </mesh>
            </geometry>
            <material>

            </material>
        </visual>
        <collision name='collision'>
            <pose frame=''>0 0 0 0 1.5708 0</pose>
            <geometry>
                <cylinder>
                    <radius>0.007</radius> 
                    <length>0.014</length> 
                </cylinder> 
            </geometry>
        </collision>
    </link>

    <link name = "proximal_link_lf">
        <pose frame=''>-0.031 -0.01 0.3335 0 0 0</pose>
        <inertial>
            <pose frame=''>0 0 0.0225 0 0 0</pose>
            <mass>0.03</mass>
            <inertia>
                <ixx>9.8e-06</ixx>
                <ixy>0</ixy>
                <ixz>0</ixz>
                <iyy>1.0e-05</iyy>
                <iyz>0</iyz>
                <izz>1.8e-06</izz>
            </inertia>
        </inertial>
        
        <visual name='visual'>
            
            <geometry>
                <mesh>
                    <scale>0.001 0.001 0.001</scale>
                    <uri>model://shadow_hand/F3.dae</uri>
                </mesh>
            </geometry>
            <material>

            </material>
        </visual>
        <collision name='collision'>
            <pose frame=''>0 0 0.025 0 0 0</pose>
            <geometry>
                <cylinder>
                    <radius>0.007</radius> 
                    <length>0.040</length> 
                </cylinder> 
            </geometry>
        </collision>
    </link>
    <link name = "middle_link_lf">
        <pose frame=''>-0.031 -0.01 0.3785 0 0 0</pose>
        <inertial>
            <pose frame=''>0 0 0.0125 0 0 0</pose>
            <mass>0.017</mass>
            <inertia>
                <ixx>2.6e-06</ixx>
                <ixy>0</ixy>
                <ixz>0</ixz>
                <iyy>2.7e-06</iyy>
                <iyz>0</iyz>
                <izz>8.7e-07</izz>
            </inertia>
        </inertial>
      
        <visual name='visual'>
            
            <geometry>
                <mesh>
                    <scale>0.001 0.001 0.001</scale>
                    <uri>model://shadow_hand/F2.dae</uri>
                </mesh>
            </geometry>
            <material>
                <script>
                    <uri>file://media/materials/scripts/gazebo.material</uri>
                    <name>Gazebo/Blue</name>
                </script>
            </material>
        </visual>
        <collision name='collision'>
            <pose frame=''>0 0 0.0125 0 0 0</pose>
            <geometry>
                <cylinder>
                    <radius>0.007</radius> 
                    <length>0.025</length> 
                </cylinder> 
            </geometry>
        </collision>
    </link>
    <link name = "distal_link_lf">
        <pose frame=''>-0.031 -0.01 0.4035 0 0 0</pose>
        <inertial>
            <pose frame=''>0 0 0.012 0 0 0</pose>
            <mass>0.012</mass>
            <inertia>
                <ixx>9.4e-07</ixx>
                <ixy>0</ixy>
                <ixz>0</ixz>
                <iyy>1.1e-06</iyy>
                <iyz>0</iyz>
                <izz>5.3e-07</izz>
            </inertia>
        </inertial>
      
        <visual name='visual'>
            
            <geometry>
                <mesh>
                    <scale>0.001 0.001 0.001</scale>
                    <uri>model://shadow_hand/F1.dae</uri>
                </mesh>
            </geometry>
            <material>
                 <script>
                    <uri>file://media/materials/scripts/gazebo.material</uri>
                    <name>Gazebo/Red</name>
                </script>
            </material>
        </visual>
        <collision name='collision'>
            <geometry>
                <mesh>
                    <scale>0.001 0.001 0.001</scale>
                    <uri>model://shadow_hand/F1.dae</uri>
                </mesh>
            </geometry>
        </collision>
    </link>


    <link name = "thbases_link">
        <pose frame=''>0.034 -0.0185 0.276 0.0 0.785398 0</pose>
        <inertial>
            <pose frame=''>0 0 0 0 0 0</pose>
            <mass>0.01</mass>
            <inertia>
                <ixx>1.6e-07</ixx>
                <ixy>0</ixy>
                <ixz>0</ixz>
                <iyy>1.6e-07</iyy>
                <iyz>0</iyz>
                <izz>1.6e-07</izz>
            </inertia>
        </inertial>
        <visual name='visual'>
            
            <geometry>
                <box>
                    <size>0.001 0.001 0.001</size>
                </box>
            </geometry>
            <material>

            </material>
        </visual>
        <collision name='collision'>
            <pose frame=''>0 0 0 0 0 0</pose>
            <geometry>
                <sphere>
                    <radius>0.011</radius>
                </sphere>
            </geometry>
        </collision>
        <gravity>1</gravity>
        <velocity_decay/>
        <self_collide>0</self_collide>
    </link>
    <link name = "thproximal_link">
            
        <pose frame=''>0.034 -0.0185 0.276 0.0 0.785398 0.0</pose>
        <inertial>
            <pose frame=''>0 0 0.019 0 0 0</pose>
            <mass>0.04</mass>
            <inertia>
                <ixx>1.36e-05</ixx>
                <ixy>0</ixy>
                <ixz>0</ixz>
                <iyy>1.36e-05</iyy>
                <iyz>0</iyz>
                <izz>3.13e-06</izz>
            </inertia>
        </inertial>
    
        <visual name='visual'>
            
            <geometry>
                <mesh>
                    <scale>0.001 0.001 0.001</scale>
                    <uri>model://shadow_hand/TH3_z.dae</uri>
                </mesh>
            </geometry>
            <material>

            </material>
        </visual>
        <collision name='collision'>
            <pose frame=''>0 0 0.020 0 0 0</pose>
            <geometry>
                <cylinder>
                    <radius>0.012</radius>
                    <length>0.018</length>
                </cylinder>
            </geometry>
        </collision>
    </link>
    <link name = "thmiddle_link">
            
        <pose frame=''>0.06087000000000001 -0.0185 0.30287000000000003 0.0 0.785398 0.0</pose>
        <inertial>
            <pose frame=''>0 0 14 0 0 0</pose>
            <mass>0.02</mass>
            <inertia>
                <ixx>5.1e-06</ixx>
                <ixy>0</ixy>
                <ixz>0</ixz>
                <iyy>5.1e-06</iyy>
                <iyz>0</iyz>
                <izz>1.21e-06</izz>
            </inertia>
        </inertial>

        <visual name='visual'>
            
            <geometry>
                <mesh>
                    <scale>0.001 0.001 0.001</scale>
                    <uri>model://shadow_hand/TH2_z.dae</uri>
                </mesh>
            </geometry>
            <material>

            </material>
        </visual>

        <collision name='collision'>
            <pose frame=''>0 0 0.012 0 0 0</pose>
            <geometry>
                <cylinder>
                    <radius>0.011</radius>
                    <length>0.018</length>
                </cylinder>
            </geometry>
        </collision>
    </link>
    <link name = "thdistal_link">
            
        <pose frame=''>0.083498 -0.0185 0.32549700000000004 -0.785398 0.0 -1.5708</pose>
        <inertial>
            <pose frame=''>0 0 765 0 0 0</pose>
            <mass>0.016</mass>
            <inertia>
                <ixx>2.1e-06</ixx>
                <ixy>0</ixy>
                <ixz>0</ixz>
                <iyy>2.2e-06</iyy>
                <iyz>0</iyz>
                <izz>1.0e-06</izz>
            </inertia>
        </inertial>

        <visual name='visual'>
            
            <geometry>
                <mesh>
                    <scale>0.001 0.001 0.001</scale>
                    <uri>model://shadow_hand/TH1_z.dae</uri>
                </mesh>
            </geometry>
            <material>

            </material>
        </visual>
        <collision name='collision'>
            <geometry>
                <mesh>
                    <scale>0.001 0.001 0.001</scale>
                    <uri>model://shadow_hand/TH1_z.dae</uri>
                </mesh>
            </geometry>
        </collision>
    </link>
 
    
        <joint name ="THJ5"  type ="revolute">
            <child>thbase_link</child>
            <parent>palm_link</parent>
            <axis>
                <xyz>0 0 1</xyz>
                <limit>
                    <lower>-3.141592653589793 </lower>
                    <upper>0.0 </upper>
                    <effort>0.2 </effort>
                    <velocity>4.0 </velocity>
                </limit>
                <dynamics>
                <damping>0.2</damping>
                </dynamics>
            </axis>
        </joint>
    
        <joint name ="THJ4"  type ="revolute">
            <child>thproximal_link</child>
            <parent>thbase_link</parent>
            <axis>
                <xyz>1 0 0</xyz>
                <limit>
                    <lower>0 </lower>
                    <upper>0.0 </upper>
                    <effort>3.0 </effort>
                    <velocity>4.0 </velocity>
                </limit>
                <dynamics>
                <damping>0.2</damping>
                </dynamics>
            </axis>
        </joint>
    
        <joint name ="THJ2"  type ="revolute">
            <child>thmiddle_link</child>
            <parent>thhub_link</parent>
            <axis>
                <xyz>0 -1 0</xyz>
                <limit>
                    <lower>-3.141592653589793 </lower>
                    <upper>0.0 </upper>
                    <effort>2.0 </effort>
                    <velocity>2.0 </velocity>
                </limit>
                <dynamics>
                <damping>0.1</damping>
                </dynamics>
            </axis>
        </joint>
    
        <joint name ="THJ1"  type ="revolute">
            <child>thdistal_link</child>
            <parent>thmiddle_link</parent>
            <axis>
                <xyz>1 0 0</xyz>
                <limit>
                    <lower>0 </lower>
                    <upper>1.5707963267948966 </upper>
                    <effort>1.0 </effort>
                    <velocity>4.0 </velocity>
                </limit>
                <dynamics>
                <damping>0.2</damping>
                </dynamics>
            </axis>
        </joint>
    
    <joint name ="THJ3"  type ="fixed">
        <child>thhub_link</child>
        <parent>thproximal_link</parent>
        <axis>
            <xyz>1 0 0</xyz>
        </axis>
    </joint>

 
--> 
</model>
</sdf>