<?xml version="1.0" ?>



<sdf version='1.6'>
  <model name="kuka_handlit">
    <!--KUKA-->
    <link name = "world">
        <pose frame=''>0 0 0 0 0 0</pose>
        <inertial>
            <pose frame=''>0 0 0.0 0 0 0</pose>
            <mass>0.0</mass>
            <inertia>
                <ixx>0.</ixx>
                <ixy>0</ixy>
                <ixz>0</ixz>
                <iyy>0.</iyy>
                <iyz>0</iyz>
                <izz>0.</izz>
            </inertia>
        </inertial>
    </link>
    <joint name="world" type="fixed">
        <child>lbr_iiwa_link_0</child>
        <parent>world</parent>
    </joint>
    
      <link name="lbr_iiwa_link_0">
        <pose frame=''>0 0 0 0 0 0</pose>
        <inertial>
            <pose frame=''>-0.1 0 0.07 0 0 0</pose>
            <mass>5</mass>
            <inertia>
                <ixx>0.05</ixx>
                <ixy>0</ixy>
                <ixz>0</ixz>
                <iyy>0.06</iyy>
                <iyz>0</iyz>
                <izz>0.03</izz>
            </inertia>
        </inertial>
        <collision name='lbr_iiwa_link_0_collision'>
          <pose frame=''>0 0 0 0 -0 0</pose>
          <geometry>
            <mesh>
              
              <scale>1 1 1</scale>
              <uri>/home/mamad/hand_RL_ws/src/iiwa_pybullet_integration/Training/kuka_handlit/kuka_handlit/envs/kuka_handlit_model/meshes/kuka/collision/link_0.stl</uri>
              
            </mesh>
          </geometry>
        </collision>
        <visual name='lbr_iiwa_link_0_visual'>
          <pose frame=''>0 0 0 0 -0 0</pose>
          <geometry>
            <mesh>
              <scale>1 1 1</scale>
              <uri>/home/mamad/hand_RL_ws/src/iiwa_pybullet_integration/Training/kuka_handlit/kuka_handlit/envs/kuka_handlit_model/meshes/kuka/visual/link_0.stl</uri>
            </mesh>
          </geometry>
          <material>
            <ambient>0.029177691860564403 0.38360983216904254 0.4788004576876289 1</ambient>
            <diffuse>0.028510521981042314 0.5216440387189814 0.5137553443750607 1</diffuse>
            <specular>0.47066963185891675 0.8070768356933045 0.9735708736450418 1</specular>
            <emissive>0 0 0 0</emissive>
          </material>
        </visual>
      </link>
    
      <link name="lbr_iiwa_link_1">
        <pose frame=''>0 0 0.1575 0 0 0</pose>
        <inertial>
            <pose frame=''>0 -0.03 0.12 0 0 0</pose>
            <mass>3.4525</mass>
            <inertia>
                <ixx>0.02183</ixx>
                <ixy>0</ixy>
                <ixz>0</ixz>
                <iyy>0.007703</iyy>
                <iyz>-0.003887</iyz>
                <izz>0.02083</izz>
            </inertia>
        </inertial>
        <collision name='lbr_iiwa_link_1_collision'>
          <pose frame=''>0 0 0 0 -0 0</pose>
          <geometry>
            <mesh>
              
              <scale>1 1 1</scale>
              <uri>/home/mamad/hand_RL_ws/src/iiwa_pybullet_integration/Training/kuka_handlit/kuka_handlit/envs/kuka_handlit_model/meshes/kuka/collision/link_1.stl</uri>
              
            </mesh>
          </geometry>
        </collision>
        <visual name='lbr_iiwa_link_1_visual'>
          <pose frame=''>0 0 0 0 -0 0</pose>
          <geometry>
            <mesh>
              <scale>1 1 1</scale>
              <uri>/home/mamad/hand_RL_ws/src/iiwa_pybullet_integration/Training/kuka_handlit/kuka_handlit/envs/kuka_handlit_model/meshes/kuka/visual/link_1.stl</uri>
            </mesh>
          </geometry>
          <material>
            <ambient>0.9340386993084026 0.16025632495717146 0.5679249456756562 1</ambient>
            <diffuse>0.07179829014030814 0.7442286435937927 0.32394919751379836 1</diffuse>
            <specular>0.3066348255397444 0.49653181127455903 0.9166073825026828 1</specular>
            <emissive>0 0 0 0</emissive>
          </material>
        </visual>
      </link>
    
      <link name="lbr_iiwa_link_2">
        <pose frame=''>0 0 0.34 1.5708 0 -3.14159</pose>
        <inertial>
            <pose frame=''>0.0003 0.059 0.042 0 0 0</pose>
            <mass>3.4821</mass>
            <inertia>
                <ixx>0.02076</ixx>
                <ixy>0</ixy>
                <ixz>0.003626</ixz>
                <iyy>0.02179</iyy>
                <iyz>0</iyz>
                <izz>0.00779</izz>
            </inertia>
        </inertial>
        <collision name='lbr_iiwa_link_2_collision'>
          <pose frame=''>0 0 0 0 -0 0</pose>
          <geometry>
            <mesh>
              
              <scale>1 1 1</scale>
              <uri>/home/mamad/hand_RL_ws/src/iiwa_pybullet_integration/Training/kuka_handlit/kuka_handlit/envs/kuka_handlit_model/meshes/kuka/collision/link_2.stl</uri>
              
            </mesh>
          </geometry>
        </collision>
        <visual name='lbr_iiwa_link_2_visual'>
          <pose frame=''>0 0 0 0 -0 0</pose>
          <geometry>
            <mesh>
              <scale>1 1 1</scale>
              <uri>/home/mamad/hand_RL_ws/src/iiwa_pybullet_integration/Training/kuka_handlit/kuka_handlit/envs/kuka_handlit_model/meshes/kuka/visual/link_2.stl</uri>
            </mesh>
          </geometry>
          <material>
            <ambient>0.30418928788168464 0.2887004334214349 0.9966549985203718 1</ambient>
            <diffuse>0.5827199944534526 0.2323968769254542 0.42655923000443896 1</diffuse>
            <specular>0.28634451778251535 0.48842876778804656 0.10211211172689694 1</specular>
            <emissive>0 0 0 0</emissive>
          </material>
        </visual>
      </link>
    
      <link name="lbr_iiwa_link_3">
        <pose frame=''>0 0 0.524 0 0 0</pose>
        <inertial>
            <pose frame=''>0 0.03 0.13 0 0 0</pose>
            <mass>4.05623</mass>
            <inertia>
                <ixx>0.03204</ixx>
                <ixy>0</ixy>
                <ixz>0</ixz>
                <iyy>0.00972</iyy>
                <iyz>0.006227</iyz>
                <izz>0.03042</izz>
            </inertia>
        </inertial>
        <collision name='lbr_iiwa_link_3_collision'>
          <pose frame=''>0 0 0 0 -0 0</pose>
          <geometry>
            <mesh>
              
              <scale>1 1 1</scale>
              <uri>/home/mamad/hand_RL_ws/src/iiwa_pybullet_integration/Training/kuka_handlit/kuka_handlit/envs/kuka_handlit_model/meshes/kuka/collision/link_3.stl</uri>
              
            </mesh>
          </geometry>
        </collision>
        <visual name='lbr_iiwa_link_3_visual'>
          <pose frame=''>0 0 0 0 -0 0</pose>
          <geometry>
            <mesh>
              <scale>1 1 1</scale>
              <uri>/home/mamad/hand_RL_ws/src/iiwa_pybullet_integration/Training/kuka_handlit/kuka_handlit/envs/kuka_handlit_model/meshes/kuka/visual/link_3.stl</uri>
            </mesh>
          </geometry>
          <material>
            <ambient>0.057485364679969675 0.6873669319872434 0.5437887780039987 1</ambient>
            <diffuse>0.3530662522606628 0.3174601173871693 0.14889164755008977 1</diffuse>
            <specular>0.616808079385568 0.37291055770673875 0.8847163817976015 1</specular>
            <emissive>0 0 0 0</emissive>
          </material>
        </visual>
      </link>
    
      <link name="lbr_iiwa_link_4">
        <pose frame=''>0 0 0.74 1.5708 0 0</pose>
        <inertial>
            <pose frame=''>0 0.067 0.034 0 0 0</pose>
            <mass>3.4822</mass>
            <inertia>
                <ixx>0.02178</ixx>
                <ixy>0</ixy>
                <ixz>0</ixz>
                <iyy>0.02075</iyy>
                <iyz>-0.003625</iyz>
                <izz>0.007785</izz>
            </inertia>
        </inertial>
        <collision name='lbr_iiwa_link_4_collision'>
          <pose frame=''>0 0 0 0 -0 0</pose>
          <geometry>
            <mesh>
              
              <scale>1 1 1</scale>
              <uri>/home/mamad/hand_RL_ws/src/iiwa_pybullet_integration/Training/kuka_handlit/kuka_handlit/envs/kuka_handlit_model/meshes/kuka/collision/link_4.stl</uri>
              
            </mesh>
          </geometry>
        </collision>
        <visual name='lbr_iiwa_link_4_visual'>
          <pose frame=''>0 0 0 0 -0 0</pose>
          <geometry>
            <mesh>
              <scale>1 1 1</scale>
              <uri>/home/mamad/hand_RL_ws/src/iiwa_pybullet_integration/Training/kuka_handlit/kuka_handlit/envs/kuka_handlit_model/meshes/kuka/visual/link_4.stl</uri>
            </mesh>
          </geometry>
          <material>
            <ambient>0.2782380219681019 0.8752654511586538 0.18733361208807597 1</ambient>
            <diffuse>0.7973116868031425 0.6380354290514675 0.12763975022640506 1</diffuse>
            <specular>0.07128029602817465 0.9342978414590011 0.531971387960536 1</specular>
            <emissive>0 0 0 0</emissive>
          </material>
        </visual>
      </link>
    
      <link name="lbr_iiwa_link_5">
        <pose frame=''>0 0 0.9239999999999999 0 0 -3.14159</pose>
        <inertial>
            <pose frame=''>0.0001 0.021 0.076 0 0 0</pose>
            <mass>2.1633</mass>
            <inertia>
                <ixx>0.01287</ixx>
                <ixy>0</ixy>
                <ixz>0</ixz>
                <iyy>0.005708</iyy>
                <iyz>-0.003946</iyz>
                <izz>0.01112</izz>
            </inertia>
        </inertial>
        <collision name='lbr_iiwa_link_5_collision'>
          <pose frame=''>0 0 0 0 -0 0</pose>
          <geometry>
            <mesh>
              
              <scale>1 1 1</scale>
              <uri>/home/mamad/hand_RL_ws/src/iiwa_pybullet_integration/Training/kuka_handlit/kuka_handlit/envs/kuka_handlit_model/meshes/kuka/collision/link_5.stl</uri>
              
            </mesh>
          </geometry>
        </collision>
        <visual name='lbr_iiwa_link_5_visual'>
          <pose frame=''>0 0 0 0 -0 0</pose>
          <geometry>
            <mesh>
              <scale>1 1 1</scale>
              <uri>/home/mamad/hand_RL_ws/src/iiwa_pybullet_integration/Training/kuka_handlit/kuka_handlit/envs/kuka_handlit_model/meshes/kuka/visual/link_5.stl</uri>
            </mesh>
          </geometry>
          <material>
            <ambient>0.45722154422483974 0.4534899750385818 0.5391708185999798 1</ambient>
            <diffuse>0.7692275508625543 0.5517704752835565 0.3090559384014542 1</diffuse>
            <specular>0.8278454398108658 0.9013066940656081 0.5701178012811688 1</specular>
            <emissive>0 0 0 0</emissive>
          </material>
        </visual>
      </link>
    
      <link name="lbr_iiwa_link_6">
        <pose frame=''>0 -0.0607 1.14 1.5708 0 -3.14159</pose>
        <inertial>
            <pose frame=''>0 0.0006 0.0004 0 0 0</pose>
            <mass>2.3466</mass>
            <inertia>
                <ixx>0.006509</ixx>
                <ixy>0</ixy>
                <ixz>0</ixz>
                <iyy>0.006259</iyy>
                <iyz>0.00031891</iyz>
                <izz>0.004527</izz>
            </inertia>
        </inertial>
        <collision name='lbr_iiwa_link_6_collision'>
          <pose frame=''>0 0 0 0 -0 0</pose>
          <geometry>
            <mesh>
              
              <scale>1 1 1</scale>
              <uri>/home/mamad/hand_RL_ws/src/iiwa_pybullet_integration/Training/kuka_handlit/kuka_handlit/envs/kuka_handlit_model/meshes/kuka/collision/link_6.stl</uri>
              
            </mesh>
          </geometry>
        </collision>
        <visual name='lbr_iiwa_link_6_visual'>
          <pose frame=''>0 0 0 0 -0 0</pose>
          <geometry>
            <mesh>
              <scale>1 1 1</scale>
              <uri>/home/mamad/hand_RL_ws/src/iiwa_pybullet_integration/Training/kuka_handlit/kuka_handlit/envs/kuka_handlit_model/meshes/kuka/visual/link_6.stl</uri>
            </mesh>
          </geometry>
          <material>
            <ambient>0.7395172055163313 0.20888103100748645 0.12297306957049126 1</ambient>
            <diffuse>0.8375550107003258 0.38090347562119486 0.7955724230078445 1</diffuse>
            <specular>0.8283972976451545 0.5336534332214035 0.4990324219685146 1</specular>
            <emissive>0 0 0 0</emissive>
          </material>
        </visual>
      </link>
    
      <link name="lbr_iiwa_link_7">
        <pose frame=''>0 0 1.2205000000000001 0 0 0</pose>
        <inertial>
            <pose frame=''>0 0.00043 0.071108 0 0 0</pose>
            <mass>3.129</mass>
            <inertia>
                <ixx>0.145258</ixx>
                <ixy>0.0005912</ixy>
                <ixz>0</ixz>
                <iyy>0.145283</iyy>
                <iyz>-0.000503009</iyz>
                <izz>0.0572184</izz>
            </inertia>
        </inertial>
        <collision name='lbr_iiwa_link_7_collision'>
          <pose frame=''>0 0 0 0 -0 0</pose>
          <geometry>
            <mesh>
              
              <scale>1 1 1</scale>
              <uri>/home/mamad/hand_RL_ws/src/iiwa_pybullet_integration/Training/kuka_handlit/kuka_handlit/envs/kuka_handlit_model/meshes/kuka/collision/link_7.stl</uri>
              
            </mesh>
          </geometry>
        </collision>
        <visual name='lbr_iiwa_link_7_visual'>
          <pose frame=''>0 0 0 0 -0 0</pose>
          <geometry>
            <mesh>
              <scale>1 1 1</scale>
              <uri>/home/mamad/hand_RL_ws/src/iiwa_pybullet_integration/Training/kuka_handlit/kuka_handlit/envs/kuka_handlit_model/meshes/kuka/visual/link_7.stl</uri>
            </mesh>
          </geometry>
          <material>
            <ambient>0.6659820947537215 0.3967601107696507 0.14642002296414813 1</ambient>
            <diffuse>0.8228186776934898 0.3997900667841986 0.39809615687695643 1</diffuse>
            <specular>0.39978262403818765 0.7782922166450874 0.5240697594908595 1</specular>
            <emissive>0 0 0 0</emissive>
          </material>
        </visual>
      </link>
    
   
    
      <joint name="J0" type="revolute">
        <child>lbr_iiwa_link_1</child>
        <parent>lbr_iiwa_link_0</parent>
        <axis>
          <xyz>0 0 1</xyz>
          <limit>
            <lower>-2.96706</lower>
            <upper>2.96706</upper>
            <effort>300</effort>
            <velocity>10</velocity>
          </limit>
          <dynamics>
            <damping>0.5</damping>
            <friction>0</friction>
            <spring_reference>0</spring_reference>
            <spring_stiffness>0</spring_stiffness>
          </dynamics>
        </axis>
      </joint>
    
      <joint name="J1" type="revolute">
        <child>lbr_iiwa_link_2</child>
        <parent>lbr_iiwa_link_1</parent>
        <axis>
          <xyz>0 0 1</xyz>
          <limit>
            <lower>-2.0944</lower>
            <upper>2.0944</upper>
            <effort>300</effort>
            <velocity>10</velocity>
          </limit>
          <dynamics>
            <damping>0.5</damping>
            <friction>0</friction>
            <spring_reference>0</spring_reference>
            <spring_stiffness>0</spring_stiffness>
          </dynamics>
        </axis>
      </joint>
    
      <joint name="J2" type="revolute">
        <child>lbr_iiwa_link_3</child>
        <parent>lbr_iiwa_link_2</parent>
        <axis>
          <xyz>0 0 1</xyz>
          <limit>
            <lower>-2.96706</lower>
            <upper>2.96706</upper>
            <effort>300</effort>
            <velocity>10</velocity>
          </limit>
          <dynamics>
            <damping>0.5</damping>
            <friction>0</friction>
            <spring_reference>0</spring_reference>
            <spring_stiffness>0</spring_stiffness>
          </dynamics>
        </axis>
      </joint>
    
      <joint name="J3" type="revolute">
        <child>lbr_iiwa_link_4</child>
        <parent>lbr_iiwa_link_3</parent>
        <axis>
          <xyz>0 0 1</xyz>
          <limit>
            <lower>-2.0944</lower>
            <upper>2.0944</upper>
            <effort>300</effort>
            <velocity>10</velocity>
          </limit>
          <dynamics>
            <damping>0.5</damping>
            <friction>0</friction>
            <spring_reference>0</spring_reference>
            <spring_stiffness>0</spring_stiffness>
          </dynamics>
        </axis>
      </joint>
    
      <joint name="J4" type="revolute">
        <child>lbr_iiwa_link_5</child>
        <parent>lbr_iiwa_link_4</parent>
        <axis>
          <xyz>0 0 1</xyz>
          <limit>
            <lower>-2.96706</lower>
            <upper>2.96706</upper>
            <effort>300</effort>
            <velocity>10</velocity>
          </limit>
          <dynamics>
            <damping>0.5</damping>
            <friction>0</friction>
            <spring_reference>0</spring_reference>
            <spring_stiffness>0</spring_stiffness>
          </dynamics>
        </axis>
      </joint>
    
      <joint name="J5" type="revolute">
        <child>lbr_iiwa_link_6</child>
        <parent>lbr_iiwa_link_5</parent>
        <axis>
          <xyz>0 0 1</xyz>
          <limit>
            <lower>-2.0944</lower>
            <upper>2.0944</upper>
            <effort>300</effort>
            <velocity>10</velocity>
          </limit>
          <dynamics>
            <damping>0.5</damping>
            <friction>0</friction>
            <spring_reference>0</spring_reference>
            <spring_stiffness>0</spring_stiffness>
          </dynamics>
        </axis>
      </joint>
    
      <joint name="J6" type="revolute">
        <child>lbr_iiwa_link_7</child>
        <parent>lbr_iiwa_link_6</parent>
        <axis>
          <xyz>0 0 1</xyz>
          <limit>
            <lower>-3.05433</lower>
            <upper>3.05433</upper>
            <effort>300</effort>
            <velocity>10</velocity>
          </limit>
          <dynamics>
            <damping>0.5</damping>
            <friction>0</friction>
            <spring_reference>0</spring_reference>
            <spring_stiffness>0</spring_stiffness>
          </dynamics>
        </axis>
      </joint>
    

    <link name = "lbr_iiwa_link_ee">

        <pose frame=''>0 0 1.2655 0 0 0</pose>
        <inertial>
            <pose frame=''>0 0.00043 0.071108 0 0 0</pose>
            <mass>1.0e-22</mass>
            <inertia>
                <ixx>0.145258</ixx>
                <ixy>0.0005912</ixy>
                <ixz>0</ixz>
                <iyy>0.145283</iyy>
                <iyz>-0.000503009</iyz>
                <izz>0.0572184</izz>
            </inertia>
        </inertial>
            <visual name='visual_lbr_iiwa_link_ee'>
                <geometry>
                    <sphere>
                    <radius>0.01</radius>
                    </sphere>
                </geometry>
                <material>
                    <ambient>0.5672216218105076 0.531815859282997 0.5801439037594547 1</ambient>
                    <diffuse>0.5464167892541046 0.6932951350253517 0.22253023363722557 1</diffuse>
                    <specular>0.9022550019258972 0.9029306286118689 0.5969458319897258 1</specular>
                    <emissive>0 0 0 0</emissive>
                </material>
            </visual>
    </link>
    
    <joint name="J7" type="fixed">
        <child>lbr_iiwa_link_ee</child>
        <parent>lbr_iiwa_link_7</parent>
        <axis>

            <xyz>0 -1 0</xyz>
         </axis>
    </joint>  
    <!--Hand-->

    <joint name="forearm_world" type="fixed">
        <child>forearm</child>
        <parent>lbr_iiwa_link_ee</parent>
    </joint>

    <link name ="forearm" >
        <pose frame=''>0 0 1.2655 0 0 1.5707963267948966</pose>
        <inertial>
            <pose frame=''>0 0 0.09 0 0 0</pose>
            <mass>1.8</mass>
            <inertia>
                <ixx>0.108</ixx>
                <ixy>0</ixy>
                <ixz>0</ixz>
                <iyy>0.108</iyy>
                <iyz>0</iyz>
                <izz>0.054</izz>
            </inertia>
        </inertial>

        <visual name='visual_forearm_link'>

            <geometry>
                <mesh>
                    <scale>1 1 1</scale>
                    <uri>/home/mamad/hand_RL_ws/src/iiwa_pybullet_integration/Training/kuka_handlit/kuka_handlit/envs/kuka_handlit_model/meshes/forearm_lite.dae</uri>
                </mesh>
            </geometry>
            <material>
                <ambient>0.6169343828386191 0.7863444679172378 0.9465762515895025 1</ambient>
                <diffuse>0.9843039950901155 0.5667413102622583 0.1885970907789618 1</diffuse>
                <specular>0.7246513233449103 0.07706612967856519 0.8863849109422872 1</specular>
                <emissive>0 0 0 0</emissive>
            </material>
        </visual>
        <collision name='collision_forearm_link'>
        
            <geometry>
                <mesh>
                    <scale>1 1 1</scale>
                    <uri>/home/mamad/hand_RL_ws/src/iiwa_pybullet_integration/Training/kuka_handlit/kuka_handlit/envs/kuka_handlit_model/meshes/forearm_lite.dae</uri>
                </mesh>
            </geometry>
        </collision>
    </link>

    <link name = "palm">
        <pose frame=''>0 -0.015 1.4145 -0.6981317007977318 0 0</pose>
        <inertial>
            <pose frame=''>0 0 0.035 0 0 0</pose>
            <mass>0.3</mass>
            <inertia>
                <ixx>0.0003581</ixx>
                <ixy>0</ixy>
                <ixz>0</ixz>
                <iyy>0.0005287</iyy>
                <iyz>0</iyz>
                <izz>0.000191</izz>
            </inertia>
        </inertial>
        
        <visual name='visual_palm_link'>

            <geometry>
                <mesh>
                    <scale>-0.001 0.001 0.001</scale>
                    <uri>/home/mamad/hand_RL_ws/src/iiwa_pybullet_integration/Training/kuka_handlit/kuka_handlit/envs/kuka_handlit_model/meshes/palm2.dae</uri>
                </mesh>
            </geometry>
            <material>
                <ambient>0.9796066906624858 0.07928967051999036 0.7727354330067087 1</ambient>
                <diffuse>0.1535362201760242 0.8329230628555083 0.6304242883376938 1</diffuse>
                <specular>0.8192122960320561 0.9082294941111893 0.01938956900425537 1</specular>
                <emissive>0 0 0 0</emissive>
            </material>
        </visual>
        <collision name="collision_palm_link">

            <geometry>
                <mesh>
                    <scale>-0.001 0.001 0.001</scale>
                <uri>/home/mamad/hand_RL_ws/src/iiwa_pybullet_integration/Training/kuka_handlit/kuka_handlit/envs/kuka_handlit_model/meshes/palm2_c.dae</uri>
            </mesh>
            </geometry>
        </collision>


        
    </link>
    <joint name="palm_forearm" type="fixed">
        <child>palm</child>
        <parent>forearm</parent>
        <axis>

            <xyz>0 -1 0</xyz>
         </axis>
    </joint>  

    
    <link name = "palm_fake">

        <pose frame=''>-0.01 0.020909000000000004 1.4544000000000001 -0.6981317007977318 0 0</pose>
        <inertial>
            <pose frame=''>0 0 0.0 0 0 0</pose>
            <mass>0.0</mass>
            <inertia>
                <ixx>0.0</ixx>
                <ixy>0</ixy>
                <ixz>0</ixz>
                <iyy>0.0</iyy>
                <iyz>0</iyz>
                <izz>0.0</izz>
            </inertia>
        </inertial>
            <visual name='visual_palm_fake'>
                <geometry>
                    <sphere>
                    <radius>0.01</radius>
                    </sphere>
                </geometry>
                <material>
                    <ambient>0.5672216218105076 0.531815859282997 0.5801439037594547 1</ambient>
                    <diffuse>0.5464167892541046 0.6932951350253517 0.22253023363722557 1</diffuse>
                    <specular>0.9022550019258972 0.9029306286118689 0.5969458319897258 1</specular>
                    <emissive>0 0 0 0</emissive>
                </material>
            </visual>
    </link>

    <joint name="palm_palm_fake" type="fixed">
        <child>palm_fake</child>
        <parent>palm</parent>
        <axis>

            <xyz>0 -1 0</xyz>
         </axis>
    </joint>  

    

        <link name = "knuckle_FF">

            <pose frame=''>-0.033 0.0461 1.48727 -0.698132 0 0</pose>
            <inertial>
                <pose frame=''>0 0 0 0 0 0</pose>
                <mass>0.008</mass>
                <inertia>
                    <ixx>2.6e-07</ixx>
                    <ixy>0</ixy>
                    <ixz>0</ixz>
                    <iyy>2.6e-07</iyy>
                    <iyz>0</iyz>
                    <izz>3.2e-07</izz>
                </inertia>
            </inertial>

            <visual name='visual_knuckle_link_FF'>

                <geometry>
                    <mesh>
                        <scale>0.001 0.001 0.001</scale>
                        <uri>/home/mamad/hand_RL_ws/src/iiwa_pybullet_integration/Training/kuka_handlit/kuka_handlit/envs/kuka_handlit_model/meshes/knuckle.dae</uri>
                    </mesh>
                </geometry>
                <material>
                    <ambient>0.15550154926767246 0.9694154923447162 0.8035368497417645 1</ambient>
                    <diffuse>0.639106767455735 0.9479957307711335 0.8763550917524683 1</diffuse>
                    <specular>0.912809293716749 0.49128529639138363 0.27929382542573045 1</specular>
                    <emissive>0 0 0 0</emissive>
                </material>
            </visual>
            <collision name='collision_knuckle_link_FF'>
                <geometry>
                <mesh>
                    <scale>0.001 0.001 0.001</scale>
                    <uri>/home/mamad/hand_RL_ws/src/iiwa_pybullet_integration/Training/kuka_handlit/kuka_handlit/envs/kuka_handlit_model/meshes/knuckle.dae</uri>
                </mesh>
            </geometry>
            </collision>
        </link>
        <link name = "proximal_FF">
            <pose frame=''>-0.033 0.0461 1.48727 -0.698132 0 0</pose>
            <inertial>
                <pose frame=''>0 0 0.0225 0 0 0</pose>
                <mass>0.03</mass>
                <inertia>
                    <ixx>9.8e-06</ixx>
                    <ixy>0</ixy>
                    <ixz>0</ixz>
                    <iyy>1.0e-05</iyy>
                    <iyz>0</iyz>
                    <izz>1.8e-06</izz>
                </inertia>
            </inertial>

            <visual name='visual_proximal_link_FF'>

                <geometry>
                    <mesh>
                        <scale>0.001 0.001 0.001</scale>
                        <uri>/home/mamad/hand_RL_ws/src/iiwa_pybullet_integration/Training/kuka_handlit/kuka_handlit/envs/kuka_handlit_model/meshes/F3.dae</uri>
                    </mesh>
                </geometry>
                <material>
                    <ambient>0.23105518114551482 0.804986264154327 0.511373607326783 1</ambient>
                    <diffuse>0.7070373114108359 0.9767938533935714 0.2949854430266122 1</diffuse>
                    <specular>0.37387092493799 0.6046187973081111 0.08980577370025877 1</specular>
                    <emissive>0 0 0 0</emissive>
                </material>
            </visual>
            <collision name='collision_proximal_link_FF'>
                <geometry>
                <mesh>
                    <scale>0.001 0.001 0.001</scale>
                    <uri>/home/mamad/hand_RL_ws/src/iiwa_pybullet_integration/Training/kuka_handlit/kuka_handlit/envs/kuka_handlit_model/meshes/F3_c.dae</uri>
                </mesh>
            </geometry>
            </collision>
        </link>
        <link name = "middle_FF">
            <pose frame=''>-0.033 0.07499 1.521746 -0.698132 0 0</pose>
            <inertial>
                <pose frame=''>0 0 0.0125 0 0 0</pose>
                <mass>0.017</mass>
                <inertia>
                    <ixx>2.6e-06</ixx>
                    <ixy>0</ixy>
                    <ixz>0</ixz>
                    <iyy>2.7e-06</iyy>
                    <iyz>0</iyz>
                    <izz>8.7e-07</izz>
                </inertia>
            </inertial>

            <visual name='visual_middle_link_FF'>

                <geometry>
                    <mesh>
                        <scale>0.001 0.001 0.001</scale>
                        <uri>/home/mamad/hand_RL_ws/src/iiwa_pybullet_integration/Training/kuka_handlit/kuka_handlit/envs/kuka_handlit_model/meshes/F2.dae</uri>
                    </mesh>
                </geometry>
                <material>
                    <ambient>0.8252578105583964 0.5283489247725707 0.07738874966457276 1</ambient>
                    <diffuse>0.23269473480029534 0.0978373147477326 0.08263598659251037 1</diffuse>
                    <specular>0.40315161527276155 0.05892494036557183 0.5170229911147968 1</specular>
                    <emissive>0 0 0 0</emissive>
                </material>
            </visual>
            <collision name='collision_middle_link_FF'>
                <geometry>
                    <mesh>
                        <scale>0.001 0.001 0.001</scale>
                        <uri>/home/mamad/hand_RL_ws/src/iiwa_pybullet_integration/Training/kuka_handlit/kuka_handlit/envs/kuka_handlit_model/meshes/F2_c.dae</uri>
                    </mesh>
                </geometry>
            </collision>
        </link>
        <link name =  "distal_FF">
            <pose frame=''>-0.033 0.09106 1.540897 -0.698132 0 0</pose>
            <inertial>
                <pose frame=''>0 0 0.012 0 0 0</pose>
                <mass>0.012</mass>
                <inertia>
                    <ixx>9.4e-07</ixx>
                    <ixy>0</ixy>
                    <ixz>0</ixz>
                    <iyy>1.1e-06</iyy>
                    <iyz>0</iyz>
                    <izz>5.3e-07</izz>
                </inertia>
            </inertial>

            <visual name='visual_distal_link_FF'>

                <geometry>
                    <mesh>
                        <scale>0.001 0.001 0.001</scale>
                        <uri>/home/mamad/hand_RL_ws/src/iiwa_pybullet_integration/Training/kuka_handlit/kuka_handlit/envs/kuka_handlit_model/meshes/F1.dae</uri>
                    </mesh>
                </geometry>
                <material>
                    <ambient>0.7323766611548866 0.197585556140901 0.990090443664838 1</ambient>
                    <diffuse>0.6875192741068549 0.41167917364850104 0.7788874695745883 1</diffuse>
                    <specular>0.5240369396693455 0.4815450790604444 0.12871698858062097 1</specular>
                    <emissive>0 0 0 0</emissive>
                </material>
            </visual>
            <collision name='collision_distal_link_FF'>
                <geometry>
                    <mesh>
                        <scale>0.001 0.001 0.001</scale>
                        <uri>/home/mamad/hand_RL_ws/src/iiwa_pybullet_integration/Training/kuka_handlit/kuka_handlit/envs/kuka_handlit_model/meshes/F1.dae</uri>
                    </mesh>
                </geometry>
            </collision>
        </link>

        
            
            <joint name="J3_FF" type="revolute">
                <child>proximal_FF</child>
                <parent>knuckle_FF</parent>

                <axis>
                    <xyz>1 0 0</xyz>
                    <limit>
                        <lower>0 </lower>
                        <upper>1.5708 </upper>
                        <effort>2.0 </effort>
                        <velocity>2.0 </velocity>
                    </limit>
                    <dynamics>
                        <damping>0.1</damping>
                        <friction>0</friction>
                        <spring_reference>0</spring_reference>
                        <spring_stiffness>0</spring_stiffness>
                    </dynamics>
                </axis>
            </joint>
        
            
            <joint name="J2_FF" type="revolute">
                <child>middle_FF</child>
                <parent>proximal_FF</parent>

                <axis>
                    <xyz>1 0 0</xyz>
                    <limit>
                        <lower>0 </lower>
                        <upper>1.5708 </upper>
                        <effort>2.0 </effort>
                        <velocity>2.0 </velocity>
                    </limit>
                    <dynamics>
                        <damping>0.1</damping>
                        <friction>0</friction>
                        <spring_reference>0</spring_reference>
                        <spring_stiffness>0</spring_stiffness>
                    </dynamics>
                </axis>
            </joint>
        
            
            <joint name="J1_FF" type="revolute">
                <child>distal_FF</child>
                <parent>middle_FF</parent>

                <axis>
                    <xyz>1 0 0</xyz>
                    <limit>
                        <lower>0 </lower>
                        <upper>1.5708 </upper>
                        <effort>2.0 </effort>
                        <velocity>2.0 </velocity>
                    </limit>
                    <dynamics>
                        <damping>0.1</damping>
                        <friction>0</friction>
                        <spring_reference>0</spring_reference>
                        <spring_stiffness>0</spring_stiffness>
                    </dynamics>
                </axis>
            </joint>
        
        <joint name='J4_FF' type="revolute">
            <child>knuckle_FF</child>
            <parent>palm</parent>

            <axis>
                <xyz>0 0.766044 -0.642788</xyz>
                <limit>
                    <lower>-0.349066 </lower>
                    <upper>0.349066 </upper>
                    <effort>2.0 </effort>
                    <velocity>2.0 </velocity>
                </limit>
                <dynamics>
                    <damping>0.1</damping>
                    <friction>0</friction>
                    <spring_reference>0</spring_reference>
                    <spring_stiffness>0</spring_stiffness>
                </dynamics>
            </axis>
        </joint>

    

        <link name = "knuckle_MF">

            <pose frame=''>-0.011000000000000003 0.048636 1.4903380000000002 -0.698132 0 0</pose>
            <inertial>
                <pose frame=''>0 0 0 0 0 0</pose>
                <mass>0.008</mass>
                <inertia>
                    <ixx>2.6e-07</ixx>
                    <ixy>0</ixy>
                    <ixz>0</ixz>
                    <iyy>2.6e-07</iyy>
                    <iyz>0</iyz>
                    <izz>3.2e-07</izz>
                </inertia>
            </inertial>

            <visual name='visual_knuckle_link_MF'>

                <geometry>
                    <mesh>
                        <scale>0.001 0.001 0.001</scale>
                        <uri>/home/mamad/hand_RL_ws/src/iiwa_pybullet_integration/Training/kuka_handlit/kuka_handlit/envs/kuka_handlit_model/meshes/knuckle.dae</uri>
                    </mesh>
                </geometry>
                <material>
                    <ambient>0.275648778830468 0.33833453492136867 0.90749664736456 1</ambient>
                    <diffuse>0.45236429729922734 0.24386763974552061 0.3433998039281235 1</diffuse>
                    <specular>0.42523053015932044 0.7713862909807003 0.6603318158885436 1</specular>
                    <emissive>0 0 0 0</emissive>
                </material>
            </visual>
            <collision name='collision_knuckle_link_MF'>
                <geometry>
                <mesh>
                    <scale>0.001 0.001 0.001</scale>
                    <uri>/home/mamad/hand_RL_ws/src/iiwa_pybullet_integration/Training/kuka_handlit/kuka_handlit/envs/kuka_handlit_model/meshes/knuckle.dae</uri>
                </mesh>
            </geometry>
            </collision>
        </link>
        <link name = "proximal_MF">
            <pose frame=''>-0.011000000000000003 0.048636 1.4903380000000002 -0.698132 0 0</pose>
            <inertial>
                <pose frame=''>0 0 0.0225 0 0 0</pose>
                <mass>0.03</mass>
                <inertia>
                    <ixx>9.8e-06</ixx>
                    <ixy>0</ixy>
                    <ixz>0</ixz>
                    <iyy>1.0e-05</iyy>
                    <iyz>0</iyz>
                    <izz>1.8e-06</izz>
                </inertia>
            </inertial>

            <visual name='visual_proximal_link_MF'>

                <geometry>
                    <mesh>
                        <scale>0.001 0.001 0.001</scale>
                        <uri>/home/mamad/hand_RL_ws/src/iiwa_pybullet_integration/Training/kuka_handlit/kuka_handlit/envs/kuka_handlit_model/meshes/F3.dae</uri>
                    </mesh>
                </geometry>
                <material>
                    <ambient>0.9701909056926625 0.047795966002303625 0.4807689427754692 1</ambient>
                    <diffuse>0.9688013356922687 0.5035258182210003 0.36368038790597745 1</diffuse>
                    <specular>0.48753104961481886 0.26940682045253783 0.8274737263026539 1</specular>
                    <emissive>0 0 0 0</emissive>
                </material>
            </visual>
            <collision name='collision_proximal_link_MF'>
                <geometry>
                <mesh>
                    <scale>0.001 0.001 0.001</scale>
                    <uri>/home/mamad/hand_RL_ws/src/iiwa_pybullet_integration/Training/kuka_handlit/kuka_handlit/envs/kuka_handlit_model/meshes/F3_c.dae</uri>
                </mesh>
            </geometry>
            </collision>
        </link>
        <link name = "middle_MF">
            <pose frame=''>-0.011000000000000003 0.077526 1.5248140000000001 -0.698132 0 0</pose>
            <inertial>
                <pose frame=''>0 0 0.0125 0 0 0</pose>
                <mass>0.017</mass>
                <inertia>
                    <ixx>2.6e-06</ixx>
                    <ixy>0</ixy>
                    <ixz>0</ixz>
                    <iyy>2.7e-06</iyy>
                    <iyz>0</iyz>
                    <izz>8.7e-07</izz>
                </inertia>
            </inertial>

            <visual name='visual_middle_link_MF'>

                <geometry>
                    <mesh>
                        <scale>0.001 0.001 0.001</scale>
                        <uri>/home/mamad/hand_RL_ws/src/iiwa_pybullet_integration/Training/kuka_handlit/kuka_handlit/envs/kuka_handlit_model/meshes/F2.dae</uri>
                    </mesh>
                </geometry>
                <material>
                    <ambient>0.5424607050797831 0.740469084565567 0.18695336508436977 1</ambient>
                    <diffuse>0.2716014744285159 0.2574341532410207 0.2107949708413569 1</diffuse>
                    <specular>0.831692814958715 0.29629761823440537 0.37951519358820407 1</specular>
                    <emissive>0 0 0 0</emissive>
                </material>
            </visual>
            <collision name='collision_middle_link_MF'>
                <geometry>
                    <mesh>
                        <scale>0.001 0.001 0.001</scale>
                        <uri>/home/mamad/hand_RL_ws/src/iiwa_pybullet_integration/Training/kuka_handlit/kuka_handlit/envs/kuka_handlit_model/meshes/F2_c.dae</uri>
                    </mesh>
                </geometry>
            </collision>
        </link>
        <link name =  "distal_MF">
            <pose frame=''>-0.011000000000000003 0.093596 1.543965 -0.698132 0 0</pose>
            <inertial>
                <pose frame=''>0 0 0.012 0 0 0</pose>
                <mass>0.012</mass>
                <inertia>
                    <ixx>9.4e-07</ixx>
                    <ixy>0</ixy>
                    <ixz>0</ixz>
                    <iyy>1.1e-06</iyy>
                    <iyz>0</iyz>
                    <izz>5.3e-07</izz>
                </inertia>
            </inertial>

            <visual name='visual_distal_link_MF'>

                <geometry>
                    <mesh>
                        <scale>0.001 0.001 0.001</scale>
                        <uri>/home/mamad/hand_RL_ws/src/iiwa_pybullet_integration/Training/kuka_handlit/kuka_handlit/envs/kuka_handlit_model/meshes/F1.dae</uri>
                    </mesh>
                </geometry>
                <material>
                    <ambient>0.43802705409426435 0.14868631798406073 0.8916601450458135 1</ambient>
                    <diffuse>0.3186017778933 0.322080818406585 0.09027741439236092 1</diffuse>
                    <specular>0.22131565359708683 0.20960979033877625 0.5974365655802015 1</specular>
                    <emissive>0 0 0 0</emissive>
                </material>
            </visual>
            <collision name='collision_distal_link_MF'>
                <geometry>
                    <mesh>
                        <scale>0.001 0.001 0.001</scale>
                        <uri>/home/mamad/hand_RL_ws/src/iiwa_pybullet_integration/Training/kuka_handlit/kuka_handlit/envs/kuka_handlit_model/meshes/F1.dae</uri>
                    </mesh>
                </geometry>
            </collision>
        </link>

        
            
            <joint name="J3_MF" type="revolute">
                <child>proximal_MF</child>
                <parent>knuckle_MF</parent>

                <axis>
                    <xyz>1 0 0</xyz>
                    <limit>
                        <lower>0 </lower>
                        <upper>1.5708 </upper>
                        <effort>2.0 </effort>
                        <velocity>2.0 </velocity>
                    </limit>
                    <dynamics>
                        <damping>0.1</damping>
                        <friction>0</friction>
                        <spring_reference>0</spring_reference>
                        <spring_stiffness>0</spring_stiffness>
                    </dynamics>
                </axis>
            </joint>
        
            
            <joint name="J2_MF" type="revolute">
                <child>middle_MF</child>
                <parent>proximal_MF</parent>

                <axis>
                    <xyz>1 0 0</xyz>
                    <limit>
                        <lower>0 </lower>
                        <upper>1.5708 </upper>
                        <effort>2.0 </effort>
                        <velocity>2.0 </velocity>
                    </limit>
                    <dynamics>
                        <damping>0.1</damping>
                        <friction>0</friction>
                        <spring_reference>0</spring_reference>
                        <spring_stiffness>0</spring_stiffness>
                    </dynamics>
                </axis>
            </joint>
        
            
            <joint name="J1_MF" type="revolute">
                <child>distal_MF</child>
                <parent>middle_MF</parent>

                <axis>
                    <xyz>1 0 0</xyz>
                    <limit>
                        <lower>0 </lower>
                        <upper>1.5708 </upper>
                        <effort>2.0 </effort>
                        <velocity>2.0 </velocity>
                    </limit>
                    <dynamics>
                        <damping>0.1</damping>
                        <friction>0</friction>
                        <spring_reference>0</spring_reference>
                        <spring_stiffness>0</spring_stiffness>
                    </dynamics>
                </axis>
            </joint>
        
        <joint name='J4_MF' type="revolute">
            <child>knuckle_MF</child>
            <parent>palm</parent>

            <axis>
                <xyz>0 0.766044 -0.642788</xyz>
                <limit>
                    <lower>-0.349066 </lower>
                    <upper>0.349066 </upper>
                    <effort>2.0 </effort>
                    <velocity>2.0 </velocity>
                </limit>
                <dynamics>
                    <damping>0.1</damping>
                    <friction>0</friction>
                    <spring_reference>0</spring_reference>
                    <spring_stiffness>0</spring_stiffness>
                </dynamics>
            </axis>
        </joint>

    

        <link name = "knuckle_RF">

            <pose frame=''>0.010999999999999996 0.0461 1.48727 -0.698132 0 0</pose>
            <inertial>
                <pose frame=''>0 0 0 0 0 0</pose>
                <mass>0.008</mass>
                <inertia>
                    <ixx>2.6e-07</ixx>
                    <ixy>0</ixy>
                    <ixz>0</ixz>
                    <iyy>2.6e-07</iyy>
                    <iyz>0</iyz>
                    <izz>3.2e-07</izz>
                </inertia>
            </inertial>

            <visual name='visual_knuckle_link_RF'>

                <geometry>
                    <mesh>
                        <scale>0.001 0.001 0.001</scale>
                        <uri>/home/mamad/hand_RL_ws/src/iiwa_pybullet_integration/Training/kuka_handlit/kuka_handlit/envs/kuka_handlit_model/meshes/knuckle.dae</uri>
                    </mesh>
                </geometry>
                <material>
                    <ambient>0.49300008705319653 0.5563458259226989 0.7298994646361604 1</ambient>
                    <diffuse>0.6723547860606014 0.9612621710193542 0.948940247199631 1</diffuse>
                    <specular>0.6425970691920777 0.459015498372053 0.20093296166934538 1</specular>
                    <emissive>0 0 0 0</emissive>
                </material>
            </visual>
            <collision name='collision_knuckle_link_RF'>
                <geometry>
                <mesh>
                    <scale>0.001 0.001 0.001</scale>
                    <uri>/home/mamad/hand_RL_ws/src/iiwa_pybullet_integration/Training/kuka_handlit/kuka_handlit/envs/kuka_handlit_model/meshes/knuckle.dae</uri>
                </mesh>
            </geometry>
            </collision>
        </link>
        <link name = "proximal_RF">
            <pose frame=''>0.010999999999999996 0.0461 1.48727 -0.698132 0 0</pose>
            <inertial>
                <pose frame=''>0 0 0.0225 0 0 0</pose>
                <mass>0.03</mass>
                <inertia>
                    <ixx>9.8e-06</ixx>
                    <ixy>0</ixy>
                    <ixz>0</ixz>
                    <iyy>1.0e-05</iyy>
                    <iyz>0</iyz>
                    <izz>1.8e-06</izz>
                </inertia>
            </inertial>

            <visual name='visual_proximal_link_RF'>

                <geometry>
                    <mesh>
                        <scale>0.001 0.001 0.001</scale>
                        <uri>/home/mamad/hand_RL_ws/src/iiwa_pybullet_integration/Training/kuka_handlit/kuka_handlit/envs/kuka_handlit_model/meshes/F3.dae</uri>
                    </mesh>
                </geometry>
                <material>
                    <ambient>0.9903126770859713 0.6908483730165444 0.2884709060456371 1</ambient>
                    <diffuse>0.749365648302662 0.6030136603523888 0.9615562120520635 1</diffuse>
                    <specular>0.6183488129486167 0.8200309936576867 0.5630992416113355 1</specular>
                    <emissive>0 0 0 0</emissive>
                </material>
            </visual>
            <collision name='collision_proximal_link_RF'>
                <geometry>
                <mesh>
                    <scale>0.001 0.001 0.001</scale>
                    <uri>/home/mamad/hand_RL_ws/src/iiwa_pybullet_integration/Training/kuka_handlit/kuka_handlit/envs/kuka_handlit_model/meshes/F3_c.dae</uri>
                </mesh>
            </geometry>
            </collision>
        </link>
        <link name = "middle_RF">
            <pose frame=''>0.010999999999999996 0.07499 1.521746 -0.698132 0 0</pose>
            <inertial>
                <pose frame=''>0 0 0.0125 0 0 0</pose>
                <mass>0.017</mass>
                <inertia>
                    <ixx>2.6e-06</ixx>
                    <ixy>0</ixy>
                    <ixz>0</ixz>
                    <iyy>2.7e-06</iyy>
                    <iyz>0</iyz>
                    <izz>8.7e-07</izz>
                </inertia>
            </inertial>

            <visual name='visual_middle_link_RF'>

                <geometry>
                    <mesh>
                        <scale>0.001 0.001 0.001</scale>
                        <uri>/home/mamad/hand_RL_ws/src/iiwa_pybullet_integration/Training/kuka_handlit/kuka_handlit/envs/kuka_handlit_model/meshes/F2.dae</uri>
                    </mesh>
                </geometry>
                <material>
                    <ambient>0.9960963136895832 0.05307137393149608 0.13876223877925153 1</ambient>
                    <diffuse>0.27750250202846516 0.5105794296685936 0.42100329435233874 1</diffuse>
                    <specular>0.4091119930429781 0.5840608626771044 0.8157994496939708 1</specular>
                    <emissive>0 0 0 0</emissive>
                </material>
            </visual>
            <collision name='collision_middle_link_RF'>
                <geometry>
                    <mesh>
                        <scale>0.001 0.001 0.001</scale>
                        <uri>/home/mamad/hand_RL_ws/src/iiwa_pybullet_integration/Training/kuka_handlit/kuka_handlit/envs/kuka_handlit_model/meshes/F2_c.dae</uri>
                    </mesh>
                </geometry>
            </collision>
        </link>
        <link name =  "distal_RF">
            <pose frame=''>0.010999999999999996 0.09106 1.540897 -0.698132 0 0</pose>
            <inertial>
                <pose frame=''>0 0 0.012 0 0 0</pose>
                <mass>0.012</mass>
                <inertia>
                    <ixx>9.4e-07</ixx>
                    <ixy>0</ixy>
                    <ixz>0</ixz>
                    <iyy>1.1e-06</iyy>
                    <iyz>0</iyz>
                    <izz>5.3e-07</izz>
                </inertia>
            </inertial>

            <visual name='visual_distal_link_RF'>

                <geometry>
                    <mesh>
                        <scale>0.001 0.001 0.001</scale>
                        <uri>/home/mamad/hand_RL_ws/src/iiwa_pybullet_integration/Training/kuka_handlit/kuka_handlit/envs/kuka_handlit_model/meshes/F1.dae</uri>
                    </mesh>
                </geometry>
                <material>
                    <ambient>0.19518096003865915 0.8388501642817068 0.2928589866927753 1</ambient>
                    <diffuse>0.06719239351507056 0.843242663714649 0.6400929957213166 1</diffuse>
                    <specular>0.9298216077323667 0.9071231736986785 0.6347448659715663 1</specular>
                    <emissive>0 0 0 0</emissive>
                </material>
            </visual>
            <collision name='collision_distal_link_RF'>
                <geometry>
                    <mesh>
                        <scale>0.001 0.001 0.001</scale>
                        <uri>/home/mamad/hand_RL_ws/src/iiwa_pybullet_integration/Training/kuka_handlit/kuka_handlit/envs/kuka_handlit_model/meshes/F1.dae</uri>
                    </mesh>
                </geometry>
            </collision>
        </link>

        
            
            <joint name="J3_RF" type="revolute">
                <child>proximal_RF</child>
                <parent>knuckle_RF</parent>

                <axis>
                    <xyz>1 0 0</xyz>
                    <limit>
                        <lower>0 </lower>
                        <upper>1.5708 </upper>
                        <effort>2.0 </effort>
                        <velocity>2.0 </velocity>
                    </limit>
                    <dynamics>
                        <damping>0.1</damping>
                        <friction>0</friction>
                        <spring_reference>0</spring_reference>
                        <spring_stiffness>0</spring_stiffness>
                    </dynamics>
                </axis>
            </joint>
        
            
            <joint name="J2_RF" type="revolute">
                <child>middle_RF</child>
                <parent>proximal_RF</parent>

                <axis>
                    <xyz>1 0 0</xyz>
                    <limit>
                        <lower>0 </lower>
                        <upper>1.5708 </upper>
                        <effort>2.0 </effort>
                        <velocity>2.0 </velocity>
                    </limit>
                    <dynamics>
                        <damping>0.1</damping>
                        <friction>0</friction>
                        <spring_reference>0</spring_reference>
                        <spring_stiffness>0</spring_stiffness>
                    </dynamics>
                </axis>
            </joint>
        
            
            <joint name="J1_RF" type="revolute">
                <child>distal_RF</child>
                <parent>middle_RF</parent>

                <axis>
                    <xyz>1 0 0</xyz>
                    <limit>
                        <lower>0 </lower>
                        <upper>1.5708 </upper>
                        <effort>2.0 </effort>
                        <velocity>2.0 </velocity>
                    </limit>
                    <dynamics>
                        <damping>0.1</damping>
                        <friction>0</friction>
                        <spring_reference>0</spring_reference>
                        <spring_stiffness>0</spring_stiffness>
                    </dynamics>
                </axis>
            </joint>
        
        <joint name='J4_RF' type="revolute">
            <child>knuckle_RF</child>
            <parent>palm</parent>

            <axis>
                <xyz>0 0.766044 -0.642788</xyz>
                <limit>
                    <lower>-0.349066 </lower>
                    <upper>0.349066 </upper>
                    <effort>2.0 </effort>
                    <velocity>2.0 </velocity>
                </limit>
                <dynamics>
                    <damping>0.1</damping>
                    <friction>0</friction>
                    <spring_reference>0</spring_reference>
                    <spring_stiffness>0</spring_stiffness>
                </dynamics>
            </axis>
        </joint>

    


    <link name = "thbase">
        <pose frame=''>-0.034 -0.0028710000000000003 1.442179 0.870557 0.572429 -2.5703</pose>
        <inertial>
            <pose frame=''>0 0 0 0 0 0</pose>
            <mass>0.01</mass>
            <inertia>
                <ixx>1.6e-07</ixx>
                <ixy>0</ixy>
                <ixz>0</ixz>
                <iyy>1.6e-07</iyy>
                <iyz>0</iyz>
                <izz>1.6e-07</izz>
            </inertia>
        </inertial>
        <visual name='visual_thbase_link'>
            
            <geometry>
                <box>
                    <size>0.001 0.001 0.001</size>
                </box>
            </geometry>
            <material>
                <ambient>0.0077230897807774035 0.45636445132869796 0.4990028528978989 1</ambient>
                <diffuse>0.17505038705711962 0.8577370394394034 0.3404592687789595 1</diffuse>
                <specular>0.3433357233383624 0.5030119524890754 0.2335361492812561 1</specular>
                <emissive>0 0 0 0</emissive>
            </material>
        </visual>
        <collision name='collision_thbase_link'>
            <pose frame=''>0 0 0 0 0 0</pose>
            <geometry>

                <sphere>
                    <radius>0.011</radius>
                </sphere>
            
            </geometry>
        </collision>
    </link>
    <link name = "thproximal">
            
        <pose frame=''>-0.034 -0.0028710000000000003 1.442179 0.870557 0.572429 -2.5703</pose>
        <inertial>
            <pose frame=''>0 0 0.021111 0 0 0</pose>
            <mass>0.04</mass>
            <inertia>
                <ixx>1.36e-05</ixx>
                <ixy>0</ixy>
                <ixz>0</ixz>
                <iyy>1.36e-05</iyy>
                <iyz>0</iyz>
                <izz>3.13e-06</izz>
            </inertia>
        </inertial>

        <visual name='visual_thproximal_link'>
            
            <geometry>
                <mesh>
                    <scale>0.001 0.001 0.001</scale>
                    <uri>/home/mamad/hand_RL_ws/src/iiwa_pybullet_integration/Training/kuka_handlit/kuka_handlit/envs/kuka_handlit_model/meshes/TH3_z.dae</uri>
                </mesh>
            </geometry>
            <material>
                <ambient>0.37186401041360295 0.3830890243097014 0.671422756585133 1</ambient>
                <diffuse>0.4349258368530481 0.36340131600520054 0.30644261867329936 1</diffuse>
                <specular>0.5997973321844967 0.1176736091185625 0.6068385531042839 1</specular>
                <emissive>0 0 0 0</emissive>
            </material>
        </visual>
        <collision name='collision_thproximal_link'>
            <geometry>
                <mesh>
                    <scale>0.001 0.001 0.001</scale>
                    <uri>/home/mamad/hand_RL_ws/src/iiwa_pybullet_integration/Training/kuka_handlit/kuka_handlit/envs/kuka_handlit_model/meshes/TH3_z_c.dae</uri>
                </mesh>
            </geometry>
        </collision>
    </link>
    <link name = "thhub">
        <pose frame=''>-0.06087000000000001 0.014400999999999999 1.462763 0.870557 0.572429 -2.5703</pose>
        <inertial>
            <pose frame=''>0 0 0 0 0 0</pose>
            <mass>0.005</mass>
            <inertia>
                <ixx>1.0e-06</ixx>
                <ixy>0</ixy>
                <ixz>0</ixz>
                <iyy>1.0e-06</iyy>
                <iyz>0</iyz>
                <izz>3.0e-07</izz>
            </inertia>
        </inertial>
        <visual name='visual_thhub_link'>
            
            <geometry>
                <box>
                    <size>0.001 0.001 0.001</size>
                </box>
            </geometry>
            <material>

            </material>
        </visual>
        <collision name='collision_thhub_link'>
            <geometry>
                <box>
                    <size>0.001 0.001 0.001</size>
                </box>
            </geometry>
        </collision>
    </link>
    <link name = "thmiddle">
            
        <pose frame=''>-0.06087000000000001 0.014400999999999999 1.462763 0.870557 0.572429 -2.5703</pose>
        <inertial>
            <pose frame=''>0 0 0.16 0 0 0</pose>
            <mass>0.02</mass>
            <inertia>
                <ixx>5.1e-06</ixx>
                <ixy>0</ixy>
                <ixz>0</ixz>
                <iyy>5.1e-06</iyy>
                <iyz>0</iyz>
                <izz>1.21e-06</izz>
            </inertia>
        </inertial>

        <visual name='visual_thmiddle_link'>
            
            <geometry>
                <mesh>
                    <scale>0.001 0.001 0.001</scale>
                    <uri>/home/mamad/hand_RL_ws/src/iiwa_pybullet_integration/Training/kuka_handlit/kuka_handlit/envs/kuka_handlit_model/meshes/TH2_z.dae</uri>
                </mesh>
            </geometry>
            <material>
                <ambient>0.8458217082825595 0.2526102426030332 0.9554558921254517 1</ambient>
                <diffuse>0.6181035356171425 0.29163376658405427 0.2812932898472287 1</diffuse>
                <specular>0.34272716650845236 0.3084453574855186 0.9594352827381081 1</specular>
                <emissive>0 0 0 0</emissive>
            </material>
        </visual>

        <collision name='collision_thmiddle_link'>
            <geometry>
                <mesh>
                    <scale>0.001 0.001 0.001</scale>
                    <uri>/home/mamad/hand_RL_ws/src/iiwa_pybullet_integration/Training/kuka_handlit/kuka_handlit/envs/kuka_handlit_model/meshes/TH2_z_c.dae</uri>
                </mesh>
            </geometry>
        </collision>
    </link>
    <link name = "thdistal">
            
        <pose frame=''>-0.083498 0.028946 1.480096 -0.785398 0.698132 1.5707999999999998</pose>
        <inertial>
            <pose frame=''>0 0 0.014559 0 0 0</pose>
            <mass>0.016</mass>
            <inertia>
                <ixx>2.1e-06</ixx>
                <ixy>0</ixy>
                <ixz>0</ixz>
                <iyy>2.2e-06</iyy>
                <iyz>0</iyz>
                <izz>1.0e-06</izz>
            </inertia>
        </inertial>

        <visual name='visual_thdistal_link'>
            
            <geometry>
                <mesh>
                    <scale>0.001 0.001 0.001</scale>
                    <uri>/home/mamad/hand_RL_ws/src/iiwa_pybullet_integration/Training/kuka_handlit/kuka_handlit/envs/kuka_handlit_model/meshes/TH1_z.dae</uri>
                </mesh>
            </geometry>
            <material>
                <ambient>0.259601620138714 0.024653785012490936 0.8275598748927709 1</ambient>
                <diffuse>0.6745557509068011 0.9654514989941654 0.3063750169877907 1</diffuse>
                <specular>0.14476508992007098 0.6140038360845227 0.021297846829810063 1</specular>
                <emissive>0 0 0 0</emissive>
            </material>
        </visual>
        <collision name='collision_thdistal_link'>
            <geometry>
                <mesh>
                    <scale>0.001 0.001 0.001</scale>
                    <uri>/home/mamad/hand_RL_ws/src/iiwa_pybullet_integration/Training/kuka_handlit/kuka_handlit/envs/kuka_handlit_model/meshes/TH1_z.dae</uri>
                </mesh>
            </geometry>
        </collision>
    </link>

    
        <joint name ="THJ5"  type ="revolute">
            <child>thbase</child>
            <parent>palm</parent>
            <axis>
                <xyz>0 0 0.541675</xyz>
                <limit>
                    <lower>-1.0472 </lower>
                    <upper>1.0472 </upper>
                    <effort>5.0 </effort>
                    <velocity>4.0 </velocity>
                </limit>
                <dynamics>
                    <damping>0.2</damping>
                    <friction>0</friction>
                </dynamics>
            </axis>
        </joint>
    
        <joint name ="THJ4"  type ="revolute">
            <child>thproximal</child>
            <parent>thbase</parent>
            <axis>
                <xyz>-0.707107 -0.454519 -0.541675</xyz>
                <limit>
                    <lower>0 </lower>
                    <upper>1.22173 </upper>
                    <effort>3.0 </effort>
                    <velocity>4.0 </velocity>
                </limit>
                <dynamics>
                    <damping>0.2</damping>
                    <friction>0</friction>
                </dynamics>
            </axis>
        </joint>
    
        <joint name ="THJ2"  type ="revolute">
            <child>thmiddle</child>
            <parent>thhub</parent>
            <axis>
                <xyz>0 -0.766044 0.642788</xyz>
                <limit>
                    <lower>-0.698132 </lower>
                    <upper>0.698132 </upper>
                    <effort>2.0 </effort>
                    <velocity>2.0 </velocity>
                </limit>
                <dynamics>
                    <damping>0.1</damping>
                    <friction>0</friction>
                </dynamics>
            </axis>
        </joint>
    
        <joint name ="THJ1"  type ="revolute">
            <child>thdistal</child>
            <parent>thmiddle</parent>
            <axis>
                <xyz>0 -0.766044 0.642788</xyz>
                <limit>
                    <lower>0 </lower>
                    <upper>1.5708 </upper>
                    <effort>1.0 </effort>
                    <velocity>4.0 </velocity>
                </limit>
                <dynamics>
                    <damping>0.2</damping>
                    <friction>0</friction>
                </dynamics>
            </axis>
        </joint>
    
    <joint name ="THJ3"  type ="fixed">
        <child>thhub</child>
        <parent>thproximal</parent>
        <axis>
            <xyz>1 0 0</xyz>
        </axis>
    </joint>






 
   
  </model>

</sdf>