<?xml version='1.0'?>

<sdf version='1.6'>

<model name='shadow_hand_vijay'>
    <static>true</static>
    <link name = "forearm_link">
        <pose frame=''>0 0 0 0 0 0</pose>
        <inertial>
            <pose frame=''>0 0 0.09 0 0 0</pose>
            <mass>0</mass>
            <inertia>
                <ixx>0.0138</ixx>
                <ixy>0</ixy>
                <ixz>0</ixz>
                <iyy>0.0138</iyy>
                <iyz>0</iyz>
                <izz>0.00744</izz>
            </inertia>
        </inertial>

        <visual name='visual_forearm_link'>
            
            <geometry>
                <mesh>
                    <scale>0.001 0.001 0.001</scale>
                    <uri>meshes/forearm.dae</uri>
                </mesh>
            </geometry>
            <material>
                <ambient>0.1560669970602483 0.4732562683161714 0.692141890695694 1</ambient>
                <diffuse>0.9708815131068702 0.38737654458699455 0.09233042231119548 1</diffuse>
                <specular>0.1291999529044694 0.5754208102409267 0.9056358646889875 1</specular>
                <emissive>0.976 0.937 0.466 1</emissive>
            </material>
        </visual>
        <collision name='collision_forearm_link'>
           
            <geometry>
                <mesh>
                    <scale>0.001 0.001 0.001</scale>
                    <uri>meshes/forearm.dae</uri>
                </mesh>
            </geometry>
        </collision>
        <gravity>1</gravity>
        <velocity_decay/>
        <self_collide>0</self_collide>
    </link>
    <link name = "wrist_link">
        <pose frame=''>0.0 -0.01 0.213 0 0 0</pose>
        <inertial>
            <pose frame=''>0 0 0.029 0 0 0</pose>
            <mass>0</mass>
            <inertia>
                <ixx>3.5e-05</ixx>
                <ixy>0</ixy>
                <ixz>0</ixz>
                <iyy>6.4e-05</iyy>
                <iyz>0</iyz>
                <izz>4.38e-05</izz>
            </inertia>
        </inertial>

        <visual name='visual_wrist_link'>
            <geometry>
                <mesh>
                    <scale>0.001 0.001 0.001</scale>
                    <uri>meshes/wrist.dae</uri>
                </mesh>
            </geometry>
            <material>
                <ambient>0.9825913891190428 0.6200317375386833 0.8387730968333583 1</ambient>
                <diffuse>0.8650847438387654 0.014401378018648825 0.7796222504613648 1</diffuse>
                <specular>0.4049141884151841 0.6746759210111448 0.37513632061440505 1</specular>
                <emissive>0.3 0.2 0.2 1</emissive>
            </material>
        </visual>
        <collision name='collision_wrist_link'>
            <geometry>
                <mesh>
                    <scale>0.001 0.001 0.001</scale>
                    <uri>meshes/wrist.dae</uri>
                </mesh>
            </geometry>
        </collision>
        <gravity>1</gravity>
        <velocity_decay/>
        <self_collide>0</self_collide>
    </link>
     <joint name='WRJ2' type='revolute'>
        <child>wrist_link</child>
        <parent>forearm_link</parent>
        <axis>
            <xyz>0 1 0</xyz>
            <limit>
                <lower>-0.523599</lower>
                <upper>0.174533</upper>
                <effort>10</effort>
                <velocity>2.0</velocity>
            </limit>
            <dynamics>
                <damping>0.09017236530290439</damping>
                <friction>0.0015645137417649225</friction>
                <spring_reference>0.0</spring_reference>
                <spring_stiffness>0.0</spring_stiffness>
            </dynamics>
            <use_parent_model_frame>1</use_parent_model_frame>
        </axis>
        <physics>
            <provide_feedback>1</provide_feedback>
            <ode>
              <provide_feedback>1</provide_feedback>
              <implicit_spring_damper>1</implicit_spring_damper>
              <cfm_damping>1</cfm_damping>
              <limit>
                <cfm>0</cfm>
                <erp>0.2</erp>
              </limit>
            </ode>
        </physics>
    </joint>  


    <link name = "palm_link">
        <pose frame=''>0.0 -0.01 0.247 0 0 0</pose>
        <inertial>
            <pose frame=''>0 0 0.035 0 0 0</pose>
            <mass>0</mass>
            <inertia>
                <ixx>0.0003581</ixx>
                <ixy>0</ixy>
                <ixz>0</ixz>
                <iyy>0.0005287</iyy>
                <iyz>0</iyz>
                <izz>0.000191</izz>
            </inertia>
        </inertial>
	  
        <visual name='visual_palm_link'>
            
            <geometry>
                <mesh>
                    <scale>-0.001 0.001 0.001</scale>
                    <uri>meshes/palm_mirror.dae</uri>
                </mesh>
            </geometry>
            <material>
                <ambient>0.7968639014592575 0.30706277618514666 0.42846583343414135 1</ambient>
                <diffuse>0.8098349306582637 0.408378288085815 0.8329851021629218 1</diffuse>
                <specular>0.7822291512626016 0.04053061817602299 0.5234010027625068 1</specular>
                <emissive>0.874 0.407 0.823 1</emissive>
            </material>
        </visual>
        <collision name='collision_palm_link'>
            
            <geometry>
                <mesh>
                    <scale>-0.001 0.001 0.001</scale>
                    <uri>meshes/palm_mirror.dae</uri>
                </mesh>
            </geometry>
            <material>

            </material>
        </collision>
        <gravity>1</gravity>
        <velocity_decay/>
        <self_collide>0</self_collide>
   
    </link>
    <joint name='WRJ1' type='revolute'>
        <child>palm_link</child>
        <parent>wrist_link</parent>
        <axis>
            <xyz>1 0 0</xyz>
            <limit>
                <lower>-0.698132</lower>
                <upper>0.488692</upper>
                <effort>30</effort>
                <velocity>2.0</velocity>
            </limit>
            <dynamics>
                <damping>0.1458458989540268</damping>
                <friction>0.006001030830686604</friction>
                <spring_reference>0.0</spring_reference>
                <spring_stiffness>0.0</spring_stiffness>
            </dynamics>
            <use_parent_model_frame>1</use_parent_model_frame>
        </axis>
        <physics>
            <provide_feedback>1</provide_feedback>
            <ode>
              <provide_feedback>1</provide_feedback>
              <implicit_spring_damper>1</implicit_spring_damper>
              <cfm_damping>1</cfm_damping>
              <limit>
                <cfm>0</cfm>
                <erp>0.2</erp>
              </limit>
            </ode>
        </physics>
    </joint>   

   
  
    <link name = "knuckle_link_FF">
        
        <pose frame=''>0.033 -0.01 0.342 0 0 0</pose>
        <inertial>
            <pose frame=''>0 0 0 0 0 0</pose>
            <mass>0</mass>
            <inertia>
                <ixx>2.6e-07</ixx>
                <ixy>0</ixy>
                <ixz>0</ixz>
                <iyy>2.6e-07</iyy>
                <iyz>0</iyz>
                <izz>3.2e-07</izz>
            </inertia>
        </inertial>
      
        <visual name='visual_knuckle_link_FF'>
            
            <geometry>
                <mesh>
                    <scale>0.001 0.001 0.001</scale>
                    <uri>meshes/knuckle.dae</uri>
                </mesh>
            </geometry>
            <material>
                <ambient>0.02093995487079825 0.5617855503281475 0.7713848371650899 1</ambient>
                <diffuse>0.5007154333569727 0.7965685120431693 0.507345116433837 1</diffuse>
                <specular>0.9387850635703705 0.453510244474862 0.6473303924516735 1</specular>
                <emissive>0.3 0.2 0.2 1</emissive>
            </material>
        </visual>
        <collision name='collision_knuckle_link_FF'>
            <pose frame=''>0 0 0 0 1.5708 0</pose>
            <geometry>
                <mesh>
                    <scale>0.001 0.001 0.001</scale>
                    <uri>meshes/knuckle.dae</uri>
                </mesh>
            </geometry>
        </collision>
        <gravity>1</gravity>
        <velocity_decay/>
        <self_collide>0</self_collide>
    </link>

    <link name = "proximal_link_FF">
        <pose frame=''>0.033 -0.01 0.342 0 0 0</pose>
        <inertial>
            <pose frame=''>0 0 0.0225 0 0 0</pose>
            <mass>0</mass>
            <inertia>
                <ixx>9.8e-06</ixx>
                <ixy>0</ixy>
                <ixz>0</ixz>
                <iyy>1.0e-05</iyy>
                <iyz>0</iyz>
                <izz>1.8e-06</izz>
            </inertia>
        </inertial>
        
        <visual name='visual_proximal_link_FF'>
            
            <geometry>
                <mesh>
                    <scale>0.001 0.001 0.001</scale>
                    <uri>meshes/F3.dae</uri>
                </mesh>
            </geometry>
            <material>
                <ambient>0.1399907931637685 0.8070341381464704 0.5101094380871826 1</ambient>
                <diffuse>0.35399724956249445 0.9512729120657728 0.348711178178555 1</diffuse>
                <specular>0.4036130226945137 0.0028974600727454947 0.18174310866638876 1</specular>
                <emissive>0.3 0.2 0.2 1</emissive>
            </material>
        </visual>
        <collision name='collision_proximal_link_FF'>
            <pose frame=''>0 0 0.025 0 0 0</pose>
            <geometry>
                <mesh>
                    <scale>0.001 0.001 0.001</scale>
                    <uri>meshes/F3.dae</uri>
                </mesh>
            </geometry>
        </collision>
        <gravity>1</gravity>
        <velocity_decay/>
        <self_collide>0</self_collide>
    </link>
    <link name = "middle_link_FF">
        <pose frame=''>0.033 -0.01 0.387 0 0 1.571</pose>
        <inertial>
            <pose frame=''>0 0 0.0125 0 0 0</pose>
            <mass>0</mass>
            <inertia>
                <ixx>2.6e-06</ixx>
                <ixy>0</ixy>
                <ixz>0</ixz>
                <iyy>2.7e-06</iyy>
                <iyz>0</iyz>
                <izz>8.7e-07</izz>
            </inertia>
        </inertial>
      
        <visual name='visual_middle_link_FF'>
            
            <geometry>
                <mesh>
                    <scale>1 1 1</scale>
                    <uri>meshes/biotac_finger_adapter.dae</uri>
                </mesh>
            </geometry>
            <material>
                <ambient>0.059656608594188865 0.5009591203754322 0.800800228891361 1</ambient>
                <diffuse>0.9647384378824484 0.7956075902426756 0.464467702416993 1</diffuse>
                <specular>0.6116494687443107 0.5343012545322577 0.44852216786771926 1</specular>
                <emissive>0.3 0.2 0.2 1</emissive>
            </material>
        </visual>
        <collision name='collision_middle_link_FF'>
            <pose frame=''>0 0 0.0125 0 0 0</pose>
            <geometry>
                <mesh>
                    <scale>1 1 1</scale>
                    <uri>meshes/biotac_finger_adapter.dae</uri>
                </mesh>
            </geometry>
        </collision>
        <gravity>1</gravity>
        <velocity_decay/>
        <self_collide>0</self_collide>
    </link>
    <link name = "distal_link_FF">
        <pose frame=''>0.033 -0.01 0.394 0 0 0</pose>
        <inertial>
            <pose frame=''>0 0 0.012 0 0 0</pose>
            <mass>0</mass>
            <inertia>
                <ixx>9.4e-07</ixx>
                <ixy>0</ixy>
                <ixz>0</ixz>
                <iyy>1.1e-06</iyy>
                <iyz>0</iyz>
                <izz>5.3e-07</izz>
            </inertia>
        </inertial>
      
        <visual name='visual_distal_link_FF'>
            
            <geometry>
                <mesh>
                    <scale>0.0254 0.0254 0.0254</scale>
                    <uri>meshes/biotac_decimated.dae</uri>
                </mesh>
            </geometry>
            <material>
                <ambient>0.969019857516432 0.14104756865222356 0.38540285257997886 1</ambient>
                <diffuse>0.3435692107106785 0.36404247527414757 0.9752047349607877 1</diffuse>
                <specular>0.05411884719538573 0.7710724675621016 0.23728077312828466 1</specular>
                <emissive>0.3 0.2 0.2 1</emissive>
            </material>
        </visual>
        <collision name='collision_distal_link_FF'>
            <geometry>
                <mesh>
                    <scale>0.0254 0.0254 0.0254</scale>
                    <uri>meshes/biotac_decimated.dae</uri>
                </mesh>
            </geometry>
        </collision>
        <gravity>1</gravity>
        <velocity_decay/>
        <self_collide>0</self_collide>
    </link>
    
    
        <joint name="J3_FF" type="revolute">
            <child>proximal_link_FF</child>
            <parent>knuckle_link_FF</parent>
            
            <axis>
                <xyz>1 0 0</xyz>
                <limit>
                    <lower>0 </lower>
                    <upper>1.5707963267948966 </upper>
                    <effort>2.0 </effort>
                    <velocity>2.0 </velocity>
                </limit>
                <dynamics>
                    <damping>0.16836841608802575</damping>
                    <friction>0.0078711587018407</friction>
                    <spring_reference>0</spring_reference>
                    <spring_stiffness>0</spring_stiffness>
                </dynamics>
                <use_parent_model_frame>1</use_parent_model_frame>
            </axis>
            <physics>
                <provide_feedback>1</provide_feedback>
                <ode>
                  <provide_feedback>1</provide_feedback>
                  <implicit_spring_damper>1</implicit_spring_damper>
                  <cfm_damping>1</cfm_damping>
                  <limit>
                    <cfm>0</cfm>
                    <erp>0.2</erp>
                  </limit>
                </ode>
            </physics>
        </joint>
    
        <joint name="J2_FF" type="revolute">
            <child>middle_link_FF</child>
            <parent>proximal_link_FF</parent>
            
            <axis>
                <xyz>1 0 0</xyz>
                <limit>
                    <lower>0 </lower>
                    <upper>1.5707963267948966 </upper>
                    <effort>2.0 </effort>
                    <velocity>2.0 </velocity>
                </limit>
                <dynamics>
                    <damping>0.19250981229446282</damping>
                    <friction>0.006889674241845356</friction>
                    <spring_reference>0</spring_reference>
                    <spring_stiffness>0</spring_stiffness>
                </dynamics>
                <use_parent_model_frame>1</use_parent_model_frame>
            </axis>
            <physics>
                <provide_feedback>1</provide_feedback>
                <ode>
                  <provide_feedback>1</provide_feedback>
                  <implicit_spring_damper>1</implicit_spring_damper>
                  <cfm_damping>1</cfm_damping>
                  <limit>
                    <cfm>0</cfm>
                    <erp>0.2</erp>
                  </limit>
                </ode>
            </physics>
        </joint>
    
        <joint name="J1_FF" type="revolute">
            <child>distal_link_FF</child>
            <parent>middle_link_FF</parent>
            
            <axis>
                <xyz>1 0 0</xyz>
                <limit>
                    <lower>0 </lower>
                    <upper>1.5707963267948966 </upper>
                    <effort>2.0 </effort>
                    <velocity>2.0 </velocity>
                </limit>
                <dynamics>
                    <damping>0.10342236210674674</damping>
                    <friction>0.00877732524991378</friction>
                    <spring_reference>0</spring_reference>
                    <spring_stiffness>0</spring_stiffness>
                </dynamics>
                <use_parent_model_frame>1</use_parent_model_frame>
            </axis>
            <physics>
                <provide_feedback>1</provide_feedback>
                <ode>
                  <provide_feedback>1</provide_feedback>
                  <implicit_spring_damper>1</implicit_spring_damper>
                  <cfm_damping>1</cfm_damping>
                  <limit>
                    <cfm>0</cfm>
                    <erp>0.2</erp>
                  </limit>
                </ode>
            </physics>
        </joint>
    
    <joint name='J4_FF' type="revolute">
        <child>knuckle_link_FF</child>
        <parent>palm_link</parent>
        
        <axis>
            <xyz>0 -1 0</xyz>
            <limit>
                <lower>-3.141592653589793 </lower>
                <upper>0.0 </upper>
                <effort>2.0 </effort>
                <velocity>2.0 </velocity>
            </limit>
            <dynamics>
                <damping>0.17327440540512876</damping>
                <friction>0.007002642142496726</friction>
                <spring_reference>0</spring_reference>
                <spring_stiffness>0</spring_stiffness>
            </dynamics>
            <use_parent_model_frame>1</use_parent_model_frame>
        </axis>
        <physics>
            <provide_feedback>1</provide_feedback>
            <ode>
            <provide_feedback>1</provide_feedback>
            <implicit_spring_damper>1</implicit_spring_damper>
            <cfm_damping>1</cfm_damping>
            <limit>
                <cfm>0</cfm>
                <erp>0.2</erp>
            </limit>
            </ode>
        </physics>
    </joint>

   
  
    <link name = "knuckle_link_MF">
        
        <pose frame=''>0.011000000000000003 -0.01 0.34600000000000003 0 0 0</pose>
        <inertial>
            <pose frame=''>0 0 0 0 0 0</pose>
            <mass>0</mass>
            <inertia>
                <ixx>2.6e-07</ixx>
                <ixy>0</ixy>
                <ixz>0</ixz>
                <iyy>2.6e-07</iyy>
                <iyz>0</iyz>
                <izz>3.2e-07</izz>
            </inertia>
        </inertial>
      
        <visual name='visual_knuckle_link_MF'>
            
            <geometry>
                <mesh>
                    <scale>0.001 0.001 0.001</scale>
                    <uri>meshes/knuckle.dae</uri>
                </mesh>
            </geometry>
            <material>
                <ambient>0.7877497037632143 0.853314757140891 0.5400153559510259 1</ambient>
                <diffuse>0.8005360810734651 0.657555455072768 0.8509805891523408 1</diffuse>
                <specular>0.7287604712486588 0.35102983712221214 0.27842505653778826 1</specular>
                <emissive>0.3 0.2 0.2 1</emissive>
            </material>
        </visual>
        <collision name='collision_knuckle_link_MF'>
            <pose frame=''>0 0 0 0 1.5708 0</pose>
            <geometry>
                <mesh>
                    <scale>0.001 0.001 0.001</scale>
                    <uri>meshes/knuckle.dae</uri>
                </mesh>
            </geometry>
        </collision>
        <gravity>1</gravity>
        <velocity_decay/>
        <self_collide>0</self_collide>
    </link>

    <link name = "proximal_link_MF">
        <pose frame=''>0.011000000000000003 -0.01 0.34600000000000003 0 0 0</pose>
        <inertial>
            <pose frame=''>0 0 0.0225 0 0 0</pose>
            <mass>0</mass>
            <inertia>
                <ixx>9.8e-06</ixx>
                <ixy>0</ixy>
                <ixz>0</ixz>
                <iyy>1.0e-05</iyy>
                <iyz>0</iyz>
                <izz>1.8e-06</izz>
            </inertia>
        </inertial>
        
        <visual name='visual_proximal_link_MF'>
            
            <geometry>
                <mesh>
                    <scale>0.001 0.001 0.001</scale>
                    <uri>meshes/F3.dae</uri>
                </mesh>
            </geometry>
            <material>
                <ambient>0.37003401939557645 0.7063859252716829 0.9842502798476175 1</ambient>
                <diffuse>0.39791918886418864 0.4232116130185256 0.1942898581021557 1</diffuse>
                <specular>0.9299185890082953 0.16986257885131528 0.18818546147656212 1</specular>
                <emissive>0.3 0.2 0.2 1</emissive>
            </material>
        </visual>
        <collision name='collision_proximal_link_MF'>
            <pose frame=''>0 0 0.025 0 0 0</pose>
            <geometry>
                <mesh>
                    <scale>0.001 0.001 0.001</scale>
                    <uri>meshes/F3.dae</uri>
                </mesh>
            </geometry>
        </collision>
        <gravity>1</gravity>
        <velocity_decay/>
        <self_collide>0</self_collide>
    </link>
    <link name = "middle_link_MF">
        <pose frame=''>0.011000000000000003 -0.01 0.391 0 0 1.571</pose>
        <inertial>
            <pose frame=''>0 0 0.0125 0 0 0</pose>
            <mass>0</mass>
            <inertia>
                <ixx>2.6e-06</ixx>
                <ixy>0</ixy>
                <ixz>0</ixz>
                <iyy>2.7e-06</iyy>
                <iyz>0</iyz>
                <izz>8.7e-07</izz>
            </inertia>
        </inertial>
      
        <visual name='visual_middle_link_MF'>
            
            <geometry>
                <mesh>
                    <scale>1 1 1</scale>
                    <uri>meshes/biotac_finger_adapter.dae</uri>
                </mesh>
            </geometry>
            <material>
                <ambient>0.9781222485251395 0.7878670508016526 0.22941249173315104 1</ambient>
                <diffuse>0.3014127549489415 0.4917234884321001 0.5283135234706271 1</diffuse>
                <specular>0.1765857900679646 0.44750173250216874 0.5728606239449406 1</specular>
                <emissive>0.3 0.2 0.2 1</emissive>
            </material>
        </visual>
        <collision name='collision_middle_link_MF'>
            <pose frame=''>0 0 0.0125 0 0 0</pose>
            <geometry>
                <mesh>
                    <scale>1 1 1</scale>
                    <uri>meshes/biotac_finger_adapter.dae</uri>
                </mesh>
            </geometry>
        </collision>
        <gravity>1</gravity>
        <velocity_decay/>
        <self_collide>0</self_collide>
    </link>
    <link name = "distal_link_MF">
        <pose frame=''>0.011000000000000003 -0.01 0.398 0 0 0</pose>
        <inertial>
            <pose frame=''>0 0 0.012 0 0 0</pose>
            <mass>0</mass>
            <inertia>
                <ixx>9.4e-07</ixx>
                <ixy>0</ixy>
                <ixz>0</ixz>
                <iyy>1.1e-06</iyy>
                <iyz>0</iyz>
                <izz>5.3e-07</izz>
            </inertia>
        </inertial>
      
        <visual name='visual_distal_link_MF'>
            
            <geometry>
                <mesh>
                    <scale>0.0254 0.0254 0.0254</scale>
                    <uri>meshes/biotac_decimated.dae</uri>
                </mesh>
            </geometry>
            <material>
                <ambient>0.9585936059775723 0.4759151020710223 0.7291614234556595 1</ambient>
                <diffuse>0.5963887195320303 0.456147976476609 0.42277904116527554 1</diffuse>
                <specular>0.04436105468695162 0.13130140588497508 0.7236833437653215 1</specular>
                <emissive>0.3 0.2 0.2 1</emissive>
            </material>
        </visual>
        <collision name='collision_distal_link_MF'>
            <geometry>
                <mesh>
                    <scale>0.0254 0.0254 0.0254</scale>
                    <uri>meshes/biotac_decimated.dae</uri>
                </mesh>
            </geometry>
        </collision>
        <gravity>1</gravity>
        <velocity_decay/>
        <self_collide>0</self_collide>
    </link>
    
    
        <joint name="J3_MF" type="revolute">
            <child>proximal_link_MF</child>
            <parent>knuckle_link_MF</parent>
            
            <axis>
                <xyz>1 0 0</xyz>
                <limit>
                    <lower>0 </lower>
                    <upper>1.5707963267948966 </upper>
                    <effort>2.0 </effort>
                    <velocity>2.0 </velocity>
                </limit>
                <dynamics>
                    <damping>0.16836841608802575</damping>
                    <friction>0.0078711587018407</friction>
                    <spring_reference>0</spring_reference>
                    <spring_stiffness>0</spring_stiffness>
                </dynamics>
                <use_parent_model_frame>1</use_parent_model_frame>
            </axis>
            <physics>
                <provide_feedback>1</provide_feedback>
                <ode>
                  <provide_feedback>1</provide_feedback>
                  <implicit_spring_damper>1</implicit_spring_damper>
                  <cfm_damping>1</cfm_damping>
                  <limit>
                    <cfm>0</cfm>
                    <erp>0.2</erp>
                  </limit>
                </ode>
            </physics>
        </joint>
    
        <joint name="J2_MF" type="revolute">
            <child>middle_link_MF</child>
            <parent>proximal_link_MF</parent>
            
            <axis>
                <xyz>1 0 0</xyz>
                <limit>
                    <lower>0 </lower>
                    <upper>1.5707963267948966 </upper>
                    <effort>2.0 </effort>
                    <velocity>2.0 </velocity>
                </limit>
                <dynamics>
                    <damping>0.19250981229446282</damping>
                    <friction>0.006889674241845356</friction>
                    <spring_reference>0</spring_reference>
                    <spring_stiffness>0</spring_stiffness>
                </dynamics>
                <use_parent_model_frame>1</use_parent_model_frame>
            </axis>
            <physics>
                <provide_feedback>1</provide_feedback>
                <ode>
                  <provide_feedback>1</provide_feedback>
                  <implicit_spring_damper>1</implicit_spring_damper>
                  <cfm_damping>1</cfm_damping>
                  <limit>
                    <cfm>0</cfm>
                    <erp>0.2</erp>
                  </limit>
                </ode>
            </physics>
        </joint>
    
        <joint name="J1_MF" type="revolute">
            <child>distal_link_MF</child>
            <parent>middle_link_MF</parent>
            
            <axis>
                <xyz>1 0 0</xyz>
                <limit>
                    <lower>0 </lower>
                    <upper>1.5707963267948966 </upper>
                    <effort>2.0 </effort>
                    <velocity>2.0 </velocity>
                </limit>
                <dynamics>
                    <damping>0.10342236210674674</damping>
                    <friction>0.00877732524991378</friction>
                    <spring_reference>0</spring_reference>
                    <spring_stiffness>0</spring_stiffness>
                </dynamics>
                <use_parent_model_frame>1</use_parent_model_frame>
            </axis>
            <physics>
                <provide_feedback>1</provide_feedback>
                <ode>
                  <provide_feedback>1</provide_feedback>
                  <implicit_spring_damper>1</implicit_spring_damper>
                  <cfm_damping>1</cfm_damping>
                  <limit>
                    <cfm>0</cfm>
                    <erp>0.2</erp>
                  </limit>
                </ode>
            </physics>
        </joint>
    
    <joint name='J4_MF' type="revolute">
        <child>knuckle_link_MF</child>
        <parent>palm_link</parent>
        
        <axis>
            <xyz>0 -1 0</xyz>
            <limit>
                <lower>-3.141592653589793 </lower>
                <upper>0.0 </upper>
                <effort>2.0 </effort>
                <velocity>2.0 </velocity>
            </limit>
            <dynamics>
                <damping>0.17327440540512876</damping>
                <friction>0.007002642142496726</friction>
                <spring_reference>0</spring_reference>
                <spring_stiffness>0</spring_stiffness>
            </dynamics>
            <use_parent_model_frame>1</use_parent_model_frame>
        </axis>
        <physics>
            <provide_feedback>1</provide_feedback>
            <ode>
            <provide_feedback>1</provide_feedback>
            <implicit_spring_damper>1</implicit_spring_damper>
            <cfm_damping>1</cfm_damping>
            <limit>
                <cfm>0</cfm>
                <erp>0.2</erp>
            </limit>
            </ode>
        </physics>
    </joint>

   
  
    <link name = "knuckle_link_RF">
        
        <pose frame=''>-0.010999999999999996 -0.01 0.342 0 0 0</pose>
        <inertial>
            <pose frame=''>0 0 0 0 0 0</pose>
            <mass>0</mass>
            <inertia>
                <ixx>2.6e-07</ixx>
                <ixy>0</ixy>
                <ixz>0</ixz>
                <iyy>2.6e-07</iyy>
                <iyz>0</iyz>
                <izz>3.2e-07</izz>
            </inertia>
        </inertial>
      
        <visual name='visual_knuckle_link_RF'>
            
            <geometry>
                <mesh>
                    <scale>0.001 0.001 0.001</scale>
                    <uri>meshes/knuckle.dae</uri>
                </mesh>
            </geometry>
            <material>
                <ambient>0.5723831297728014 0.5601860783376558 0.15684408159666674 1</ambient>
                <diffuse>0.9590580517273053 0.39063082581858755 0.24348074447780577 1</diffuse>
                <specular>0.5586523797560672 0.3851354401295638 0.5770745470614318 1</specular>
                <emissive>0.3 0.2 0.2 1</emissive>
            </material>
        </visual>
        <collision name='collision_knuckle_link_RF'>
            <pose frame=''>0 0 0 0 1.5708 0</pose>
            <geometry>
                <mesh>
                    <scale>0.001 0.001 0.001</scale>
                    <uri>meshes/knuckle.dae</uri>
                </mesh>
            </geometry>
        </collision>
        <gravity>1</gravity>
        <velocity_decay/>
        <self_collide>0</self_collide>
    </link>

    <link name = "proximal_link_RF">
        <pose frame=''>-0.010999999999999996 -0.01 0.342 0 0 0</pose>
        <inertial>
            <pose frame=''>0 0 0.0225 0 0 0</pose>
            <mass>0</mass>
            <inertia>
                <ixx>9.8e-06</ixx>
                <ixy>0</ixy>
                <ixz>0</ixz>
                <iyy>1.0e-05</iyy>
                <iyz>0</iyz>
                <izz>1.8e-06</izz>
            </inertia>
        </inertial>
        
        <visual name='visual_proximal_link_RF'>
            
            <geometry>
                <mesh>
                    <scale>0.001 0.001 0.001</scale>
                    <uri>meshes/F3.dae</uri>
                </mesh>
            </geometry>
            <material>
                <ambient>0.378753064139587 0.746982776839557 0.15595840997612598 1</ambient>
                <diffuse>0.37850275741955286 0.48161865605441734 0.4781749228201728 1</diffuse>
                <specular>0.6835031906111734 0.06564700588322614 0.2962398068606672 1</specular>
                <emissive>0.3 0.2 0.2 1</emissive>
            </material>
        </visual>
        <collision name='collision_proximal_link_RF'>
            <pose frame=''>0 0 0.025 0 0 0</pose>
            <geometry>
                <mesh>
                    <scale>0.001 0.001 0.001</scale>
                    <uri>meshes/F3.dae</uri>
                </mesh>
            </geometry>
        </collision>
        <gravity>1</gravity>
        <velocity_decay/>
        <self_collide>0</self_collide>
    </link>
    <link name = "middle_link_RF">
        <pose frame=''>-0.010999999999999996 -0.01 0.387 0 0 0</pose>
        <inertial>
            <pose frame=''>0 0 0.0125 0 0 0</pose>
            <mass>0</mass>
            <inertia>
                <ixx>2.6e-06</ixx>
                <ixy>0</ixy>
                <ixz>0</ixz>
                <iyy>2.7e-06</iyy>
                <iyz>0</iyz>
                <izz>8.7e-07</izz>
            </inertia>
        </inertial>
      
        <visual name='visual_middle_link_RF'>
            
            <geometry>
                <mesh>
                    <scale>0.001 0.001 0.001</scale>
                    <uri>meshes/F2.dae</uri>
                </mesh>
            </geometry>
            <material>
                <ambient>0.3360971593829244 0.23675869770007718 0.1398682324454129 1</ambient>
                <diffuse>0.4632618867815247 0.42582759282692995 0.21718846687015447 1</diffuse>
                <specular>0.6007539513203892 0.5796152173378873 0.37326994199854335 1</specular>
                <emissive>0.3 0.2 0.2 1</emissive>
            </material>
        </visual>
        <collision name='collision_middle_link_RF'>
            <pose frame=''>0 0 0.0125 0 0 0</pose>
            <geometry>
                <mesh>
                    <scale>0.001 0.001 0.001</scale>
                    <uri>meshes/F2.dae</uri>
                </mesh>
            </geometry>
        </collision>
        <gravity>1</gravity>
        <velocity_decay/>
        <self_collide>0</self_collide>
    </link>
    <link name = "distal_link_RF">
        <pose frame=''>-0.010999999999999996 -0.01 0.41200000000000003 0 0 0</pose>
        <inertial>
            <pose frame=''>0 0 0.012 0 0 0</pose>
            <mass>0</mass>
            <inertia>
                <ixx>9.4e-07</ixx>
                <ixy>0</ixy>
                <ixz>0</ixz>
                <iyy>1.1e-06</iyy>
                <iyz>0</iyz>
                <izz>5.3e-07</izz>
            </inertia>
        </inertial>
      
        <visual name='visual_distal_link_RF'>
            
            <geometry>
                <mesh>
                    <scale>0.001 0.001 0.001</scale>
                    <uri>meshes/distal_ellipsoid_visual.dae</uri>
                </mesh>
            </geometry>
            <material>
                <ambient>0.20506367720468843 0.10563422445936843 0.46687796087288014 1</ambient>
                <diffuse>0.028550653055719466 0.29223703601690576 0.7550939666796713 1</diffuse>
                <specular>0.999768736678393 0.058555602540455 0.6331854410269984 1</specular>
                <emissive>0.3 0.2 0.2 1</emissive>
            </material>
        </visual>
        <collision name='collision_distal_link_RF'>
            <geometry>
                <mesh>
                    <scale>0.001 0.001 0.001</scale>
                    <uri>meshes/distal_ellipsoid_visual.dae</uri>
                </mesh>
            </geometry>
        </collision>
        <gravity>1</gravity>
        <velocity_decay/>
        <self_collide>0</self_collide>
    </link>
    
    
        <joint name="J3_RF" type="revolute">
            <child>proximal_link_RF</child>
            <parent>knuckle_link_RF</parent>
            
            <axis>
                <xyz>1 0 0</xyz>
                <limit>
                    <lower>0 </lower>
                    <upper>1.5707963267948966 </upper>
                    <effort>2.0 </effort>
                    <velocity>2.0 </velocity>
                </limit>
                <dynamics>
                    <damping>0.16836841608802575</damping>
                    <friction>0.0078711587018407</friction>
                    <spring_reference>0</spring_reference>
                    <spring_stiffness>0</spring_stiffness>
                </dynamics>
                <use_parent_model_frame>1</use_parent_model_frame>
            </axis>
            <physics>
                <provide_feedback>1</provide_feedback>
                <ode>
                  <provide_feedback>1</provide_feedback>
                  <implicit_spring_damper>1</implicit_spring_damper>
                  <cfm_damping>1</cfm_damping>
                  <limit>
                    <cfm>0</cfm>
                    <erp>0.2</erp>
                  </limit>
                </ode>
            </physics>
        </joint>
    
        <joint name="J2_RF" type="revolute">
            <child>middle_link_RF</child>
            <parent>proximal_link_RF</parent>
            
            <axis>
                <xyz>1 0 0</xyz>
                <limit>
                    <lower>0 </lower>
                    <upper>1.5707963267948966 </upper>
                    <effort>2.0 </effort>
                    <velocity>2.0 </velocity>
                </limit>
                <dynamics>
                    <damping>0.19250981229446282</damping>
                    <friction>0.006889674241845356</friction>
                    <spring_reference>0</spring_reference>
                    <spring_stiffness>0</spring_stiffness>
                </dynamics>
                <use_parent_model_frame>1</use_parent_model_frame>
            </axis>
            <physics>
                <provide_feedback>1</provide_feedback>
                <ode>
                  <provide_feedback>1</provide_feedback>
                  <implicit_spring_damper>1</implicit_spring_damper>
                  <cfm_damping>1</cfm_damping>
                  <limit>
                    <cfm>0</cfm>
                    <erp>0.2</erp>
                  </limit>
                </ode>
            </physics>
        </joint>
    
        <joint name="J1_RF" type="revolute">
            <child>distal_link_RF</child>
            <parent>middle_link_RF</parent>
            
            <axis>
                <xyz>1 0 0</xyz>
                <limit>
                    <lower>0 </lower>
                    <upper>1.5707963267948966 </upper>
                    <effort>2.0 </effort>
                    <velocity>2.0 </velocity>
                </limit>
                <dynamics>
                    <damping>0.10342236210674674</damping>
                    <friction>0.00877732524991378</friction>
                    <spring_reference>0</spring_reference>
                    <spring_stiffness>0</spring_stiffness>
                </dynamics>
                <use_parent_model_frame>1</use_parent_model_frame>
            </axis>
            <physics>
                <provide_feedback>1</provide_feedback>
                <ode>
                  <provide_feedback>1</provide_feedback>
                  <implicit_spring_damper>1</implicit_spring_damper>
                  <cfm_damping>1</cfm_damping>
                  <limit>
                    <cfm>0</cfm>
                    <erp>0.2</erp>
                  </limit>
                </ode>
            </physics>
        </joint>
    
    <joint name='J4_RF' type="revolute">
        <child>knuckle_link_RF</child>
        <parent>palm_link</parent>
        
        <axis>
            <xyz>0 -1 0</xyz>
            <limit>
                <lower>-3.141592653589793 </lower>
                <upper>0.0 </upper>
                <effort>2.0 </effort>
                <velocity>2.0 </velocity>
            </limit>
            <dynamics>
                <damping>0.17327440540512876</damping>
                <friction>0.007002642142496726</friction>
                <spring_reference>0</spring_reference>
                <spring_stiffness>0</spring_stiffness>
            </dynamics>
            <use_parent_model_frame>1</use_parent_model_frame>
        </axis>
        <physics>
            <provide_feedback>1</provide_feedback>
            <ode>
            <provide_feedback>1</provide_feedback>
            <implicit_spring_damper>1</implicit_spring_damper>
            <cfm_damping>1</cfm_damping>
            <limit>
                <cfm>0</cfm>
                <erp>0.2</erp>
            </limit>
            </ode>
        </physics>
    </joint>

   






    
    <link name = "metacarpal_link_lf">
        <pose frame=''>-0.031 -0.01 0.26771 0 0 0</pose>
        <inertial>
            <pose frame=''>0 0 0.04 0 0 0</pose>
            <mass>0</mass>
            <inertia>
                <ixx>1.45e-05</ixx>
                <ixy>0</ixy>
                <ixz>0</ixz>
                <iyy>1.638e-05</iyy>
                <iyz>0</iyz>
                <izz>4.272e-06</izz>
            </inertia>
        </inertial>
        <visual name='visual_metacarpal_link_lf'>
            
            <geometry>
                <mesh>
                    <scale>0.001 0.001 0.001</scale>
                    <uri>meshes/lfmetacarpal.dae</uri>
                </mesh>
            </geometry>
            <material>
                <ambient>0.8015224452611968 0.5256247197667807 0.5016093544328061 1</ambient>
                <diffuse>0.718832968123502 0.47028489407632856 0.9807414297193274 1</diffuse>
                <specular>0.42197719616724294 0.5690542232098363 0.6903310709644185 1</specular>
                <emissive>0.945 0.788 0.396 1</emissive>
            </material>
        </visual>
        <collision name='collision_metacarpal_link_lf'>
            <pose frame=''>0 0 0 0 0 0</pose>
            <geometry>
                <mesh>
                    <scale>0.001 0.001 0.001</scale>
                    <uri>meshes/lfmetacarpal.dae</uri>
                </mesh>
            </geometry>
        </collision>
        <gravity>1</gravity>
        <velocity_decay/>
        <self_collide>0</self_collide>
    </link>
   
    <link name = "knuckle_link_lf">
        
        <pose frame=''>-0.031 -0.01 0.3335 0 0 0</pose>
        <inertial>
            <pose frame=''>0 0 0 0 0 0</pose>
            <mass>0</mass>
            <inertia>
                <ixx>2.6e-07</ixx>
                <ixy>0</ixy>
                <ixz>0</ixz>
                <iyy>2.6e-07</iyy>
                <iyz>0</iyz>
                <izz>3.2e-07</izz>
            </inertia>
        </inertial>
      
        <visual name='visual_knuckle_link_lf'>
            
            <geometry>
                <mesh>
                    <scale>0.001 0.001 0.001</scale>
                    <uri>meshes/knuckle.dae</uri>
                </mesh>
            </geometry>
            <material>
                <ambient>0.7972837783572694 0.5404419337926991 0.5647085346647092 1</ambient>
                <diffuse>0.29448361145680013 0.9187092735079172 0.40229316280601657 1</diffuse>
                <specular>0.1581682635127465 0.8747217095685696 0.7831678672975002 1</specular>
                <emissive>0.945 0.788 0.396 1</emissive>
            </material>
        </visual>
        <collision name='collision_knuckle_link_lf'>
            <pose frame=''>0 0 0 0 1.5708 0</pose>
            <geometry>
                <mesh>
                    <scale>0.001 0.001 0.001</scale>
                    <uri>meshes/knuckle.dae</uri>
                </mesh>
            </geometry>
        </collision>
    </link>
  
    <link name = "proximal_link_lf">
        <pose frame=''>-0.031 -0.01 0.3335 0 0 0</pose>
        <inertial>
            <pose frame=''>0 0 0.0225 0 0 0</pose>
            <mass>0</mass>
            <inertia>
                <ixx>9.8e-06</ixx>
                <ixy>0</ixy>
                <ixz>0</ixz>
                <iyy>1.0e-05</iyy>
                <iyz>0</iyz>
                <izz>1.8e-06</izz>
            </inertia>
        </inertial>
        
        <visual name='visual_proximal_link_lf'>
            
            <geometry>
                <mesh>
                    <scale>0.001 0.001 0.001</scale>
                    <uri>meshes/F3.dae</uri>
                </mesh>
            </geometry>
            <material>
                <ambient>0.6051672807902175 0.43276485131861664 0.9044383955388844 1</ambient>
                <diffuse>0.5343329474460002 0.7963173438891926 0.842691317643577 1</diffuse>
                <specular>0.14879462653393993 0.6587604520579411 0.19886884454876275 1</specular>
                <emissive>0.945 0.788 0.396 1</emissive>
            </material>
        </visual>
        <collision name='collision_proximal_link_lf'>
            <pose frame=''>0 0 0.025 0 0 0</pose>
            <geometry>
                <mesh>
                    <scale>0.001 0.001 0.001</scale>
                    <uri>meshes/F3.dae</uri>
                </mesh>
            </geometry>
        </collision>
    </link>
    <link name = "middle_link_lf">
        <pose frame=''>-0.031 -0.01 0.3785 0 0 0</pose>
        <inertial>
            <pose frame=''>0 0 0.0125 0 0 0</pose>
            <mass>0</mass>
            <inertia>
                <ixx>2.6e-06</ixx>
                <ixy>0</ixy>
                <ixz>0</ixz>
                <iyy>2.7e-06</iyy>
                <iyz>0</iyz>
                <izz>8.7e-07</izz>
            </inertia>
        </inertial>
      
        <visual name='visual_middle_link_lf'>
            
            <geometry>
                <mesh>
                    <scale>0.001 0.001 0.001</scale>
                    <uri>meshes/F2.dae</uri>
                </mesh>
            </geometry>
            <material>
                <ambient>0.8301384954873756 0.3136515231406001 0.47455572865297524 1</ambient>
                <diffuse>0.8871452409175898 0.12868457503142483 0.9089451586053081 1</diffuse>
                <specular>0.5630010092101845 0.5363966293821469 0.564753321553671 1</specular>
                <emissive>0.945 0.788 0.396 1</emissive>
            </material>
        </visual>
        <collision name='collision_middle_link_lf'>
            <pose frame=''>0 0 0.0125 0 0 0</pose>
            <geometry>
                <mesh>
                    <scale>0.001 0.001 0.001</scale>
                    <uri>meshes/F2.dae</uri>
                </mesh>
            </geometry>
        </collision>
    </link>
    <link name = "distal_link_lf">
        <pose frame=''>-0.031 -0.01 0.4035 0 0 0</pose>
        <inertial>
            <pose frame=''>0 0 0.012 0 0 0</pose>
            <mass>0</mass>
            <inertia>
                <ixx>9.4e-07</ixx>
                <ixy>0</ixy>
                <ixz>0</ixz>
                <iyy>1.1e-06</iyy>
                <iyz>0</iyz>
                <izz>5.3e-07</izz>
            </inertia>
        </inertial>
      
        <visual name='visual_distal_link_lf'>
            
            <geometry>
                <mesh>
                    <scale>0.001 0.001 0.001</scale>
                    <uri>meshes/distal_ellipsoid_visual.dae</uri>
                </mesh>
            </geometry>
            <material>
                <ambient>0.5851543755222437 0.2906614040711536 0.44904156641590287 1</ambient>
                <diffuse>0.4305586387282002 0.7964136937148454 0.20980097628528638 1</diffuse>
                <specular>0.30002416921963637 0.7531045029583434 0.610443336269576 1</specular>
                <emissive>0.945 0.788 0.396 1</emissive>
            </material>
        </visual>
        <collision name='collision_distal_link_lf'>
            <geometry>
                <mesh>
                    <scale>0.001 0.001 0.001</scale>
                    <uri>meshes/distal_ellipsoid_visual.dae</uri>
                </mesh>
            </geometry>
        </collision>
    </link>

    
    <joint name='J3' type="revolute">
        <child>proximal_link_lf</child>
        <parent>knuckle_link_lf</parent>
        
        <axis>
            <xyz>1 0 0</xyz>
            <limit>
                <lower>0 </lower>
                <upper>1.5707963267948966 </upper>
                <effort>2.0 </effort>
                <velocity>2.0 </velocity>
            </limit>
            <dynamics>
                <damping>0.15254551920531254</damping>
                <friction>0.008413597077040716</friction>
                <spring_reference>0</spring_reference>
                <spring_stiffness>0</spring_stiffness>
            </dynamics>
            <use_parent_model_frame>1</use_parent_model_frame>
        </axis>
        <physics>
            <provide_feedback>1</provide_feedback>
            <ode>
            <provide_feedback>1</provide_feedback>
            <implicit_spring_damper>1</implicit_spring_damper>
            <cfm_damping>1</cfm_damping>
            <limit>
                <cfm>0</cfm>
                <erp>0.2</erp>
            </limit>
            </ode>
        </physics>
    </joint>
    
    <joint name='J2' type="revolute">
        <child>middle_link_lf</child>
        <parent>proximal_link_lf</parent>
        
        <axis>
            <xyz>1 0 0</xyz>
            <limit>
                <lower>0 </lower>
                <upper>1.5707963267948966 </upper>
                <effort>2.0 </effort>
                <velocity>2.0 </velocity>
            </limit>
            <dynamics>
                <damping>0.11732991266105915</damping>
                <friction>0.007628588581720865</friction>
                <spring_reference>0</spring_reference>
                <spring_stiffness>0</spring_stiffness>
            </dynamics>
            <use_parent_model_frame>1</use_parent_model_frame>
        </axis>
        <physics>
            <provide_feedback>1</provide_feedback>
            <ode>
            <provide_feedback>1</provide_feedback>
            <implicit_spring_damper>1</implicit_spring_damper>
            <cfm_damping>1</cfm_damping>
            <limit>
                <cfm>0</cfm>
                <erp>0.2</erp>
            </limit>
            </ode>
        </physics>
    </joint>
    
    <joint name='J1' type="revolute">
        <child>distal_link_lf</child>
        <parent>middle_link_lf</parent>
        
        <axis>
            <xyz>1 0 0</xyz>
            <limit>
                <lower>0 </lower>
                <upper>1.5707963267948966 </upper>
                <effort>2.0 </effort>
                <velocity>2.0 </velocity>
            </limit>
            <dynamics>
                <damping>0.15793888855054716</damping>
                <friction>0.0030899078069551535</friction>
                <spring_reference>0</spring_reference>
                <spring_stiffness>0</spring_stiffness>
            </dynamics>
            <use_parent_model_frame>1</use_parent_model_frame>
        </axis>
        <physics>
            <provide_feedback>1</provide_feedback>
            <ode>
            <provide_feedback>1</provide_feedback>
            <implicit_spring_damper>1</implicit_spring_damper>
            <cfm_damping>1</cfm_damping>
            <limit>
                <cfm>0</cfm>
                <erp>0.2</erp>
            </limit>
            </ode>
        </physics>
    </joint>
    
  
    <joint name='J4_lf' type="revolute">
        <child>knuckle_link_lf</child>
        <parent>metacarpal_link_lf</parent>
        
        <axis>
            <xyz>0 -1 0</xyz>
            <limit>
                <lower>-3.141592653589793 </lower>
                <upper>0.0 </upper>
                <effort>2.0 </effort>
                <velocity>2.0 </velocity>
            </limit>
            <dynamics>
                <damping>0.09826054254618258</damping>
                <friction>0.008475798858284967</friction>
                <spring_reference>0</spring_reference>
                <spring_stiffness>0</spring_stiffness>
            </dynamics>
            <use_parent_model_frame>1</use_parent_model_frame>
        </axis>
        <physics>
            <provide_feedback>1</provide_feedback>
            <ode>
            <provide_feedback>1</provide_feedback>
            <implicit_spring_damper>1</implicit_spring_damper>
            <cfm_damping>1</cfm_damping>
            <limit>
                <cfm>0</cfm>
                <erp>0.2</erp>
            </limit>
            </ode>
        </physics>
    </joint>
      
    <joint name='LFJ5_lf' type="revolute">
        <child>metacarpal_link_lf</child>
        <parent>palm_link</parent>
        
        <axis>
            <xyz>0 -1 0</xyz>
            <limit>
                <lower>-3.141592653589793 </lower>
                <upper>0.0 </upper>
                <effort>2.0 </effort>
                <velocity>2.0 </velocity>
            </limit>
            <dynamics>
                <damping>0.13126056323591137</damping>
                <friction>0.004569487780580281</friction>
                <spring_reference>0</spring_reference>
                <spring_stiffness>0</spring_stiffness>
            </dynamics>
            <use_parent_model_frame>1</use_parent_model_frame>
        </axis>
        <physics>
            <provide_feedback>1</provide_feedback>
            <ode>
            <provide_feedback>1</provide_feedback>
            <implicit_spring_damper>1</implicit_spring_damper>
            <cfm_damping>1</cfm_damping>
            <limit>
                <cfm>0</cfm>
                <erp>0.2</erp>
            </limit>
            </ode>
        </physics>
    </joint>
  

    <link name = "thbase_link">
        <pose frame=''>0.034 -0.0185 0.276 0.0 0.785398 0</pose>
        <inertial>
            <pose frame=''>0 0 0 0 0 0</pose>
            <mass>6</mass>
            <inertia>
                <ixx>1.6e-07</ixx>
                <ixy>0</ixy>
                <ixz>0</ixz>
                <iyy>1.6e-07</iyy>
                <iyz>0</iyz>
                <izz>1.6e-07</izz>
            </inertia>
        </inertial>
        <visual name='visual_thbase_link'>
            
            <geometry>
                <box>
                    <size>0.001 0.001 0.001</size>
                </box>
            </geometry>
            <material>
                <ambient>0.728227192699274 0.26945765476938877 0.34173733582462895 1</ambient>
                <diffuse>0.47330010355462904 0.957921635353911 0.2647573891025756 1</diffuse>
                <specular>0.05963608219881855 0.26150824751755053 0.8720081104101699 1</specular>
                <emissive>0.3 0.2 0.2 1</emissive>
            </material>
        </visual>
        <collision name='collision_thbase_link'>
            <pose frame=''>0 0 0 0 0 0</pose>
            <geometry>
               
                    <sphere>
                        <radius>0.011</radius>
                    </sphere>
            
            </geometry>
        </collision>
        <gravity>1</gravity>
        <velocity_decay/>
        <self_collide>0</self_collide>
    </link>
    <link name = "thproximal_link">
            
        <pose frame=''>0.034 -0.0185 0.276 0.0 0.785398 0.0</pose>
        <inertial>
            <pose frame=''>0 0 0.019 0 0 0</pose>
            <mass>0</mass>
            <inertia>
                <ixx>1.36e-05</ixx>
                <ixy>0</ixy>
                <ixz>0</ixz>
                <iyy>1.36e-05</iyy>
                <iyz>0</iyz>
                <izz>3.13e-06</izz>
            </inertia>
        </inertial>
    
        <visual name='visual_thproximal_link'>
            
            <geometry>
                <mesh>
                    <scale>0.001 0.001 0.001</scale>
                    <uri>meshes/TH3_z.dae</uri>
                </mesh>
            </geometry>
            <material>
                <ambient>0.973615653056957 0.29753482399448994 0.9641832563323531 1</ambient>
                <diffuse>0.44011858478856813 0.8725750797405716 0.7492983091229823 1</diffuse>
                <specular>0.48496981664089556 0.2403575847132413 0.1606748591501661 1</specular>
                <emissive>0.3 0.2 0.2 1</emissive>
            </material>
        </visual>
        <collision name='collision_thproximal_link'>
            <pose frame=''>0 0 0.020 0 0 0</pose>
            <geometry>
                <mesh>
                    <scale>0.001 0.001 0.001</scale>
                    <uri>meshes/TH3_z.dae</uri>
                </mesh>
            </geometry>
        </collision>
    </link>
    <link name = "thhub_link">
            
        <pose frame=''>0.06087000000000001 -0.0185 0.30287000000000003 0.0 0.785398 0.0</pose>
        <inertial>
            <pose frame=''>0 0 0 0 0 0</pose>
            <mass>7</mass>
            <inertia>
                <ixx>1.0e-06</ixx>
                <ixy>0</ixy>
                <ixz>0</ixz>
                <iyy>1.0e-06</iyy>
                <iyz>0</iyz>
                <izz>3.0e-07</izz>
            </inertia>
        </inertial>
    
        <visual name='visual_thhub_link'>
            
            <geometry>
                
                     <box>
                        <size>0.001 0.001 0.001</size>
                    </box>
                
            </geometry>
            <material>

            </material>
        </visual>
        <collision name='collision_thhub_link'>
            <pose frame=''>0 0 0.020 0 0 0</pose>
            <geometry>
              
                    <box>
                        <size>0.001 0.001 0.001</size>
                    </box>
             
            </geometry>
        </collision>
    </link>
    <link name = "thmiddle_link">
            
        <pose frame=''>0.06087000000000001 -0.0185 0.30287000000000003 0.0 0.785398 0.0</pose>
        <inertial>
            <pose frame=''>0 0 14 0 0 0</pose>
            <mass>0</mass>
            <inertia>
                <ixx>5.1e-06</ixx>
                <ixy>0</ixy>
                <ixz>0</ixz>
                <iyy>5.1e-06</iyy>
                <iyz>0</iyz>
                <izz>1.21e-06</izz>
            </inertia>
        </inertial>

        <visual name='visual_thmiddle_link'>
            
            <geometry>
                <mesh>
                    <scale>0.001 0.001 0.001</scale>
                    <uri>meshes/TH2_z.dae</uri>
                </mesh>
            </geometry>
            <material>
                <ambient>0.46278560127488955 0.0043440794132239 0.27528971248043554 1</ambient>
                <diffuse>0.6665635290034194 0.5376923669147383 0.8656635531152418 1</diffuse>
                <specular>0.48479380034275776 0.39663998066772777 0.8091755324332103 1</specular>
                <emissive>0.3 0.2 0.2 1</emissive>
            </material>
        </visual>

        <collision name='collision_thmiddle_link'>
            <pose frame=''>0 0 0.012 0 0 0</pose>
           <geometry>
                <mesh>
                    <scale>0.001 0.001 0.001</scale>
                    <uri>meshes/TH2_z.dae</uri>
                </mesh>
            </geometry>
        </collision>
    </link>
    <link name = "thdistal_link">
            
        <pose frame=''>0.083498 -0.0185 0.32549700000000004 -0.785398 0.0 -1.5708</pose>
        <inertial>
            <pose frame=''>0 0 765 0 0 0</pose>
            <mass>0</mass>
            <inertia>
                <ixx>2.1e-06</ixx>
                <ixy>0</ixy>
                <ixz>0</ixz>
                <iyy>2.2e-06</iyy>
                <iyz>0</iyz>
                <izz>1.0e-06</izz>
            </inertia>
        </inertial>

        <visual name='visual_thdistal_link'>
            
            <geometry>
                <mesh>
                    <scale>0.001 0.001 0.001</scale>
                    <uri>meshes/thdistal_ellipsoid_visual.dae</uri>
                </mesh>
            </geometry>
            <material>
                <ambient>0.6945585613591468 0.9379105563691027 0.06286317807789232 1</ambient>
                <diffuse>0.04025793403915656 0.26950383070775974 0.18411998119377715 1</diffuse>
                <specular>0.03255942298870507 0.8500117004444478 0.9415245791500634 1</specular>
                <emissive>0.3 0.2 0.2 1</emissive>
            </material>
        </visual>
        <collision name='collision_thdistal_link'>
            <geometry>
                <mesh>
                    <scale>0.001 0.001 0.001</scale>
                    <uri>meshes/thdistal_ellipsoid_visual.dae</uri>
                </mesh>
            </geometry>
        </collision>
    </link>
 
    
        <joint name ="THJ5"  type ="revolute">
            <child>thbase_link</child>
            <parent>palm_link</parent>
            <axis>
                <xyz>0 0 1</xyz>
                <limit>
                    <lower>-3.141592653589793 </lower>
                    <upper>0.0 </upper>
                    <effort>0.2 </effort>
                    <velocity>4.0 </velocity>
                </limit>
                <dynamics>
                <damping>0.13205857334358223</damping>
                <friction>0.0066413778274969975</friction>
                </dynamics>
            </axis>
        </joint>
    
        <joint name ="THJ4"  type ="revolute">
            <child>thproximal_link</child>
            <parent>thbase_link</parent>
            <axis>
                <xyz>1 0 0</xyz>
                <limit>
                    <lower>0 </lower>
                    <upper>0.0 </upper>
                    <effort>3.0 </effort>
                    <velocity>4.0 </velocity>
                </limit>
                <dynamics>
                <damping>0.1695835655187726</damping>
                <friction>0.009601531633121444</friction>
                </dynamics>
            </axis>
        </joint>
    
        <joint name ="THJ2"  type ="revolute">
            <child>thmiddle_link</child>
            <parent>thhub_link</parent>
            <axis>
                <xyz>0 -1 0</xyz>
                <limit>
                    <lower>-3.141592653589793 </lower>
                    <upper>0.0 </upper>
                    <effort>2.0 </effort>
                    <velocity>2.0 </velocity>
                </limit>
                <dynamics>
                <damping>0.10838943428787143</damping>
                <friction>0.009008295376470804</friction>
                </dynamics>
            </axis>
        </joint>
    
        <joint name ="THJ1"  type ="revolute">
            <child>thdistal_link</child>
            <parent>thmiddle_link</parent>
            <axis>
                <xyz>1 0 0</xyz>
                <limit>
                    <lower>0 </lower>
                    <upper>1.5707963267948966 </upper>
                    <effort>1.0 </effort>
                    <velocity>4.0 </velocity>
                </limit>
                <dynamics>
                <damping>0.15713556912421178</damping>
                <friction>0.005496512452556625</friction>
                </dynamics>
            </axis>
        </joint>
    
    <joint name ="THJ3"  type ="fixed">
        <child>thhub_link</child>
        <parent>thproximal_link</parent>
        <axis>
            <xyz>1 0 0</xyz>
        </axis>
    </joint>

 

</model>
</sdf>