<?xml version="1.0"?>
<robot xmlns:xacro="http://www.ros.org/wiki/xacro">
  
  <!-- Import all Gazebo-customization elements, including Gazebo colors -->
  <xacro:include filename="$(find iiwa_fri_description)/urdf/iiwa.gazebo.xacro" />
  <!-- Import Transmissions -->
  <xacro:include filename="$(find iiwa_fri_description)/urdf/iiwa.transmission.xacro" />
  <xacro:include filename="$(find iiwa_fri_description)/urdf/iiwa_torque.transmission.xacro" />
  <!-- Include Utilities -->
  <xacro:include filename="$(find iiwa_fri_description)/urdf/utilities.xacro" />
  
  <!-- some constants -->
  <xacro:property name="safety_controller_k_pos" value="100" />
  <xacro:property name="safety_controller_k_vel" value="2" /> 
  <xacro:property name="joint_damping" value="0" />
  <xacro:property name="max_effort" value="100"/>
  <xacro:property name="max_velocity" value="10"/>
  
  <xacro:macro name="gripper">
    
    <link name="housing">
      <pose xyz="0 0 1.33" rpy="0 0 0" />
      <inertial>
        <origin xyz="0 0 0" rpy="0 0 0"/>
        <mass value="1.2"/>
        <inertia ixx="1"  ixy="0"  ixz="0" iyy="1" iyz="0" izz="1" />
      </inertial>
      
      <visual>
        <origin xyz="0 0 0" rpy="0 0 0"/>
        <geometry>
          <mesh filename="package://iiwa_fri_description/meshes/Housing.stl"/>
        </geometry>
        <material name="Grey"/>
      </visual>
      
      <collision>
        <origin xyz="-0.0011 -0.0011 -0.005" rpy="0 0 0"/>
        <geometry>
          <cylinder radius="0.065" length="0.065"/>
        </geometry>
        <material name="Grey"/>
      </collision>      
    </link>
    
    <!-- joint between gripper_left and housing -->
    <joint name="left_gripper_to_housing" type="prismatic">
      <parent link="housing"/>
      <child link="gripper_left"/>
      <origin xyz="-0.0005 -0.0335 -0.06221" rpy="0 0 0"/>
      <axis xyz="0 1 0"/>
      <limit lower="0" upper="0.02"
             effort="${max_effort}" velocity="${max_velocity}" />
      <dynamics damping="${joint_damping}"/>
    </joint>
    
    <link name="gripper_left">
      <pose xyz="0 0 0" rpy="0 0 0" />
      <inertial>
        <origin xyz="0 0 0.04" rpy="0 0 0"/>
        <mass value="0.1"/>
        <inertia ixx="0.1"  ixy="0"  ixz="0" iyy="0.1" iyz="0" izz="0.1" />
      </inertial>
      
      <visual>
        <origin xyz="0 0 0" rpy="0 0 0"/>
        <geometry>
          <mesh filename="package://iiwa_fri_description/meshes/Gripper.stl"/>
        </geometry>
        <material name="Grey"/>
      </visual>
      
      <collision>
        <!--origin xyz="-0.03 0.0119 -0.1106" rpy="0 0 0"/-->
        <origin xyz="-0.03 0.0119 -0.1106" rpy="0 0 0"/>
        <geometry>
          <mesh filename="package://iiwa_fri_description/meshes/gripper_c.stl"/>
        </geometry>
        <material name="Orange"/>
      </collision>
    </link>
    
    <!-- joint between gripper_right and housing -->
    <joint name="right_gripper_to_housing" type="prismatic">
      <parent link="housing"/>
      <child link="gripper_right"/>
      <origin xyz="-0.0005 0.03 -0.0623" rpy="0 0 3.14"/>
      <axis xyz="0 1 0"/>
      <limit lower="0" upper="0.02"
             effort="${max_effort}" velocity="${max_velocity}" />
      <dynamics damping="${joint_damping}"/>
    </joint>
    
    <link name="gripper_right">
      <pose xyz="0 0 0" rpy="0 0 0" />
      <inertial>
        <origin xyz="0 0 0.04" rpy="0 0 3.14"/>
        <mass value="0.1"/>
        <inertia ixx="0.1"  ixy="0"  ixz="0" iyy="0.1" iyz="0" izz="0.1" />
      </inertial>
      
      <visual>
        <origin xyz="0 0 0" rpy="0 0 0"/>
        <geometry>
          <mesh filename="package://iiwa_fri_description/meshes/Gripper.stl"/>
        </geometry>
        <material name="Orange"/>
      </visual>
      
      <collision>
        <!--origin xyz="-0.03 0.0119 -0.1106" rpy="0 0 3.14"/-->
        <origin xyz="-0.03 0.0119 -0.1106" rpy="0 0 0"/>
        <geometry>
          <mesh filename="package://iiwa_fri_description/meshes/gripper_c.stl"/>
        </geometry>
        <material name="Orange"/>
      </collision>
    </link>
  
  </xacro:macro>
  
</robot>
