<?xml version="1.0" ?>



<sdf version='1.6'>
  <model name="kuka_handlit">
    <!--KUKA-->
    <link name = "world">
        <pose frame=''>0 0 0 0 0 0</pose>
        <inertial>
            <pose frame=''>0 0 0.0 0 0 0</pose>
            <mass>0.0</mass>
            <inertia>
                <ixx>0.</ixx>
                <ixy>0</ixy>
                <ixz>0</ixz>
                <iyy>0.</iyy>
                <iyz>0</iyz>
                <izz>0.</izz>
            </inertia>
        </inertial>
    </link>
    <joint name="world" type="fixed">
        <child>lbr_iiwa_link_0</child>
        <parent>world</parent>
    </joint>
    
      <link name="lbr_iiwa_link_0">
        <pose frame=''>0 0 0 0 0 0</pose>
        <inertial>
            <pose frame=''>-0.1 0 0.07 0 0 0</pose>
            <mass>5</mass>
            <inertia>
                <ixx>0.05</ixx>
                <ixy>0</ixy>
                <ixz>0</ixz>
                <iyy>0.06</iyy>
                <iyz>0</iyz>
                <izz>0.03</izz>
            </inertia>
        </inertial>
        <collision name='lbr_iiwa_link_0_collision'>
          <pose frame=''>0 0 0 0 -0 0</pose>
          <geometry>
            <mesh>
              
              <scale>1 1 1</scale>
              <uri>/home/mamad/hand_RL_ws/src/iiwa_pybullet_integration/Training/kuka_handlit/kuka_handlit/envs/kuka_handlit_model/meshes/kuka/collision/link_0.stl</uri>
              
            </mesh>
          </geometry>
        </collision>
        <visual name='lbr_iiwa_link_0_visual'>
          <pose frame=''>0 0 0 0 -0 0</pose>
          <geometry>
            <mesh>
              <scale>1 1 1</scale>
              <uri>/home/mamad/hand_RL_ws/src/iiwa_pybullet_integration/Training/kuka_handlit/kuka_handlit/envs/kuka_handlit_model/meshes/kuka/visual/link_0.stl</uri>
            </mesh>
          </geometry>
          <material>
            <ambient>0.6685190352779818 0.6618153884409476 0.6017555355914131 1</ambient>
            <diffuse>0.019548635332963804 0.7604135956981863 0.8516134119157788 1</diffuse>
            <specular>0.5398453732540311 0.7180635218600271 0.7224320670473794 1</specular>
            <emissive>0 0 0 0</emissive>
          </material>
        </visual>
      </link>
    
      <link name="lbr_iiwa_link_1">
        <pose frame=''>0 0 0.1575 0 0 0</pose>
        <inertial>
            <pose frame=''>0 -0.03 0.12 0 0 0</pose>
            <mass>3.4525</mass>
            <inertia>
                <ixx>0.02183</ixx>
                <ixy>0</ixy>
                <ixz>0</ixz>
                <iyy>0.007703</iyy>
                <iyz>-0.003887</iyz>
                <izz>0.02083</izz>
            </inertia>
        </inertial>
        <collision name='lbr_iiwa_link_1_collision'>
          <pose frame=''>0 0 0 0 -0 0</pose>
          <geometry>
            <mesh>
              
              <scale>1 1 1</scale>
              <uri>/home/mamad/hand_RL_ws/src/iiwa_pybullet_integration/Training/kuka_handlit/kuka_handlit/envs/kuka_handlit_model/meshes/kuka/collision/link_1.stl</uri>
              
            </mesh>
          </geometry>
        </collision>
        <visual name='lbr_iiwa_link_1_visual'>
          <pose frame=''>0 0 0 0 -0 0</pose>
          <geometry>
            <mesh>
              <scale>1 1 1</scale>
              <uri>/home/mamad/hand_RL_ws/src/iiwa_pybullet_integration/Training/kuka_handlit/kuka_handlit/envs/kuka_handlit_model/meshes/kuka/visual/link_1.stl</uri>
            </mesh>
          </geometry>
          <material>
            <ambient>0.21219691096009163 0.9427982999661084 0.72558775860083 1</ambient>
            <diffuse>0.1090570972653756 0.690355643780133 0.8068568491846713 1</diffuse>
            <specular>0.7815550067292474 0.8059748155985231 0.5980554060514204 1</specular>
            <emissive>0 0 0 0</emissive>
          </material>
        </visual>
      </link>
    
      <link name="lbr_iiwa_link_2">
        <pose frame=''>0 0 0.34 1.5708 0 -3.14159</pose>
        <inertial>
            <pose frame=''>0.0003 0.059 0.042 0 0 0</pose>
            <mass>3.4821</mass>
            <inertia>
                <ixx>0.02076</ixx>
                <ixy>0</ixy>
                <ixz>0.003626</ixz>
                <iyy>0.02179</iyy>
                <iyz>0</iyz>
                <izz>0.00779</izz>
            </inertia>
        </inertial>
        <collision name='lbr_iiwa_link_2_collision'>
          <pose frame=''>0 0 0 0 -0 0</pose>
          <geometry>
            <mesh>
              
              <scale>1 1 1</scale>
              <uri>/home/mamad/hand_RL_ws/src/iiwa_pybullet_integration/Training/kuka_handlit/kuka_handlit/envs/kuka_handlit_model/meshes/kuka/collision/link_2.stl</uri>
              
            </mesh>
          </geometry>
        </collision>
        <visual name='lbr_iiwa_link_2_visual'>
          <pose frame=''>0 0 0 0 -0 0</pose>
          <geometry>
            <mesh>
              <scale>1 1 1</scale>
              <uri>/home/mamad/hand_RL_ws/src/iiwa_pybullet_integration/Training/kuka_handlit/kuka_handlit/envs/kuka_handlit_model/meshes/kuka/visual/link_2.stl</uri>
            </mesh>
          </geometry>
          <material>
            <ambient>0.9593275007064787 0.8089337025745748 0.9638764554208212 1</ambient>
            <diffuse>0.5044754605608244 0.731689690121993 0.4441758735876664 1</diffuse>
            <specular>0.5353896752629307 0.6755011708969372 0.07027064138246097 1</specular>
            <emissive>0 0 0 0</emissive>
          </material>
        </visual>
      </link>
    
      <link name="lbr_iiwa_link_3">
        <pose frame=''>0 0 0.524 0 0 0</pose>
        <inertial>
            <pose frame=''>0 0.03 0.13 0 0 0</pose>
            <mass>4.05623</mass>
            <inertia>
                <ixx>0.03204</ixx>
                <ixy>0</ixy>
                <ixz>0</ixz>
                <iyy>0.00972</iyy>
                <iyz>0.006227</iyz>
                <izz>0.03042</izz>
            </inertia>
        </inertial>
        <collision name='lbr_iiwa_link_3_collision'>
          <pose frame=''>0 0 0 0 -0 0</pose>
          <geometry>
            <mesh>
              
              <scale>1 1 1</scale>
              <uri>/home/mamad/hand_RL_ws/src/iiwa_pybullet_integration/Training/kuka_handlit/kuka_handlit/envs/kuka_handlit_model/meshes/kuka/collision/link_3.stl</uri>
              
            </mesh>
          </geometry>
        </collision>
        <visual name='lbr_iiwa_link_3_visual'>
          <pose frame=''>0 0 0 0 -0 0</pose>
          <geometry>
            <mesh>
              <scale>1 1 1</scale>
              <uri>/home/mamad/hand_RL_ws/src/iiwa_pybullet_integration/Training/kuka_handlit/kuka_handlit/envs/kuka_handlit_model/meshes/kuka/visual/link_3.stl</uri>
            </mesh>
          </geometry>
          <material>
            <ambient>0.3616686097048326 0.3999791571204647 0.6037311963134075 1</ambient>
            <diffuse>0.31581852827754087 0.9267145796721682 0.607442649363556 1</diffuse>
            <specular>0.84532539751372 0.5414642362619656 0.48391624654894616 1</specular>
            <emissive>0 0 0 0</emissive>
          </material>
        </visual>
      </link>
    
      <link name="lbr_iiwa_link_4">
        <pose frame=''>0 0 0.74 1.5708 0 0</pose>
        <inertial>
            <pose frame=''>0 0.067 0.034 0 0 0</pose>
            <mass>3.4822</mass>
            <inertia>
                <ixx>0.02178</ixx>
                <ixy>0</ixy>
                <ixz>0</ixz>
                <iyy>0.02075</iyy>
                <iyz>-0.003625</iyz>
                <izz>0.007785</izz>
            </inertia>
        </inertial>
        <collision name='lbr_iiwa_link_4_collision'>
          <pose frame=''>0 0 0 0 -0 0</pose>
          <geometry>
            <mesh>
              
              <scale>1 1 1</scale>
              <uri>/home/mamad/hand_RL_ws/src/iiwa_pybullet_integration/Training/kuka_handlit/kuka_handlit/envs/kuka_handlit_model/meshes/kuka/collision/link_4.stl</uri>
              
            </mesh>
          </geometry>
        </collision>
        <visual name='lbr_iiwa_link_4_visual'>
          <pose frame=''>0 0 0 0 -0 0</pose>
          <geometry>
            <mesh>
              <scale>1 1 1</scale>
              <uri>/home/mamad/hand_RL_ws/src/iiwa_pybullet_integration/Training/kuka_handlit/kuka_handlit/envs/kuka_handlit_model/meshes/kuka/visual/link_4.stl</uri>
            </mesh>
          </geometry>
          <material>
            <ambient>0.739011243895945 0.04758514821571325 0.8211156798183269 1</ambient>
            <diffuse>0.006107234454062138 0.2158901891280003 0.4444398702722747 1</diffuse>
            <specular>0.006010878420253274 0.6692260708006913 0.46953457954642375 1</specular>
            <emissive>0 0 0 0</emissive>
          </material>
        </visual>
      </link>
    
      <link name="lbr_iiwa_link_5">
        <pose frame=''>0 0 0.9239999999999999 0 0 -3.14159</pose>
        <inertial>
            <pose frame=''>0.0001 0.021 0.076 0 0 0</pose>
            <mass>2.1633</mass>
            <inertia>
                <ixx>0.01287</ixx>
                <ixy>0</ixy>
                <ixz>0</ixz>
                <iyy>0.005708</iyy>
                <iyz>-0.003946</iyz>
                <izz>0.01112</izz>
            </inertia>
        </inertial>
        <collision name='lbr_iiwa_link_5_collision'>
          <pose frame=''>0 0 0 0 -0 0</pose>
          <geometry>
            <mesh>
              
              <scale>1 1 1</scale>
              <uri>/home/mamad/hand_RL_ws/src/iiwa_pybullet_integration/Training/kuka_handlit/kuka_handlit/envs/kuka_handlit_model/meshes/kuka/collision/link_5.stl</uri>
              
            </mesh>
          </geometry>
        </collision>
        <visual name='lbr_iiwa_link_5_visual'>
          <pose frame=''>0 0 0 0 -0 0</pose>
          <geometry>
            <mesh>
              <scale>1 1 1</scale>
              <uri>/home/mamad/hand_RL_ws/src/iiwa_pybullet_integration/Training/kuka_handlit/kuka_handlit/envs/kuka_handlit_model/meshes/kuka/visual/link_5.stl</uri>
            </mesh>
          </geometry>
          <material>
            <ambient>0.426160567745945 0.13651091406046112 0.8019462541825157 1</ambient>
            <diffuse>0.6710883491438747 0.376400180644767 0.10448795524769006 1</diffuse>
            <specular>0.9704525704467196 0.42639634348932387 0.5446857682074601 1</specular>
            <emissive>0 0 0 0</emissive>
          </material>
        </visual>
      </link>
    
      <link name="lbr_iiwa_link_6">
        <pose frame=''>0 -0.0607 1.14 1.5708 0 -3.14159</pose>
        <inertial>
            <pose frame=''>0 0.0006 0.0004 0 0 0</pose>
            <mass>2.3466</mass>
            <inertia>
                <ixx>0.006509</ixx>
                <ixy>0</ixy>
                <ixz>0</ixz>
                <iyy>0.006259</iyy>
                <iyz>0.00031891</iyz>
                <izz>0.004527</izz>
            </inertia>
        </inertial>
        <collision name='lbr_iiwa_link_6_collision'>
          <pose frame=''>0 0 0 0 -0 0</pose>
          <geometry>
            <mesh>
              
              <scale>1 1 1</scale>
              <uri>/home/mamad/hand_RL_ws/src/iiwa_pybullet_integration/Training/kuka_handlit/kuka_handlit/envs/kuka_handlit_model/meshes/kuka/collision/link_6.stl</uri>
              
            </mesh>
          </geometry>
        </collision>
        <visual name='lbr_iiwa_link_6_visual'>
          <pose frame=''>0 0 0 0 -0 0</pose>
          <geometry>
            <mesh>
              <scale>1 1 1</scale>
              <uri>/home/mamad/hand_RL_ws/src/iiwa_pybullet_integration/Training/kuka_handlit/kuka_handlit/envs/kuka_handlit_model/meshes/kuka/visual/link_6.stl</uri>
            </mesh>
          </geometry>
          <material>
            <ambient>0.14799203533486094 0.7589838455222753 0.33924942045506434 1</ambient>
            <diffuse>0.2870972078175582 0.1917045797937914 0.228303464597715 1</diffuse>
            <specular>0.7442390357672767 0.36469819173277807 0.37421743203145297 1</specular>
            <emissive>0 0 0 0</emissive>
          </material>
        </visual>
      </link>
    
      <link name="lbr_iiwa_link_7">
        <pose frame=''>0 0 1.2205000000000001 0 0 0</pose>
        <inertial>
            <pose frame=''>0 0.00043 0.071108 0 0 0</pose>
            <mass>3.129</mass>
            <inertia>
                <ixx>0.145258</ixx>
                <ixy>0.0005912</ixy>
                <ixz>0</ixz>
                <iyy>0.145283</iyy>
                <iyz>-0.000503009</iyz>
                <izz>0.0572184</izz>
            </inertia>
        </inertial>
        <collision name='lbr_iiwa_link_7_collision'>
          <pose frame=''>0 0 0 0 -0 0</pose>
          <geometry>
            <mesh>
              
              <scale>1 1 1</scale>
              <uri>/home/mamad/hand_RL_ws/src/iiwa_pybullet_integration/Training/kuka_handlit/kuka_handlit/envs/kuka_handlit_model/meshes/kuka/collision/link_7.stl</uri>
              
            </mesh>
          </geometry>
        </collision>
        <visual name='lbr_iiwa_link_7_visual'>
          <pose frame=''>0 0 0 0 -0 0</pose>
          <geometry>
            <mesh>
              <scale>1 1 1</scale>
              <uri>/home/mamad/hand_RL_ws/src/iiwa_pybullet_integration/Training/kuka_handlit/kuka_handlit/envs/kuka_handlit_model/meshes/kuka/visual/link_7.stl</uri>
            </mesh>
          </geometry>
          <material>
            <ambient>0.3198564076814344 0.46014522604761265 0.4165140274494319 1</ambient>
            <diffuse>0.018342052323270353 0.5143496104284513 0.08770634402676492 1</diffuse>
            <specular>0.2801849490923479 0.9875857144410016 0.5286038502154824 1</specular>
            <emissive>0 0 0 0</emissive>
          </material>
        </visual>
      </link>
    
   
    
      <joint name="J0" type="revolute">
        <child>lbr_iiwa_link_1</child>
        <parent>lbr_iiwa_link_0</parent>
        <axis>
          <xyz>0 0 1</xyz>
          <limit>
            <lower>-2.96706</lower>
            <upper>2.96706</upper>
            <effort>300</effort>
            <velocity>10</velocity>
          </limit>
          <dynamics>
            <damping>0.5</damping>
            <friction>0</friction>
            <spring_reference>0</spring_reference>
            <spring_stiffness>0</spring_stiffness>
          </dynamics>
        </axis>
      </joint>
    
      <joint name="J1" type="revolute">
        <child>lbr_iiwa_link_2</child>
        <parent>lbr_iiwa_link_1</parent>
        <axis>
          <xyz>0 0 1</xyz>
          <limit>
            <lower>-2.0944</lower>
            <upper>2.0944</upper>
            <effort>300</effort>
            <velocity>10</velocity>
          </limit>
          <dynamics>
            <damping>0.5</damping>
            <friction>0</friction>
            <spring_reference>0</spring_reference>
            <spring_stiffness>0</spring_stiffness>
          </dynamics>
        </axis>
      </joint>
    
      <joint name="J2" type="revolute">
        <child>lbr_iiwa_link_3</child>
        <parent>lbr_iiwa_link_2</parent>
        <axis>
          <xyz>0 0 1</xyz>
          <limit>
            <lower>-2.96706</lower>
            <upper>2.96706</upper>
            <effort>300</effort>
            <velocity>10</velocity>
          </limit>
          <dynamics>
            <damping>0.5</damping>
            <friction>0</friction>
            <spring_reference>0</spring_reference>
            <spring_stiffness>0</spring_stiffness>
          </dynamics>
        </axis>
      </joint>
    
      <joint name="J3" type="revolute">
        <child>lbr_iiwa_link_4</child>
        <parent>lbr_iiwa_link_3</parent>
        <axis>
          <xyz>0 0 1</xyz>
          <limit>
            <lower>-2.0944</lower>
            <upper>2.0944</upper>
            <effort>300</effort>
            <velocity>10</velocity>
          </limit>
          <dynamics>
            <damping>0.5</damping>
            <friction>0</friction>
            <spring_reference>0</spring_reference>
            <spring_stiffness>0</spring_stiffness>
          </dynamics>
        </axis>
      </joint>
    
      <joint name="J4" type="revolute">
        <child>lbr_iiwa_link_5</child>
        <parent>lbr_iiwa_link_4</parent>
        <axis>
          <xyz>0 0 1</xyz>
          <limit>
            <lower>-2.96706</lower>
            <upper>2.96706</upper>
            <effort>300</effort>
            <velocity>10</velocity>
          </limit>
          <dynamics>
            <damping>0.5</damping>
            <friction>0</friction>
            <spring_reference>0</spring_reference>
            <spring_stiffness>0</spring_stiffness>
          </dynamics>
        </axis>
      </joint>
    
      <joint name="J5" type="revolute">
        <child>lbr_iiwa_link_6</child>
        <parent>lbr_iiwa_link_5</parent>
        <axis>
          <xyz>0 0 1</xyz>
          <limit>
            <lower>-2.0944</lower>
            <upper>2.0944</upper>
            <effort>300</effort>
            <velocity>10</velocity>
          </limit>
          <dynamics>
            <damping>0.5</damping>
            <friction>0</friction>
            <spring_reference>0</spring_reference>
            <spring_stiffness>0</spring_stiffness>
          </dynamics>
        </axis>
      </joint>
    
      <joint name="J6" type="revolute">
        <child>lbr_iiwa_link_7</child>
        <parent>lbr_iiwa_link_6</parent>
        <axis>
          <xyz>0 0 1</xyz>
          <limit>
            <lower>-3.05433</lower>
            <upper>3.05433</upper>
            <effort>300</effort>
            <velocity>10</velocity>
          </limit>
          <dynamics>
            <damping>0.5</damping>
            <friction>0</friction>
            <spring_reference>0</spring_reference>
            <spring_stiffness>0</spring_stiffness>
          </dynamics>
        </axis>
      </joint>
    

    <link name = "lbr_iiwa_link_ee">

        <pose frame=''>0 0 1.2655 0 0 0</pose>
        <inertial>
            <pose frame=''>0 0.00043 0.071108 0 0 0</pose>
            <mass>1.0e-22</mass>
            <inertia>
                <ixx>0.145258</ixx>
                <ixy>0.0005912</ixy>
                <ixz>0</ixz>
                <iyy>0.145283</iyy>
                <iyz>-0.000503009</iyz>
                <izz>0.0572184</izz>
            </inertia>
        </inertial>
            <visual name='visual_lbr_iiwa_link_ee'>
                <geometry>
                    <sphere>
                    <radius>0.01</radius>
                    </sphere>
                </geometry>
                <material>
                    <ambient>0.5672216218105076 0.531815859282997 0.5801439037594547 1</ambient>
                    <diffuse>0.5464167892541046 0.6932951350253517 0.22253023363722557 1</diffuse>
                    <specular>0.9022550019258972 0.9029306286118689 0.5969458319897258 1</specular>
                    <emissive>0 0 0 0</emissive>
                </material>
            </visual>
    </link>
    
    <joint name="J7" type="fixed">
        <child>lbr_iiwa_link_ee</child>
        <parent>lbr_iiwa_link_7</parent>
        <axis>

            <xyz>0 -1 0</xyz>
         </axis>
    </joint>  
    <!--Hand-->

    <joint name="forearm_world" type="fixed">
        <child>forearm</child>
        <parent>lbr_iiwa_link_ee</parent>
    </joint>

    <link name ="forearm" >
        <pose frame=''>0 0 1.2655 0 0 1.5707963267948966</pose>
        <inertial>
            <pose frame=''>0 0 0.09 0 0 0</pose>
            <mass>1.8</mass>
            <inertia>
                <ixx>0.108</ixx>
                <ixy>0</ixy>
                <ixz>0</ixz>
                <iyy>0.108</iyy>
                <iyz>0</iyz>
                <izz>0.054</izz>
            </inertia>
        </inertial>

        <visual name='visual_forearm_link'>

            <geometry>
                <mesh>
                    <scale>1 1 1</scale>
                    <uri>/home/mamad/hand_RL_ws/src/iiwa_pybullet_integration/Training/kuka_handlit/kuka_handlit/envs/kuka_handlit_model/meshes/forearm_lite.dae</uri>
                </mesh>
            </geometry>
            <material>
                <ambient>0.05433570636822227 0.0923562004455889 0.6078280127617282 1</ambient>
                <diffuse>0.18646445175623283 0.9764361979960658 0.7663519627113367 1</diffuse>
                <specular>0.21610886748688773 0.8749864245789083 0.940895980046642 1</specular>
                <emissive>0 0 0 0</emissive>
            </material>
        </visual>
        <collision name='collision_forearm_link'>
        
            <geometry>
                <mesh>
                    <scale>1 1 1</scale>
                    <uri>/home/mamad/hand_RL_ws/src/iiwa_pybullet_integration/Training/kuka_handlit/kuka_handlit/envs/kuka_handlit_model/meshes/forearm_lite.dae</uri>
                </mesh>
            </geometry>
        </collision>
    </link>

    <link name = "palm">
        <pose frame=''>0 -0.015 1.4145 -0.6981317007977318 0 0</pose>
        <inertial>
            <pose frame=''>0 0 0.035 0 0 0</pose>
            <mass>0.3</mass>
            <inertia>
                <ixx>0.0003581</ixx>
                <ixy>0</ixy>
                <ixz>0</ixz>
                <iyy>0.0005287</iyy>
                <iyz>0</iyz>
                <izz>0.000191</izz>
            </inertia>
        </inertial>
        
        <visual name='visual_palm_link'>

            <geometry>
                <mesh>
                    <scale>-0.001 0.001 0.001</scale>
                    <uri>/home/mamad/hand_RL_ws/src/iiwa_pybullet_integration/Training/kuka_handlit/kuka_handlit/envs/kuka_handlit_model/meshes/palm2.dae</uri>
                </mesh>
            </geometry>
            <material>
                <ambient>0.9869775341041793 0.8384296724958386 0.9127235835531301 1</ambient>
                <diffuse>0.6324855905457833 0.26380788344559836 0.83948289629652 1</diffuse>
                <specular>0.5045522664541845 0.7172570331276149 0.7715017157002823 1</specular>
                <emissive>0 0 0 0</emissive>
            </material>
        </visual>
        <collision name="collision_palm_link">

            <geometry>
                <mesh>
                    <scale>-0.001 0.001 0.001</scale>
                <uri>/home/mamad/hand_RL_ws/src/iiwa_pybullet_integration/Training/kuka_handlit/kuka_handlit/envs/kuka_handlit_model/meshes/palm2_c.dae</uri>
            </mesh>
            </geometry>
        </collision>


        
    </link>
    <joint name="palm_forearm" type="fixed">
        <child>palm</child>
        <parent>forearm</parent>
        <axis>

            <xyz>0 -1 0</xyz>
         </axis>
    </joint>  

    
    <link name = "palm_fake">

        <pose frame=''>-0.01 0.020909000000000004 1.4544000000000001 -0.6981317007977318 0 0</pose>
        <inertial>
            <pose frame=''>0 0 0.0 0 0 0</pose>
            <mass>0.0</mass>
            <inertia>
                <ixx>0.0</ixx>
                <ixy>0</ixy>
                <ixz>0</ixz>
                <iyy>0.0</iyy>
                <iyz>0</iyz>
                <izz>0.0</izz>
            </inertia>
        </inertial>
            <visual name='visual_palm_fake'>
                <geometry>
                    <sphere>
                    <radius>0.01</radius>
                    </sphere>
                </geometry>
                <material>
                    <ambient>0.5672216218105076 0.531815859282997 0.5801439037594547 1</ambient>
                    <diffuse>0.5464167892541046 0.6932951350253517 0.22253023363722557 1</diffuse>
                    <specular>0.9022550019258972 0.9029306286118689 0.5969458319897258 1</specular>
                    <emissive>0 0 0 0</emissive>
                </material>
            </visual>
    </link>

    <joint name="palm_palm_fake" type="fixed">
        <child>palm_fake</child>
        <parent>palm</parent>
        <axis>

            <xyz>0 -1 0</xyz>
         </axis>
    </joint>  

    

        <link name = "knuckle_FF">

            <pose frame=''>-0.033 0.0461 1.48727 -0.698132 0 0</pose>
            <inertial>
                <pose frame=''>0 0 0 0 0 0</pose>
                <mass>0.008</mass>
                <inertia>
                    <ixx>2.6e-07</ixx>
                    <ixy>0</ixy>
                    <ixz>0</ixz>
                    <iyy>2.6e-07</iyy>
                    <iyz>0</iyz>
                    <izz>3.2e-07</izz>
                </inertia>
            </inertial>

            <visual name='visual_knuckle_link_FF'>

                <geometry>
                    <mesh>
                        <scale>0.001 0.001 0.001</scale>
                        <uri>/home/mamad/hand_RL_ws/src/iiwa_pybullet_integration/Training/kuka_handlit/kuka_handlit/envs/kuka_handlit_model/meshes/knuckle.dae</uri>
                    </mesh>
                </geometry>
                <material>
                    <ambient>0.11170500913399062 0.3669781765368426 0.7741806257294539 1</ambient>
                    <diffuse>0.6903800753319268 0.4793825303811243 0.848824324415701 1</diffuse>
                    <specular>0.7300750259445424 0.4490591189905909 0.9334239737672162 1</specular>
                    <emissive>0 0 0 0</emissive>
                </material>
            </visual>
            <collision name='collision_knuckle_link_FF'>
                <geometry>
                <mesh>
                    <scale>0.001 0.001 0.001</scale>
                    <uri>/home/mamad/hand_RL_ws/src/iiwa_pybullet_integration/Training/kuka_handlit/kuka_handlit/envs/kuka_handlit_model/meshes/knuckle.dae</uri>
                </mesh>
            </geometry>
            </collision>
        </link>
        <link name = "proximal_FF">
            <pose frame=''>-0.033 0.0461 1.48727 -0.698132 0 0</pose>
            <inertial>
                <pose frame=''>0 0 0.0225 0 0 0</pose>
                <mass>0.03</mass>
                <inertia>
                    <ixx>9.8e-06</ixx>
                    <ixy>0</ixy>
                    <ixz>0</ixz>
                    <iyy>1.0e-05</iyy>
                    <iyz>0</iyz>
                    <izz>1.8e-06</izz>
                </inertia>
            </inertial>

            <visual name='visual_proximal_link_FF'>

                <geometry>
                    <mesh>
                        <scale>0.001 0.001 0.001</scale>
                        <uri>/home/mamad/hand_RL_ws/src/iiwa_pybullet_integration/Training/kuka_handlit/kuka_handlit/envs/kuka_handlit_model/meshes/F3.dae</uri>
                    </mesh>
                </geometry>
                <material>
                    <ambient>0.3049055100377105 0.21098205790393176 0.6450165728272487 1</ambient>
                    <diffuse>0.04450554728487521 0.4657500786762745 0.5386627910480523 1</diffuse>
                    <specular>0.7857364515171629 0.4205964218877639 0.20762868604653273 1</specular>
                    <emissive>0 0 0 0</emissive>
                </material>
            </visual>
            <collision name='collision_proximal_link_FF'>
                <geometry>
                <mesh>
                    <scale>0.001 0.001 0.001</scale>
                    <uri>/home/mamad/hand_RL_ws/src/iiwa_pybullet_integration/Training/kuka_handlit/kuka_handlit/envs/kuka_handlit_model/meshes/F3_c.dae</uri>
                </mesh>
            </geometry>
            </collision>
        </link>
        <link name = "middle_FF">
            <pose frame=''>-0.033 0.07499 1.521746 -0.698132 0 0</pose>
            <inertial>
                <pose frame=''>0 0 0.0125 0 0 0</pose>
                <mass>0.017</mass>
                <inertia>
                    <ixx>2.6e-06</ixx>
                    <ixy>0</ixy>
                    <ixz>0</ixz>
                    <iyy>2.7e-06</iyy>
                    <iyz>0</iyz>
                    <izz>8.7e-07</izz>
                </inertia>
            </inertial>

            <visual name='visual_middle_link_FF'>

                <geometry>
                    <mesh>
                        <scale>0.001 0.001 0.001</scale>
                        <uri>/home/mamad/hand_RL_ws/src/iiwa_pybullet_integration/Training/kuka_handlit/kuka_handlit/envs/kuka_handlit_model/meshes/F2.dae</uri>
                    </mesh>
                </geometry>
                <material>
                    <ambient>0.7468642354354483 0.4906554874818173 0.05684487557950246 1</ambient>
                    <diffuse>0.2158525936518899 0.6174870697328089 0.12683870424433774 1</diffuse>
                    <specular>0.8837401386177449 0.6693690206997305 0.7904029037832123 1</specular>
                    <emissive>0 0 0 0</emissive>
                </material>
            </visual>
            <collision name='collision_middle_link_FF'>
                <geometry>
                    <mesh>
                        <scale>0.001 0.001 0.001</scale>
                        <uri>/home/mamad/hand_RL_ws/src/iiwa_pybullet_integration/Training/kuka_handlit/kuka_handlit/envs/kuka_handlit_model/meshes/F2_c.dae</uri>
                    </mesh>
                </geometry>
            </collision>
        </link>
        <link name =  "distal_FF">
            <pose frame=''>-0.033 0.09106 1.540897 -0.698132 0 0</pose>
            <inertial>
                <pose frame=''>0 0 0.012 0 0 0</pose>
                <mass>0.012</mass>
                <inertia>
                    <ixx>9.4e-07</ixx>
                    <ixy>0</ixy>
                    <ixz>0</ixz>
                    <iyy>1.1e-06</iyy>
                    <iyz>0</iyz>
                    <izz>5.3e-07</izz>
                </inertia>
            </inertial>

            <visual name='visual_distal_link_FF'>

                <geometry>
                    <mesh>
                        <scale>0.001 0.001 0.001</scale>
                        <uri>/home/mamad/hand_RL_ws/src/iiwa_pybullet_integration/Training/kuka_handlit/kuka_handlit/envs/kuka_handlit_model/meshes/F1.dae</uri>
                    </mesh>
                </geometry>
                <material>
                    <ambient>0.8884803287041303 0.5477811638584582 0.6752640741774826 1</ambient>
                    <diffuse>0.22709617255117198 0.008181551027436673 0.9316726165090642 1</diffuse>
                    <specular>0.16330976247432205 0.37170271121831766 0.14964517848159786 1</specular>
                    <emissive>0 0 0 0</emissive>
                </material>
            </visual>
            <collision name='collision_distal_link_FF'>
                <geometry>
                    <mesh>
                        <scale>0.001 0.001 0.001</scale>
                        <uri>/home/mamad/hand_RL_ws/src/iiwa_pybullet_integration/Training/kuka_handlit/kuka_handlit/envs/kuka_handlit_model/meshes/F1.dae</uri>
                    </mesh>
                </geometry>
            </collision>
        </link>

        
            
            <joint name="J3_FF" type="revolute">
                <child>proximal_FF</child>
                <parent>knuckle_FF</parent>

                <axis>
                    <xyz>1 0 0</xyz>
                    <limit>
                        <lower>0 </lower>
                        <upper>1.5708 </upper>
                        <effort>2.0 </effort>
                        <velocity>2.0 </velocity>
                    </limit>
                    <dynamics>
                        <damping>0.1</damping>
                        <friction>0</friction>
                        <spring_reference>0</spring_reference>
                        <spring_stiffness>0</spring_stiffness>
                    </dynamics>
                </axis>
            </joint>
        
            
            <joint name="J2_FF" type="revolute">
                <child>middle_FF</child>
                <parent>proximal_FF</parent>

                <axis>
                    <xyz>1 0 0</xyz>
                    <limit>
                        <lower>0 </lower>
                        <upper>1.5708 </upper>
                        <effort>2.0 </effort>
                        <velocity>2.0 </velocity>
                    </limit>
                    <dynamics>
                        <damping>0.1</damping>
                        <friction>0</friction>
                        <spring_reference>0</spring_reference>
                        <spring_stiffness>0</spring_stiffness>
                    </dynamics>
                </axis>
            </joint>
        
            
            <joint name="J1_FF" type="revolute">
                <child>distal_FF</child>
                <parent>middle_FF</parent>

                <axis>
                    <xyz>1 0 0</xyz>
                    <limit>
                        <lower>0 </lower>
                        <upper>1.5708 </upper>
                        <effort>2.0 </effort>
                        <velocity>2.0 </velocity>
                    </limit>
                    <dynamics>
                        <damping>0.1</damping>
                        <friction>0</friction>
                        <spring_reference>0</spring_reference>
                        <spring_stiffness>0</spring_stiffness>
                    </dynamics>
                </axis>
            </joint>
        
        <joint name='J4_FF' type="revolute">
            <child>knuckle_FF</child>
            <parent>palm</parent>

            <axis>
                <xyz>0 0.766044 -0.642788</xyz>
                <limit>
                    <lower>-0.349066 </lower>
                    <upper>0.349066 </upper>
                    <effort>2.0 </effort>
                    <velocity>2.0 </velocity>
                </limit>
                <dynamics>
                    <damping>0.1</damping>
                    <friction>0</friction>
                    <spring_reference>0</spring_reference>
                    <spring_stiffness>0</spring_stiffness>
                </dynamics>
            </axis>
        </joint>

    

        <link name = "knuckle_MF">

            <pose frame=''>-0.011000000000000003 0.048636 1.4903380000000002 -0.698132 0 0</pose>
            <inertial>
                <pose frame=''>0 0 0 0 0 0</pose>
                <mass>0.008</mass>
                <inertia>
                    <ixx>2.6e-07</ixx>
                    <ixy>0</ixy>
                    <ixz>0</ixz>
                    <iyy>2.6e-07</iyy>
                    <iyz>0</iyz>
                    <izz>3.2e-07</izz>
                </inertia>
            </inertial>

            <visual name='visual_knuckle_link_MF'>

                <geometry>
                    <mesh>
                        <scale>0.001 0.001 0.001</scale>
                        <uri>/home/mamad/hand_RL_ws/src/iiwa_pybullet_integration/Training/kuka_handlit/kuka_handlit/envs/kuka_handlit_model/meshes/knuckle.dae</uri>
                    </mesh>
                </geometry>
                <material>
                    <ambient>0.5746990530747502 0.1619826312904995 0.8178982894472206 1</ambient>
                    <diffuse>0.7279073018404281 0.5205094807465086 0.6061518962592563 1</diffuse>
                    <specular>0.9944417189619681 0.18798314754960066 0.5887289109366386 1</specular>
                    <emissive>0 0 0 0</emissive>
                </material>
            </visual>
            <collision name='collision_knuckle_link_MF'>
                <geometry>
                <mesh>
                    <scale>0.001 0.001 0.001</scale>
                    <uri>/home/mamad/hand_RL_ws/src/iiwa_pybullet_integration/Training/kuka_handlit/kuka_handlit/envs/kuka_handlit_model/meshes/knuckle.dae</uri>
                </mesh>
            </geometry>
            </collision>
        </link>
        <link name = "proximal_MF">
            <pose frame=''>-0.011000000000000003 0.048636 1.4903380000000002 -0.698132 0 0</pose>
            <inertial>
                <pose frame=''>0 0 0.0225 0 0 0</pose>
                <mass>0.03</mass>
                <inertia>
                    <ixx>9.8e-06</ixx>
                    <ixy>0</ixy>
                    <ixz>0</ixz>
                    <iyy>1.0e-05</iyy>
                    <iyz>0</iyz>
                    <izz>1.8e-06</izz>
                </inertia>
            </inertial>

            <visual name='visual_proximal_link_MF'>

                <geometry>
                    <mesh>
                        <scale>0.001 0.001 0.001</scale>
                        <uri>/home/mamad/hand_RL_ws/src/iiwa_pybullet_integration/Training/kuka_handlit/kuka_handlit/envs/kuka_handlit_model/meshes/F3.dae</uri>
                    </mesh>
                </geometry>
                <material>
                    <ambient>0.10704143325021331 0.39948676903365476 0.6446016535345727 1</ambient>
                    <diffuse>0.23246413512080932 0.19845579733136698 0.7313323098322102 1</diffuse>
                    <specular>0.7303889379630525 0.8043227634460812 0.8648690421281109 1</specular>
                    <emissive>0 0 0 0</emissive>
                </material>
            </visual>
            <collision name='collision_proximal_link_MF'>
                <geometry>
                <mesh>
                    <scale>0.001 0.001 0.001</scale>
                    <uri>/home/mamad/hand_RL_ws/src/iiwa_pybullet_integration/Training/kuka_handlit/kuka_handlit/envs/kuka_handlit_model/meshes/F3_c.dae</uri>
                </mesh>
            </geometry>
            </collision>
        </link>
        <link name = "middle_MF">
            <pose frame=''>-0.011000000000000003 0.077526 1.5248140000000001 -0.698132 0 0</pose>
            <inertial>
                <pose frame=''>0 0 0.0125 0 0 0</pose>
                <mass>0.017</mass>
                <inertia>
                    <ixx>2.6e-06</ixx>
                    <ixy>0</ixy>
                    <ixz>0</ixz>
                    <iyy>2.7e-06</iyy>
                    <iyz>0</iyz>
                    <izz>8.7e-07</izz>
                </inertia>
            </inertial>

            <visual name='visual_middle_link_MF'>

                <geometry>
                    <mesh>
                        <scale>0.001 0.001 0.001</scale>
                        <uri>/home/mamad/hand_RL_ws/src/iiwa_pybullet_integration/Training/kuka_handlit/kuka_handlit/envs/kuka_handlit_model/meshes/F2.dae</uri>
                    </mesh>
                </geometry>
                <material>
                    <ambient>0.6685303493992164 0.37515249683512697 0.8195468710594107 1</ambient>
                    <diffuse>0.867916925094574 0.9981355402684797 0.8211965607168856 1</diffuse>
                    <specular>0.28154730546081375 0.4045926136656688 0.8086397909620961 1</specular>
                    <emissive>0 0 0 0</emissive>
                </material>
            </visual>
            <collision name='collision_middle_link_MF'>
                <geometry>
                    <mesh>
                        <scale>0.001 0.001 0.001</scale>
                        <uri>/home/mamad/hand_RL_ws/src/iiwa_pybullet_integration/Training/kuka_handlit/kuka_handlit/envs/kuka_handlit_model/meshes/F2_c.dae</uri>
                    </mesh>
                </geometry>
            </collision>
        </link>
        <link name =  "distal_MF">
            <pose frame=''>-0.011000000000000003 0.093596 1.543965 -0.698132 0 0</pose>
            <inertial>
                <pose frame=''>0 0 0.012 0 0 0</pose>
                <mass>0.012</mass>
                <inertia>
                    <ixx>9.4e-07</ixx>
                    <ixy>0</ixy>
                    <ixz>0</ixz>
                    <iyy>1.1e-06</iyy>
                    <iyz>0</iyz>
                    <izz>5.3e-07</izz>
                </inertia>
            </inertial>

            <visual name='visual_distal_link_MF'>

                <geometry>
                    <mesh>
                        <scale>0.001 0.001 0.001</scale>
                        <uri>/home/mamad/hand_RL_ws/src/iiwa_pybullet_integration/Training/kuka_handlit/kuka_handlit/envs/kuka_handlit_model/meshes/F1.dae</uri>
                    </mesh>
                </geometry>
                <material>
                    <ambient>0.6610116364408164 0.7018469879629047 0.0053829444155577555 1</ambient>
                    <diffuse>0.44387859322134815 0.9879307028572593 0.34922910723503797 1</diffuse>
                    <specular>0.7262764876184304 0.35802546832824034 0.37424481217892924 1</specular>
                    <emissive>0 0 0 0</emissive>
                </material>
            </visual>
            <collision name='collision_distal_link_MF'>
                <geometry>
                    <mesh>
                        <scale>0.001 0.001 0.001</scale>
                        <uri>/home/mamad/hand_RL_ws/src/iiwa_pybullet_integration/Training/kuka_handlit/kuka_handlit/envs/kuka_handlit_model/meshes/F1.dae</uri>
                    </mesh>
                </geometry>
            </collision>
        </link>

        
            
            <joint name="J3_MF" type="revolute">
                <child>proximal_MF</child>
                <parent>knuckle_MF</parent>

                <axis>
                    <xyz>1 0 0</xyz>
                    <limit>
                        <lower>0 </lower>
                        <upper>1.5708 </upper>
                        <effort>2.0 </effort>
                        <velocity>2.0 </velocity>
                    </limit>
                    <dynamics>
                        <damping>0.1</damping>
                        <friction>0</friction>
                        <spring_reference>0</spring_reference>
                        <spring_stiffness>0</spring_stiffness>
                    </dynamics>
                </axis>
            </joint>
        
            
            <joint name="J2_MF" type="revolute">
                <child>middle_MF</child>
                <parent>proximal_MF</parent>

                <axis>
                    <xyz>1 0 0</xyz>
                    <limit>
                        <lower>0 </lower>
                        <upper>1.5708 </upper>
                        <effort>2.0 </effort>
                        <velocity>2.0 </velocity>
                    </limit>
                    <dynamics>
                        <damping>0.1</damping>
                        <friction>0</friction>
                        <spring_reference>0</spring_reference>
                        <spring_stiffness>0</spring_stiffness>
                    </dynamics>
                </axis>
            </joint>
        
            
            <joint name="J1_MF" type="revolute">
                <child>distal_MF</child>
                <parent>middle_MF</parent>

                <axis>
                    <xyz>1 0 0</xyz>
                    <limit>
                        <lower>0 </lower>
                        <upper>1.5708 </upper>
                        <effort>2.0 </effort>
                        <velocity>2.0 </velocity>
                    </limit>
                    <dynamics>
                        <damping>0.1</damping>
                        <friction>0</friction>
                        <spring_reference>0</spring_reference>
                        <spring_stiffness>0</spring_stiffness>
                    </dynamics>
                </axis>
            </joint>
        
        <joint name='J4_MF' type="revolute">
            <child>knuckle_MF</child>
            <parent>palm</parent>

            <axis>
                <xyz>0 0.766044 -0.642788</xyz>
                <limit>
                    <lower>-0.349066 </lower>
                    <upper>0.349066 </upper>
                    <effort>2.0 </effort>
                    <velocity>2.0 </velocity>
                </limit>
                <dynamics>
                    <damping>0.1</damping>
                    <friction>0</friction>
                    <spring_reference>0</spring_reference>
                    <spring_stiffness>0</spring_stiffness>
                </dynamics>
            </axis>
        </joint>

    

        <link name = "knuckle_RF">

            <pose frame=''>0.010999999999999996 0.0461 1.48727 -0.698132 0 0</pose>
            <inertial>
                <pose frame=''>0 0 0 0 0 0</pose>
                <mass>0.008</mass>
                <inertia>
                    <ixx>2.6e-07</ixx>
                    <ixy>0</ixy>
                    <ixz>0</ixz>
                    <iyy>2.6e-07</iyy>
                    <iyz>0</iyz>
                    <izz>3.2e-07</izz>
                </inertia>
            </inertial>

            <visual name='visual_knuckle_link_RF'>

                <geometry>
                    <mesh>
                        <scale>0.001 0.001 0.001</scale>
                        <uri>/home/mamad/hand_RL_ws/src/iiwa_pybullet_integration/Training/kuka_handlit/kuka_handlit/envs/kuka_handlit_model/meshes/knuckle.dae</uri>
                    </mesh>
                </geometry>
                <material>
                    <ambient>0.3897990879308091 0.40237589963469356 0.7957828485512505 1</ambient>
                    <diffuse>0.7882518830163517 0.6887973929315642 0.5810917597886689 1</diffuse>
                    <specular>0.8907038915618307 0.2819949841256125 0.12930675134306502 1</specular>
                    <emissive>0 0 0 0</emissive>
                </material>
            </visual>
            <collision name='collision_knuckle_link_RF'>
                <geometry>
                <mesh>
                    <scale>0.001 0.001 0.001</scale>
                    <uri>/home/mamad/hand_RL_ws/src/iiwa_pybullet_integration/Training/kuka_handlit/kuka_handlit/envs/kuka_handlit_model/meshes/knuckle.dae</uri>
                </mesh>
            </geometry>
            </collision>
        </link>
        <link name = "proximal_RF">
            <pose frame=''>0.010999999999999996 0.0461 1.48727 -0.698132 0 0</pose>
            <inertial>
                <pose frame=''>0 0 0.0225 0 0 0</pose>
                <mass>0.03</mass>
                <inertia>
                    <ixx>9.8e-06</ixx>
                    <ixy>0</ixy>
                    <ixz>0</ixz>
                    <iyy>1.0e-05</iyy>
                    <iyz>0</iyz>
                    <izz>1.8e-06</izz>
                </inertia>
            </inertial>

            <visual name='visual_proximal_link_RF'>

                <geometry>
                    <mesh>
                        <scale>0.001 0.001 0.001</scale>
                        <uri>/home/mamad/hand_RL_ws/src/iiwa_pybullet_integration/Training/kuka_handlit/kuka_handlit/envs/kuka_handlit_model/meshes/F3.dae</uri>
                    </mesh>
                </geometry>
                <material>
                    <ambient>0.38143280289471737 0.3289402174142657 0.01907294870776477 1</ambient>
                    <diffuse>0.9348130844908454 0.6516220445476829 0.004152863423997455 1</diffuse>
                    <specular>0.9093648057951567 0.47591190758752233 0.5033166564630196 1</specular>
                    <emissive>0 0 0 0</emissive>
                </material>
            </visual>
            <collision name='collision_proximal_link_RF'>
                <geometry>
                <mesh>
                    <scale>0.001 0.001 0.001</scale>
                    <uri>/home/mamad/hand_RL_ws/src/iiwa_pybullet_integration/Training/kuka_handlit/kuka_handlit/envs/kuka_handlit_model/meshes/F3_c.dae</uri>
                </mesh>
            </geometry>
            </collision>
        </link>
        <link name = "middle_RF">
            <pose frame=''>0.010999999999999996 0.07499 1.521746 -0.698132 0 0</pose>
            <inertial>
                <pose frame=''>0 0 0.0125 0 0 0</pose>
                <mass>0.017</mass>
                <inertia>
                    <ixx>2.6e-06</ixx>
                    <ixy>0</ixy>
                    <ixz>0</ixz>
                    <iyy>2.7e-06</iyy>
                    <iyz>0</iyz>
                    <izz>8.7e-07</izz>
                </inertia>
            </inertial>

            <visual name='visual_middle_link_RF'>

                <geometry>
                    <mesh>
                        <scale>0.001 0.001 0.001</scale>
                        <uri>/home/mamad/hand_RL_ws/src/iiwa_pybullet_integration/Training/kuka_handlit/kuka_handlit/envs/kuka_handlit_model/meshes/F2.dae</uri>
                    </mesh>
                </geometry>
                <material>
                    <ambient>0.8857529221269986 0.4804729626543388 0.6497157810425427 1</ambient>
                    <diffuse>0.5243179746655996 0.21699367520605417 0.08838954888655759 1</diffuse>
                    <specular>0.7686200840790285 0.9102960277990962 0.9451760935133815 1</specular>
                    <emissive>0 0 0 0</emissive>
                </material>
            </visual>
            <collision name='collision_middle_link_RF'>
                <geometry>
                    <mesh>
                        <scale>0.001 0.001 0.001</scale>
                        <uri>/home/mamad/hand_RL_ws/src/iiwa_pybullet_integration/Training/kuka_handlit/kuka_handlit/envs/kuka_handlit_model/meshes/F2_c.dae</uri>
                    </mesh>
                </geometry>
            </collision>
        </link>
        <link name =  "distal_RF">
            <pose frame=''>0.010999999999999996 0.09106 1.540897 -0.698132 0 0</pose>
            <inertial>
                <pose frame=''>0 0 0.012 0 0 0</pose>
                <mass>0.012</mass>
                <inertia>
                    <ixx>9.4e-07</ixx>
                    <ixy>0</ixy>
                    <ixz>0</ixz>
                    <iyy>1.1e-06</iyy>
                    <iyz>0</iyz>
                    <izz>5.3e-07</izz>
                </inertia>
            </inertial>

            <visual name='visual_distal_link_RF'>

                <geometry>
                    <mesh>
                        <scale>0.001 0.001 0.001</scale>
                        <uri>/home/mamad/hand_RL_ws/src/iiwa_pybullet_integration/Training/kuka_handlit/kuka_handlit/envs/kuka_handlit_model/meshes/F1.dae</uri>
                    </mesh>
                </geometry>
                <material>
                    <ambient>0.2854276792349477 0.0776045394517847 0.39546252447208885 1</ambient>
                    <diffuse>0.8381144054193668 0.03836595010378463 0.541573566641211 1</diffuse>
                    <specular>0.22749595719719484 0.5082847839132307 0.6817716182470605 1</specular>
                    <emissive>0 0 0 0</emissive>
                </material>
            </visual>
            <collision name='collision_distal_link_RF'>
                <geometry>
                    <mesh>
                        <scale>0.001 0.001 0.001</scale>
                        <uri>/home/mamad/hand_RL_ws/src/iiwa_pybullet_integration/Training/kuka_handlit/kuka_handlit/envs/kuka_handlit_model/meshes/F1.dae</uri>
                    </mesh>
                </geometry>
            </collision>
        </link>

        
            
            <joint name="J3_RF" type="revolute">
                <child>proximal_RF</child>
                <parent>knuckle_RF</parent>

                <axis>
                    <xyz>1 0 0</xyz>
                    <limit>
                        <lower>0 </lower>
                        <upper>1.5708 </upper>
                        <effort>2.0 </effort>
                        <velocity>2.0 </velocity>
                    </limit>
                    <dynamics>
                        <damping>0.1</damping>
                        <friction>0</friction>
                        <spring_reference>0</spring_reference>
                        <spring_stiffness>0</spring_stiffness>
                    </dynamics>
                </axis>
            </joint>
        
            
            <joint name="J2_RF" type="revolute">
                <child>middle_RF</child>
                <parent>proximal_RF</parent>

                <axis>
                    <xyz>1 0 0</xyz>
                    <limit>
                        <lower>0 </lower>
                        <upper>1.5708 </upper>
                        <effort>2.0 </effort>
                        <velocity>2.0 </velocity>
                    </limit>
                    <dynamics>
                        <damping>0.1</damping>
                        <friction>0</friction>
                        <spring_reference>0</spring_reference>
                        <spring_stiffness>0</spring_stiffness>
                    </dynamics>
                </axis>
            </joint>
        
            
            <joint name="J1_RF" type="revolute">
                <child>distal_RF</child>
                <parent>middle_RF</parent>

                <axis>
                    <xyz>1 0 0</xyz>
                    <limit>
                        <lower>0 </lower>
                        <upper>1.5708 </upper>
                        <effort>2.0 </effort>
                        <velocity>2.0 </velocity>
                    </limit>
                    <dynamics>
                        <damping>0.1</damping>
                        <friction>0</friction>
                        <spring_reference>0</spring_reference>
                        <spring_stiffness>0</spring_stiffness>
                    </dynamics>
                </axis>
            </joint>
        
        <joint name='J4_RF' type="revolute">
            <child>knuckle_RF</child>
            <parent>palm</parent>

            <axis>
                <xyz>0 0.766044 -0.642788</xyz>
                <limit>
                    <lower>-0.349066 </lower>
                    <upper>0.349066 </upper>
                    <effort>2.0 </effort>
                    <velocity>2.0 </velocity>
                </limit>
                <dynamics>
                    <damping>0.1</damping>
                    <friction>0</friction>
                    <spring_reference>0</spring_reference>
                    <spring_stiffness>0</spring_stiffness>
                </dynamics>
            </axis>
        </joint>

    


    <link name = "thbase">
        <pose frame=''>-0.034 -0.0028710000000000003 1.442179 0.870557 0.572429 -2.5703</pose>
        <inertial>
            <pose frame=''>0 0 0 0 0 0</pose>
            <mass>0.01</mass>
            <inertia>
                <ixx>1.6e-07</ixx>
                <ixy>0</ixy>
                <ixz>0</ixz>
                <iyy>1.6e-07</iyy>
                <iyz>0</iyz>
                <izz>1.6e-07</izz>
            </inertia>
        </inertial>
        <visual name='visual_thbase_link'>
            
            <geometry>
                <box>
                    <size>0.001 0.001 0.001</size>
                </box>
            </geometry>
            <material>
                <ambient>0.4066514770564892 0.9709570007350858 0.6694482802574214 1</ambient>
                <diffuse>0.13810151492078993 0.14617574408119127 0.017868227782951607 1</diffuse>
                <specular>0.6311750144180934 0.799130299430009 0.502613479676914 1</specular>
                <emissive>0 0 0 0</emissive>
            </material>
        </visual>
        <collision name='collision_thbase_link'>
            <pose frame=''>0 0 0 0 0 0</pose>
            <geometry>

                <sphere>
                    <radius>0.011</radius>
                </sphere>
            
            </geometry>
        </collision>
    </link>
    <link name = "thproximal">
            
        <pose frame=''>-0.034 -0.0028710000000000003 1.442179 0.870557 0.572429 -2.5703</pose>
        <inertial>
            <pose frame=''>0 0 0.021111 0 0 0</pose>
            <mass>0.04</mass>
            <inertia>
                <ixx>1.36e-05</ixx>
                <ixy>0</ixy>
                <ixz>0</ixz>
                <iyy>1.36e-05</iyy>
                <iyz>0</iyz>
                <izz>3.13e-06</izz>
            </inertia>
        </inertial>

        <visual name='visual_thproximal_link'>
            
            <geometry>
                <mesh>
                    <scale>0.001 0.001 0.001</scale>
                    <uri>/home/mamad/hand_RL_ws/src/iiwa_pybullet_integration/Training/kuka_handlit/kuka_handlit/envs/kuka_handlit_model/meshes/TH3_z.dae</uri>
                </mesh>
            </geometry>
            <material>
                <ambient>0.7524062774567564 0.8454424604682191 0.9574713617633925 1</ambient>
                <diffuse>0.15845288880505604 0.37478494547288 0.9551348103654532 1</diffuse>
                <specular>0.684502549160446 0.7796957534332425 0.783939178719036 1</specular>
                <emissive>0 0 0 0</emissive>
            </material>
        </visual>
        <collision name='collision_thproximal_link'>
            <geometry>
                <mesh>
                    <scale>0.001 0.001 0.001</scale>
                    <uri>/home/mamad/hand_RL_ws/src/iiwa_pybullet_integration/Training/kuka_handlit/kuka_handlit/envs/kuka_handlit_model/meshes/TH3_z_c.dae</uri>
                </mesh>
            </geometry>
        </collision>
    </link>
    <link name = "thhub">
        <pose frame=''>-0.06087000000000001 0.014400999999999999 1.462763 0.870557 0.572429 -2.5703</pose>
        <inertial>
            <pose frame=''>0 0 0 0 0 0</pose>
            <mass>0.005</mass>
            <inertia>
                <ixx>1.0e-06</ixx>
                <ixy>0</ixy>
                <ixz>0</ixz>
                <iyy>1.0e-06</iyy>
                <iyz>0</iyz>
                <izz>3.0e-07</izz>
            </inertia>
        </inertial>
        <visual name='visual_thhub_link'>
            
            <geometry>
                <box>
                    <size>0.001 0.001 0.001</size>
                </box>
            </geometry>
            <material>

            </material>
        </visual>
        <collision name='collision_thhub_link'>
            <geometry>
                <box>
                    <size>0.001 0.001 0.001</size>
                </box>
            </geometry>
        </collision>
    </link>
    <link name = "thmiddle">
            
        <pose frame=''>-0.06087000000000001 0.014400999999999999 1.462763 0.870557 0.572429 -2.5703</pose>
        <inertial>
            <pose frame=''>0 0 0.16 0 0 0</pose>
            <mass>0.02</mass>
            <inertia>
                <ixx>5.1e-06</ixx>
                <ixy>0</ixy>
                <ixz>0</ixz>
                <iyy>5.1e-06</iyy>
                <iyz>0</iyz>
                <izz>1.21e-06</izz>
            </inertia>
        </inertial>

        <visual name='visual_thmiddle_link'>
            
            <geometry>
                <mesh>
                    <scale>0.001 0.001 0.001</scale>
                    <uri>/home/mamad/hand_RL_ws/src/iiwa_pybullet_integration/Training/kuka_handlit/kuka_handlit/envs/kuka_handlit_model/meshes/TH2_z.dae</uri>
                </mesh>
            </geometry>
            <material>
                <ambient>0.7178306415374487 0.7343261238653883 0.294416696252788 1</ambient>
                <diffuse>0.9229007096407251 0.6679332119948269 0.17599650935524958 1</diffuse>
                <specular>0.5250989299771538 0.6525643250326857 0.5985260291695738 1</specular>
                <emissive>0 0 0 0</emissive>
            </material>
        </visual>

        <collision name='collision_thmiddle_link'>
            <geometry>
                <mesh>
                    <scale>0.001 0.001 0.001</scale>
                    <uri>/home/mamad/hand_RL_ws/src/iiwa_pybullet_integration/Training/kuka_handlit/kuka_handlit/envs/kuka_handlit_model/meshes/TH2_z_c.dae</uri>
                </mesh>
            </geometry>
        </collision>
    </link>
    <link name = "thdistal">
            
        <pose frame=''>-0.083498 0.028946 1.480096 -0.785398 0.698132 1.5707999999999998</pose>
        <inertial>
            <pose frame=''>0 0 0.014559 0 0 0</pose>
            <mass>0.016</mass>
            <inertia>
                <ixx>2.1e-06</ixx>
                <ixy>0</ixy>
                <ixz>0</ixz>
                <iyy>2.2e-06</iyy>
                <iyz>0</iyz>
                <izz>1.0e-06</izz>
            </inertia>
        </inertial>

        <visual name='visual_thdistal_link'>
            
            <geometry>
                <mesh>
                    <scale>0.001 0.001 0.001</scale>
                    <uri>/home/mamad/hand_RL_ws/src/iiwa_pybullet_integration/Training/kuka_handlit/kuka_handlit/envs/kuka_handlit_model/meshes/TH1_z.dae</uri>
                </mesh>
            </geometry>
            <material>
                <ambient>0.41608399946176045 0.7773886450603091 0.015132587104755069 1</ambient>
                <diffuse>0.6549988903979924 0.8743652172211523 0.5774131152967948 1</diffuse>
                <specular>0.8213778255856892 0.7154251504419811 0.14606746000321646 1</specular>
                <emissive>0 0 0 0</emissive>
            </material>
        </visual>
        <collision name='collision_thdistal_link'>
            <geometry>
                <mesh>
                    <scale>0.001 0.001 0.001</scale>
                    <uri>/home/mamad/hand_RL_ws/src/iiwa_pybullet_integration/Training/kuka_handlit/kuka_handlit/envs/kuka_handlit_model/meshes/TH1_z.dae</uri>
                </mesh>
            </geometry>
        </collision>
    </link>

    
        <joint name ="THJ5"  type ="revolute">
            <child>thbase</child>
            <parent>palm</parent>
            <axis>
                <xyz>0 0 0.541675</xyz>
                <limit>
                    <lower>-1.0472 </lower>
                    <upper>1.0472 </upper>
                    <effort>5.0 </effort>
                    <velocity>4.0 </velocity>
                </limit>
                <dynamics>
                    <damping>0.2</damping>
                    <friction>0</friction>
                </dynamics>
            </axis>
        </joint>
    
        <joint name ="THJ4"  type ="revolute">
            <child>thproximal</child>
            <parent>thbase</parent>
            <axis>
                <xyz>-0.707107 -0.454519 -0.541675</xyz>
                <limit>
                    <lower>0 </lower>
                    <upper>1.22173 </upper>
                    <effort>3.0 </effort>
                    <velocity>4.0 </velocity>
                </limit>
                <dynamics>
                    <damping>0.2</damping>
                    <friction>0</friction>
                </dynamics>
            </axis>
        </joint>
    
        <joint name ="THJ2"  type ="revolute">
            <child>thmiddle</child>
            <parent>thhub</parent>
            <axis>
                <xyz>0 -0.766044 0.642788</xyz>
                <limit>
                    <lower>-0.698132 </lower>
                    <upper>0.698132 </upper>
                    <effort>2.0 </effort>
                    <velocity>2.0 </velocity>
                </limit>
                <dynamics>
                    <damping>0.1</damping>
                    <friction>0</friction>
                </dynamics>
            </axis>
        </joint>
    
        <joint name ="THJ1"  type ="revolute">
            <child>thdistal</child>
            <parent>thmiddle</parent>
            <axis>
                <xyz>0 -0.766044 0.642788</xyz>
                <limit>
                    <lower>0 </lower>
                    <upper>1.5708 </upper>
                    <effort>1.0 </effort>
                    <velocity>4.0 </velocity>
                </limit>
                <dynamics>
                    <damping>0.2</damping>
                    <friction>0</friction>
                </dynamics>
            </axis>
        </joint>
    
    <joint name ="THJ3"  type ="fixed">
        <child>thhub</child>
        <parent>thproximal</parent>
        <axis>
            <xyz>1 0 0</xyz>
        </axis>
    </joint>






 
   
  </model>

</sdf>