<?xml version="1.0" ?>



<sdf version='1.6'>
  <model name="kuka_handlit">
    <!--KUKA-->
    <link name = "world">
        <pose frame=''>0 0 0 0 0 0</pose>
        <inertial>
            <pose frame=''>0 0 0.0 0 0 0</pose>
            <mass>0.0</mass>
            <inertia>
                <ixx>0.</ixx>
                <ixy>0</ixy>
                <ixz>0</ixz>
                <iyy>0.</iyy>
                <iyz>0</iyz>
                <izz>0.</izz>
            </inertia>
        </inertial>
    </link>
    <joint name="world" type="fixed">
        <child>lbr_iiwa_link_0</child>
        <parent>world</parent>
    </joint>
    
      <link name="lbr_iiwa_link_0">
        <pose frame=''>0 0 0 0 0 0</pose>
        <inertial>
            <pose frame=''>-0.1 0 0.07 0 0 0</pose>
            <mass>5</mass>
            <inertia>
                <ixx>0.05</ixx>
                <ixy>0</ixy>
                <ixz>0</ixz>
                <iyy>0.06</iyy>
                <iyz>0</iyz>
                <izz>0.03</izz>
            </inertia>
        </inertial>
        <collision name='lbr_iiwa_link_0_collision'>
          <pose frame=''>0 0 0 0 -0 0</pose>
          <geometry>
            <mesh>
              
              <scale>1 1 1</scale>
              <uri>meshes/kuka/collision/link_0.stl</uri>
              
            </mesh>
          </geometry>
        </collision>
        <visual name='lbr_iiwa_link_0_visual'>
          <pose frame=''>0 0 0 0 -0 0</pose>
          <geometry>
            <mesh>
              <scale>1 1 1</scale>
              <uri>meshes/kuka/visual/link_0.stl</uri>
            </mesh>
          </geometry>
          <material>
            <ambient>0.3367399614617729 0.7414331802625604 0.40570997643654094 1</ambient>
            <diffuse>0.9162245096086706 0.5665492166409747 0.03746744971782989 1</diffuse>
            <specular>0.22509477542553968 0.04753205724439924 0.8782283143365941 1</specular>
            <emissive>0 0 0 0</emissive>
          </material>
        </visual>
      </link>
    
      <link name="lbr_iiwa_link_1">
        <pose frame=''>0 0 0.1575 0 0 0</pose>
        <inertial>
            <pose frame=''>0 -0.03 0.12 0 0 0</pose>
            <mass>3.4525</mass>
            <inertia>
                <ixx>0.02183</ixx>
                <ixy>0</ixy>
                <ixz>0</ixz>
                <iyy>0.007703</iyy>
                <iyz>-0.003887</iyz>
                <izz>0.02083</izz>
            </inertia>
        </inertial>
        <collision name='lbr_iiwa_link_1_collision'>
          <pose frame=''>0 0 0 0 -0 0</pose>
          <geometry>
            <mesh>
              
              <scale>1 1 1</scale>
              <uri>meshes/kuka/collision/link_1.stl</uri>
              
            </mesh>
          </geometry>
        </collision>
        <visual name='lbr_iiwa_link_1_visual'>
          <pose frame=''>0 0 0 0 -0 0</pose>
          <geometry>
            <mesh>
              <scale>1 1 1</scale>
              <uri>meshes/kuka/visual/link_1.stl</uri>
            </mesh>
          </geometry>
          <material>
            <ambient>0.3676838283447742 0.7147572932094733 0.21453007423920878 1</ambient>
            <diffuse>0.06809110657541362 0.43508772755744296 0.6567709052628188 1</diffuse>
            <specular>0.6036097767517847 0.7174493320806896 0.48894615316175727 1</specular>
            <emissive>0 0 0 0</emissive>
          </material>
        </visual>
      </link>
    
      <link name="lbr_iiwa_link_2">
        <pose frame=''>0 0 0.34 1.5708 0 -3.14159</pose>
        <inertial>
            <pose frame=''>0.0003 0.059 0.042 0 0 0</pose>
            <mass>3.4821</mass>
            <inertia>
                <ixx>0.02076</ixx>
                <ixy>0</ixy>
                <ixz>0.003626</ixz>
                <iyy>0.02179</iyy>
                <iyz>0</iyz>
                <izz>0.00779</izz>
            </inertia>
        </inertial>
        <collision name='lbr_iiwa_link_2_collision'>
          <pose frame=''>0 0 0 0 -0 0</pose>
          <geometry>
            <mesh>
              
              <scale>1 1 1</scale>
              <uri>meshes/kuka/collision/link_2.stl</uri>
              
            </mesh>
          </geometry>
        </collision>
        <visual name='lbr_iiwa_link_2_visual'>
          <pose frame=''>0 0 0 0 -0 0</pose>
          <geometry>
            <mesh>
              <scale>1 1 1</scale>
              <uri>meshes/kuka/visual/link_2.stl</uri>
            </mesh>
          </geometry>
          <material>
            <ambient>0.132792471668006 0.7070971258539145 0.9373547913900974 1</ambient>
            <diffuse>0.3942301742859382 0.9370923542306061 0.19050016105410816 1</diffuse>
            <specular>0.26660151582933256 0.0816029643055094 0.858532308006913 1</specular>
            <emissive>0 0 0 0</emissive>
          </material>
        </visual>
      </link>
    
      <link name="lbr_iiwa_link_3">
        <pose frame=''>0 0 0.524 0 0 0</pose>
        <inertial>
            <pose frame=''>0 0.03 0.13 0 0 0</pose>
            <mass>4.05623</mass>
            <inertia>
                <ixx>0.03204</ixx>
                <ixy>0</ixy>
                <ixz>0</ixz>
                <iyy>0.00972</iyy>
                <iyz>0.006227</iyz>
                <izz>0.03042</izz>
            </inertia>
        </inertial>
        <collision name='lbr_iiwa_link_3_collision'>
          <pose frame=''>0 0 0 0 -0 0</pose>
          <geometry>
            <mesh>
              
              <scale>1 1 1</scale>
              <uri>meshes/kuka/collision/link_3.stl</uri>
              
            </mesh>
          </geometry>
        </collision>
        <visual name='lbr_iiwa_link_3_visual'>
          <pose frame=''>0 0 0 0 -0 0</pose>
          <geometry>
            <mesh>
              <scale>1 1 1</scale>
              <uri>meshes/kuka/visual/link_3.stl</uri>
            </mesh>
          </geometry>
          <material>
            <ambient>0.31271097834082173 0.5803736845398528 0.5098008236448861 1</ambient>
            <diffuse>0.10950989864334637 0.6017530018816065 0.25237453183300484 1</diffuse>
            <specular>0.4734351132280217 0.7273863742298214 0.7319564340228216 1</specular>
            <emissive>0 0 0 0</emissive>
          </material>
        </visual>
      </link>
    
      <link name="lbr_iiwa_link_4">
        <pose frame=''>0 0 0.74 1.5708 0 0</pose>
        <inertial>
            <pose frame=''>0 0.067 0.034 0 0 0</pose>
            <mass>3.4822</mass>
            <inertia>
                <ixx>0.02178</ixx>
                <ixy>0</ixy>
                <ixz>0</ixz>
                <iyy>0.02075</iyy>
                <iyz>-0.003625</iyz>
                <izz>0.007785</izz>
            </inertia>
        </inertial>
        <collision name='lbr_iiwa_link_4_collision'>
          <pose frame=''>0 0 0 0 -0 0</pose>
          <geometry>
            <mesh>
              
              <scale>1 1 1</scale>
              <uri>meshes/kuka/collision/link_4.stl</uri>
              
            </mesh>
          </geometry>
        </collision>
        <visual name='lbr_iiwa_link_4_visual'>
          <pose frame=''>0 0 0 0 -0 0</pose>
          <geometry>
            <mesh>
              <scale>1 1 1</scale>
              <uri>meshes/kuka/visual/link_4.stl</uri>
            </mesh>
          </geometry>
          <material>
            <ambient>0.9164542299502111 0.7853076024965244 0.2228232683462834 1</ambient>
            <diffuse>0.2520001493898394 0.0252364260249196 0.3378811417667926 1</diffuse>
            <specular>0.8631345676085618 0.38090882436275675 0.6772826097757653 1</specular>
            <emissive>0 0 0 0</emissive>
          </material>
        </visual>
      </link>
    
      <link name="lbr_iiwa_link_5">
        <pose frame=''>0 0 0.9239999999999999 0 0 -3.14159</pose>
        <inertial>
            <pose frame=''>0.0001 0.021 0.076 0 0 0</pose>
            <mass>2.1633</mass>
            <inertia>
                <ixx>0.01287</ixx>
                <ixy>0</ixy>
                <ixz>0</ixz>
                <iyy>0.005708</iyy>
                <iyz>-0.003946</iyz>
                <izz>0.01112</izz>
            </inertia>
        </inertial>
        <collision name='lbr_iiwa_link_5_collision'>
          <pose frame=''>0 0 0 0 -0 0</pose>
          <geometry>
            <mesh>
              
              <scale>1 1 1</scale>
              <uri>meshes/kuka/collision/link_5.stl</uri>
              
            </mesh>
          </geometry>
        </collision>
        <visual name='lbr_iiwa_link_5_visual'>
          <pose frame=''>0 0 0 0 -0 0</pose>
          <geometry>
            <mesh>
              <scale>1 1 1</scale>
              <uri>meshes/kuka/visual/link_5.stl</uri>
            </mesh>
          </geometry>
          <material>
            <ambient>0.5321849023235071 0.042808305907034216 0.4560824422397254 1</ambient>
            <diffuse>0.31873693809192216 0.9247953160776298 0.01629908063437513 1</diffuse>
            <specular>0.38738319931109555 0.35244440956230294 0.9783248865894361 1</specular>
            <emissive>0 0 0 0</emissive>
          </material>
        </visual>
      </link>
    
      <link name="lbr_iiwa_link_6">
        <pose frame=''>0 -0.0607 1.14 1.5708 0 -3.14159</pose>
        <inertial>
            <pose frame=''>0 0.0006 0.0004 0 0 0</pose>
            <mass>2.3466</mass>
            <inertia>
                <ixx>0.006509</ixx>
                <ixy>0</ixy>
                <ixz>0</ixz>
                <iyy>0.006259</iyy>
                <iyz>0.00031891</iyz>
                <izz>0.004527</izz>
            </inertia>
        </inertial>
        <collision name='lbr_iiwa_link_6_collision'>
          <pose frame=''>0 0 0 0 -0 0</pose>
          <geometry>
            <mesh>
              
              <scale>1 1 1</scale>
              <uri>meshes/kuka/collision/link_6.stl</uri>
              
            </mesh>
          </geometry>
        </collision>
        <visual name='lbr_iiwa_link_6_visual'>
          <pose frame=''>0 0 0 0 -0 0</pose>
          <geometry>
            <mesh>
              <scale>1 1 1</scale>
              <uri>meshes/kuka/visual/link_6.stl</uri>
            </mesh>
          </geometry>
          <material>
            <ambient>0.015602484766856106 0.1459067209509255 0.9176545757718714 1</ambient>
            <diffuse>0.07874111507651127 0.286544123125129 0.4764587634006837 1</diffuse>
            <specular>0.8744338001556777 0.8424887274653808 0.7131000909956022 1</specular>
            <emissive>0 0 0 0</emissive>
          </material>
        </visual>
      </link>
    
      <link name="lbr_iiwa_link_7">
        <pose frame=''>0 0 1.2205000000000001 0 0 0</pose>
        <inertial>
            <pose frame=''>0 0.00043 0.071108 0 0 0</pose>
            <mass>3.129</mass>
            <inertia>
                <ixx>0.145258</ixx>
                <ixy>0.0005912</ixy>
                <ixz>0</ixz>
                <iyy>0.145283</iyy>
                <iyz>-0.000503009</iyz>
                <izz>0.0572184</izz>
            </inertia>
        </inertial>
        <collision name='lbr_iiwa_link_7_collision'>
          <pose frame=''>0 0 0 0 -0 0</pose>
          <geometry>
            <mesh>
              
              <scale>1 1 1</scale>
              <uri>meshes/kuka/collision/link_7.stl</uri>
              
            </mesh>
          </geometry>
        </collision>
        <visual name='lbr_iiwa_link_7_visual'>
          <pose frame=''>0 0 0 0 -0 0</pose>
          <geometry>
            <mesh>
              <scale>1 1 1</scale>
              <uri>meshes/kuka/visual/link_7.stl</uri>
            </mesh>
          </geometry>
          <material>
            <ambient>0.6589558862013887 0.5135497767564464 0.6485866070948216 1</ambient>
            <diffuse>0.04137381206812385 0.4441415495585319 0.5212042065130861 1</diffuse>
            <specular>0.9123542609391112 0.9692797688612402 0.7136833284947544 1</specular>
            <emissive>0 0 0 0</emissive>
          </material>
        </visual>
      </link>
    
   
    
      <joint name="J0" type="revolute">
        <child>lbr_iiwa_link_1</child>
        <parent>lbr_iiwa_link_0</parent>
        <axis>
          <xyz>0 0 1</xyz>
          <limit>
            <lower>-2.96706</lower>
            <upper>2.96706</upper>
            <effort>300</effort>
            <velocity>10</velocity>
          </limit>
          <dynamics>
            <damping>0.5</damping>
            <friction>0</friction>
            <spring_reference>0</spring_reference>
            <spring_stiffness>0</spring_stiffness>
          </dynamics>
        </axis>
      </joint>
    
      <joint name="J1" type="revolute">
        <child>lbr_iiwa_link_2</child>
        <parent>lbr_iiwa_link_1</parent>
        <axis>
          <xyz>0 0 1</xyz>
          <limit>
            <lower>-2.0944</lower>
            <upper>2.0944</upper>
            <effort>300</effort>
            <velocity>10</velocity>
          </limit>
          <dynamics>
            <damping>0.5</damping>
            <friction>0</friction>
            <spring_reference>0</spring_reference>
            <spring_stiffness>0</spring_stiffness>
          </dynamics>
        </axis>
      </joint>
    
      <joint name="J2" type="revolute">
        <child>lbr_iiwa_link_3</child>
        <parent>lbr_iiwa_link_2</parent>
        <axis>
          <xyz>0 0 1</xyz>
          <limit>
            <lower>-2.96706</lower>
            <upper>2.96706</upper>
            <effort>300</effort>
            <velocity>10</velocity>
          </limit>
          <dynamics>
            <damping>0.5</damping>
            <friction>0</friction>
            <spring_reference>0</spring_reference>
            <spring_stiffness>0</spring_stiffness>
          </dynamics>
        </axis>
      </joint>
    
      <joint name="J3" type="revolute">
        <child>lbr_iiwa_link_4</child>
        <parent>lbr_iiwa_link_3</parent>
        <axis>
          <xyz>0 0 1</xyz>
          <limit>
            <lower>-2.0944</lower>
            <upper>2.0944</upper>
            <effort>300</effort>
            <velocity>10</velocity>
          </limit>
          <dynamics>
            <damping>0.5</damping>
            <friction>0</friction>
            <spring_reference>0</spring_reference>
            <spring_stiffness>0</spring_stiffness>
          </dynamics>
        </axis>
      </joint>
    
      <joint name="J4" type="revolute">
        <child>lbr_iiwa_link_5</child>
        <parent>lbr_iiwa_link_4</parent>
        <axis>
          <xyz>0 0 1</xyz>
          <limit>
            <lower>-2.96706</lower>
            <upper>2.96706</upper>
            <effort>300</effort>
            <velocity>10</velocity>
          </limit>
          <dynamics>
            <damping>0.5</damping>
            <friction>0</friction>
            <spring_reference>0</spring_reference>
            <spring_stiffness>0</spring_stiffness>
          </dynamics>
        </axis>
      </joint>
    
      <joint name="J5" type="revolute">
        <child>lbr_iiwa_link_6</child>
        <parent>lbr_iiwa_link_5</parent>
        <axis>
          <xyz>0 0 1</xyz>
          <limit>
            <lower>-2.0944</lower>
            <upper>2.0944</upper>
            <effort>300</effort>
            <velocity>10</velocity>
          </limit>
          <dynamics>
            <damping>0.5</damping>
            <friction>0</friction>
            <spring_reference>0</spring_reference>
            <spring_stiffness>0</spring_stiffness>
          </dynamics>
        </axis>
      </joint>
    
      <joint name="J6" type="revolute">
        <child>lbr_iiwa_link_7</child>
        <parent>lbr_iiwa_link_6</parent>
        <axis>
          <xyz>0 0 1</xyz>
          <limit>
            <lower>-3.05433</lower>
            <upper>3.05433</upper>
            <effort>300</effort>
            <velocity>10</velocity>
          </limit>
          <dynamics>
            <damping>0.5</damping>
            <friction>0</friction>
            <spring_reference>0</spring_reference>
            <spring_stiffness>0</spring_stiffness>
          </dynamics>
        </axis>
      </joint>
    

    <link name = "lbr_iiwa_link_ee">

        <pose frame=''>0 0 1.2655 0 0 0</pose>
        <inertial>
            <pose frame=''>0 0.00043 0.071108 0 0 0</pose>
            <mass>1.0e-22</mass>
            <inertia>
                <ixx>0.145258</ixx>
                <ixy>0.0005912</ixy>
                <ixz>0</ixz>
                <iyy>0.145283</iyy>
                <iyz>-0.000503009</iyz>
                <izz>0.0572184</izz>
            </inertia>
        </inertial>
            <visual name='visual_lbr_iiwa_link_ee'>
                <geometry>
                    <sphere>
                    <radius>0.01</radius>
                    </sphere>
                </geometry>
                <material>
                    <ambient>0.5672216218105076 0.531815859282997 0.5801439037594547 1</ambient>
                    <diffuse>0.5464167892541046 0.6932951350253517 0.22253023363722557 1</diffuse>
                    <specular>0.9022550019258972 0.9029306286118689 0.5969458319897258 1</specular>
                    <emissive>0 0 0 0</emissive>
                </material>
            </visual>
    </link>
    
    <joint name="J7" type="fixed">
        <child>lbr_iiwa_link_ee</child>
        <parent>lbr_iiwa_link_7</parent>
        <axis>

            <xyz>0 -1 0</xyz>
         </axis>
    </joint>  
    <!--Hand-->

    <joint name="forearm_world" type="fixed">
        <child>forearm</child>
        <parent>lbr_iiwa_link_ee</parent>
    </joint>

    <link name ="forearm" >
        <pose frame=''>0 0 1.2655 0 0 1.5707963267948966</pose>
        <inertial>
            <pose frame=''>0 0 0.09 0 0 0</pose>
            <mass>1.8</mass>
            <inertia>
                <ixx>0.108</ixx>
                <ixy>0</ixy>
                <ixz>0</ixz>
                <iyy>0.108</iyy>
                <iyz>0</iyz>
                <izz>0.054</izz>
            </inertia>
        </inertial>

        <visual name='visual_forearm_link'>

            <geometry>
                <mesh>
                    <scale>1 1 1</scale>
                    <uri>meshes/forearm_lite.dae</uri>
                </mesh>
            </geometry>
            <material>
                <ambient>0.8462405766151607 0.8086480856248766 0.9679670756484364 1</ambient>
                <diffuse>0.07947083800924148 0.4210169187052112 0.13304673362025699 1</diffuse>
                <specular>0.12115210880836325 0.701985749525643 0.8275936389322843 1</specular>
                <emissive>0 0 0 0</emissive>
            </material>
        </visual>
        <collision name='collision_forearm_link'>
        
            <geometry>
                <mesh>
                    <scale>1 1 1</scale>
                    <uri>meshes/forearm_lite.dae</uri>
                </mesh>
            </geometry>
        </collision>
    </link>

    <link name = "palm">
        <pose frame=''>0 -0.015 1.4145 -0.6981317007977318 0 0</pose>
        <inertial>
            <pose frame=''>0 0 0.035 0 0 0</pose>
            <mass>0.3</mass>
            <inertia>
                <ixx>0.0003581</ixx>
                <ixy>0</ixy>
                <ixz>0</ixz>
                <iyy>0.0005287</iyy>
                <iyz>0</iyz>
                <izz>0.000191</izz>
            </inertia>
        </inertial>
        
        <visual name='visual_palm_link'>

            <geometry>
                <mesh>
                    <scale>-0.001 0.001 0.001</scale>
                    <uri>meshes/palm2.dae</uri>
                </mesh>
            </geometry>
            <material>
                <ambient>0.24858535218297617 0.34119533927412216 0.08010254409723472 1</ambient>
                <diffuse>0.13296176708870877 0.6862308755356751 0.2675585327269441 1</diffuse>
                <specular>0.9130287708895869 0.1358021430443217 0.3218158568070173 1</specular>
                <emissive>0 0 0 0</emissive>
            </material>
        </visual>
        <collision name="collision_palm_link">

            <geometry>
                <mesh>
                    <scale>-0.001 0.001 0.001</scale>
                <uri>meshes/palm5_c.dae</uri>
            </mesh>
            </geometry>
        </collision>


        
    </link>
    <joint name="palm_forearm" type="fixed">
        <child>palm</child>
        <parent>forearm</parent>
        <axis>

            <xyz>0 -1 0</xyz>
         </axis>
    </joint>  

    
    <link name = "palm_fake">

        <pose frame=''>-0.01 0.020909000000000004 1.4544000000000001 -0.6981317007977318 0 0</pose>
        <inertial>
            <pose frame=''>0 0 0.0 0 0 0</pose>
            <mass>0.0</mass>
            <inertia>
                <ixx>0.0</ixx>
                <ixy>0</ixy>
                <ixz>0</ixz>
                <iyy>0.0</iyy>
                <iyz>0</iyz>
                <izz>0.0</izz>
            </inertia>
        </inertial>
            <visual name='visual_palm_fake'>
                <geometry>
                    <sphere>
                    <radius>0.01</radius>
                    </sphere>
                </geometry>
                <material>
                    <ambient>0.5672216218105076 0.531815859282997 0.5801439037594547 1</ambient>
                    <diffuse>0.5464167892541046 0.6932951350253517 0.22253023363722557 1</diffuse>
                    <specular>0.9022550019258972 0.9029306286118689 0.5969458319897258 1</specular>
                    <emissive>0 0 0 0</emissive>
                </material>
            </visual>
    </link>

    <joint name="palm_palm_fake" type="fixed">
        <child>palm_fake</child>
        <parent>palm</parent>
        <axis>

            <xyz>0 -1 0</xyz>
         </axis>
    </joint>  

    

        <link name = "knuckle_FF">

            <pose frame=''>-0.033 0.0461 1.48727 -0.698132 0 0</pose>
            <inertial>
                <pose frame=''>0 0 0 0 0 0</pose>
                <mass>0.008</mass>
                <inertia>
                    <ixx>2.6e-07</ixx>
                    <ixy>0</ixy>
                    <ixz>0</ixz>
                    <iyy>2.6e-07</iyy>
                    <iyz>0</iyz>
                    <izz>3.2e-07</izz>
                </inertia>
            </inertial>

            <visual name='visual_knuckle_link_FF'>

                <geometry>
                    <mesh>
                        <scale>0.001 0.001 0.001</scale>
                        <uri>meshes/knuckle.dae</uri>
                    </mesh>
                </geometry>
                <material>
                    <ambient>0.44761287473313005 0.582031862046245 0.14209197618719316 1</ambient>
                    <diffuse>0.08699630145349635 0.820685556309175 0.2714793949162245 1</diffuse>
                    <specular>0.980210470722176 0.37056543972026024 0.6942645036234143 1</specular>
                    <emissive>0 0 0 0</emissive>
                </material>
            </visual>
            <collision name='collision_knuckle_link_FF'>
                <geometry>
                <mesh>
                    <scale>0.001 0.001 0.001</scale>
                    <uri>meshes/knuckle.dae</uri>
                </mesh>
            </geometry>
            </collision>
        </link>
        <link name = "proximal_FF">
            <pose frame=''>-0.033 0.0461 1.48727 -0.698132 0 0</pose>
            <inertial>
                <pose frame=''>0 0 0.0225 0 0 0</pose>
                <mass>0.03</mass>
                <inertia>
                    <ixx>9.8e-06</ixx>
                    <ixy>0</ixy>
                    <ixz>0</ixz>
                    <iyy>1.0e-05</iyy>
                    <iyz>0</iyz>
                    <izz>1.8e-06</izz>
                </inertia>
            </inertial>

            <visual name='visual_proximal_link_FF'>

                <geometry>
                    <mesh>
                        <scale>0.001 0.001 0.001</scale>
                        <uri>meshes/F3.dae</uri>
                    </mesh>
                </geometry>
                <material>
                    <ambient>0.8285972664634467 0.5501642312135296 0.9680893672283098 1</ambient>
                    <diffuse>0.03513114786561222 0.4960871911176059 0.4482981606468712 1</diffuse>
                    <specular>0.5231902072283844 0.6477025719038838 0.07841678414780329 1</specular>
                    <emissive>0 0 0 0</emissive>
                </material>
            </visual>
            <collision name='collision_proximal_link_FF'>
                <geometry>
                <mesh>
                    <scale>0.001 0.001 0.001</scale>
                    <uri>meshes/F3_c.dae</uri>
                </mesh>
            </geometry>
            </collision>
        </link>
        <link name = "middle_FF">
            <pose frame=''>-0.033 0.07499 1.521746 -0.698132 0 0</pose>
            <inertial>
                <pose frame=''>0 0 0.0125 0 0 0</pose>
                <mass>0.017</mass>
                <inertia>
                    <ixx>2.6e-06</ixx>
                    <ixy>0</ixy>
                    <ixz>0</ixz>
                    <iyy>2.7e-06</iyy>
                    <iyz>0</iyz>
                    <izz>8.7e-07</izz>
                </inertia>
            </inertial>

            <visual name='visual_middle_link_FF'>

                <geometry>
                    <mesh>
                        <scale>0.001 0.001 0.001</scale>
                        <uri>meshes/F2.dae</uri>
                    </mesh>
                </geometry>
                <material>
                    <ambient>0.07824542795593581 0.7018841473118799 0.919062249370691 1</ambient>
                    <diffuse>0.7075916011913964 0.5761243614084942 0.024579113656221563 1</diffuse>
                    <specular>0.33491822841368857 0.005705114129016864 0.36784338947662465 1</specular>
                    <emissive>0 0 0 0</emissive>
                </material>
            </visual>
            <collision name='collision_middle_link_FF'>
                <geometry>
                    <mesh>
                        <scale>0.001 0.001 0.001</scale>
                        <uri>meshes/F2_c.dae</uri>
                    </mesh>
                </geometry>
            </collision>
        </link>
        <link name =  "distal_FF">
            <pose frame=''>-0.033 0.09106 1.540897 -0.698132 0 0</pose>
            <inertial>
                <pose frame=''>0 0 0.012 0 0 0</pose>
                <mass>0.012</mass>
                <inertia>
                    <ixx>9.4e-07</ixx>
                    <ixy>0</ixy>
                    <ixz>0</ixz>
                    <iyy>1.1e-06</iyy>
                    <iyz>0</iyz>
                    <izz>5.3e-07</izz>
                </inertia>
            </inertial>

            <visual name='visual_distal_link_FF'>

                <geometry>
                    <mesh>
                        <scale>0.001 0.001 0.001</scale>
                        <uri>meshes/F1.dae</uri>
                    </mesh>
                </geometry>
                <material>
                    <ambient>0.8943604373194574 0.16732986179794396 0.4049885131416958 1</ambient>
                    <diffuse>0.45777200935844975 0.7945025517920716 0.7007388395570585 1</diffuse>
                    <specular>0.16142265704454395 0.4868478071493161 0.9331773983549567 1</specular>
                    <emissive>0 0 0 0</emissive>
                </material>
            </visual>
            <collision name='collision_distal_link_FF'>
                <geometry>
                    <mesh>
                        <scale>0.001 0.001 0.001</scale>
                        <uri>meshes/F1.dae</uri>
                    </mesh>
                </geometry>
            </collision>
        </link>

        
            
            <joint name="J3_FF" type="revolute">
                <child>proximal_FF</child>
                <parent>knuckle_FF</parent>

                <axis>
                    <xyz>1 0 0</xyz>
                    <limit>
                        <lower>0 </lower>
                        <upper>1.5708 </upper>
                        <effort>6.0 </effort>
                        <velocity>0.8 </velocity>
                    </limit>
                    <dynamics>
                        <damping>0.1</damping>
                        <friction>0</friction>
                        <spring_reference>0</spring_reference>
                        <spring_stiffness>0</spring_stiffness>
                    </dynamics>
                </axis>
            </joint>
        
            
            <joint name="J2_FF" type="revolute">
                <child>middle_FF</child>
                <parent>proximal_FF</parent>

                <axis>
                    <xyz>1 0 0</xyz>
                    <limit>
                        <lower>0 </lower>
                        <upper>1.5708 </upper>
                        <effort>6.0 </effort>
                        <velocity>0.8 </velocity>
                    </limit>
                    <dynamics>
                        <damping>0.1</damping>
                        <friction>0</friction>
                        <spring_reference>0</spring_reference>
                        <spring_stiffness>0</spring_stiffness>
                    </dynamics>
                </axis>
            </joint>
        
            
            <joint name="J1_FF" type="revolute">
                <child>distal_FF</child>
                <parent>middle_FF</parent>

                <axis>
                    <xyz>1 0 0</xyz>
                    <limit>
                        <lower>0 </lower>
                        <upper>1.5708 </upper>
                        <effort>6.0 </effort>
                        <velocity>0.8 </velocity>
                    </limit>
                    <dynamics>
                        <damping>0.1</damping>
                        <friction>0</friction>
                        <spring_reference>0</spring_reference>
                        <spring_stiffness>0</spring_stiffness>
                    </dynamics>
                </axis>
            </joint>
        
        <joint name='J4_FF' type="revolute">
            <child>knuckle_FF</child>
            <parent>palm</parent>

            <axis>
                <xyz>0 0.766044 -0.642788</xyz>
                <limit>
                    <lower>-0.349066 </lower>
                    <upper>0.349066 </upper>
                    <effort>6.0 </effort>
                    <velocity>0.8 </velocity>
                </limit>
                <dynamics>
                    <damping>0.1</damping>
                    <friction>0</friction>
                    <spring_reference>0</spring_reference>
                    <spring_stiffness>0</spring_stiffness>
                </dynamics>
            </axis>
        </joint>

    

        <link name = "knuckle_MF">

            <pose frame=''>-0.011000000000000003 0.048636 1.4903380000000002 -0.698132 0 0</pose>
            <inertial>
                <pose frame=''>0 0 0 0 0 0</pose>
                <mass>0.008</mass>
                <inertia>
                    <ixx>2.6e-07</ixx>
                    <ixy>0</ixy>
                    <ixz>0</ixz>
                    <iyy>2.6e-07</iyy>
                    <iyz>0</iyz>
                    <izz>3.2e-07</izz>
                </inertia>
            </inertial>

            <visual name='visual_knuckle_link_MF'>

                <geometry>
                    <mesh>
                        <scale>0.001 0.001 0.001</scale>
                        <uri>meshes/knuckle.dae</uri>
                    </mesh>
                </geometry>
                <material>
                    <ambient>0.9241459201554139 0.9455169358013608 0.32689130810626443 1</ambient>
                    <diffuse>0.06475862904159457 0.3307740853500488 0.6420630619266952 1</diffuse>
                    <specular>0.6355398697064741 0.45932455435029296 0.5082041503579314 1</specular>
                    <emissive>0 0 0 0</emissive>
                </material>
            </visual>
            <collision name='collision_knuckle_link_MF'>
                <geometry>
                <mesh>
                    <scale>0.001 0.001 0.001</scale>
                    <uri>meshes/knuckle.dae</uri>
                </mesh>
            </geometry>
            </collision>
        </link>
        <link name = "proximal_MF">
            <pose frame=''>-0.011000000000000003 0.048636 1.4903380000000002 -0.698132 0 0</pose>
            <inertial>
                <pose frame=''>0 0 0.0225 0 0 0</pose>
                <mass>0.03</mass>
                <inertia>
                    <ixx>9.8e-06</ixx>
                    <ixy>0</ixy>
                    <ixz>0</ixz>
                    <iyy>1.0e-05</iyy>
                    <iyz>0</iyz>
                    <izz>1.8e-06</izz>
                </inertia>
            </inertial>

            <visual name='visual_proximal_link_MF'>

                <geometry>
                    <mesh>
                        <scale>0.001 0.001 0.001</scale>
                        <uri>meshes/F3.dae</uri>
                    </mesh>
                </geometry>
                <material>
                    <ambient>0.6483684299427129 0.15364769792697985 0.04915958491244632 1</ambient>
                    <diffuse>0.7845207030624126 0.41176125840562416 0.9258732210693401 1</diffuse>
                    <specular>0.7719212901791926 0.8701433132067687 0.18341607610009336 1</specular>
                    <emissive>0 0 0 0</emissive>
                </material>
            </visual>
            <collision name='collision_proximal_link_MF'>
                <geometry>
                <mesh>
                    <scale>0.001 0.001 0.001</scale>
                    <uri>meshes/F3_c.dae</uri>
                </mesh>
            </geometry>
            </collision>
        </link>
        <link name = "middle_MF">
            <pose frame=''>-0.011000000000000003 0.077526 1.5248140000000001 -0.698132 0 0</pose>
            <inertial>
                <pose frame=''>0 0 0.0125 0 0 0</pose>
                <mass>0.017</mass>
                <inertia>
                    <ixx>2.6e-06</ixx>
                    <ixy>0</ixy>
                    <ixz>0</ixz>
                    <iyy>2.7e-06</iyy>
                    <iyz>0</iyz>
                    <izz>8.7e-07</izz>
                </inertia>
            </inertial>

            <visual name='visual_middle_link_MF'>

                <geometry>
                    <mesh>
                        <scale>0.001 0.001 0.001</scale>
                        <uri>meshes/F2.dae</uri>
                    </mesh>
                </geometry>
                <material>
                    <ambient>0.5897563975117571 0.7049409711490382 0.05695634600478694 1</ambient>
                    <diffuse>0.8828010257478518 0.4040791087409211 0.039687419930376944 1</diffuse>
                    <specular>0.0014686066171147871 0.06149475955132855 0.25837143759353054 1</specular>
                    <emissive>0 0 0 0</emissive>
                </material>
            </visual>
            <collision name='collision_middle_link_MF'>
                <geometry>
                    <mesh>
                        <scale>0.001 0.001 0.001</scale>
                        <uri>meshes/F2_c.dae</uri>
                    </mesh>
                </geometry>
            </collision>
        </link>
        <link name =  "distal_MF">
            <pose frame=''>-0.011000000000000003 0.093596 1.543965 -0.698132 0 0</pose>
            <inertial>
                <pose frame=''>0 0 0.012 0 0 0</pose>
                <mass>0.012</mass>
                <inertia>
                    <ixx>9.4e-07</ixx>
                    <ixy>0</ixy>
                    <ixz>0</ixz>
                    <iyy>1.1e-06</iyy>
                    <iyz>0</iyz>
                    <izz>5.3e-07</izz>
                </inertia>
            </inertial>

            <visual name='visual_distal_link_MF'>

                <geometry>
                    <mesh>
                        <scale>0.001 0.001 0.001</scale>
                        <uri>meshes/F1.dae</uri>
                    </mesh>
                </geometry>
                <material>
                    <ambient>0.019872644039839238 0.03912872318888938 0.37498517793714825 1</ambient>
                    <diffuse>0.9939495636223032 0.2016552632915224 0.38353688499660266 1</diffuse>
                    <specular>0.46920265682162887 0.16636937064708168 0.5911028317558269 1</specular>
                    <emissive>0 0 0 0</emissive>
                </material>
            </visual>
            <collision name='collision_distal_link_MF'>
                <geometry>
                    <mesh>
                        <scale>0.001 0.001 0.001</scale>
                        <uri>meshes/F1.dae</uri>
                    </mesh>
                </geometry>
            </collision>
        </link>

        
            
            <joint name="J3_MF" type="revolute">
                <child>proximal_MF</child>
                <parent>knuckle_MF</parent>

                <axis>
                    <xyz>1 0 0</xyz>
                    <limit>
                        <lower>0 </lower>
                        <upper>1.5708 </upper>
                        <effort>6.0 </effort>
                        <velocity>0.8 </velocity>
                    </limit>
                    <dynamics>
                        <damping>0.1</damping>
                        <friction>0</friction>
                        <spring_reference>0</spring_reference>
                        <spring_stiffness>0</spring_stiffness>
                    </dynamics>
                </axis>
            </joint>
        
            
            <joint name="J2_MF" type="revolute">
                <child>middle_MF</child>
                <parent>proximal_MF</parent>

                <axis>
                    <xyz>1 0 0</xyz>
                    <limit>
                        <lower>0 </lower>
                        <upper>1.5708 </upper>
                        <effort>6.0 </effort>
                        <velocity>0.8 </velocity>
                    </limit>
                    <dynamics>
                        <damping>0.1</damping>
                        <friction>0</friction>
                        <spring_reference>0</spring_reference>
                        <spring_stiffness>0</spring_stiffness>
                    </dynamics>
                </axis>
            </joint>
        
            
            <joint name="J1_MF" type="revolute">
                <child>distal_MF</child>
                <parent>middle_MF</parent>

                <axis>
                    <xyz>1 0 0</xyz>
                    <limit>
                        <lower>0 </lower>
                        <upper>1.5708 </upper>
                        <effort>6.0 </effort>
                        <velocity>0.8 </velocity>
                    </limit>
                    <dynamics>
                        <damping>0.1</damping>
                        <friction>0</friction>
                        <spring_reference>0</spring_reference>
                        <spring_stiffness>0</spring_stiffness>
                    </dynamics>
                </axis>
            </joint>
        
        <joint name='J4_MF' type="revolute">
            <child>knuckle_MF</child>
            <parent>palm</parent>

            <axis>
                <xyz>0 0.766044 -0.642788</xyz>
                <limit>
                    <lower>-0.349066 </lower>
                    <upper>0.349066 </upper>
                    <effort>6.0 </effort>
                    <velocity>0.8 </velocity>
                </limit>
                <dynamics>
                    <damping>0.1</damping>
                    <friction>0</friction>
                    <spring_reference>0</spring_reference>
                    <spring_stiffness>0</spring_stiffness>
                </dynamics>
            </axis>
        </joint>

    

        <link name = "knuckle_RF">

            <pose frame=''>0.010999999999999996 0.0461 1.48727 -0.698132 0 0</pose>
            <inertial>
                <pose frame=''>0 0 0 0 0 0</pose>
                <mass>0.008</mass>
                <inertia>
                    <ixx>2.6e-07</ixx>
                    <ixy>0</ixy>
                    <ixz>0</ixz>
                    <iyy>2.6e-07</iyy>
                    <iyz>0</iyz>
                    <izz>3.2e-07</izz>
                </inertia>
            </inertial>

            <visual name='visual_knuckle_link_RF'>

                <geometry>
                    <mesh>
                        <scale>0.001 0.001 0.001</scale>
                        <uri>meshes/knuckle.dae</uri>
                    </mesh>
                </geometry>
                <material>
                    <ambient>0.8858436075415228 0.6660039244103632 0.1394950747389868 1</ambient>
                    <diffuse>0.6924482217087503 0.47063679732868235 0.7942407622048315 1</diffuse>
                    <specular>0.5191513312116104 0.5691347816207535 0.5561468255417495 1</specular>
                    <emissive>0 0 0 0</emissive>
                </material>
            </visual>
            <collision name='collision_knuckle_link_RF'>
                <geometry>
                <mesh>
                    <scale>0.001 0.001 0.001</scale>
                    <uri>meshes/knuckle.dae</uri>
                </mesh>
            </geometry>
            </collision>
        </link>
        <link name = "proximal_RF">
            <pose frame=''>0.010999999999999996 0.0461 1.48727 -0.698132 0 0</pose>
            <inertial>
                <pose frame=''>0 0 0.0225 0 0 0</pose>
                <mass>0.03</mass>
                <inertia>
                    <ixx>9.8e-06</ixx>
                    <ixy>0</ixy>
                    <ixz>0</ixz>
                    <iyy>1.0e-05</iyy>
                    <iyz>0</iyz>
                    <izz>1.8e-06</izz>
                </inertia>
            </inertial>

            <visual name='visual_proximal_link_RF'>

                <geometry>
                    <mesh>
                        <scale>0.001 0.001 0.001</scale>
                        <uri>meshes/F3.dae</uri>
                    </mesh>
                </geometry>
                <material>
                    <ambient>0.8282163735541653 0.212256290509515 0.2545684372986182 1</ambient>
                    <diffuse>0.5809828091531676 0.647964776898653 0.08640955629875291 1</diffuse>
                    <specular>0.024383461145647822 0.1377067698901142 0.9133052826456225 1</specular>
                    <emissive>0 0 0 0</emissive>
                </material>
            </visual>
            <collision name='collision_proximal_link_RF'>
                <geometry>
                <mesh>
                    <scale>0.001 0.001 0.001</scale>
                    <uri>meshes/F3_c.dae</uri>
                </mesh>
            </geometry>
            </collision>
        </link>
        <link name = "middle_RF">
            <pose frame=''>0.010999999999999996 0.07499 1.521746 -0.698132 0 0</pose>
            <inertial>
                <pose frame=''>0 0 0.0125 0 0 0</pose>
                <mass>0.017</mass>
                <inertia>
                    <ixx>2.6e-06</ixx>
                    <ixy>0</ixy>
                    <ixz>0</ixz>
                    <iyy>2.7e-06</iyy>
                    <iyz>0</iyz>
                    <izz>8.7e-07</izz>
                </inertia>
            </inertial>

            <visual name='visual_middle_link_RF'>

                <geometry>
                    <mesh>
                        <scale>0.001 0.001 0.001</scale>
                        <uri>meshes/F2.dae</uri>
                    </mesh>
                </geometry>
                <material>
                    <ambient>0.949822500821519 0.2572216171251829 0.2441405144420674 1</ambient>
                    <diffuse>0.6634803725666846 0.7452481081757626 0.7675249759469359 1</diffuse>
                    <specular>0.8609413509229288 0.2842742516957534 0.5412465764026907 1</specular>
                    <emissive>0 0 0 0</emissive>
                </material>
            </visual>
            <collision name='collision_middle_link_RF'>
                <geometry>
                    <mesh>
                        <scale>0.001 0.001 0.001</scale>
                        <uri>meshes/F2_c.dae</uri>
                    </mesh>
                </geometry>
            </collision>
        </link>
        <link name =  "distal_RF">
            <pose frame=''>0.010999999999999996 0.09106 1.540897 -0.698132 0 0</pose>
            <inertial>
                <pose frame=''>0 0 0.012 0 0 0</pose>
                <mass>0.012</mass>
                <inertia>
                    <ixx>9.4e-07</ixx>
                    <ixy>0</ixy>
                    <ixz>0</ixz>
                    <iyy>1.1e-06</iyy>
                    <iyz>0</iyz>
                    <izz>5.3e-07</izz>
                </inertia>
            </inertial>

            <visual name='visual_distal_link_RF'>

                <geometry>
                    <mesh>
                        <scale>0.001 0.001 0.001</scale>
                        <uri>meshes/F1.dae</uri>
                    </mesh>
                </geometry>
                <material>
                    <ambient>0.3544069676337859 0.7451066688348225 0.3111059033554311 1</ambient>
                    <diffuse>0.643902128659518 0.7268328476940501 0.06013241917633916 1</diffuse>
                    <specular>0.4483351840790777 0.5171935535233495 0.9762892560655339 1</specular>
                    <emissive>0 0 0 0</emissive>
                </material>
            </visual>
            <collision name='collision_distal_link_RF'>
                <geometry>
                    <mesh>
                        <scale>0.001 0.001 0.001</scale>
                        <uri>meshes/F1.dae</uri>
                    </mesh>
                </geometry>
            </collision>
        </link>

        
            
            <joint name="J3_RF" type="revolute">
                <child>proximal_RF</child>
                <parent>knuckle_RF</parent>

                <axis>
                    <xyz>1 0 0</xyz>
                    <limit>
                        <lower>0 </lower>
                        <upper>1.5708 </upper>
                        <effort>6.0 </effort>
                        <velocity>0.8 </velocity>
                    </limit>
                    <dynamics>
                        <damping>0.1</damping>
                        <friction>0</friction>
                        <spring_reference>0</spring_reference>
                        <spring_stiffness>0</spring_stiffness>
                    </dynamics>
                </axis>
            </joint>
        
            
            <joint name="J2_RF" type="revolute">
                <child>middle_RF</child>
                <parent>proximal_RF</parent>

                <axis>
                    <xyz>1 0 0</xyz>
                    <limit>
                        <lower>0 </lower>
                        <upper>1.5708 </upper>
                        <effort>6.0 </effort>
                        <velocity>0.8 </velocity>
                    </limit>
                    <dynamics>
                        <damping>0.1</damping>
                        <friction>0</friction>
                        <spring_reference>0</spring_reference>
                        <spring_stiffness>0</spring_stiffness>
                    </dynamics>
                </axis>
            </joint>
        
            
            <joint name="J1_RF" type="revolute">
                <child>distal_RF</child>
                <parent>middle_RF</parent>

                <axis>
                    <xyz>1 0 0</xyz>
                    <limit>
                        <lower>0 </lower>
                        <upper>1.5708 </upper>
                        <effort>6.0 </effort>
                        <velocity>0.8 </velocity>
                    </limit>
                    <dynamics>
                        <damping>0.1</damping>
                        <friction>0</friction>
                        <spring_reference>0</spring_reference>
                        <spring_stiffness>0</spring_stiffness>
                    </dynamics>
                </axis>
            </joint>
        
        <joint name='J4_RF' type="revolute">
            <child>knuckle_RF</child>
            <parent>palm</parent>

            <axis>
                <xyz>0 0.766044 -0.642788</xyz>
                <limit>
                    <lower>-0.349066 </lower>
                    <upper>0.349066 </upper>
                    <effort>6.0 </effort>
                    <velocity>0.8 </velocity>
                </limit>
                <dynamics>
                    <damping>0.1</damping>
                    <friction>0</friction>
                    <spring_reference>0</spring_reference>
                    <spring_stiffness>0</spring_stiffness>
                </dynamics>
            </axis>
        </joint>

    


    <link name = "thbase">
        <pose frame=''>-0.034 -0.0028710000000000003 1.442179 0.870557 0.572429 -2.5703</pose>
        <inertial>
            <pose frame=''>0 0 0 0 0 0</pose>
            <mass>0.01</mass>
            <inertia>
                <ixx>1.6e-07</ixx>
                <ixy>0</ixy>
                <ixz>0</ixz>
                <iyy>1.6e-07</iyy>
                <iyz>0</iyz>
                <izz>1.6e-07</izz>
            </inertia>
        </inertial>
        <visual name='visual_thbase_link'>
            
            <geometry>
                <box>
                    <size>0.001 0.001 0.001</size>
                </box>
            </geometry>
            <material>
                <ambient>0.5988530601885489 0.8315048649970432 0.14418352802495182 1</ambient>
                <diffuse>0.3490197232019263 0.5743144258250429 0.01135580658615809 1</diffuse>
                <specular>0.9392259338108638 0.5676428845839995 0.02531172780815838 1</specular>
                <emissive>0 0 0 0</emissive>
            </material>
        </visual>
        <collision name='collision_thbase_link'>
            <pose frame=''>0 0 0 0 0 0</pose>
            <geometry>

                <sphere>
                    <radius>0.005</radius>
                </sphere>
            
            </geometry>
        </collision>
    </link>
    <link name = "thproximal">
            
        <pose frame=''>-0.034 -0.0028710000000000003 1.442179 0.870557 0.572429 -2.5703</pose>
        <inertial>
            <pose frame=''>0 0 0.021111 0 0 0</pose>
            <mass>0.04</mass>
            <inertia>
                <ixx>1.36e-05</ixx>
                <ixy>0</ixy>
                <ixz>0</ixz>
                <iyy>1.36e-05</iyy>
                <iyz>0</iyz>
                <izz>3.13e-06</izz>
            </inertia>
        </inertial>

        <visual name='visual_thproximal_link'>
            
            <geometry>
                <mesh>
                    <scale>0.001 0.001 0.001</scale>
                    <uri>meshes/TH3_z.dae</uri>
                </mesh>
            </geometry>
            <material>
                <ambient>0.013316980753193763 0.4800364416747631 0.030009927819456106 1</ambient>
                <diffuse>0.12829286815105534 0.8219270094275845 0.8467292385499785 1</diffuse>
                <specular>0.6982610382235869 0.4542297439925529 0.03702075919271741 1</specular>
                <emissive>0 0 0 0</emissive>
            </material>
        </visual>
        <collision name='collision_thproximal_link'>
            <geometry>
                <mesh>
                    <scale>0.001 0.001 0.001</scale>
                    <uri>meshes/TH3_z_c.dae</uri>
                </mesh>
            </geometry>
        </collision>
    </link>
    <link name = "thhub">
        <pose frame=''>-0.06087000000000001 0.014400999999999999 1.462763 0.870557 0.572429 -2.5703</pose>
        <inertial>
            <pose frame=''>0 0 0 0 0 0</pose>
            <mass>0.005</mass>
            <inertia>
                <ixx>1.0e-06</ixx>
                <ixy>0</ixy>
                <ixz>0</ixz>
                <iyy>1.0e-06</iyy>
                <iyz>0</iyz>
                <izz>3.0e-07</izz>
            </inertia>
        </inertial>
        <visual name='visual_thhub_link'>
            
            <geometry>
                <box>
                    <size>0.001 0.001 0.001</size>
                </box>
            </geometry>
            <material>

            </material>
        </visual>
        <collision name='collision_thhub_link'>
            <geometry>
                <box>
                    <size>0.001 0.001 0.001</size>
                </box>
            </geometry>
        </collision>
    </link>
    <link name = "thmiddle">
            
        <pose frame=''>-0.06087000000000001 0.014400999999999999 1.462763 0.870557 0.572429 -2.5703</pose>
        <inertial>
            <pose frame=''>0 0 0.16 0 0 0</pose>
            <mass>0.02</mass>
            <inertia>
                <ixx>5.1e-06</ixx>
                <ixy>0</ixy>
                <ixz>0</ixz>
                <iyy>5.1e-06</iyy>
                <iyz>0</iyz>
                <izz>1.21e-06</izz>
            </inertia>
        </inertial>

        <visual name='visual_thmiddle_link'>
            
            <geometry>
                <mesh>
                    <scale>0.001 0.001 0.001</scale>
                    <uri>meshes/TH2_z.dae</uri>
                </mesh>
            </geometry>
            <material>
                <ambient>0.9780815435960593 0.30670955597595906 0.8417740628239813 1</ambient>
                <diffuse>0.06129841584666851 0.3759417881746583 0.8947081522419466 1</diffuse>
                <specular>0.3738826109473955 0.3150650624449538 0.660207398729264 1</specular>
                <emissive>0 0 0 0</emissive>
            </material>
        </visual>

        <collision name='collision_thmiddle_link'>
            <geometry>
                <mesh>
                    <scale>0.001 0.001 0.001</scale>
                    <uri>meshes/TH2_z_c.dae</uri>
                </mesh>
            </geometry>
        </collision>
    </link>
    <link name = "thdistal">
            
        <pose frame=''>-0.083498 0.028946 1.480096 -0.785398 0.698132 1.5707999999999998</pose>
        <inertial>
            <pose frame=''>0 0 0.014559 0 0 0</pose>
            <mass>0.016</mass>
            <inertia>
                <ixx>2.1e-06</ixx>
                <ixy>0</ixy>
                <ixz>0</ixz>
                <iyy>2.2e-06</iyy>
                <iyz>0</iyz>
                <izz>1.0e-06</izz>
            </inertia>
        </inertial>

        <visual name='visual_thdistal_link'>
            
            <geometry>
                <mesh>
                    <scale>0.001 0.001 0.001</scale>
                    <uri>meshes/TH1_z.dae</uri>
                </mesh>
            </geometry>
            <material>
                <ambient>0.12114380185198237 0.26132821858472055 0.9700723833363697 1</ambient>
                <diffuse>0.3538882200278408 0.40636369857130317 0.8538664829220025 1</diffuse>
                <specular>0.4698368630702595 0.5192529416925025 0.2093220632029772 1</specular>
                <emissive>0 0 0 0</emissive>
            </material>
        </visual>
        <collision name='collision_thdistal_link'>
            <geometry>
                <mesh>
                    <scale>0.001 0.001 0.001</scale>
                    <uri>meshes/TH1_z.dae</uri>
                </mesh>
            </geometry>
        </collision>
    </link>

    
        <joint name ="THJ5"  type ="revolute">
            <child>thbase</child>
            <parent>palm</parent>
            <axis>
                <xyz>0 0 0.541675</xyz>
                <limit>
                    <lower>-1.0472 </lower>
                    <upper>1.0472 </upper>
                    <effort>8.0 </effort>
                    <velocity>0.7 </velocity>
                </limit>
                <dynamics>
                    <damping>0.1</damping>
                    <friction>0</friction>
                </dynamics>
            </axis>
        </joint>
    
        <joint name ="THJ4"  type ="revolute">
            <child>thproximal</child>
            <parent>thbase</parent>
            <axis>
                <xyz>-0.707107 -0.454519 -0.541675</xyz>
                <limit>
                    <lower>0 </lower>
                    <upper>1.22173 </upper>
                    <effort>8.0 </effort>
                    <velocity>0.7 </velocity>
                </limit>
                <dynamics>
                    <damping>0.2</damping>
                    <friction>0</friction>
                </dynamics>
            </axis>
        </joint>
    
        <joint name ="THJ2"  type ="revolute">
            <child>thmiddle</child>
            <parent>thhub</parent>
            <axis>
                <xyz>0 -0.766044 0.642788</xyz>
                <limit>
                    <lower>-0.698132 </lower>
                    <upper>0.698132 </upper>
                    <effort>8.0 </effort>
                    <velocity>0.7 </velocity>
                </limit>
                <dynamics>
                    <damping>0.1</damping>
                    <friction>0</friction>
                </dynamics>
            </axis>
        </joint>
    
        <joint name ="THJ1"  type ="revolute">
            <child>thdistal</child>
            <parent>thmiddle</parent>
            <axis>
                <xyz>1 0 0</xyz>
                <limit>
                    <lower>0 </lower>
                    <upper>1.5708 </upper>
                    <effort>8.0 </effort>
                    <velocity>0.7 </velocity>
                </limit>
                <dynamics>
                    <damping>0.2</damping>
                    <friction>0</friction>
                </dynamics>
            </axis>
        </joint>
    
    <joint name ="THJ3"  type ="fixed">
        <child>thhub</child>
        <parent>thproximal</parent>
        <axis>
            <xyz>1 0 0</xyz>
        </axis>
    </joint>






 
   
  </model>

</sdf>