<?xml version="1.0" ?>



<sdf version='1.6'>
  <model name="kuka_handlit">
    <!--KUKA-->
    <link name = "world">
        <pose frame=''>0 0 0 0 0 0</pose>
        <inertial>
            <pose frame=''>0 0 0.0 0 0 0</pose>
            <mass>0.0</mass>
            <inertia>
                <ixx>0.</ixx>
                <ixy>0</ixy>
                <ixz>0</ixz>
                <iyy>0.</iyy>
                <iyz>0</iyz>
                <izz>0.</izz>
            </inertia>
        </inertial>
    </link>
    <joint name="world" type="fixed">
        <child>lbr_iiwa_link_0</child>
        <parent>world</parent>
    </joint>
    
      <link name="lbr_iiwa_link_0">
        <pose frame=''>0 0 0 0 0 0</pose>
        <inertial>
            <pose frame=''>-0.1 0 0.07 0 0 0</pose>
            <mass>5</mass>
            <inertia>
                <ixx>0.05</ixx>
                <ixy>0</ixy>
                <ixz>0</ixz>
                <iyy>0.06</iyy>
                <iyz>0</iyz>
                <izz>0.03</izz>
            </inertia>
        </inertial>
        <collision name='lbr_iiwa_link_0_collision'>
          <pose frame=''>0 0 0 0 -0 0</pose>
          <geometry>
            <mesh>
              
              <scale>1 1 1</scale>
              <uri>/home/mamad/hand_RL_ws/src/iiwa_pybullet_integration/Training/kuka_handlit/kuka_handlit/envs/kuka_handlit_model/meshes/kuka/collision/link_0.stl</uri>
              
            </mesh>
          </geometry>
        </collision>
        <visual name='lbr_iiwa_link_0_visual'>
          <pose frame=''>0 0 0 0 -0 0</pose>
          <geometry>
            <mesh>
              <scale>1 1 1</scale>
              <uri>/home/mamad/hand_RL_ws/src/iiwa_pybullet_integration/Training/kuka_handlit/kuka_handlit/envs/kuka_handlit_model/meshes/kuka/visual/link_0.stl</uri>
            </mesh>
          </geometry>
          <material>
            <ambient>0.09982092679158605 0.06430732705276665 0.5441517278100191 1</ambient>
            <diffuse>0.7928354137402459 0.7427246826949092 0.20304066944229016 1</diffuse>
            <specular>0.9747575453412468 0.9285371262323193 0.8399576901001933 1</specular>
            <emissive>0 0 0 0</emissive>
          </material>
        </visual>
      </link>
    
      <link name="lbr_iiwa_link_1">
        <pose frame=''>0 0 0.1575 0 0 0</pose>
        <inertial>
            <pose frame=''>0 -0.03 0.12 0 0 0</pose>
            <mass>3.4525</mass>
            <inertia>
                <ixx>0.02183</ixx>
                <ixy>0</ixy>
                <ixz>0</ixz>
                <iyy>0.007703</iyy>
                <iyz>-0.003887</iyz>
                <izz>0.02083</izz>
            </inertia>
        </inertial>
        <collision name='lbr_iiwa_link_1_collision'>
          <pose frame=''>0 0 0 0 -0 0</pose>
          <geometry>
            <mesh>
              
              <scale>1 1 1</scale>
              <uri>/home/mamad/hand_RL_ws/src/iiwa_pybullet_integration/Training/kuka_handlit/kuka_handlit/envs/kuka_handlit_model/meshes/kuka/collision/link_1.stl</uri>
              
            </mesh>
          </geometry>
        </collision>
        <visual name='lbr_iiwa_link_1_visual'>
          <pose frame=''>0 0 0 0 -0 0</pose>
          <geometry>
            <mesh>
              <scale>1 1 1</scale>
              <uri>/home/mamad/hand_RL_ws/src/iiwa_pybullet_integration/Training/kuka_handlit/kuka_handlit/envs/kuka_handlit_model/meshes/kuka/visual/link_1.stl</uri>
            </mesh>
          </geometry>
          <material>
            <ambient>0.8035419475615483 0.44930974373878185 0.48765176240742913 1</ambient>
            <diffuse>0.8386070012929939 0.0055855295750742995 0.796844612886487 1</diffuse>
            <specular>0.2040552538788395 0.5760774067187461 0.9480190520706837 1</specular>
            <emissive>0 0 0 0</emissive>
          </material>
        </visual>
      </link>
    
      <link name="lbr_iiwa_link_2">
        <pose frame=''>0 0 0.34 1.5708 0 -3.14159</pose>
        <inertial>
            <pose frame=''>0.0003 0.059 0.042 0 0 0</pose>
            <mass>3.4821</mass>
            <inertia>
                <ixx>0.02076</ixx>
                <ixy>0</ixy>
                <ixz>0.003626</ixz>
                <iyy>0.02179</iyy>
                <iyz>0</iyz>
                <izz>0.00779</izz>
            </inertia>
        </inertial>
        <collision name='lbr_iiwa_link_2_collision'>
          <pose frame=''>0 0 0 0 -0 0</pose>
          <geometry>
            <mesh>
              
              <scale>1 1 1</scale>
              <uri>/home/mamad/hand_RL_ws/src/iiwa_pybullet_integration/Training/kuka_handlit/kuka_handlit/envs/kuka_handlit_model/meshes/kuka/collision/link_2.stl</uri>
              
            </mesh>
          </geometry>
        </collision>
        <visual name='lbr_iiwa_link_2_visual'>
          <pose frame=''>0 0 0 0 -0 0</pose>
          <geometry>
            <mesh>
              <scale>1 1 1</scale>
              <uri>/home/mamad/hand_RL_ws/src/iiwa_pybullet_integration/Training/kuka_handlit/kuka_handlit/envs/kuka_handlit_model/meshes/kuka/visual/link_2.stl</uri>
            </mesh>
          </geometry>
          <material>
            <ambient>0.8093967347902027 0.7391150173814187 0.16876782539335133 1</ambient>
            <diffuse>0.8360564134194196 0.9306421956929284 0.7571459367507092 1</diffuse>
            <specular>0.6910911999505522 0.44192973907338995 0.5796001301040447 1</specular>
            <emissive>0 0 0 0</emissive>
          </material>
        </visual>
      </link>
    
      <link name="lbr_iiwa_link_3">
        <pose frame=''>0 0 0.524 0 0 0</pose>
        <inertial>
            <pose frame=''>0 0.03 0.13 0 0 0</pose>
            <mass>4.05623</mass>
            <inertia>
                <ixx>0.03204</ixx>
                <ixy>0</ixy>
                <ixz>0</ixz>
                <iyy>0.00972</iyy>
                <iyz>0.006227</iyz>
                <izz>0.03042</izz>
            </inertia>
        </inertial>
        <collision name='lbr_iiwa_link_3_collision'>
          <pose frame=''>0 0 0 0 -0 0</pose>
          <geometry>
            <mesh>
              
              <scale>1 1 1</scale>
              <uri>/home/mamad/hand_RL_ws/src/iiwa_pybullet_integration/Training/kuka_handlit/kuka_handlit/envs/kuka_handlit_model/meshes/kuka/collision/link_3.stl</uri>
              
            </mesh>
          </geometry>
        </collision>
        <visual name='lbr_iiwa_link_3_visual'>
          <pose frame=''>0 0 0 0 -0 0</pose>
          <geometry>
            <mesh>
              <scale>1 1 1</scale>
              <uri>/home/mamad/hand_RL_ws/src/iiwa_pybullet_integration/Training/kuka_handlit/kuka_handlit/envs/kuka_handlit_model/meshes/kuka/visual/link_3.stl</uri>
            </mesh>
          </geometry>
          <material>
            <ambient>0.5175030939071077 0.6979127710813796 0.6251331381034946 1</ambient>
            <diffuse>0.842381111638176 0.1345857292659033 0.8275798101051064 1</diffuse>
            <specular>0.3135417421864888 0.5255345458301733 0.9730110275164343 1</specular>
            <emissive>0 0 0 0</emissive>
          </material>
        </visual>
      </link>
    
      <link name="lbr_iiwa_link_4">
        <pose frame=''>0 0 0.74 1.5708 0 0</pose>
        <inertial>
            <pose frame=''>0 0.067 0.034 0 0 0</pose>
            <mass>3.4822</mass>
            <inertia>
                <ixx>0.02178</ixx>
                <ixy>0</ixy>
                <ixz>0</ixz>
                <iyy>0.02075</iyy>
                <iyz>-0.003625</iyz>
                <izz>0.007785</izz>
            </inertia>
        </inertial>
        <collision name='lbr_iiwa_link_4_collision'>
          <pose frame=''>0 0 0 0 -0 0</pose>
          <geometry>
            <mesh>
              
              <scale>1 1 1</scale>
              <uri>/home/mamad/hand_RL_ws/src/iiwa_pybullet_integration/Training/kuka_handlit/kuka_handlit/envs/kuka_handlit_model/meshes/kuka/collision/link_4.stl</uri>
              
            </mesh>
          </geometry>
        </collision>
        <visual name='lbr_iiwa_link_4_visual'>
          <pose frame=''>0 0 0 0 -0 0</pose>
          <geometry>
            <mesh>
              <scale>1 1 1</scale>
              <uri>/home/mamad/hand_RL_ws/src/iiwa_pybullet_integration/Training/kuka_handlit/kuka_handlit/envs/kuka_handlit_model/meshes/kuka/visual/link_4.stl</uri>
            </mesh>
          </geometry>
          <material>
            <ambient>0.1448044560452254 0.44704076511666435 0.630224991723628 1</ambient>
            <diffuse>0.1433931723756866 0.13956901081745277 0.608415849072882 1</diffuse>
            <specular>0.27168489308502053 0.7092785171775294 0.4402420152452019 1</specular>
            <emissive>0 0 0 0</emissive>
          </material>
        </visual>
      </link>
    
      <link name="lbr_iiwa_link_5">
        <pose frame=''>0 0 0.9239999999999999 0 0 -3.14159</pose>
        <inertial>
            <pose frame=''>0.0001 0.021 0.076 0 0 0</pose>
            <mass>2.1633</mass>
            <inertia>
                <ixx>0.01287</ixx>
                <ixy>0</ixy>
                <ixz>0</ixz>
                <iyy>0.005708</iyy>
                <iyz>-0.003946</iyz>
                <izz>0.01112</izz>
            </inertia>
        </inertial>
        <collision name='lbr_iiwa_link_5_collision'>
          <pose frame=''>0 0 0 0 -0 0</pose>
          <geometry>
            <mesh>
              
              <scale>1 1 1</scale>
              <uri>/home/mamad/hand_RL_ws/src/iiwa_pybullet_integration/Training/kuka_handlit/kuka_handlit/envs/kuka_handlit_model/meshes/kuka/collision/link_5.stl</uri>
              
            </mesh>
          </geometry>
        </collision>
        <visual name='lbr_iiwa_link_5_visual'>
          <pose frame=''>0 0 0 0 -0 0</pose>
          <geometry>
            <mesh>
              <scale>1 1 1</scale>
              <uri>/home/mamad/hand_RL_ws/src/iiwa_pybullet_integration/Training/kuka_handlit/kuka_handlit/envs/kuka_handlit_model/meshes/kuka/visual/link_5.stl</uri>
            </mesh>
          </geometry>
          <material>
            <ambient>0.6025516719361926 0.3984332272616695 0.03577154361348034 1</ambient>
            <diffuse>0.13448138638905427 0.6726161253837171 0.5879522254046716 1</diffuse>
            <specular>0.7853195487428044 0.4499097540175492 0.1331609172900864 1</specular>
            <emissive>0 0 0 0</emissive>
          </material>
        </visual>
      </link>
    
      <link name="lbr_iiwa_link_6">
        <pose frame=''>0 -0.0607 1.14 1.5708 0 -3.14159</pose>
        <inertial>
            <pose frame=''>0 0.0006 0.0004 0 0 0</pose>
            <mass>2.3466</mass>
            <inertia>
                <ixx>0.006509</ixx>
                <ixy>0</ixy>
                <ixz>0</ixz>
                <iyy>0.006259</iyy>
                <iyz>0.00031891</iyz>
                <izz>0.004527</izz>
            </inertia>
        </inertial>
        <collision name='lbr_iiwa_link_6_collision'>
          <pose frame=''>0 0 0 0 -0 0</pose>
          <geometry>
            <mesh>
              
              <scale>1 1 1</scale>
              <uri>/home/mamad/hand_RL_ws/src/iiwa_pybullet_integration/Training/kuka_handlit/kuka_handlit/envs/kuka_handlit_model/meshes/kuka/collision/link_6.stl</uri>
              
            </mesh>
          </geometry>
        </collision>
        <visual name='lbr_iiwa_link_6_visual'>
          <pose frame=''>0 0 0 0 -0 0</pose>
          <geometry>
            <mesh>
              <scale>1 1 1</scale>
              <uri>/home/mamad/hand_RL_ws/src/iiwa_pybullet_integration/Training/kuka_handlit/kuka_handlit/envs/kuka_handlit_model/meshes/kuka/visual/link_6.stl</uri>
            </mesh>
          </geometry>
          <material>
            <ambient>0.30554539891335697 0.3377095865713967 0.6566192115639864 1</ambient>
            <diffuse>0.6218764761489273 0.03532637441791431 0.3854214205386971 1</diffuse>
            <specular>0.4264408206631719 0.21098388318847772 0.6025725143556274 1</specular>
            <emissive>0 0 0 0</emissive>
          </material>
        </visual>
      </link>
    
      <link name="lbr_iiwa_link_7">
        <pose frame=''>0 0 1.2205000000000001 0 0 0</pose>
        <inertial>
            <pose frame=''>0 0.00043 0.071108 0 0 0</pose>
            <mass>3.129</mass>
            <inertia>
                <ixx>0.145258</ixx>
                <ixy>0.0005912</ixy>
                <ixz>0</ixz>
                <iyy>0.145283</iyy>
                <iyz>-0.000503009</iyz>
                <izz>0.0572184</izz>
            </inertia>
        </inertial>
        <collision name='lbr_iiwa_link_7_collision'>
          <pose frame=''>0 0 0 0 -0 0</pose>
          <geometry>
            <mesh>
              
              <scale>1 1 1</scale>
              <uri>/home/mamad/hand_RL_ws/src/iiwa_pybullet_integration/Training/kuka_handlit/kuka_handlit/envs/kuka_handlit_model/meshes/kuka/collision/link_7.stl</uri>
              
            </mesh>
          </geometry>
        </collision>
        <visual name='lbr_iiwa_link_7_visual'>
          <pose frame=''>0 0 0 0 -0 0</pose>
          <geometry>
            <mesh>
              <scale>1 1 1</scale>
              <uri>/home/mamad/hand_RL_ws/src/iiwa_pybullet_integration/Training/kuka_handlit/kuka_handlit/envs/kuka_handlit_model/meshes/kuka/visual/link_7.stl</uri>
            </mesh>
          </geometry>
          <material>
            <ambient>0.4130351776367057 0.8249987806198549 0.2658539872000073 1</ambient>
            <diffuse>0.4941188188944595 0.11310690251521105 0.2262838681651187 1</diffuse>
            <specular>0.1612778488732436 0.5446308493598492 0.16886666295035768 1</specular>
            <emissive>0 0 0 0</emissive>
          </material>
        </visual>
      </link>
    
   
    
      <joint name="J0" type="revolute">
        <child>lbr_iiwa_link_1</child>
        <parent>lbr_iiwa_link_0</parent>
        <axis>
          <xyz>0 0 1</xyz>
          <limit>
            <lower>-2.96706</lower>
            <upper>2.96706</upper>
            <effort>300</effort>
            <velocity>10</velocity>
          </limit>
          <dynamics>
            <damping>0.5</damping>
            <friction>0</friction>
            <spring_reference>0</spring_reference>
            <spring_stiffness>0</spring_stiffness>
          </dynamics>
        </axis>
      </joint>
    
      <joint name="J1" type="revolute">
        <child>lbr_iiwa_link_2</child>
        <parent>lbr_iiwa_link_1</parent>
        <axis>
          <xyz>0 0 1</xyz>
          <limit>
            <lower>-2.0944</lower>
            <upper>2.0944</upper>
            <effort>300</effort>
            <velocity>10</velocity>
          </limit>
          <dynamics>
            <damping>0.5</damping>
            <friction>0</friction>
            <spring_reference>0</spring_reference>
            <spring_stiffness>0</spring_stiffness>
          </dynamics>
        </axis>
      </joint>
    
      <joint name="J2" type="revolute">
        <child>lbr_iiwa_link_3</child>
        <parent>lbr_iiwa_link_2</parent>
        <axis>
          <xyz>0 0 1</xyz>
          <limit>
            <lower>-2.96706</lower>
            <upper>2.96706</upper>
            <effort>300</effort>
            <velocity>10</velocity>
          </limit>
          <dynamics>
            <damping>0.5</damping>
            <friction>0</friction>
            <spring_reference>0</spring_reference>
            <spring_stiffness>0</spring_stiffness>
          </dynamics>
        </axis>
      </joint>
    
      <joint name="J3" type="revolute">
        <child>lbr_iiwa_link_4</child>
        <parent>lbr_iiwa_link_3</parent>
        <axis>
          <xyz>0 0 1</xyz>
          <limit>
            <lower>-2.0944</lower>
            <upper>2.0944</upper>
            <effort>300</effort>
            <velocity>10</velocity>
          </limit>
          <dynamics>
            <damping>0.5</damping>
            <friction>0</friction>
            <spring_reference>0</spring_reference>
            <spring_stiffness>0</spring_stiffness>
          </dynamics>
        </axis>
      </joint>
    
      <joint name="J4" type="revolute">
        <child>lbr_iiwa_link_5</child>
        <parent>lbr_iiwa_link_4</parent>
        <axis>
          <xyz>0 0 1</xyz>
          <limit>
            <lower>-2.96706</lower>
            <upper>2.96706</upper>
            <effort>300</effort>
            <velocity>10</velocity>
          </limit>
          <dynamics>
            <damping>0.5</damping>
            <friction>0</friction>
            <spring_reference>0</spring_reference>
            <spring_stiffness>0</spring_stiffness>
          </dynamics>
        </axis>
      </joint>
    
      <joint name="J5" type="revolute">
        <child>lbr_iiwa_link_6</child>
        <parent>lbr_iiwa_link_5</parent>
        <axis>
          <xyz>0 0 1</xyz>
          <limit>
            <lower>-2.0944</lower>
            <upper>2.0944</upper>
            <effort>300</effort>
            <velocity>10</velocity>
          </limit>
          <dynamics>
            <damping>0.5</damping>
            <friction>0</friction>
            <spring_reference>0</spring_reference>
            <spring_stiffness>0</spring_stiffness>
          </dynamics>
        </axis>
      </joint>
    
      <joint name="J6" type="revolute">
        <child>lbr_iiwa_link_7</child>
        <parent>lbr_iiwa_link_6</parent>
        <axis>
          <xyz>0 0 1</xyz>
          <limit>
            <lower>-3.05433</lower>
            <upper>3.05433</upper>
            <effort>300</effort>
            <velocity>10</velocity>
          </limit>
          <dynamics>
            <damping>0.5</damping>
            <friction>0</friction>
            <spring_reference>0</spring_reference>
            <spring_stiffness>0</spring_stiffness>
          </dynamics>
        </axis>
      </joint>
    

    <link name = "lbr_iiwa_link_ee">

        <pose frame=''>0 0 1.2655 0 0 0</pose>
        <inertial>
            <pose frame=''>0 0.00043 0.071108 0 0 0</pose>
            <mass>1.0e-22</mass>
            <inertia>
                <ixx>0.145258</ixx>
                <ixy>0.0005912</ixy>
                <ixz>0</ixz>
                <iyy>0.145283</iyy>
                <iyz>-0.000503009</iyz>
                <izz>0.0572184</izz>
            </inertia>
        </inertial>
            <visual name='visual_lbr_iiwa_link_ee'>
                <geometry>
                    <sphere>
                    <radius>0.01</radius>
                    </sphere>
                </geometry>
                <material>
                    <ambient>0.5672216218105076 0.531815859282997 0.5801439037594547 1</ambient>
                    <diffuse>0.5464167892541046 0.6932951350253517 0.22253023363722557 1</diffuse>
                    <specular>0.9022550019258972 0.9029306286118689 0.5969458319897258 1</specular>
                    <emissive>0 0 0 0</emissive>
                </material>
            </visual>
    </link>
    
    <joint name="J7" type="fixed">
        <child>lbr_iiwa_link_ee</child>
        <parent>lbr_iiwa_link_7</parent>
        <axis>

            <xyz>0 -1 0</xyz>
         </axis>
    </joint>  
    <!--Hand-->

    <joint name="forearm_world" type="fixed">
        <child>forearm</child>
        <parent>lbr_iiwa_link_ee</parent>
    </joint>

    <link name ="forearm" >
        <pose frame=''>0 0 1.2655 0 0 1.5707963267948966</pose>
        <inertial>
            <pose frame=''>0 0 0.09 0 0 0</pose>
            <mass>1.8</mass>
            <inertia>
                <ixx>0.108</ixx>
                <ixy>0</ixy>
                <ixz>0</ixz>
                <iyy>0.108</iyy>
                <iyz>0</iyz>
                <izz>0.054</izz>
            </inertia>
        </inertial>

        <visual name='visual_forearm_link'>

            <geometry>
                <mesh>
                    <scale>1 1 1</scale>
                    <uri>/home/mamad/hand_RL_ws/src/iiwa_pybullet_integration/Training/kuka_handlit/kuka_handlit/envs/kuka_handlit_model/meshes/forearm_lite.dae</uri>
                </mesh>
            </geometry>
            <material>
                <ambient>0.7210405712038199 0.849209566207975 0.7842762850461621 1</ambient>
                <diffuse>0.9274032231385696 0.6149382935732248 0.6592687957418542 1</diffuse>
                <specular>0.12522355849418887 0.9002701050203398 0.4470211221985202 1</specular>
                <emissive>0 0 0 0</emissive>
            </material>
        </visual>
        <collision name='collision_forearm_link'>
        
            <geometry>
                <mesh>
                    <scale>1 1 1</scale>
                    <uri>/home/mamad/hand_RL_ws/src/iiwa_pybullet_integration/Training/kuka_handlit/kuka_handlit/envs/kuka_handlit_model/meshes/forearm_lite.dae</uri>
                </mesh>
            </geometry>
        </collision>
    </link>

    <link name = "palm">
        <pose frame=''>0 -0.015 1.4145 -0.6981317007977318 0 0</pose>
        <inertial>
            <pose frame=''>0 0 0.035 0 0 0</pose>
            <mass>0.3</mass>
            <inertia>
                <ixx>0.0003581</ixx>
                <ixy>0</ixy>
                <ixz>0</ixz>
                <iyy>0.0005287</iyy>
                <iyz>0</iyz>
                <izz>0.000191</izz>
            </inertia>
        </inertial>
        
        <visual name='visual_palm_link'>

            <geometry>
                <mesh>
                    <scale>-0.001 0.001 0.001</scale>
                    <uri>/home/mamad/hand_RL_ws/src/iiwa_pybullet_integration/Training/kuka_handlit/kuka_handlit/envs/kuka_handlit_model/meshes/palm2.dae</uri>
                </mesh>
            </geometry>
            <material>
                <ambient>0.46147773965113426 0.06454143573423154 0.2699971686048499 1</ambient>
                <diffuse>0.29025420610548247 0.9298417458012347 0.44072599478395247 1</diffuse>
                <specular>0.7548582328402516 0.9950004903899247 0.27934932280667435 1</specular>
                <emissive>0 0 0 0</emissive>
            </material>
        </visual>
        <collision name="collision_palm_link">

            <geometry>
                <mesh>
                    <scale>-0.001 0.001 0.001</scale>
                <uri>/home/mamad/hand_RL_ws/src/iiwa_pybullet_integration/Training/kuka_handlit/kuka_handlit/envs/kuka_handlit_model/meshes/palm2_c.dae</uri>
            </mesh>
            </geometry>
        </collision>


        
    </link>
    <joint name="palm_forearm" type="fixed">
        <child>palm</child>
        <parent>forearm</parent>
        <axis>

            <xyz>0 -1 0</xyz>
         </axis>
    </joint>  

    
    <link name = "palm_fake">

        <pose frame=''>-0.01 0.020909000000000004 1.4544000000000001 -0.6981317007977318 0 0</pose>
        <inertial>
            <pose frame=''>0 0 0.0 0 0 0</pose>
            <mass>0.0</mass>
            <inertia>
                <ixx>0.0</ixx>
                <ixy>0</ixy>
                <ixz>0</ixz>
                <iyy>0.0</iyy>
                <iyz>0</iyz>
                <izz>0.0</izz>
            </inertia>
        </inertial>
            <visual name='visual_palm_fake'>
                <geometry>
                    <sphere>
                    <radius>0.01</radius>
                    </sphere>
                </geometry>
                <material>
                    <ambient>0.5672216218105076 0.531815859282997 0.5801439037594547 1</ambient>
                    <diffuse>0.5464167892541046 0.6932951350253517 0.22253023363722557 1</diffuse>
                    <specular>0.9022550019258972 0.9029306286118689 0.5969458319897258 1</specular>
                    <emissive>0 0 0 0</emissive>
                </material>
            </visual>
    </link>

    <joint name="palm_palm_fake" type="fixed">
        <child>palm_fake</child>
        <parent>palm</parent>
        <axis>

            <xyz>0 -1 0</xyz>
         </axis>
    </joint>  

    

        <link name = "knuckle_FF">

            <pose frame=''>-0.033 0.0461 1.48727 -0.698132 0 0</pose>
            <inertial>
                <pose frame=''>0 0 0 0 0 0</pose>
                <mass>0.008</mass>
                <inertia>
                    <ixx>2.6e-07</ixx>
                    <ixy>0</ixy>
                    <ixz>0</ixz>
                    <iyy>2.6e-07</iyy>
                    <iyz>0</iyz>
                    <izz>3.2e-07</izz>
                </inertia>
            </inertial>

            <visual name='visual_knuckle_link_FF'>

                <geometry>
                    <mesh>
                        <scale>0.001 0.001 0.001</scale>
                        <uri>/home/mamad/hand_RL_ws/src/iiwa_pybullet_integration/Training/kuka_handlit/kuka_handlit/envs/kuka_handlit_model/meshes/knuckle.dae</uri>
                    </mesh>
                </geometry>
                <material>
                    <ambient>0.5605556142773309 0.5017587001370489 0.8647618500926135 1</ambient>
                    <diffuse>0.5257893745347387 0.21237666008892364 0.0894775597938069 1</diffuse>
                    <specular>0.15619826286547778 0.03963633244429343 0.1782557790389434 1</specular>
                    <emissive>0 0 0 0</emissive>
                </material>
            </visual>
            <collision name='collision_knuckle_link_FF'>
                <geometry>
                <mesh>
                    <scale>0.001 0.001 0.001</scale>
                    <uri>/home/mamad/hand_RL_ws/src/iiwa_pybullet_integration/Training/kuka_handlit/kuka_handlit/envs/kuka_handlit_model/meshes/knuckle.dae</uri>
                </mesh>
            </geometry>
            </collision>
        </link>
        <link name = "proximal_FF">
            <pose frame=''>-0.033 0.0461 1.48727 -0.698132 0 0</pose>
            <inertial>
                <pose frame=''>0 0 0.0225 0 0 0</pose>
                <mass>0.03</mass>
                <inertia>
                    <ixx>9.8e-06</ixx>
                    <ixy>0</ixy>
                    <ixz>0</ixz>
                    <iyy>1.0e-05</iyy>
                    <iyz>0</iyz>
                    <izz>1.8e-06</izz>
                </inertia>
            </inertial>

            <visual name='visual_proximal_link_FF'>

                <geometry>
                    <mesh>
                        <scale>0.001 0.001 0.001</scale>
                        <uri>/home/mamad/hand_RL_ws/src/iiwa_pybullet_integration/Training/kuka_handlit/kuka_handlit/envs/kuka_handlit_model/meshes/F3.dae</uri>
                    </mesh>
                </geometry>
                <material>
                    <ambient>0.13678599769167998 0.05643529725553387 0.6777020362297309 1</ambient>
                    <diffuse>0.029410007460838883 0.28315558228104054 0.6866702810630484 1</diffuse>
                    <specular>0.6822061057353228 0.025068816657379478 0.5794641622708371 1</specular>
                    <emissive>0 0 0 0</emissive>
                </material>
            </visual>
            <collision name='collision_proximal_link_FF'>
                <geometry>
                <mesh>
                    <scale>0.001 0.001 0.001</scale>
                    <uri>/home/mamad/hand_RL_ws/src/iiwa_pybullet_integration/Training/kuka_handlit/kuka_handlit/envs/kuka_handlit_model/meshes/F3_c.dae</uri>
                </mesh>
            </geometry>
            </collision>
        </link>
        <link name = "middle_FF">
            <pose frame=''>-0.033 0.07499 1.521746 -0.698132 0 0</pose>
            <inertial>
                <pose frame=''>0 0 0.0125 0 0 0</pose>
                <mass>0.017</mass>
                <inertia>
                    <ixx>2.6e-06</ixx>
                    <ixy>0</ixy>
                    <ixz>0</ixz>
                    <iyy>2.7e-06</iyy>
                    <iyz>0</iyz>
                    <izz>8.7e-07</izz>
                </inertia>
            </inertial>

            <visual name='visual_middle_link_FF'>

                <geometry>
                    <mesh>
                        <scale>0.001 0.001 0.001</scale>
                        <uri>/home/mamad/hand_RL_ws/src/iiwa_pybullet_integration/Training/kuka_handlit/kuka_handlit/envs/kuka_handlit_model/meshes/F2.dae</uri>
                    </mesh>
                </geometry>
                <material>
                    <ambient>0.5827252540927166 0.8848010006601591 0.4057328333576884 1</ambient>
                    <diffuse>0.11180043162313691 0.5323418860136984 0.02677816380345055 1</diffuse>
                    <specular>0.7058525090072514 0.8847412285730551 0.6683735158422595 1</specular>
                    <emissive>0 0 0 0</emissive>
                </material>
            </visual>
            <collision name='collision_middle_link_FF'>
                <geometry>
                    <mesh>
                        <scale>0.001 0.001 0.001</scale>
                        <uri>/home/mamad/hand_RL_ws/src/iiwa_pybullet_integration/Training/kuka_handlit/kuka_handlit/envs/kuka_handlit_model/meshes/F2_c.dae</uri>
                    </mesh>
                </geometry>
            </collision>
        </link>
        <link name =  "distal_FF">
            <pose frame=''>-0.033 0.09106 1.540897 -0.698132 0 0</pose>
            <inertial>
                <pose frame=''>0 0 0.012 0 0 0</pose>
                <mass>0.012</mass>
                <inertia>
                    <ixx>9.4e-07</ixx>
                    <ixy>0</ixy>
                    <ixz>0</ixz>
                    <iyy>1.1e-06</iyy>
                    <iyz>0</iyz>
                    <izz>5.3e-07</izz>
                </inertia>
            </inertial>

            <visual name='visual_distal_link_FF'>

                <geometry>
                    <mesh>
                        <scale>0.001 0.001 0.001</scale>
                        <uri>/home/mamad/hand_RL_ws/src/iiwa_pybullet_integration/Training/kuka_handlit/kuka_handlit/envs/kuka_handlit_model/meshes/F1.dae</uri>
                    </mesh>
                </geometry>
                <material>
                    <ambient>0.2200907693150258 0.06400547557865366 0.24156511625693966 1</ambient>
                    <diffuse>0.5964443829264718 0.6656497886204316 0.3330380026923567 1</diffuse>
                    <specular>0.7812791485967288 0.8409741216395554 0.4754915199427656 1</specular>
                    <emissive>0 0 0 0</emissive>
                </material>
            </visual>
            <collision name='collision_distal_link_FF'>
                <geometry>
                    <mesh>
                        <scale>0.001 0.001 0.001</scale>
                        <uri>/home/mamad/hand_RL_ws/src/iiwa_pybullet_integration/Training/kuka_handlit/kuka_handlit/envs/kuka_handlit_model/meshes/F1.dae</uri>
                    </mesh>
                </geometry>
            </collision>
        </link>

        
            
            <joint name="J3_FF" type="revolute">
                <child>proximal_FF</child>
                <parent>knuckle_FF</parent>

                <axis>
                    <xyz>1 0 0</xyz>
                    <limit>
                        <lower>0 </lower>
                        <upper>1.5708 </upper>
                        <effort>2.0 </effort>
                        <velocity>2.0 </velocity>
                    </limit>
                    <dynamics>
                        <damping>0.1</damping>
                        <friction>0</friction>
                        <spring_reference>0</spring_reference>
                        <spring_stiffness>0</spring_stiffness>
                    </dynamics>
                </axis>
            </joint>
        
            
            <joint name="J2_FF" type="revolute">
                <child>middle_FF</child>
                <parent>proximal_FF</parent>

                <axis>
                    <xyz>1 0 0</xyz>
                    <limit>
                        <lower>0 </lower>
                        <upper>1.5708 </upper>
                        <effort>2.0 </effort>
                        <velocity>2.0 </velocity>
                    </limit>
                    <dynamics>
                        <damping>0.1</damping>
                        <friction>0</friction>
                        <spring_reference>0</spring_reference>
                        <spring_stiffness>0</spring_stiffness>
                    </dynamics>
                </axis>
            </joint>
        
            
            <joint name="J1_FF" type="revolute">
                <child>distal_FF</child>
                <parent>middle_FF</parent>

                <axis>
                    <xyz>1 0 0</xyz>
                    <limit>
                        <lower>0 </lower>
                        <upper>1.5708 </upper>
                        <effort>2.0 </effort>
                        <velocity>2.0 </velocity>
                    </limit>
                    <dynamics>
                        <damping>0.1</damping>
                        <friction>0</friction>
                        <spring_reference>0</spring_reference>
                        <spring_stiffness>0</spring_stiffness>
                    </dynamics>
                </axis>
            </joint>
        
        <joint name='J4_FF' type="revolute">
            <child>knuckle_FF</child>
            <parent>palm</parent>

            <axis>
                <xyz>0 0.766044 -0.642788</xyz>
                <limit>
                    <lower>-0.349066 </lower>
                    <upper>0.349066 </upper>
                    <effort>2.0 </effort>
                    <velocity>2.0 </velocity>
                </limit>
                <dynamics>
                    <damping>0.1</damping>
                    <friction>0</friction>
                    <spring_reference>0</spring_reference>
                    <spring_stiffness>0</spring_stiffness>
                </dynamics>
            </axis>
        </joint>

    

        <link name = "knuckle_MF">

            <pose frame=''>-0.011000000000000003 0.048636 1.4903380000000002 -0.698132 0 0</pose>
            <inertial>
                <pose frame=''>0 0 0 0 0 0</pose>
                <mass>0.008</mass>
                <inertia>
                    <ixx>2.6e-07</ixx>
                    <ixy>0</ixy>
                    <ixz>0</ixz>
                    <iyy>2.6e-07</iyy>
                    <iyz>0</iyz>
                    <izz>3.2e-07</izz>
                </inertia>
            </inertial>

            <visual name='visual_knuckle_link_MF'>

                <geometry>
                    <mesh>
                        <scale>0.001 0.001 0.001</scale>
                        <uri>/home/mamad/hand_RL_ws/src/iiwa_pybullet_integration/Training/kuka_handlit/kuka_handlit/envs/kuka_handlit_model/meshes/knuckle.dae</uri>
                    </mesh>
                </geometry>
                <material>
                    <ambient>0.4603190725187596 0.3441414113352047 0.10123961167269624 1</ambient>
                    <diffuse>0.7456351421620493 0.041105807178658305 0.44883999001667074 1</diffuse>
                    <specular>0.5188788662352769 0.24879564109394803 0.5015916272266003 1</specular>
                    <emissive>0 0 0 0</emissive>
                </material>
            </visual>
            <collision name='collision_knuckle_link_MF'>
                <geometry>
                <mesh>
                    <scale>0.001 0.001 0.001</scale>
                    <uri>/home/mamad/hand_RL_ws/src/iiwa_pybullet_integration/Training/kuka_handlit/kuka_handlit/envs/kuka_handlit_model/meshes/knuckle.dae</uri>
                </mesh>
            </geometry>
            </collision>
        </link>
        <link name = "proximal_MF">
            <pose frame=''>-0.011000000000000003 0.048636 1.4903380000000002 -0.698132 0 0</pose>
            <inertial>
                <pose frame=''>0 0 0.0225 0 0 0</pose>
                <mass>0.03</mass>
                <inertia>
                    <ixx>9.8e-06</ixx>
                    <ixy>0</ixy>
                    <ixz>0</ixz>
                    <iyy>1.0e-05</iyy>
                    <iyz>0</iyz>
                    <izz>1.8e-06</izz>
                </inertia>
            </inertial>

            <visual name='visual_proximal_link_MF'>

                <geometry>
                    <mesh>
                        <scale>0.001 0.001 0.001</scale>
                        <uri>/home/mamad/hand_RL_ws/src/iiwa_pybullet_integration/Training/kuka_handlit/kuka_handlit/envs/kuka_handlit_model/meshes/F3.dae</uri>
                    </mesh>
                </geometry>
                <material>
                    <ambient>0.43945837998996773 0.35491863900340226 0.40580939467925425 1</ambient>
                    <diffuse>0.6770098300508693 0.29022186298075725 0.15030461577746168 1</diffuse>
                    <specular>0.21849653395915247 0.9662654435076447 0.4968097411151513 1</specular>
                    <emissive>0 0 0 0</emissive>
                </material>
            </visual>
            <collision name='collision_proximal_link_MF'>
                <geometry>
                <mesh>
                    <scale>0.001 0.001 0.001</scale>
                    <uri>/home/mamad/hand_RL_ws/src/iiwa_pybullet_integration/Training/kuka_handlit/kuka_handlit/envs/kuka_handlit_model/meshes/F3_c.dae</uri>
                </mesh>
            </geometry>
            </collision>
        </link>
        <link name = "middle_MF">
            <pose frame=''>-0.011000000000000003 0.077526 1.5248140000000001 -0.698132 0 0</pose>
            <inertial>
                <pose frame=''>0 0 0.0125 0 0 0</pose>
                <mass>0.017</mass>
                <inertia>
                    <ixx>2.6e-06</ixx>
                    <ixy>0</ixy>
                    <ixz>0</ixz>
                    <iyy>2.7e-06</iyy>
                    <iyz>0</iyz>
                    <izz>8.7e-07</izz>
                </inertia>
            </inertial>

            <visual name='visual_middle_link_MF'>

                <geometry>
                    <mesh>
                        <scale>0.001 0.001 0.001</scale>
                        <uri>/home/mamad/hand_RL_ws/src/iiwa_pybullet_integration/Training/kuka_handlit/kuka_handlit/envs/kuka_handlit_model/meshes/F2.dae</uri>
                    </mesh>
                </geometry>
                <material>
                    <ambient>0.6408233758247813 0.6103800933775925 0.6503873074662856 1</ambient>
                    <diffuse>0.4063396334585414 0.843900643548342 0.3827481233700476 1</diffuse>
                    <specular>0.7530332498060957 0.3999715613106447 0.7289966275714517 1</specular>
                    <emissive>0 0 0 0</emissive>
                </material>
            </visual>
            <collision name='collision_middle_link_MF'>
                <geometry>
                    <mesh>
                        <scale>0.001 0.001 0.001</scale>
                        <uri>/home/mamad/hand_RL_ws/src/iiwa_pybullet_integration/Training/kuka_handlit/kuka_handlit/envs/kuka_handlit_model/meshes/F2_c.dae</uri>
                    </mesh>
                </geometry>
            </collision>
        </link>
        <link name =  "distal_MF">
            <pose frame=''>-0.011000000000000003 0.093596 1.543965 -0.698132 0 0</pose>
            <inertial>
                <pose frame=''>0 0 0.012 0 0 0</pose>
                <mass>0.012</mass>
                <inertia>
                    <ixx>9.4e-07</ixx>
                    <ixy>0</ixy>
                    <ixz>0</ixz>
                    <iyy>1.1e-06</iyy>
                    <iyz>0</iyz>
                    <izz>5.3e-07</izz>
                </inertia>
            </inertial>

            <visual name='visual_distal_link_MF'>

                <geometry>
                    <mesh>
                        <scale>0.001 0.001 0.001</scale>
                        <uri>/home/mamad/hand_RL_ws/src/iiwa_pybullet_integration/Training/kuka_handlit/kuka_handlit/envs/kuka_handlit_model/meshes/F1.dae</uri>
                    </mesh>
                </geometry>
                <material>
                    <ambient>0.9619052936680963 0.11319018858933805 0.37168717968406106 1</ambient>
                    <diffuse>0.015402222703669866 0.9953197605062118 0.7085077619265786 1</diffuse>
                    <specular>0.39670169352775997 0.4967765409654441 0.9844010641082341 1</specular>
                    <emissive>0 0 0 0</emissive>
                </material>
            </visual>
            <collision name='collision_distal_link_MF'>
                <geometry>
                    <mesh>
                        <scale>0.001 0.001 0.001</scale>
                        <uri>/home/mamad/hand_RL_ws/src/iiwa_pybullet_integration/Training/kuka_handlit/kuka_handlit/envs/kuka_handlit_model/meshes/F1.dae</uri>
                    </mesh>
                </geometry>
            </collision>
        </link>

        
            
            <joint name="J3_MF" type="revolute">
                <child>proximal_MF</child>
                <parent>knuckle_MF</parent>

                <axis>
                    <xyz>1 0 0</xyz>
                    <limit>
                        <lower>0 </lower>
                        <upper>1.5708 </upper>
                        <effort>2.0 </effort>
                        <velocity>2.0 </velocity>
                    </limit>
                    <dynamics>
                        <damping>0.1</damping>
                        <friction>0</friction>
                        <spring_reference>0</spring_reference>
                        <spring_stiffness>0</spring_stiffness>
                    </dynamics>
                </axis>
            </joint>
        
            
            <joint name="J2_MF" type="revolute">
                <child>middle_MF</child>
                <parent>proximal_MF</parent>

                <axis>
                    <xyz>1 0 0</xyz>
                    <limit>
                        <lower>0 </lower>
                        <upper>1.5708 </upper>
                        <effort>2.0 </effort>
                        <velocity>2.0 </velocity>
                    </limit>
                    <dynamics>
                        <damping>0.1</damping>
                        <friction>0</friction>
                        <spring_reference>0</spring_reference>
                        <spring_stiffness>0</spring_stiffness>
                    </dynamics>
                </axis>
            </joint>
        
            
            <joint name="J1_MF" type="revolute">
                <child>distal_MF</child>
                <parent>middle_MF</parent>

                <axis>
                    <xyz>1 0 0</xyz>
                    <limit>
                        <lower>0 </lower>
                        <upper>1.5708 </upper>
                        <effort>2.0 </effort>
                        <velocity>2.0 </velocity>
                    </limit>
                    <dynamics>
                        <damping>0.1</damping>
                        <friction>0</friction>
                        <spring_reference>0</spring_reference>
                        <spring_stiffness>0</spring_stiffness>
                    </dynamics>
                </axis>
            </joint>
        
        <joint name='J4_MF' type="revolute">
            <child>knuckle_MF</child>
            <parent>palm</parent>

            <axis>
                <xyz>0 0.766044 -0.642788</xyz>
                <limit>
                    <lower>-0.349066 </lower>
                    <upper>0.349066 </upper>
                    <effort>2.0 </effort>
                    <velocity>2.0 </velocity>
                </limit>
                <dynamics>
                    <damping>0.1</damping>
                    <friction>0</friction>
                    <spring_reference>0</spring_reference>
                    <spring_stiffness>0</spring_stiffness>
                </dynamics>
            </axis>
        </joint>

    

        <link name = "knuckle_RF">

            <pose frame=''>0.010999999999999996 0.0461 1.48727 -0.698132 0 0</pose>
            <inertial>
                <pose frame=''>0 0 0 0 0 0</pose>
                <mass>0.008</mass>
                <inertia>
                    <ixx>2.6e-07</ixx>
                    <ixy>0</ixy>
                    <ixz>0</ixz>
                    <iyy>2.6e-07</iyy>
                    <iyz>0</iyz>
                    <izz>3.2e-07</izz>
                </inertia>
            </inertial>

            <visual name='visual_knuckle_link_RF'>

                <geometry>
                    <mesh>
                        <scale>0.001 0.001 0.001</scale>
                        <uri>/home/mamad/hand_RL_ws/src/iiwa_pybullet_integration/Training/kuka_handlit/kuka_handlit/envs/kuka_handlit_model/meshes/knuckle.dae</uri>
                    </mesh>
                </geometry>
                <material>
                    <ambient>0.10622884959686951 0.42383556877232087 0.23224899953321654 1</ambient>
                    <diffuse>0.7689503067636093 0.25342493852476855 0.6623729651791458 1</diffuse>
                    <specular>0.6252183190528897 0.3742780421054621 0.44126532780824856 1</specular>
                    <emissive>0 0 0 0</emissive>
                </material>
            </visual>
            <collision name='collision_knuckle_link_RF'>
                <geometry>
                <mesh>
                    <scale>0.001 0.001 0.001</scale>
                    <uri>/home/mamad/hand_RL_ws/src/iiwa_pybullet_integration/Training/kuka_handlit/kuka_handlit/envs/kuka_handlit_model/meshes/knuckle.dae</uri>
                </mesh>
            </geometry>
            </collision>
        </link>
        <link name = "proximal_RF">
            <pose frame=''>0.010999999999999996 0.0461 1.48727 -0.698132 0 0</pose>
            <inertial>
                <pose frame=''>0 0 0.0225 0 0 0</pose>
                <mass>0.03</mass>
                <inertia>
                    <ixx>9.8e-06</ixx>
                    <ixy>0</ixy>
                    <ixz>0</ixz>
                    <iyy>1.0e-05</iyy>
                    <iyz>0</iyz>
                    <izz>1.8e-06</izz>
                </inertia>
            </inertial>

            <visual name='visual_proximal_link_RF'>

                <geometry>
                    <mesh>
                        <scale>0.001 0.001 0.001</scale>
                        <uri>/home/mamad/hand_RL_ws/src/iiwa_pybullet_integration/Training/kuka_handlit/kuka_handlit/envs/kuka_handlit_model/meshes/F3.dae</uri>
                    </mesh>
                </geometry>
                <material>
                    <ambient>0.5522671617962415 0.5583888401430785 0.2411671150832002 1</ambient>
                    <diffuse>0.3392971397111616 0.06503060026336094 0.40217802457627183 1</diffuse>
                    <specular>0.5869997066299337 0.1474833854440155 0.819793271403549 1</specular>
                    <emissive>0 0 0 0</emissive>
                </material>
            </visual>
            <collision name='collision_proximal_link_RF'>
                <geometry>
                <mesh>
                    <scale>0.001 0.001 0.001</scale>
                    <uri>/home/mamad/hand_RL_ws/src/iiwa_pybullet_integration/Training/kuka_handlit/kuka_handlit/envs/kuka_handlit_model/meshes/F3_c.dae</uri>
                </mesh>
            </geometry>
            </collision>
        </link>
        <link name = "middle_RF">
            <pose frame=''>0.010999999999999996 0.07499 1.521746 -0.698132 0 0</pose>
            <inertial>
                <pose frame=''>0 0 0.0125 0 0 0</pose>
                <mass>0.017</mass>
                <inertia>
                    <ixx>2.6e-06</ixx>
                    <ixy>0</ixy>
                    <ixz>0</ixz>
                    <iyy>2.7e-06</iyy>
                    <iyz>0</iyz>
                    <izz>8.7e-07</izz>
                </inertia>
            </inertial>

            <visual name='visual_middle_link_RF'>

                <geometry>
                    <mesh>
                        <scale>0.001 0.001 0.001</scale>
                        <uri>/home/mamad/hand_RL_ws/src/iiwa_pybullet_integration/Training/kuka_handlit/kuka_handlit/envs/kuka_handlit_model/meshes/F2.dae</uri>
                    </mesh>
                </geometry>
                <material>
                    <ambient>0.8425373387814724 0.9225194082454455 0.5878647221203473 1</ambient>
                    <diffuse>0.13239536755121972 0.1420816622854184 0.35586067870406135 1</diffuse>
                    <specular>0.2498217031186849 0.09340645507894774 0.7936453394753733 1</specular>
                    <emissive>0 0 0 0</emissive>
                </material>
            </visual>
            <collision name='collision_middle_link_RF'>
                <geometry>
                    <mesh>
                        <scale>0.001 0.001 0.001</scale>
                        <uri>/home/mamad/hand_RL_ws/src/iiwa_pybullet_integration/Training/kuka_handlit/kuka_handlit/envs/kuka_handlit_model/meshes/F2_c.dae</uri>
                    </mesh>
                </geometry>
            </collision>
        </link>
        <link name =  "distal_RF">
            <pose frame=''>0.010999999999999996 0.09106 1.540897 -0.698132 0 0</pose>
            <inertial>
                <pose frame=''>0 0 0.012 0 0 0</pose>
                <mass>0.012</mass>
                <inertia>
                    <ixx>9.4e-07</ixx>
                    <ixy>0</ixy>
                    <ixz>0</ixz>
                    <iyy>1.1e-06</iyy>
                    <iyz>0</iyz>
                    <izz>5.3e-07</izz>
                </inertia>
            </inertial>

            <visual name='visual_distal_link_RF'>

                <geometry>
                    <mesh>
                        <scale>0.001 0.001 0.001</scale>
                        <uri>/home/mamad/hand_RL_ws/src/iiwa_pybullet_integration/Training/kuka_handlit/kuka_handlit/envs/kuka_handlit_model/meshes/F1.dae</uri>
                    </mesh>
                </geometry>
                <material>
                    <ambient>0.6557195067472302 0.691500669526891 0.37828002366839353 1</ambient>
                    <diffuse>0.3607779035010181 0.10114442863175366 0.1950152998593343 1</diffuse>
                    <specular>0.570924930517464 0.22498456192252536 0.9255985008628732 1</specular>
                    <emissive>0 0 0 0</emissive>
                </material>
            </visual>
            <collision name='collision_distal_link_RF'>
                <geometry>
                    <mesh>
                        <scale>0.001 0.001 0.001</scale>
                        <uri>/home/mamad/hand_RL_ws/src/iiwa_pybullet_integration/Training/kuka_handlit/kuka_handlit/envs/kuka_handlit_model/meshes/F1.dae</uri>
                    </mesh>
                </geometry>
            </collision>
        </link>

        
            
            <joint name="J3_RF" type="revolute">
                <child>proximal_RF</child>
                <parent>knuckle_RF</parent>

                <axis>
                    <xyz>1 0 0</xyz>
                    <limit>
                        <lower>0 </lower>
                        <upper>1.5708 </upper>
                        <effort>2.0 </effort>
                        <velocity>2.0 </velocity>
                    </limit>
                    <dynamics>
                        <damping>0.1</damping>
                        <friction>0</friction>
                        <spring_reference>0</spring_reference>
                        <spring_stiffness>0</spring_stiffness>
                    </dynamics>
                </axis>
            </joint>
        
            
            <joint name="J2_RF" type="revolute">
                <child>middle_RF</child>
                <parent>proximal_RF</parent>

                <axis>
                    <xyz>1 0 0</xyz>
                    <limit>
                        <lower>0 </lower>
                        <upper>1.5708 </upper>
                        <effort>2.0 </effort>
                        <velocity>2.0 </velocity>
                    </limit>
                    <dynamics>
                        <damping>0.1</damping>
                        <friction>0</friction>
                        <spring_reference>0</spring_reference>
                        <spring_stiffness>0</spring_stiffness>
                    </dynamics>
                </axis>
            </joint>
        
            
            <joint name="J1_RF" type="revolute">
                <child>distal_RF</child>
                <parent>middle_RF</parent>

                <axis>
                    <xyz>1 0 0</xyz>
                    <limit>
                        <lower>0 </lower>
                        <upper>1.5708 </upper>
                        <effort>2.0 </effort>
                        <velocity>2.0 </velocity>
                    </limit>
                    <dynamics>
                        <damping>0.1</damping>
                        <friction>0</friction>
                        <spring_reference>0</spring_reference>
                        <spring_stiffness>0</spring_stiffness>
                    </dynamics>
                </axis>
            </joint>
        
        <joint name='J4_RF' type="revolute">
            <child>knuckle_RF</child>
            <parent>palm</parent>

            <axis>
                <xyz>0 0.766044 -0.642788</xyz>
                <limit>
                    <lower>-0.349066 </lower>
                    <upper>0.349066 </upper>
                    <effort>2.0 </effort>
                    <velocity>2.0 </velocity>
                </limit>
                <dynamics>
                    <damping>0.1</damping>
                    <friction>0</friction>
                    <spring_reference>0</spring_reference>
                    <spring_stiffness>0</spring_stiffness>
                </dynamics>
            </axis>
        </joint>

    


    <link name = "thbase">
        <pose frame=''>-0.034 -0.0028710000000000003 1.442179 0.870557 0.572429 -2.5703</pose>
        <inertial>
            <pose frame=''>0 0 0 0 0 0</pose>
            <mass>0.01</mass>
            <inertia>
                <ixx>1.6e-07</ixx>
                <ixy>0</ixy>
                <ixz>0</ixz>
                <iyy>1.6e-07</iyy>
                <iyz>0</iyz>
                <izz>1.6e-07</izz>
            </inertia>
        </inertial>
        <visual name='visual_thbase_link'>
            
            <geometry>
                <box>
                    <size>0.001 0.001 0.001</size>
                </box>
            </geometry>
            <material>
                <ambient>0.15695111627466052 0.39077146457006595 0.5358811809809237 1</ambient>
                <diffuse>0.5497860785176218 0.9998754090787048 0.8654831447989003 1</diffuse>
                <specular>0.14293573335480037 0.9052209466632715 0.6920169202476428 1</specular>
                <emissive>0 0 0 0</emissive>
            </material>
        </visual>
        <collision name='collision_thbase_link'>
            <pose frame=''>0 0 0 0 0 0</pose>
            <geometry>

                <sphere>
                    <radius>0.011</radius>
                </sphere>
            
            </geometry>
        </collision>
    </link>
    <link name = "thproximal">
            
        <pose frame=''>-0.034 -0.0028710000000000003 1.442179 0.870557 0.572429 -2.5703</pose>
        <inertial>
            <pose frame=''>0 0 0.021111 0 0 0</pose>
            <mass>0.04</mass>
            <inertia>
                <ixx>1.36e-05</ixx>
                <ixy>0</ixy>
                <ixz>0</ixz>
                <iyy>1.36e-05</iyy>
                <iyz>0</iyz>
                <izz>3.13e-06</izz>
            </inertia>
        </inertial>

        <visual name='visual_thproximal_link'>
            
            <geometry>
                <mesh>
                    <scale>0.001 0.001 0.001</scale>
                    <uri>/home/mamad/hand_RL_ws/src/iiwa_pybullet_integration/Training/kuka_handlit/kuka_handlit/envs/kuka_handlit_model/meshes/TH3_z.dae</uri>
                </mesh>
            </geometry>
            <material>
                <ambient>0.31419183113777294 0.08686052510701248 0.7033296099895879 1</ambient>
                <diffuse>0.8146404706714643 0.4254524815728523 0.894171892469319 1</diffuse>
                <specular>0.09864039031555061 0.1092905074847309 0.6144052415803773 1</specular>
                <emissive>0 0 0 0</emissive>
            </material>
        </visual>
        <collision name='collision_thproximal_link'>
            <geometry>
                <mesh>
                    <scale>0.001 0.001 0.001</scale>
                    <uri>/home/mamad/hand_RL_ws/src/iiwa_pybullet_integration/Training/kuka_handlit/kuka_handlit/envs/kuka_handlit_model/meshes/TH3_z_c.dae</uri>
                </mesh>
            </geometry>
        </collision>
    </link>
    <link name = "thhub">
        <pose frame=''>-0.06087000000000001 0.014400999999999999 1.462763 0.870557 0.572429 -2.5703</pose>
        <inertial>
            <pose frame=''>0 0 0 0 0 0</pose>
            <mass>0.005</mass>
            <inertia>
                <ixx>1.0e-06</ixx>
                <ixy>0</ixy>
                <ixz>0</ixz>
                <iyy>1.0e-06</iyy>
                <iyz>0</iyz>
                <izz>3.0e-07</izz>
            </inertia>
        </inertial>
        <visual name='visual_thhub_link'>
            
            <geometry>
                <box>
                    <size>0.001 0.001 0.001</size>
                </box>
            </geometry>
            <material>

            </material>
        </visual>
        <collision name='collision_thhub_link'>
            <geometry>
                <box>
                    <size>0.001 0.001 0.001</size>
                </box>
            </geometry>
        </collision>
    </link>
    <link name = "thmiddle">
            
        <pose frame=''>-0.06087000000000001 0.014400999999999999 1.462763 0.870557 0.572429 -2.5703</pose>
        <inertial>
            <pose frame=''>0 0 0.16 0 0 0</pose>
            <mass>0.02</mass>
            <inertia>
                <ixx>5.1e-06</ixx>
                <ixy>0</ixy>
                <ixz>0</ixz>
                <iyy>5.1e-06</iyy>
                <iyz>0</iyz>
                <izz>1.21e-06</izz>
            </inertia>
        </inertial>

        <visual name='visual_thmiddle_link'>
            
            <geometry>
                <mesh>
                    <scale>0.001 0.001 0.001</scale>
                    <uri>/home/mamad/hand_RL_ws/src/iiwa_pybullet_integration/Training/kuka_handlit/kuka_handlit/envs/kuka_handlit_model/meshes/TH2_z.dae</uri>
                </mesh>
            </geometry>
            <material>
                <ambient>0.524513356076782 0.09337890061160714 0.9082616827859553 1</ambient>
                <diffuse>0.48208468099803814 0.3856662113733156 0.11535349239542403 1</diffuse>
                <specular>0.6330948182642258 0.9420835952768053 0.7485958820915617 1</specular>
                <emissive>0 0 0 0</emissive>
            </material>
        </visual>

        <collision name='collision_thmiddle_link'>
            <geometry>
                <mesh>
                    <scale>0.001 0.001 0.001</scale>
                    <uri>/home/mamad/hand_RL_ws/src/iiwa_pybullet_integration/Training/kuka_handlit/kuka_handlit/envs/kuka_handlit_model/meshes/TH2_z_c.dae</uri>
                </mesh>
            </geometry>
        </collision>
    </link>
    <link name = "thdistal">
            
        <pose frame=''>-0.083498 0.028946 1.480096 -0.785398 0.698132 1.5707999999999998</pose>
        <inertial>
            <pose frame=''>0 0 0.014559 0 0 0</pose>
            <mass>0.016</mass>
            <inertia>
                <ixx>2.1e-06</ixx>
                <ixy>0</ixy>
                <ixz>0</ixz>
                <iyy>2.2e-06</iyy>
                <iyz>0</iyz>
                <izz>1.0e-06</izz>
            </inertia>
        </inertial>

        <visual name='visual_thdistal_link'>
            
            <geometry>
                <mesh>
                    <scale>0.001 0.001 0.001</scale>
                    <uri>/home/mamad/hand_RL_ws/src/iiwa_pybullet_integration/Training/kuka_handlit/kuka_handlit/envs/kuka_handlit_model/meshes/TH1_z.dae</uri>
                </mesh>
            </geometry>
            <material>
                <ambient>0.5234495072879087 0.21852680577483918 0.03100699962915232 1</ambient>
                <diffuse>0.61045165094429 0.2596235869024949 0.7796556559613698 1</diffuse>
                <specular>0.19799471868108454 0.6741793103391681 0.1579465072415509 1</specular>
                <emissive>0 0 0 0</emissive>
            </material>
        </visual>
        <collision name='collision_thdistal_link'>
            <geometry>
                <mesh>
                    <scale>0.001 0.001 0.001</scale>
                    <uri>/home/mamad/hand_RL_ws/src/iiwa_pybullet_integration/Training/kuka_handlit/kuka_handlit/envs/kuka_handlit_model/meshes/TH1_z.dae</uri>
                </mesh>
            </geometry>
        </collision>
    </link>

    
        <joint name ="THJ5"  type ="revolute">
            <child>thbase</child>
            <parent>palm</parent>
            <axis>
                <xyz>0 0 0.541675</xyz>
                <limit>
                    <lower>-1.0472 </lower>
                    <upper>1.0472 </upper>
                    <effort>5.0 </effort>
                    <velocity>4.0 </velocity>
                </limit>
                <dynamics>
                    <damping>0.2</damping>
                    <friction>0</friction>
                </dynamics>
            </axis>
        </joint>
    
        <joint name ="THJ4"  type ="revolute">
            <child>thproximal</child>
            <parent>thbase</parent>
            <axis>
                <xyz>-0.707107 -0.454519 -0.541675</xyz>
                <limit>
                    <lower>0 </lower>
                    <upper>1.22173 </upper>
                    <effort>3.0 </effort>
                    <velocity>4.0 </velocity>
                </limit>
                <dynamics>
                    <damping>0.2</damping>
                    <friction>0</friction>
                </dynamics>
            </axis>
        </joint>
    
        <joint name ="THJ2"  type ="revolute">
            <child>thmiddle</child>
            <parent>thhub</parent>
            <axis>
                <xyz>0 -0.766044 0.642788</xyz>
                <limit>
                    <lower>-0.698132 </lower>
                    <upper>0.698132 </upper>
                    <effort>2.0 </effort>
                    <velocity>2.0 </velocity>
                </limit>
                <dynamics>
                    <damping>0.1</damping>
                    <friction>0</friction>
                </dynamics>
            </axis>
        </joint>
    
        <joint name ="THJ1"  type ="revolute">
            <child>thdistal</child>
            <parent>thmiddle</parent>
            <axis>
                <xyz>0 -0.766044 0.642788</xyz>
                <limit>
                    <lower>0 </lower>
                    <upper>1.5708 </upper>
                    <effort>1.0 </effort>
                    <velocity>4.0 </velocity>
                </limit>
                <dynamics>
                    <damping>0.2</damping>
                    <friction>0</friction>
                </dynamics>
            </axis>
        </joint>
    
    <joint name ="THJ3"  type ="fixed">
        <child>thhub</child>
        <parent>thproximal</parent>
        <axis>
            <xyz>1 0 0</xyz>
        </axis>
    </joint>






 
   
  </model>

</sdf>