<sdf version='1.6'>
  <model name='hand_iiwa'>
    <link name='hand_iiwa_link_0'>
      <pose frame=''>0 0 0 0 -0 0</pose>
      <inertial>
        <pose frame=''>-0.1 0 0.07 0 -0 0</pose>
        <mass>5</mass>
        <inertia>
          <ixx>0.05</ixx>
          <ixy>0</ixy>
          <ixz>0</ixz>
          <iyy>0.06</iyy>
          <iyz>0</iyz>
          <izz>0.03</izz>
        </inertia>
      </inertial>
      <collision name='hand_iiwa_link_0_collision'>
        <pose frame=''>0 0 0 0 -0 0</pose>
        <geometry>
          <mesh>
            <scale>1 1 1</scale>
            <uri>model://iiwa_fri_description/meshes/iiwa7/collision/link_0.stl</uri>
          </mesh>
        </geometry>
        <surface>
          <contact>
            <ode/>
          </contact>
          <friction>
            <ode>
              <mu>0.2</mu>
              <mu2>0.2</mu2>
            </ode>
          </friction>
        </surface>
      </collision>
      <visual name='hand_iiwa_link_0_visual'>
        <pose frame=''>0 0 0 0 -0 0</pose>
        <geometry>
          <mesh>
            <scale>1 1 1</scale>
            <uri>model://iiwa_fri_description/meshes/iiwa7/visual/link_0.stl</uri>
          </mesh>
        </geometry>
        <material>
          <script>
            <name>Gazebo/Grey</name>
            <uri>file://media/materials/scripts/gazebo.material</uri>
          </script>
        </material>
      </visual>
      <gravity>1</gravity>
      <velocity_decay/>
      <self_collide>0</self_collide>
    </link>
    <link name='hand_iiwa_link_1'>
      <pose frame=''>0 0 0.15 0 -0 0</pose>
      <inertial>
        <pose frame=''>0 -0.03 0.12 0 -0 0</pose>
        <mass>3.4525</mass>
        <inertia>
          <ixx>0.02183</ixx>
          <ixy>0</ixy>
          <ixz>0</ixz>
          <iyy>0.007703</iyy>
          <iyz>-0.003887</iyz>
          <izz>0.02083</izz>
        </inertia>
      </inertial>
      <collision name='hand_iiwa_link_1_collision'>
        <pose frame=''>0 0 0.0075 0 -0 0</pose>
        <geometry>
          <mesh>
            <scale>1 1 1</scale>
            <uri>model://iiwa_fri_description/meshes/iiwa7/collision/link_1.stl</uri>
          </mesh>
        </geometry>
        <surface>
          <contact>
            <ode/>
          </contact>
          <friction>
            <ode>
              <mu>0.2</mu>
              <mu2>0.2</mu2>
            </ode>
          </friction>
        </surface>
      </collision>
      <visual name='hand_iiwa_link_1_visual'>
        <pose frame=''>0 0 0.0075 0 -0 0</pose>
        <geometry>
          <mesh>
            <scale>1 1 1</scale>
            <uri>model://iiwa_fri_description/meshes/iiwa7/visual/link_1.stl</uri>
          </mesh>
        </geometry>
        <material>
          <script>
            <name>Gazebo/Orange</name>
            <uri>file://media/materials/scripts/gazebo.material</uri>
          </script>
        </material>
      </visual>
      <gravity>1</gravity>
      <velocity_decay/>
      <self_collide>0</self_collide>
    </link>
    <joint name='hand_iiwa_joint_1' type='revolute'>
      <child>hand_iiwa_link_1</child>
      <parent>hand_iiwa_link_0</parent>
      <axis>
        <xyz>0 0 1</xyz>
        <limit>
          <lower>-2.96706</lower>
          <upper>2.96706</upper>
          <effort>300</effort>
          <velocity>10</velocity>
        </limit>
        <dynamics>
          <damping>0.5</damping>
          <friction>0</friction>
          <spring_reference>0</spring_reference>
          <spring_stiffness>0</spring_stiffness>
        </dynamics>
        <use_parent_model_frame>1</use_parent_model_frame>
      </axis>
    </joint>
    <link name='hand_iiwa_link_2'>
      <pose frame=''>0 0 0.34 1.5708 -0 -3.14159</pose>
      <inertial>
        <pose frame=''>0.0003 0.059 0.042 0 -0 0</pose>
        <mass>3.4821</mass>
        <inertia>
          <ixx>0.02076</ixx>
          <ixy>0</ixy>
          <ixz>-0.003626</ixz>
          <iyy>0.02179</iyy>
          <iyz>0</iyz>
          <izz>0.00779</izz>
        </inertia>
      </inertial>
      <collision name='hand_iiwa_link_2_collision'>
        <pose frame=''>0 0 0 0 -0 0</pose>
        <geometry>
          <mesh>
            <scale>1 1 1</scale>
            <uri>model://iiwa_fri_description/meshes/iiwa7/collision/link_2.stl</uri>
          </mesh>
        </geometry>
        <surface>
          <contact>
            <ode/>
          </contact>
          <friction>
            <ode>
              <mu>0.2</mu>
              <mu2>0.2</mu2>
            </ode>
          </friction>
        </surface>
      </collision>
      <visual name='hand_iiwa_link_2_visual'>
        <pose frame=''>0 0 0 0 -0 0</pose>
        <geometry>
          <mesh>
            <scale>1 1 1</scale>
            <uri>model://iiwa_fri_description/meshes/iiwa7/visual/link_2.stl</uri>
          </mesh>
        </geometry>
        <material>
          <script>
            <name>Gazebo/Orange</name>
            <uri>file://media/materials/scripts/gazebo.material</uri>
          </script>
        </material>
      </visual>
      <gravity>1</gravity>
      <velocity_decay/>
      <self_collide>0</self_collide>
    </link>
    <joint name='hand_iiwa_joint_2' type='revolute'>
      <child>hand_iiwa_link_2</child>
      <parent>hand_iiwa_link_1</parent>
      <axis>
        <xyz>-0 1 0</xyz>
        <limit>
          <lower>-2.0944</lower>
          <upper>2.0944</upper>
          <effort>300</effort>
          <velocity>10</velocity>
        </limit>
        <dynamics>
          <damping>0.5</damping>
          <friction>0</friction>
          <spring_reference>0</spring_reference>
          <spring_stiffness>0</spring_stiffness>
        </dynamics>
        <use_parent_model_frame>1</use_parent_model_frame>
      </axis>
    </joint>
    <link name='hand_iiwa_link_3'>
      <pose frame=''>0 -0 0.55 0 0 0</pose>
      <inertial>
        <pose frame=''>0 0.03 0.13 0 -0 0</pose>
        <mass>4.05623</mass>
        <inertia>
          <ixx>0.03204</ixx>
          <ixy>0</ixy>
          <ixz>0</ixz>
          <iyy>0.00972</iyy>
          <iyz>0.006227</iyz>
          <izz>0.03042</izz>
        </inertia>
      </inertial>
      <collision name='hand_iiwa_link_3_collision'>
        <pose frame=''>0 0 -0.026 0 -0 0</pose>
        <geometry>
          <mesh>
            <scale>1 1 1</scale>
            <uri>model://iiwa_fri_description/meshes/iiwa7/collision/link_3.stl</uri>
          </mesh>
        </geometry>
        <surface>
          <contact>
            <ode/>
          </contact>
          <friction>
            <ode>
              <mu>0.2</mu>
              <mu2>0.2</mu2>
            </ode>
          </friction>
        </surface>
      </collision>
      <visual name='hand_iiwa_link_3_visual'>
        <pose frame=''>0 0 -0.026 0 -0 0</pose>
        <geometry>
          <mesh>
            <scale>1 1 1</scale>
            <uri>model://iiwa_fri_description/meshes/iiwa7/visual/link_3.stl</uri>
          </mesh>
        </geometry>
        <material>
          <script>
            <name>Gazebo/Orange</name>
            <uri>file://media/materials/scripts/gazebo.material</uri>
          </script>
        </material>
      </visual>
      <gravity>1</gravity>
      <velocity_decay/>
      <self_collide>0</self_collide>
    </link>
    <joint name='hand_iiwa_joint_3' type='revolute'>
      <child>hand_iiwa_link_3</child>
      <parent>hand_iiwa_link_2</parent>
      <axis>
        <xyz>0 0 1</xyz>
        <limit>
          <lower>-2.96706</lower>
          <upper>2.96706</upper>
          <effort>300</effort>
          <velocity>10</velocity>
        </limit>
        <dynamics>
          <damping>0.5</damping>
          <friction>0</friction>
          <spring_reference>0</spring_reference>
          <spring_stiffness>0</spring_stiffness>
        </dynamics>
        <use_parent_model_frame>1</use_parent_model_frame>
      </axis>
    </joint>
    <link name='hand_iiwa_link_4'>
      <pose frame=''>0 -0 0.74 1.5708 0 0</pose>
      <inertial>
        <pose frame=''>0 0.067 0.034 0 -0 0</pose>
        <mass>3.4822</mass>
        <inertia>
          <ixx>0.02178</ixx>
          <ixy>0</ixy>
          <ixz>0</ixz>
          <iyy>0.02075</iyy>
          <iyz>-0.003625</iyz>
          <izz>0.007785</izz>
        </inertia>
      </inertial>
      <collision name='hand_iiwa_link_4_collision'>
        <pose frame=''>0 0 0 0 -0 0</pose>
        <geometry>
          <mesh>
            <scale>1 1 1</scale>
            <uri>model://iiwa_fri_description/meshes/iiwa7/collision/link_4.stl</uri>
          </mesh>
        </geometry>
        <surface>
          <contact>
            <ode/>
          </contact>
          <friction>
            <ode>
              <mu>0.2</mu>
              <mu2>0.2</mu2>
            </ode>
          </friction>
        </surface>
      </collision>
      <visual name='hand_iiwa_link_4_visual'>
        <pose frame=''>0 0 0 0 -0 0</pose>
        <geometry>
          <mesh>
            <scale>1 1 1</scale>
            <uri>model://iiwa_fri_description/meshes/iiwa7/visual/link_4.stl</uri>
          </mesh>
        </geometry>
        <material>
          <script>
            <name>Gazebo/Orange</name>
            <uri>file://media/materials/scripts/gazebo.material</uri>
          </script>
        </material>
      </visual>
      <gravity>1</gravity>
      <velocity_decay/>
      <self_collide>0</self_collide>
    </link>
    <joint name='hand_iiwa_joint_4' type='revolute'>
      <child>hand_iiwa_link_4</child>
      <parent>hand_iiwa_link_3</parent>
      <axis>
        <xyz>0 -1 0</xyz>
        <limit>
          <lower>-2.0944</lower>
          <upper>2.0944</upper>
          <effort>300</effort>
          <velocity>10</velocity>
        </limit>
        <dynamics>
          <damping>0.5</damping>
          <friction>0</friction>
          <spring_reference>0</spring_reference>
          <spring_stiffness>0</spring_stiffness>
        </dynamics>
        <use_parent_model_frame>1</use_parent_model_frame>
      </axis>
    </joint>
    <link name='hand_iiwa_link_5'>
      <pose frame=''>0 0 0.95 0 -0 -3.14159</pose>
      <inertial>
        <pose frame=''>0.0001 0.021 0.076 0 -0 0</pose>
        <mass>2.1633</mass>
        <inertia>
          <ixx>0.01287</ixx>
          <ixy>0</ixy>
          <ixz>0</ixz>
          <iyy>0.005708</iyy>
          <iyz>-0.003946</iyz>
          <izz>0.01112</izz>
        </inertia>
      </inertial>
      <collision name='hand_iiwa_link_5_collision'>
        <pose frame=''>0 0 -0.026 0 -0 0</pose>
        <geometry>
          <mesh>
            <scale>1 1 1</scale>
            <uri>model://iiwa_fri_description/meshes/iiwa7/collision/link_5.stl</uri>
          </mesh>
        </geometry>
        <surface>
          <contact>
            <ode/>
          </contact>
          <friction>
            <ode>
              <mu>0.2</mu>
              <mu2>0.2</mu2>
            </ode>
          </friction>
        </surface>
      </collision>
      <visual name='hand_iiwa_link_5_visual'>
        <pose frame=''>0 0 -0.026 0 -0 0</pose>
        <geometry>
          <mesh>
            <scale>1 1 1</scale>
            <uri>model://iiwa_fri_description/meshes/iiwa7/visual/link_5.stl</uri>
          </mesh>
        </geometry>
        <material>
          <script>
            <name>Gazebo/Orange</name>
            <uri>file://media/materials/scripts/gazebo.material</uri>
          </script>
        </material>
      </visual>
      <gravity>1</gravity>
      <velocity_decay/>
      <self_collide>0</self_collide>
    </link>
    <joint name='hand_iiwa_joint_5' type='revolute'>
      <child>hand_iiwa_link_5</child>
      <parent>hand_iiwa_link_4</parent>
      <axis>
        <xyz>0 0 1</xyz>
        <limit>
          <lower>-2.96706</lower>
          <upper>2.96706</upper>
          <effort>300</effort>
          <velocity>10</velocity>
        </limit>
        <dynamics>
          <damping>0.5</damping>
          <friction>0</friction>
          <spring_reference>0</spring_reference>
          <spring_stiffness>0</spring_stiffness>
        </dynamics>
        <use_parent_model_frame>1</use_parent_model_frame>
      </axis>
    </joint>
    <link name='hand_iiwa_link_6'>
      <pose frame=''>0 -0.0607 1.14 1.5708 -0 -3.14159</pose>
      <inertial>
        <pose frame=''>0 0.0006 0.0004 0 -0 0</pose>
        <mass>2.3466</mass>
        <inertia>
          <ixx>0.006509</ixx>
          <ixy>0</ixy>
          <ixz>0</ixz>
          <iyy>0.006259</iyy>
          <iyz>0.00031891</iyz>
          <izz>0.004527</izz>
        </inertia>
      </inertial>
      <collision name='hand_iiwa_link_6_collision'>
        <pose frame=''>0 0 0 0 -0 0</pose>
        <geometry>
          <mesh>
            <scale>1 1 1</scale>
            <uri>model://iiwa_fri_description/meshes/iiwa7/collision/link_6.stl</uri>
          </mesh>
        </geometry>
        <surface>
          <contact>
            <ode/>
          </contact>
          <friction>
            <ode>
              <mu>0.2</mu>
              <mu2>0.2</mu2>
            </ode>
          </friction>
        </surface>
      </collision>
      <visual name='hand_iiwa_link_6_visual'>
        <pose frame=''>0 0 0 0 -0 0</pose>
        <geometry>
          <mesh>
            <scale>1 1 1</scale>
            <uri>model://iiwa_fri_description/meshes/iiwa7/visual/link_6.stl</uri>
          </mesh>
        </geometry>
        <material>
          <script>
            <name>Gazebo/Orange</name>
            <uri>file://media/materials/scripts/gazebo.material</uri>
          </script>
        </material>
      </visual>
      <gravity>1</gravity>
      <velocity_decay/>
      <self_collide>0</self_collide>
    </link>
    <joint name='hand_iiwa_joint_6' type='revolute'>
      <child>hand_iiwa_link_6</child>
      <parent>hand_iiwa_link_5</parent>
      <axis>
        <xyz>-0 1 -0</xyz>
        <limit>
          <lower>-2.0944</lower>
          <upper>2.0944</upper>
          <effort>300</effort>
          <velocity>10</velocity>
        </limit>
        <dynamics>
          <damping>0.5</damping>
          <friction>0</friction>
          <spring_reference>0</spring_reference>
          <spring_stiffness>0</spring_stiffness>
        </dynamics>
        <use_parent_model_frame>1</use_parent_model_frame>
      </axis>
    </joint>
    <link name='hand_iiwa_link_7'>
      <pose frame=''>0 0 1.221 0 0 0</pose>
      <inertial>
        <pose frame=''>0 0.00043 0.071108 0 -0 0</pose>
        <mass>5.229</mass>
        <inertia>
          <ixx>0.145258</ixx>
          <ixy>0.0005912</ixy>
          <ixz>0</ixz>
          <iyy>0.145283</iyy>
          <iyz>-0.000503009</iyz>
          <izz>0.0572184</izz>
        </inertia>
      </inertial>
      <collision name='hand_iiwa_link_7_collision'>
        <pose frame=''>0 0 -0.0005 0 -0 0</pose>
        <geometry>
          <mesh>
            <scale>1 1 1</scale>
            <uri>model://iiwa_fri_description/meshes/iiwa7/collision/link_7.stl</uri>
          </mesh>
        </geometry>
        <surface>
          <contact>
            <ode/>
          </contact>
          <friction>
            <ode>
              <mu>0.2</mu>
              <mu2>0.2</mu2>
            </ode>
          </friction>
        </surface>
      </collision>
      <collision name='hand_iiwa_link_7_fixed_joint_lump__lh_forearm_collision_1'>
        <pose frame=''>0 0 0.11 0 -0 0</pose>
        <geometry>
          <box>
            <size>0.12 0.109 0.13</size>
          </box>
        </geometry>
      </collision>
      <collision name='hand_iiwa_link_7_fixed_joint_lump__lh_palm_collision_2'>
        <pose frame=''>-0.011 0.015937 0.217646 -0.698132 0 0</pose>
        <geometry>
          <box>
            <size>0.062 0.007 0.098</size>
          </box>
        </geometry>
        <surface>
          <contact>
            <ode/>
          </contact>
          <friction>
            <ode/>
          </friction>
        </surface>
      </collision>
      <collision name='hand_iiwa_link_7_fixed_joint_lump__lh_palm_collision_3'>
        <pose frame=''>-0.0005 0.006745 0.225359 -0.698132 0 0</pose>
        <geometry>
          <box>
            <size>0.041 0.017 0.098</size>
          </box>
        </geometry>
        <surface>
          <contact>
            <ode/>
          </contact>
          <friction>
            <ode/>
          </friction>
        </surface>
      </collision>
      <collision name='hand_iiwa_link_7_fixed_joint_lump__lh_palm_collision_4'>
        <pose frame=''>-0.0315 0.029242 0.252171 -0.698132 0 0</pose>
        <geometry>
          <box>
            <size>0.021 0.017 0.028</size>
          </box>
        </geometry>
        <surface>
          <contact>
            <ode/>
          </contact>
          <friction>
            <ode/>
          </friction>
        </surface>
      </collision>
      <collision name='hand_iiwa_link_7_fixed_joint_lump__lh_palm_collision_5'>
        <pose frame=''>-0.0315 -0.020869 0.20023 -0.698132 0 0</pose>
        <geometry>
          <box>
            <size>0.021 0.027 0.024</size>
          </box>
        </geometry>
        <surface>
          <contact>
            <ode/>
          </contact>
          <friction>
            <ode/>
          </friction>
        </surface>
      </collision>
      <collision name='hand_iiwa_link_7_fixed_joint_lump__lh_palm_collision_6'>
        <pose frame=''>-0.01 -0.020952 0.213354 -0.698132 0 0</pose>
        <geometry>
          <box>
            <size>0.022 0.01 0.044</size>
          </box>
        </geometry>
        <surface>
          <contact>
            <ode/>
          </contact>
          <friction>
            <ode/>
          </friction>
        </surface>
      </collision>
      <collision name='hand_iiwa_link_7_fixed_joint_lump__lh_palm_collision_7'>
        <pose frame=''>-0.011 0.042208 0.262178 -0.698132 0 0</pose>
        <geometry>
          <box>
            <size>0.018 0.024 0.004</size>
          </box>
        </geometry>
        <surface>
          <contact>
            <ode/>
          </contact>
          <friction>
            <ode/>
          </friction>
        </surface>
      </collision>
      <collision name='hand_iiwa_link_7_fixed_joint_lump__lh_palm_collision_8'>
        <pose frame=''>0.03 -0.009215 0.200894 -0.698132 0 0</pose>
        <geometry>
          <box>
            <size>0.02 0.024 0.04</size>
          </box>
        </geometry>
        <surface>
          <contact>
            <ode/>
          </contact>
          <friction>
            <ode/>
          </friction>
        </surface>
      </collision>
      <visual name='hand_iiwa_link_7_visual'>
        <pose frame=''>0 0 -0.0005 0 -0 0</pose>
        <geometry>
          <mesh>
            <scale>1 1 1</scale>
            <uri>model://iiwa_fri_description/meshes/iiwa7/visual/link_7.stl</uri>
          </mesh>
        </geometry>
        <material>
          <script>
            <name>Gazebo/Grey</name>
            <uri>file://media/materials/scripts/gazebo.material</uri>
          </script>
        </material>
      </visual>
      <visual name='hand_iiwa_link_7_fixed_joint_lump__lh_forearm_visual_1'>
        <pose frame=''>0 0 0.045 0 -0 1.5708</pose>
        <geometry>
          <mesh>
            <scale>1 1 1</scale>
            <uri>model://sr_description/hand/model/forearm_lite.dae</uri>
          </mesh>
        </geometry>
      </visual>
      <visual name='hand_iiwa_link_7_fixed_joint_lump__lh_palm_visual_2'>
        <pose frame=''>0 -0.015 0.194 -0.698132 0 0</pose>
        <geometry>
          <mesh>
            <scale>-0.001 0.001 0.001</scale>
            <uri>model://sr_description/hand/model/palm.dae</uri>
          </mesh>
        </geometry>
        <material>
          <script>
            <uri>__default__</uri>
            <name>__default__</name>
          </script>
        </material>
      </visual>
      <velocity_decay/>
      <gravity>1</gravity>
      <velocity_decay/>
      <self_collide>0</self_collide>
      <sensor name='lh_palm_contact' type='contact'>
        <always_on>1</always_on>
        <update_rate>1000</update_rate>
        <contact>
          <topic>lh_palm_collision</topic>
          <collision>lh_forearm_collision_lh_palm</collision>
        </contact>
        <plugin name='lh_palm_gazebo_ros_bumper_controller' filename='libgazebo_ros_bumper.so'>
          <alwaysOn>true</alwaysOn>
          <frameName>lh_palm</frameName>
          <updateRate>100.0</updateRate>
          <bumperTopicName>contacts/lh_palm</bumperTopicName>
        </plugin>
        <pose frame=''>0 -0.015 0.194 -0.698132 0 0</pose>
      </sensor>
    </link>
    <joint name='hand_iiwa_joint_7' type='revolute'>
      <child>hand_iiwa_link_7</child>
      <parent>hand_iiwa_link_6</parent>
      <axis>
        <xyz>0 0 1</xyz>
        <limit>
          <lower>-3.05433</lower>
          <upper>3.05433</upper>
          <effort>300</effort>
          <velocity>10</velocity>
        </limit>
        <dynamics>
          <damping>0.5</damping>
          <friction>0</friction>
          <spring_reference>0</spring_reference>
          <spring_stiffness>0</spring_stiffness>
        </dynamics>
        <use_parent_model_frame>1</use_parent_model_frame>
      </axis>
    </joint>
    <link name='lh_ffknuckle'>
      <pose frame=''>-0.033 0.046065 1.48777 -0.698132 0 0</pose>
      <inertial>
        <pose frame=''>0 0 0 0 -0 0</pose>
        <mass>0.008</mass>
        <inertia>
          <ixx>2.6e-07</ixx>
          <ixy>0</ixy>
          <ixz>0</ixz>
          <iyy>2.6e-07</iyy>
          <iyz>0</iyz>
          <izz>3.2e-07</izz>
        </inertia>
      </inertial>
      <collision name='lh_ffknuckle_collision'>
        <pose frame=''>0 0 0 3.14159 1.57079 3.14159</pose>
        <geometry>
          <cylinder>
            <length>0.014</length>
            <radius>0.007</radius>
          </cylinder>
        </geometry>
        <surface>
          <contact>
            <ode/>
          </contact>
          <friction>
            <ode/>
          </friction>
        </surface>
      </collision>
      <visual name='lh_ffknuckle_visual'>
        <pose frame=''>0 0 0.0005 0 -0 0</pose>
        <geometry>
          <mesh>
            <scale>0.001 0.001 0.001</scale>
            <uri>model://sr_description/hand/model/knuckle.dae</uri>
          </mesh>
        </geometry>
        <material>
          <script>
            <name>Gazebo/Grey</name>
            <uri>file://media/materials/scripts/gazebo.material</uri>
          </script>
        </material>
      </visual>
      <gravity>1</gravity>
      <velocity_decay/>
      <self_collide>0</self_collide>
      <sensor name='lh_ffknuckle_contact' type='contact'>
        <always_on>1</always_on>
        <update_rate>1000</update_rate>
        <contact>
          <collision>lh_ffknuckle_collision</collision>
          <topic>lh_ffknuckle_collision</topic>
        </contact>
        <plugin name='lh_ffknuckle_gazebo_ros_bumper_controller' filename='libgazebo_ros_bumper.so'>
          <alwaysOn>true</alwaysOn>
          <frameName>lh_ffknuckle</frameName>
          <updateRate>100.0</updateRate>
          <bumperTopicName>contacts/lh_ff/knuckle</bumperTopicName>
        </plugin>
      </sensor>
    </link>
    <joint name='lh_FFJ4' type='revolute'>
      <child>lh_ffknuckle</child>
      <parent>hand_iiwa_link_7</parent>
      <axis>
        <xyz>-0 0.766044 -0.642788</xyz>
        <limit>
          <lower>-0.349066</lower>
          <upper>0.349066</upper>
          <effort>2</effort>
          <velocity>2</velocity>
        </limit>
        <dynamics>
          <damping>0.1</damping>
          <friction>0</friction>
          <spring_reference>0</spring_reference>
          <spring_stiffness>0</spring_stiffness>
        </dynamics>
        <use_parent_model_frame>1</use_parent_model_frame>
      </axis>
      <physics>
        <provide_feedback>1</provide_feedback>
        <ode>
          <provide_feedback>1</provide_feedback>
          <implicit_spring_damper>1</implicit_spring_damper>
          <cfm_damping>1</cfm_damping>
          <limit>
            <cfm>0</cfm>
            <erp>0.2</erp>
          </limit>
        </ode>
      </physics>
    </joint>
    <link name='lh_ffproximal'>
      <pose frame=''>-0.033 0.046065 1.48777 -0.698132 0 0</pose>
      <inertial>
        <pose frame=''>0 0 0.0225 0 -0 0</pose>
        <mass>0.03</mass>
        <inertia>
          <ixx>9.8e-06</ixx>
          <ixy>0</ixy>
          <ixz>0</ixz>
          <iyy>1e-05</iyy>
          <iyz>0</iyz>
          <izz>1.8e-06</izz>
        </inertia>
      </inertial>
      <collision name='lh_ffproximal_collision'>
        <pose frame=''>0 0 0.025 0 -0 0</pose>
        <geometry>
          <cylinder>
            <length>0.04</length>
            <radius>0.007</radius>
          </cylinder>
        </geometry>
        <surface>
          <contact>
            <ode/>
          </contact>
          <friction>
            <ode/>
          </friction>
        </surface>
      </collision>
      <visual name='lh_ffproximal_visual'>
        <pose frame=''>0 0 0 0 -0 0</pose>
        <geometry>
          <mesh>
            <scale>0.001 0.001 0.001</scale>
            <uri>model://sr_description/hand/model/F3.dae</uri>
          </mesh>
        </geometry>
        <material>
          <script>
            <uri>__default__</uri>
            <name>__default__</name>
          </script>
        </material>
      </visual>
      <gravity>1</gravity>
      <velocity_decay/>
      <self_collide>1</self_collide>
      <sensor name='lh_ffproximal_contact' type='contact'>
        <always_on>1</always_on>
        <update_rate>1000</update_rate>
        <contact>
          <collision>lh_ffproximal_collision</collision>
          <topic>lh_ffproximal_collision</topic>
        </contact>
        <plugin name='lh_ffproximal_gazebo_ros_bumper_controller' filename='libgazebo_ros_bumper.so'>
          <alwaysOn>true</alwaysOn>
          <frameName>lh_ffproximal</frameName>
          <updateRate>100.0</updateRate>
          <bumperTopicName>contacts/lh_ff/proximal</bumperTopicName>
        </plugin>
      </sensor>
    </link>
    <joint name='lh_FFJ3' type='revolute'>
      <child>lh_ffproximal</child>
      <parent>lh_ffknuckle</parent>
      <axis>
        <xyz>1 0 -0</xyz>
        <limit>
          <lower>0</lower>
          <upper>1.5708</upper>
          <effort>2</effort>
          <velocity>2</velocity>
        </limit>
        <dynamics>
          <damping>0.1</damping>
          <friction>0</friction>
          <spring_reference>0</spring_reference>
          <spring_stiffness>0</spring_stiffness>
        </dynamics>
        <use_parent_model_frame>1</use_parent_model_frame>
      </axis>
      <physics>
        <provide_feedback>1</provide_feedback>
        <ode>
          <provide_feedback>1</provide_feedback>
          <implicit_spring_damper>1</implicit_spring_damper>
          <cfm_damping>1</cfm_damping>
          <limit>
            <cfm>0</cfm>
            <erp>0.2</erp>
          </limit>
        </ode>
      </physics>
    </joint>
    <link name='lh_ffmiddle'>
      <pose frame=''>-0.033 0.07499 1.52225 -0.698132 0 0</pose>
      <inertial>
        <pose frame=''>0 0 0.0125 0 -0 0</pose>
        <mass>0.017</mass>
        <inertia>
          <ixx>2.6e-06</ixx>
          <ixy>0</ixy>
          <ixz>0</ixz>
          <iyy>2.7e-06</iyy>
          <iyz>0</iyz>
          <izz>8.7e-07</izz>
        </inertia>
      </inertial>
      <collision name='lh_ffmiddle_collision'>
        <pose frame=''>0 0 0.0125 0 -0 0</pose>
        <geometry>
          <cylinder>
            <length>0.025</length>
            <radius>0.007</radius>
          </cylinder>
        </geometry>
        <surface>
          <contact>
            <ode/>
          </contact>
          <friction>
            <ode/>
          </friction>
        </surface>
      </collision>
      <collision name='lh_ffmiddle_collision_1'>
        <pose frame=''>0 0 0 0 -0 0</pose>
        <geometry>
          <sphere>
            <radius>0.007</radius>
          </sphere>
        </geometry>
        <surface>
          <contact>
            <ode/>
          </contact>
          <friction>
            <ode/>
          </friction>
        </surface>
      </collision>
      <collision name='lh_ffmiddle_collision_2'>
        <pose frame=''>0 0 0.025 0 -0 0</pose>
        <geometry>
          <sphere>
            <radius>0.007</radius>
          </sphere>
        </geometry>
        <surface>
          <contact>
            <ode/>
          </contact>
          <friction>
            <ode/>
          </friction>
        </surface>
      </collision>
      <visual name='lh_ffmiddle_visual'>
        <pose frame=''>0 0 0 0 -0 0</pose>
        <geometry>
          <mesh>
            <scale>0.001 0.001 0.001</scale>
            <uri>model://sr_description/hand/model/F2.dae</uri>
          </mesh>
        </geometry>
        <material>
          <script>
            <uri>__default__</uri>
            <name>__default__</name>
          </script>
        </material>
      </visual>
      <gravity>1</gravity>
      <velocity_decay/>
      <self_collide>1</self_collide>
      <sensor name='lh_ffmiddle_contact' type='contact'>
        <always_on>1</always_on>
        <update_rate>1000</update_rate>
        <contact>
          <collision>lh_ffmiddle_collision</collision>
          <topic>lh_ffmiddle_collision</topic>
        </contact>
        <plugin name='lh_ffproximal_gazebo_ros_bumper_controller' filename='libgazebo_ros_bumper.so'>
          <alwaysOn>true</alwaysOn>
          <frameName>lh_ffmiddle</frameName>
          <updateRate>100.0</updateRate>
          <bumperTopicName>contacts/lh_ff/middle</bumperTopicName>
        </plugin>
      </sensor>
    </link>
    <joint name='lh_FFJ2' type='revolute'>
      <child>lh_ffmiddle</child>
      <parent>lh_ffproximal</parent>
      <axis>
        <xyz>1 0 -0</xyz>
        <limit>
          <lower>0</lower>
          <upper>1.5708</upper>
          <effort>2</effort>
          <velocity>2</velocity>
        </limit>
        <dynamics>
          <damping>0.1</damping>
          <friction>0</friction>
          <spring_reference>0</spring_reference>
          <spring_stiffness>0</spring_stiffness>
        </dynamics>
        <use_parent_model_frame>1</use_parent_model_frame>
      </axis>
      <physics>
        <provide_feedback>1</provide_feedback>
        <ode>
          <provide_feedback>1</provide_feedback>
          <implicit_spring_damper>1</implicit_spring_damper>
          <cfm_damping>1</cfm_damping>
          <limit>
            <cfm>0</cfm>
            <erp>0.2</erp>
          </limit>
        </ode>
      </physics>
    </joint>
    <link name='lh_ffdistal'>
      <pose frame=''>-0.033 0.09106 1.5414 -0.698132 0 0</pose>
      <inertial>
        <pose frame=''>0 0 0.013077 0 -0 0</pose>
        <mass>0.013</mass>
        <inertia>
          <ixx>1.12092e-06</ixx>
          <ixy>0</ixy>
          <ixz>0</ixz>
          <iyy>1.28092e-06</iyy>
          <iyz>0</iyz>
          <izz>5.3e-07</izz>
        </inertia>
      </inertial>
      <collision name='lh_ffdistal_collision'>
        <pose frame=''>0 0 0 0 -0 0</pose>
        <geometry>
          <mesh>
            <scale>0.001 0.001 0.001</scale>
            <uri>model://sr_description/hand/model/F1.dae</uri>
          </mesh>
        </geometry>
        <surface>
          <contact>
            <ode>
              <kp>1e+07</kp>
              <kd>1</kd>
            </ode>
          </contact>
          <friction>
            <ode>
              <mu>500</mu>
              <mu2>500</mu2>
            </ode>
          </friction>
        </surface>
      </collision>
      <visual name='lh_ffdistal_visual'>
        <pose frame=''>0 0 0 0 -0 0</pose>
        <geometry>
          <mesh>
            <scale>0.001 0.001 0.001</scale>
            <uri>model://sr_description/hand/model/F1.dae</uri>
          </mesh>
        </geometry>
        <material>
          <script>
            <uri>__default__</uri>
            <name>__default__</name>
          </script>
        </material>
      </visual>
      <gravity>1</gravity>
      <velocity_decay/>
      <self_collide>1</self_collide>
      <sensor name='lh_ffdistal_contact' type='contact'>
        <always_on>1</always_on>
        <update_rate>1000</update_rate>
        <contact>
          <collision>lh_ffdistal_collision</collision>
          <topic>lh_ffdistal_collision</topic>
        </contact>
        <plugin name='lh_ffdistal_gazebo_ros_bumper_controller' filename='libgazebo_ros_bumper.so'>
          <alwaysOn>true</alwaysOn>
          <frameName>lh_ffdistal</frameName>
          <updateRate>100.0</updateRate>
          <bumperTopicName>contacts/lh_ff/distal</bumperTopicName>
        </plugin>
      </sensor>
    </link>
    <joint name='lh_FFJ1' type='revolute'>
      <child>lh_ffdistal</child>
      <parent>lh_ffmiddle</parent>
      <axis>
        <xyz>1 0 -0</xyz>
        <limit>
          <lower>0</lower>
          <upper>1.5708</upper>
          <effort>2</effort>
          <velocity>2</velocity>
        </limit>
        <dynamics>
          <damping>0.1</damping>
          <friction>0</friction>
          <spring_reference>0</spring_reference>
          <spring_stiffness>0</spring_stiffness>
        </dynamics>
        <use_parent_model_frame>1</use_parent_model_frame>
      </axis>
      <physics>
        <provide_feedback>1</provide_feedback>
        <ode>
          <provide_feedback>1</provide_feedback>
          <implicit_spring_damper>1</implicit_spring_damper>
          <cfm_damping>1</cfm_damping>
          <limit>
            <cfm>0</cfm>
            <erp>0.2</erp>
          </limit>
        </ode>
      </physics>
    </joint>
    <link name='lh_mfknuckle'>
      <pose frame=''>-0.011 0.048636 1.49084 -0.698132 0 0</pose>
      <inertial>
        <pose frame=''>0 0 0 0 -0 0</pose>
        <mass>0.008</mass>
        <inertia>
          <ixx>2.6e-07</ixx>
          <ixy>0</ixy>
          <ixz>0</ixz>
          <iyy>2.6e-07</iyy>
          <iyz>0</iyz>
          <izz>3.2e-07</izz>
        </inertia>
      </inertial>
      <collision name='lh_mfknuckle_collision'>
        <pose frame=''>0 0 0 3.14159 1.57079 3.14159</pose>
        <geometry>
          <cylinder>
            <length>0.014</length>
            <radius>0.007</radius>
          </cylinder>
        </geometry>
        <surface>
          <contact>
            <ode/>
          </contact>
          <friction>
            <ode/>
          </friction>
        </surface>
      </collision>
      <visual name='lh_mfknuckle_visual'>
        <pose frame=''>0 0 0.0005 0 -0 0</pose>
        <geometry>
          <mesh>
            <scale>0.001 0.001 0.001</scale>
            <uri>model://sr_description/hand/model/knuckle.dae</uri>
          </mesh>
        </geometry>
        <material>
          <script>
            <name>Gazebo/Grey</name>
            <uri>file://media/materials/scripts/gazebo.material</uri>
          </script>
        </material>
      </visual>
      <gravity>1</gravity>
      <velocity_decay/>
      <self_collide>0</self_collide>
      <sensor name='lh_mfknuckle_contact' type='contact'>
        <always_on>1</always_on>
        <update_rate>1000</update_rate>
        <contact>
          <collision>lh_mfknuckle_collision</collision>
          <topic>lh_mfknuckle_collision</topic>
        </contact>
        <plugin name='lh_mfknuckle_gazebo_ros_bumper_controller' filename='libgazebo_ros_bumper.so'>
          <alwaysOn>true</alwaysOn>
          <frameName>lh_mfknuckle</frameName>
          <updateRate>100.0</updateRate>
          <bumperTopicName>contacts/lh_mf/knuckle</bumperTopicName>
        </plugin>
      </sensor>
    </link>
    <joint name='lh_MFJ4' type='revolute'>
      <child>lh_mfknuckle</child>
      <parent>hand_iiwa_link_7</parent>
      <axis>
        <xyz>-0 0.766044 -0.642788</xyz>
        <limit>
          <lower>-0.349066</lower>
          <upper>0.349066</upper>
          <effort>2</effort>
          <velocity>2</velocity>
        </limit>
        <dynamics>
          <damping>0.1</damping>
          <friction>0</friction>
          <spring_reference>0</spring_reference>
          <spring_stiffness>0</spring_stiffness>
        </dynamics>
        <use_parent_model_frame>1</use_parent_model_frame>
      </axis>
      <physics>
        <provide_feedback>1</provide_feedback>
        <ode>
          <provide_feedback>1</provide_feedback>
          <implicit_spring_damper>1</implicit_spring_damper>
          <cfm_damping>1</cfm_damping>
          <limit>
            <cfm>0</cfm>
            <erp>0.2</erp>
          </limit>
        </ode>
      </physics>
    </joint>
    <link name='lh_mfproximal'>
      <pose frame=''>-0.011 0.048636 1.49084 -0.698132 0 0</pose>
      <inertial>
        <pose frame=''>0 0 0.0225 0 -0 0</pose>
        <mass>0.03</mass>
        <inertia>
          <ixx>9.8e-06</ixx>
          <ixy>0</ixy>
          <ixz>0</ixz>
          <iyy>1e-05</iyy>
          <iyz>0</iyz>
          <izz>1.8e-06</izz>
        </inertia>
      </inertial>
      <collision name='lh_mfproximal_collision'>
        <pose frame=''>0 0 0.025 0 -0 0</pose>
        <geometry>
          <cylinder>
            <length>0.04</length>
            <radius>0.007</radius>
          </cylinder>
        </geometry>
        <surface>
          <contact>
            <ode/>
          </contact>
          <friction>
            <ode/>
          </friction>
        </surface>
      </collision>
      <visual name='lh_mfproximal_visual'>
        <pose frame=''>0 0 0 0 -0 0</pose>
        <geometry>
          <mesh>
            <scale>0.001 0.001 0.001</scale>
            <uri>model://sr_description/hand/model/F3.dae</uri>
          </mesh>
        </geometry>
        <material>
          <script>
            <uri>__default__</uri>
            <name>__default__</name>
          </script>
        </material>
      </visual>
      <gravity>1</gravity>
      <velocity_decay/>
      <self_collide>1</self_collide>
      <sensor name='lh_mfproximal_contact' type='contact'>
        <always_on>1</always_on>
        <update_rate>1000</update_rate>
        <contact>
          <collision>lh_mfproximal_collision</collision>
          <topic>lh_mfproximal_collision</topic>
        </contact>
        <plugin name='lh_mfproximal_gazebo_ros_bumper_controller' filename='libgazebo_ros_bumper.so'>
          <alwaysOn>true</alwaysOn>
          <frameName>lh_mfproximal</frameName>
          <updateRate>100.0</updateRate>
          <bumperTopicName>contacts/lh_mf/proximal</bumperTopicName>
        </plugin>
      </sensor>
    </link>
    <joint name='lh_MFJ3' type='revolute'>
      <child>lh_mfproximal</child>
      <parent>lh_mfknuckle</parent>
      <axis>
        <xyz>1 0 -0</xyz>
        <limit>
          <lower>0</lower>
          <upper>1.5708</upper>
          <effort>2</effort>
          <velocity>2</velocity>
        </limit>
        <dynamics>
          <damping>0.1</damping>
          <friction>0</friction>
          <spring_reference>0</spring_reference>
          <spring_stiffness>0</spring_stiffness>
        </dynamics>
        <use_parent_model_frame>1</use_parent_model_frame>
      </axis>
      <physics>
        <provide_feedback>1</provide_feedback>
        <ode>
          <provide_feedback>1</provide_feedback>
          <implicit_spring_damper>1</implicit_spring_damper>
          <cfm_damping>1</cfm_damping>
          <limit>
            <cfm>0</cfm>
            <erp>0.2</erp>
          </limit>
        </ode>
      </physics>
    </joint>
    <link name='lh_mfmiddle'>
      <pose frame=''>-0.011 0.077561 1.52531 -0.698132 0 0</pose>
      <inertial>
        <pose frame=''>0 0 0.0125 0 -0 0</pose>
        <mass>0.017</mass>
        <inertia>
          <ixx>2.6e-06</ixx>
          <ixy>0</ixy>
          <ixz>0</ixz>
          <iyy>2.7e-06</iyy>
          <iyz>0</iyz>
          <izz>8.7e-07</izz>
        </inertia>
      </inertial>
      <collision name='lh_mfmiddle_collision'>
        <pose frame=''>0 0 0.0125 0 -0 0</pose>
        <geometry>
          <cylinder>
            <length>0.025</length>
            <radius>0.007</radius>
          </cylinder>
        </geometry>
        <surface>
          <contact>
            <ode/>
          </contact>
          <friction>
            <ode/>
          </friction>
        </surface>
      </collision>
      <collision name='lh_mfmiddle_collision_1'>
        <pose frame=''>0 0 0 0 -0 0</pose>
        <geometry>
          <sphere>
            <radius>0.007</radius>
          </sphere>
        </geometry>
        <surface>
          <contact>
            <ode/>
          </contact>
          <friction>
            <ode/>
          </friction>
        </surface>
      </collision>
      <collision name='lh_mfmiddle_collision_2'>
        <pose frame=''>0 0 0.025 0 -0 0</pose>
        <geometry>
          <sphere>
            <radius>0.007</radius>
          </sphere>
        </geometry>
        <surface>
          <contact>
            <ode/>
          </contact>
          <friction>
            <ode/>
          </friction>
        </surface>
      </collision>
      <visual name='lh_mfmiddle_visual'>
        <pose frame=''>0 0 0 0 -0 0</pose>
        <geometry>
          <mesh>
            <scale>0.001 0.001 0.001</scale>
            <uri>model://sr_description/hand/model/F2.dae</uri>
          </mesh>
        </geometry>
        <material>
          <script>
            <uri>__default__</uri>
            <name>__default__</name>
          </script>
        </material>
      </visual>
      <gravity>1</gravity>
      <velocity_decay/>
      <self_collide>1</self_collide>
      <sensor name='lh_mfmiddle_contact' type='contact'>
        <always_on>1</always_on>
        <update_rate>1000</update_rate>
        <contact>
          <collision>lh_mfmiddle_collision</collision>
          <topic>lh_mfmiddle_collision</topic>
        </contact>
        <plugin name='lh_mfproximal_gazebo_ros_bumper_controller' filename='libgazebo_ros_bumper.so'>
          <alwaysOn>true</alwaysOn>
          <frameName>lh_mfmiddle</frameName>
          <updateRate>100.0</updateRate>
          <bumperTopicName>contacts/lh_mf/middle</bumperTopicName>
        </plugin>
      </sensor>
    </link>
    <joint name='lh_MFJ2' type='revolute'>
      <child>lh_mfmiddle</child>
      <parent>lh_mfproximal</parent>
      <axis>
        <xyz>1 0 -0</xyz>
        <limit>
          <lower>0</lower>
          <upper>1.5708</upper>
          <effort>2</effort>
          <velocity>2</velocity>
        </limit>
        <dynamics>
          <damping>0.1</damping>
          <friction>0</friction>
          <spring_reference>0</spring_reference>
          <spring_stiffness>0</spring_stiffness>
        </dynamics>
        <use_parent_model_frame>1</use_parent_model_frame>
      </axis>
      <physics>
        <provide_feedback>1</provide_feedback>
        <ode>
          <provide_feedback>1</provide_feedback>
          <implicit_spring_damper>1</implicit_spring_damper>
          <cfm_damping>1</cfm_damping>
          <limit>
            <cfm>0</cfm>
            <erp>0.2</erp>
          </limit>
        </ode>
      </physics>
    </joint>
    <link name='lh_mfdistal'>
      <pose frame=''>-0.011 0.093631 1.54446 -0.698132 0 0</pose>
      <inertial>
        <pose frame=''>0 0 0.013077 0 -0 0</pose>
        <mass>0.013</mass>
        <inertia>
          <ixx>1.12092e-06</ixx>
          <ixy>0</ixy>
          <ixz>0</ixz>
          <iyy>1.28092e-06</iyy>
          <iyz>0</iyz>
          <izz>5.3e-07</izz>
        </inertia>
      </inertial>
      <collision name='lh_mfdistal_collision'>
        <pose frame=''>0 0 0 0 -0 0</pose>
        <geometry>
          <mesh>
            <scale>0.001 0.001 0.001</scale>
            <uri>model://sr_description/hand/model/F1.dae</uri>
          </mesh>
        </geometry>
        <surface>
          <contact>
            <ode>
              <kp>1e+07</kp>
              <kd>1</kd>
            </ode>
          </contact>
          <friction>
            <ode>
              <mu>500</mu>
              <mu2>500</mu2>
            </ode>
          </friction>
        </surface>
      </collision>
      <visual name='lh_mfdistal_visual'>
        <pose frame=''>0 0 0 0 -0 0</pose>
        <geometry>
          <mesh>
            <scale>0.001 0.001 0.001</scale>
            <uri>model://sr_description/hand/model/F1.dae</uri>
          </mesh>
        </geometry>
        <material>
          <script>
            <uri>__default__</uri>
            <name>__default__</name>
          </script>
        </material>
      </visual>
      <gravity>1</gravity>
      <velocity_decay/>
      <self_collide>1</self_collide>
      <sensor name='lh_mfdistal_contact' type='contact'>
        <always_on>1</always_on>
        <update_rate>1000</update_rate>
        <contact>
          <collision>lh_mfdistal_collision</collision>
          <topic>lh_mfdistal_collision</topic>
        </contact>
        <plugin name='lh_mfdistal_gazebo_ros_bumper_controller' filename='libgazebo_ros_bumper.so'>
          <alwaysOn>true</alwaysOn>
          <frameName>lh_mfdistal</frameName>
          <updateRate>100.0</updateRate>
          <bumperTopicName>contacts/lh_mf/distal</bumperTopicName>
        </plugin>
      </sensor>
    </link>
    <joint name='lh_MFJ1' type='revolute'>
      <child>lh_mfdistal</child>
      <parent>lh_mfmiddle</parent>
      <axis>
        <xyz>1 0 -0</xyz>
        <limit>
          <lower>0</lower>
          <upper>1.5708</upper>
          <effort>2</effort>
          <velocity>2</velocity>
        </limit>
        <dynamics>
          <damping>0.1</damping>
          <friction>0</friction>
          <spring_reference>0</spring_reference>
          <spring_stiffness>0</spring_stiffness>
        </dynamics>
        <use_parent_model_frame>1</use_parent_model_frame>
      </axis>
      <physics>
        <provide_feedback>1</provide_feedback>
        <ode>
          <provide_feedback>1</provide_feedback>
          <implicit_spring_damper>1</implicit_spring_damper>
          <cfm_damping>1</cfm_damping>
          <limit>
            <cfm>0</cfm>
            <erp>0.2</erp>
          </limit>
        </ode>
      </physics>
    </joint>
    <link name='lh_rfknuckle'>
      <pose frame=''>0.011 0.046065 1.48777 -0.698132 0 0</pose>
      <inertial>
        <pose frame=''>0 0 0 0 -0 0</pose>
        <mass>0.008</mass>
        <inertia>
          <ixx>2.6e-07</ixx>
          <ixy>0</ixy>
          <ixz>0</ixz>
          <iyy>2.6e-07</iyy>
          <iyz>0</iyz>
          <izz>3.2e-07</izz>
        </inertia>
      </inertial>
      <collision name='lh_rfknuckle_collision'>
        <pose frame=''>0 0 0 3.14159 1.57079 3.14159</pose>
        <geometry>
          <cylinder>
            <length>0.014</length>
            <radius>0.007</radius>
          </cylinder>
        </geometry>
        <surface>
          <contact>
            <ode/>
          </contact>
          <friction>
            <ode/>
          </friction>
        </surface>
      </collision>
      <visual name='lh_rfknuckle_visual'>
        <pose frame=''>0 0 0.0005 0 -0 0</pose>
        <geometry>
          <mesh>
            <scale>0.001 0.001 0.001</scale>
            <uri>model://sr_description/hand/model/knuckle.dae</uri>
          </mesh>
        </geometry>
        <material>
          <script>
            <name>Gazebo/Grey</name>
            <uri>file://media/materials/scripts/gazebo.material</uri>
          </script>
        </material>
      </visual>
      <gravity>1</gravity>
      <velocity_decay/>
      <self_collide>0</self_collide>
      <sensor name='lh_rfknuckle_contact' type='contact'>
        <always_on>1</always_on>
        <update_rate>1000</update_rate>
        <contact>
          <collision>lh_rfknuckle_collision</collision>
          <topic>lh_rfknuckle_collision</topic>
        </contact>
        <plugin name='lh_rfknuckle_gazebo_ros_bumper_controller' filename='libgazebo_ros_bumper.so'>
          <alwaysOn>true</alwaysOn>
          <frameName>lh_rfknuckle</frameName>
          <updateRate>100.0</updateRate>
          <bumperTopicName>contacts/lh_rf/knuckle</bumperTopicName>
        </plugin>
      </sensor>
    </link>
    <joint name='lh_RFJ4' type='revolute'>
      <child>lh_rfknuckle</child>
      <parent>hand_iiwa_link_7</parent>
      <axis>
        <xyz>0 -0.766044 0.642788</xyz>
        <limit>
          <lower>-0.349066</lower>
          <upper>0.349066</upper>
          <effort>2</effort>
          <velocity>2</velocity>
        </limit>
        <dynamics>
          <damping>0.1</damping>
          <friction>0</friction>
          <spring_reference>0</spring_reference>
          <spring_stiffness>0</spring_stiffness>
        </dynamics>
        <use_parent_model_frame>1</use_parent_model_frame>
      </axis>
      <physics>
        <provide_feedback>1</provide_feedback>
        <ode>
          <provide_feedback>1</provide_feedback>
          <implicit_spring_damper>1</implicit_spring_damper>
          <cfm_damping>1</cfm_damping>
          <limit>
            <cfm>0</cfm>
            <erp>0.2</erp>
          </limit>
        </ode>
      </physics>
    </joint>
    <link name='lh_rfproximal'>
      <pose frame=''>0.011 0.046065 1.48777 -0.698132 0 0</pose>
      <inertial>
        <pose frame=''>0 0 0.0225 0 -0 0</pose>
        <mass>0.03</mass>
        <inertia>
          <ixx>9.8e-06</ixx>
          <ixy>0</ixy>
          <ixz>0</ixz>
          <iyy>1e-05</iyy>
          <iyz>0</iyz>
          <izz>1.8e-06</izz>
        </inertia>
      </inertial>
      <collision name='lh_rfproximal_collision'>
        <pose frame=''>0 0 0.025 0 -0 0</pose>
        <geometry>
          <cylinder>
            <length>0.04</length>
            <radius>0.007</radius>
          </cylinder>
        </geometry>
        <surface>
          <contact>
            <ode/>
          </contact>
          <friction>
            <ode/>
          </friction>
        </surface>
      </collision>
      <visual name='lh_rfproximal_visual'>
        <pose frame=''>0 0 0 0 -0 0</pose>
        <geometry>
          <mesh>
            <scale>0.001 0.001 0.001</scale>
            <uri>model://sr_description/hand/model/F3.dae</uri>
          </mesh>
        </geometry>
        <material>
          <script>
            <uri>__default__</uri>
            <name>__default__</name>
          </script>
        </material>
      </visual>
      <gravity>1</gravity>
      <velocity_decay/>
      <self_collide>1</self_collide>
      <sensor name='lh_rfproximal_contact' type='contact'>
        <always_on>1</always_on>
        <update_rate>1000</update_rate>
        <contact>
          <collision>lh_rfproximal_collision</collision>
          <topic>lh_rfproximal_collision</topic>
        </contact>
        <plugin name='lh_rfproximal_gazebo_ros_bumper_controller' filename='libgazebo_ros_bumper.so'>
          <alwaysOn>true</alwaysOn>
          <frameName>lh_rfproximal</frameName>
          <updateRate>100.0</updateRate>
          <bumperTopicName>contacts/lh_rf/proximal</bumperTopicName>
        </plugin>
      </sensor>
    </link>
    <joint name='lh_RFJ3' type='revolute'>
      <child>lh_rfproximal</child>
      <parent>lh_rfknuckle</parent>
      <axis>
        <xyz>1 0 -0</xyz>
        <limit>
          <lower>0</lower>
          <upper>1.5708</upper>
          <effort>2</effort>
          <velocity>2</velocity>
        </limit>
        <dynamics>
          <damping>0.1</damping>
          <friction>0</friction>
          <spring_reference>0</spring_reference>
          <spring_stiffness>0</spring_stiffness>
        </dynamics>
        <use_parent_model_frame>1</use_parent_model_frame>
      </axis>
      <physics>
        <provide_feedback>1</provide_feedback>
        <ode>
          <provide_feedback>1</provide_feedback>
          <implicit_spring_damper>1</implicit_spring_damper>
          <cfm_damping>1</cfm_damping>
          <limit>
            <cfm>0</cfm>
            <erp>0.2</erp>
          </limit>
        </ode>
      </physics>
    </joint>
    <link name='lh_rfmiddle'>
      <pose frame=''>0.011 0.07499 1.52225 -0.698132 0 0</pose>
      <inertial>
        <pose frame=''>0 0 0.0125 0 -0 0</pose>
        <mass>0.017</mass>
        <inertia>
          <ixx>2.6e-06</ixx>
          <ixy>0</ixy>
          <ixz>0</ixz>
          <iyy>2.7e-06</iyy>
          <iyz>0</iyz>
          <izz>8.7e-07</izz>
        </inertia>
      </inertial>
      <collision name='lh_rfmiddle_collision'>
        <pose frame=''>0 0 0.0125 0 -0 0</pose>
        <geometry>
          <cylinder>
            <length>0.025</length>
            <radius>0.007</radius>
          </cylinder>
        </geometry>
        <surface>
          <contact>
            <ode/>
          </contact>
          <friction>
            <ode/>
          </friction>
        </surface>
      </collision>
      <collision name='lh_rfmiddle_collision_1'>
        <pose frame=''>0 0 0 0 -0 0</pose>
        <geometry>
          <sphere>
            <radius>0.007</radius>
          </sphere>
        </geometry>
        <surface>
          <contact>
            <ode/>
          </contact>
          <friction>
            <ode/>
          </friction>
        </surface>
      </collision>
      <collision name='lh_rfmiddle_collision_2'>
        <pose frame=''>0 0 0.025 0 -0 0</pose>
        <geometry>
          <sphere>
            <radius>0.007</radius>
          </sphere>
        </geometry>
        <surface>
          <contact>
            <ode/>
          </contact>
          <friction>
            <ode/>
          </friction>
        </surface>
      </collision>
      <visual name='lh_rfmiddle_visual'>
        <pose frame=''>0 0 0 0 -0 0</pose>
        <geometry>
          <mesh>
            <scale>0.001 0.001 0.001</scale>
            <uri>model://sr_description/hand/model/F2.dae</uri>
          </mesh>
        </geometry>
        <material>
          <script>
            <uri>__default__</uri>
            <name>__default__</name>
          </script>
        </material>
      </visual>
      <gravity>1</gravity>
      <velocity_decay/>
      <self_collide>1</self_collide>
      <sensor name='lh_rfmiddle_contact' type='contact'>
        <always_on>1</always_on>
        <update_rate>1000</update_rate>
        <contact>
          <collision>lh_rfmiddle_collision</collision>
          <topic>lh_rfmiddle_collision</topic>
        </contact>
        <plugin name='lh_rfproximal_gazebo_ros_bumper_controller' filename='libgazebo_ros_bumper.so'>
          <alwaysOn>true</alwaysOn>
          <frameName>lh_rfmiddle</frameName>
          <updateRate>100.0</updateRate>
          <bumperTopicName>contacts/lh_rf/middle</bumperTopicName>
        </plugin>
      </sensor>
    </link>
    <joint name='lh_RFJ2' type='revolute'>
      <child>lh_rfmiddle</child>
      <parent>lh_rfproximal</parent>
      <axis>
        <xyz>1 0 -0</xyz>
        <limit>
          <lower>0</lower>
          <upper>1.5708</upper>
          <effort>2</effort>
          <velocity>2</velocity>
        </limit>
        <dynamics>
          <damping>0.1</damping>
          <friction>0</friction>
          <spring_reference>0</spring_reference>
          <spring_stiffness>0</spring_stiffness>
        </dynamics>
        <use_parent_model_frame>1</use_parent_model_frame>
      </axis>
      <physics>
        <provide_feedback>1</provide_feedback>
        <ode>
          <provide_feedback>1</provide_feedback>
          <implicit_spring_damper>1</implicit_spring_damper>
          <cfm_damping>1</cfm_damping>
          <limit>
            <cfm>0</cfm>
            <erp>0.2</erp>
          </limit>
        </ode>
      </physics>
    </joint>
    <link name='lh_rfdistal'>
      <pose frame=''>0.011 0.09106 1.5414 -0.698132 0 0</pose>
      <inertial>
        <pose frame=''>0 0 0.013077 0 -0 0</pose>
        <mass>0.013</mass>
        <inertia>
          <ixx>1.12092e-06</ixx>
          <ixy>0</ixy>
          <ixz>0</ixz>
          <iyy>1.28092e-06</iyy>
          <iyz>0</iyz>
          <izz>5.3e-07</izz>
        </inertia>
      </inertial>
      <collision name='lh_rfdistal_collision'>
        <pose frame=''>0 0 0 0 -0 0</pose>
        <geometry>
          <mesh>
            <scale>0.001 0.001 0.001</scale>
            <uri>model://sr_description/hand/model/F1.dae</uri>
          </mesh>
        </geometry>
        <surface>
          <contact>
            <ode>
              <kp>1e+07</kp>
              <kd>1</kd>
            </ode>
          </contact>
          <friction>
            <ode>
              <mu>500</mu>
              <mu2>500</mu2>
            </ode>
          </friction>
        </surface>
      </collision>
      <visual name='lh_rfdistal_visual'>
        <pose frame=''>0 0 0 0 -0 0</pose>
        <geometry>
          <mesh>
            <scale>0.001 0.001 0.001</scale>
            <uri>model://sr_description/hand/model/F1.dae</uri>
          </mesh>
        </geometry>
        <material>
          <script>
            <uri>__default__</uri>
            <name>__default__</name>
          </script>
        </material>
      </visual>
      <gravity>1</gravity>
      <velocity_decay/>
      <self_collide>1</self_collide>
      <sensor name='lh_rfdistal_contact' type='contact'>
        <always_on>1</always_on>
        <update_rate>1000</update_rate>
        <contact>
          <collision>lh_rfdistal_collision</collision>
          <topic>lh_rfdistal_collision</topic>
        </contact>
        <plugin name='lh_rfdistal_gazebo_ros_bumper_controller' filename='libgazebo_ros_bumper.so'>
          <alwaysOn>true</alwaysOn>
          <frameName>lh_rfdistal</frameName>
          <updateRate>100.0</updateRate>
          <bumperTopicName>contacts/lh_rf/distal</bumperTopicName>
        </plugin>
      </sensor>
    </link>
    <joint name='lh_RFJ1' type='revolute'>
      <child>lh_rfdistal</child>
      <parent>lh_rfmiddle</parent>
      <axis>
        <xyz>1 0 -0</xyz>
        <limit>
          <lower>0</lower>
          <upper>1.5708</upper>
          <effort>2</effort>
          <velocity>2</velocity>
        </limit>
        <dynamics>
          <damping>0.1</damping>
          <friction>0</friction>
          <spring_reference>0</spring_reference>
          <spring_stiffness>0</spring_stiffness>
        </dynamics>
        <use_parent_model_frame>1</use_parent_model_frame>
      </axis>
      <physics>
        <provide_feedback>1</provide_feedback>
        <ode>
          <provide_feedback>1</provide_feedback>
          <implicit_spring_damper>1</implicit_spring_damper>
          <cfm_damping>1</cfm_damping>
          <limit>
            <cfm>0</cfm>
            <erp>0.2</erp>
          </limit>
        </ode>
      </physics>
    </joint>
    <link name='lh_thbase'>
      <pose frame=''>-0.034 -0.002871 1.44268 0.870557 0.572429 -2.5703</pose>
      <inertial>
        <pose frame=''>0 0 0 0 -0 0</pose>
        <mass>0.01</mass>
        <inertia>
          <ixx>1.6e-07</ixx>
          <ixy>0</ixy>
          <ixz>0</ixz>
          <iyy>1.6e-07</iyy>
          <iyz>0</iyz>
          <izz>1.6e-07</izz>
        </inertia>
      </inertial>
      <collision name='lh_thbase_collision'>
        <pose frame=''>0 0 0 0 -0 0</pose>
        <geometry>
          <sphere>
            <radius>0.011</radius>
          </sphere>
        </geometry>
        <surface>
          <contact>
            <ode/>
          </contact>
          <friction>
            <ode/>
          </friction>
        </surface>
      </collision>
      <visual name='lh_thbase_visual'>
        <pose frame=''>0 0 0 0 -0 0</pose>
        <geometry>
          <box>
            <size>0.001 0.001 0.001</size>
          </box>
        </geometry>
        <material>
          <script>
            <uri>__default__</uri>
            <name>__default__</name>
          </script>
        </material>
      </visual>
      <gravity>1</gravity>
      <velocity_decay/>
      <self_collide>0</self_collide>
      <sensor name='lh_thbase_contact' type='contact'>
        <always_on>1</always_on>
        <update_rate>1000</update_rate>
        <contact>
          <collision>lh_thbase_collision</collision>
          <topic>lh_thbase_collision</topic>
        </contact>
        <plugin name='lh_thbase_gazebo_ros_bumper_controller' filename='libgazebo_ros_bumper.so'>
          <alwaysOn>true</alwaysOn>
          <frameName>lh_thbase</frameName>
          <updateRate>100.0</updateRate>
          <bumperTopicName>contacts/lh_th/base</bumperTopicName>
        </plugin>
      </sensor>
    </link>
    <joint name='lh_THJ5' type='revolute'>
      <child>lh_thbase</child>
      <parent>hand_iiwa_link_7</parent>
      <axis>
        <xyz>-0.707107 0.454519 0.541675</xyz>
        <limit>
          <lower>-1.0472</lower>
          <upper>1.0472</upper>
          <effort>5</effort>
          <velocity>4</velocity>
        </limit>
        <dynamics>
          <damping>0.2</damping>
          <friction>0</friction>
          <spring_reference>0</spring_reference>
          <spring_stiffness>0</spring_stiffness>
        </dynamics>
        <use_parent_model_frame>1</use_parent_model_frame>
      </axis>
      <physics>
        <provide_feedback>1</provide_feedback>
        <ode>
          <provide_feedback>1</provide_feedback>
          <implicit_spring_damper>1</implicit_spring_damper>
          <cfm_damping>1</cfm_damping>
          <limit>
            <cfm>0</cfm>
            <erp>0.2</erp>
          </limit>
        </ode>
      </physics>
    </joint>
    <link name='lh_thproximal'>
      <pose frame=''>-0.034 -0.002871 1.44268 0.870557 0.572429 -2.5703</pose>
      <inertial>
        <pose frame=''>0 0 0.021111 0 -0 0</pose>
        <mass>0.045</mass>
        <inertia>
          <ixx>1.62044e-05</ixx>
          <ixy>0</ixy>
          <ixz>0</ixz>
          <iyy>1.62044e-05</iyy>
          <iyz>0</iyz>
          <izz>3.43e-06</izz>
        </inertia>
      </inertial>
      <collision name='lh_thproximal_collision'>
        <pose frame=''>0 0 0.02 0 -0 0</pose>
        <geometry>
          <cylinder>
            <length>0.018</length>
            <radius>0.012</radius>
          </cylinder>
        </geometry>
        <surface>
          <contact>
            <ode/>
          </contact>
          <friction>
            <ode/>
          </friction>
        </surface>
      </collision>
      <collision name='lh_thproximal_fixed_joint_lump__lh_thhub_collision_1'>
        <pose frame=''>0 0 0.038 0 -0 0</pose>
        <geometry>
          <sphere>
            <radius>0.01</radius>
          </sphere>
        </geometry>
        <surface>
          <contact>
            <ode/>
          </contact>
          <friction>
            <ode/>
          </friction>
        </surface>
      </collision>
      <visual name='lh_thproximal_visual'>
        <pose frame=''>0 0 0 0 -0 0</pose>
        <geometry>
          <mesh>
            <scale>0.001 0.001 0.001</scale>
            <uri>model://sr_description/hand/model/TH3_z.dae</uri>
          </mesh>
        </geometry>
        <material>
          <script>
            <uri>__default__</uri>
            <name>__default__</name>
          </script>
        </material>
      </visual>
      <visual name='lh_thproximal_fixed_joint_lump__lh_thhub_visual_1'>
        <pose frame=''>0 0 0.038 0 -0 0</pose>
        <geometry>
          <box>
            <size>0.001 0.001 0.001</size>
          </box>
        </geometry>
        <material>
          <script>
            <uri>__default__</uri>
            <name>__default__</name>
          </script>
        </material>
      </visual>
      <velocity_decay/>
      <sensor name='lh_thproximal_contact' type='contact'>
        <always_on>1</always_on>
        <update_rate>1000</update_rate>
        <contact>
          <collision>lh_thproximal_collision</collision>
          <topic>lh_thproximal_collision</topic>
        </contact>
        <plugin name='lh_thproximal_gazebo_ros_bumper_controller' filename='libgazebo_ros_bumper.so'>
          <alwaysOn>true</alwaysOn>
          <frameName>lh_thproximal</frameName>
          <updateRate>100.0</updateRate>
          <bumperTopicName>contacts/lh_th/proximal</bumperTopicName>
        </plugin>
      </sensor>
      <gravity>1</gravity>
      <velocity_decay/>
      <self_collide>1</self_collide>
      <sensor name='lh_thhub_contact' type='contact'>
        <always_on>1</always_on>
        <update_rate>1000</update_rate>
        <contact>
          <topic>lh_thhub_collision</topic>
          <collision>lh_thproximal_collision_lh_thhub</collision>
        </contact>
        <plugin name='lh_thhub_gazebo_ros_bumper_controller' filename='libgazebo_ros_bumper.so'>
          <alwaysOn>true</alwaysOn>
          <frameName>lh_thhub</frameName>
          <updateRate>100.0</updateRate>
          <bumperTopicName>contacts/lh_th/hub</bumperTopicName>
        </plugin>
        <pose frame=''>0 0 0.038 0 -0 0</pose>
      </sensor>
    </link>
    <joint name='lh_THJ4' type='revolute'>
      <child>lh_thproximal</child>
      <parent>lh_thbase</parent>
      <axis>
        <xyz>0.707107 0.454519 0.541675</xyz>
        <limit>
          <lower>0</lower>
          <upper>1.22173</upper>
          <effort>3</effort>
          <velocity>4</velocity>
        </limit>
        <dynamics>
          <damping>0.2</damping>
          <friction>0</friction>
          <spring_reference>0</spring_reference>
          <spring_stiffness>0</spring_stiffness>
        </dynamics>
        <use_parent_model_frame>1</use_parent_model_frame>
      </axis>
      <physics>
        <provide_feedback>1</provide_feedback>
        <ode>
          <provide_feedback>1</provide_feedback>
          <implicit_spring_damper>1</implicit_spring_damper>
          <cfm_damping>1</cfm_damping>
          <limit>
            <cfm>0</cfm>
            <erp>0.2</erp>
          </limit>
        </ode>
      </physics>
    </joint>
    <link name='lh_thmiddle'>
      <pose frame=''>-0.06087 0.014401 1.46326 0.870557 0.572429 -2.5703</pose>
      <inertial>
        <pose frame=''>0 0 0.016 0 -0 0</pose>
        <mass>0.02</mass>
        <inertia>
          <ixx>5.1e-06</ixx>
          <ixy>0</ixy>
          <ixz>0</ixz>
          <iyy>5.1e-06</iyy>
          <iyz>0</iyz>
          <izz>1.21e-06</izz>
        </inertia>
      </inertial>
      <collision name='lh_thmiddle_collision'>
        <pose frame=''>0 0 0.012 0 -0 0</pose>
        <geometry>
          <cylinder>
            <length>0.018</length>
            <radius>0.011</radius>
          </cylinder>
        </geometry>
        <surface>
          <contact>
            <ode/>
          </contact>
          <friction>
            <ode/>
          </friction>
        </surface>
      </collision>
      <collision name='lh_thmiddle_collision_1'>
        <pose frame=''>0 0 0.019 0 -0 0</pose>
        <geometry>
          <sphere>
            <radius>0.011</radius>
          </sphere>
        </geometry>
        <surface>
          <contact>
            <ode/>
          </contact>
          <friction>
            <ode/>
          </friction>
        </surface>
      </collision>
      <visual name='lh_thmiddle_visual'>
        <pose frame=''>0 0 0 0 -0 0</pose>
        <geometry>
          <mesh>
            <scale>0.001 0.001 0.001</scale>
            <uri>model://sr_description/hand/model/TH2_z.dae</uri>
          </mesh>
        </geometry>
        <material>
          <script>
            <uri>__default__</uri>
            <name>__default__</name>
          </script>
        </material>
      </visual>
      <gravity>1</gravity>
      <velocity_decay/>
      <self_collide>1</self_collide>
      <sensor name='lh_thmiddle_contact' type='contact'>
        <always_on>1</always_on>
        <update_rate>1000</update_rate>
        <contact>
          <collision>lh_thmiddle_collision</collision>
          <topic>lh_thmiddle_collision</topic>
        </contact>
        <plugin name='lh_thmiddle_gazebo_ros_bumper_controller' filename='libgazebo_ros_bumper.so'>
          <alwaysOn>true</alwaysOn>
          <frameName>lh_thmiddle</frameName>
          <updateRate>100.0</updateRate>
          <bumperTopicName>contacts/lh_th/middle</bumperTopicName>
        </plugin>
      </sensor>
    </link>
    <joint name='lh_THJ2' type='revolute'>
      <child>lh_thmiddle</child>
      <parent>lh_thproximal</parent>
      <axis>
        <xyz>-0 0.766044 -0.642788</xyz>
        <limit>
          <lower>-0.698132</lower>
          <upper>0.698132</upper>
          <effort>2</effort>
          <velocity>2</velocity>
        </limit>
        <dynamics>
          <damping>0.1</damping>
          <friction>0</friction>
          <spring_reference>0</spring_reference>
          <spring_stiffness>0</spring_stiffness>
        </dynamics>
        <use_parent_model_frame>1</use_parent_model_frame>
      </axis>
      <physics>
        <provide_feedback>1</provide_feedback>
        <ode>
          <provide_feedback>1</provide_feedback>
          <implicit_spring_damper>1</implicit_spring_damper>
          <cfm_damping>1</cfm_damping>
          <limit>
            <cfm>0</cfm>
            <erp>0.2</erp>
          </limit>
        </ode>
      </physics>
    </joint>
    <link name='lh_thdistal'>
      <pose frame=''>-0.083498 0.028946 1.4806 -0.785398 0.698132 1.5708</pose>
      <inertial>
        <pose frame=''>0 0 0.014559 0 -0 0</pose>
        <mass>0.017</mass>
        <inertia>
          <ixx>2.27794e-06</ixx>
          <ixy>0</ixy>
          <ixz>0</ixz>
          <iyy>2.37794e-06</iyy>
          <iyz>0</iyz>
          <izz>1e-06</izz>
        </inertia>
      </inertial>
      <collision name='lh_thdistal_collision'>
        <pose frame=''>0 0 0 0 -0 0</pose>
        <geometry>
          <mesh>
            <scale>0.001 0.001 0.001</scale>
            <uri>model://sr_description/hand/model/TH1_z.dae</uri>
          </mesh>
        </geometry>
        <surface>
          <contact>
            <ode>
              <kp>1e+07</kp>
              <kd>1</kd>
            </ode>
          </contact>
          <friction>
            <ode>
              <mu>500</mu>
              <mu2>500</mu2>
            </ode>
          </friction>
        </surface>
      </collision>
      <visual name='lh_thdistal_visual'>
        <pose frame=''>0 0 0 0 -0 0</pose>
        <geometry>
          <mesh>
            <scale>0.001 0.001 0.001</scale>
            <uri>model://sr_description/hand/model/TH1_z.dae</uri>
          </mesh>
        </geometry>
        <material>
          <script>
            <uri>__default__</uri>
            <name>__default__</name>
          </script>
        </material>
      </visual>
      <gravity>1</gravity>
      <velocity_decay/>
      <self_collide>1</self_collide>
      <sensor name='lh_thdistal_contact' type='contact'>
        <always_on>1</always_on>
        <update_rate>1000</update_rate>
        <contact>
          <collision>lh_thdistal_collision</collision>
          <topic>lh_thdistal_collision</topic>
        </contact>
        <plugin name='lh_thdistal_gazebo_ros_bumper_controller' filename='libgazebo_ros_bumper.so'>
          <alwaysOn>true</alwaysOn>
          <frameName>lh_thdistal</frameName>
          <updateRate>100.0</updateRate>
          <bumperTopicName>contacts/lh_th/distal</bumperTopicName>
        </plugin>
      </sensor>
    </link>
    <joint name='lh_THJ1' type='revolute'>
      <child>lh_thdistal</child>
      <parent>lh_thmiddle</parent>
      <axis>
        <xyz>-0 0.766044 -0.642788</xyz>
        <limit>
          <lower>0</lower>
          <upper>1.5708</upper>
          <effort>1</effort>
          <velocity>4</velocity>
        </limit>
        <dynamics>
          <damping>0.2</damping>
          <friction>0</friction>
          <spring_reference>0</spring_reference>
          <spring_stiffness>0</spring_stiffness>
        </dynamics>
        <use_parent_model_frame>1</use_parent_model_frame>
      </axis>
      <physics>
        <provide_feedback>1</provide_feedback>
        <ode>
          <provide_feedback>1</provide_feedback>
          <implicit_spring_damper>1</implicit_spring_damper>
          <cfm_damping>1</cfm_damping>
          <limit>
            <cfm>0</cfm>
            <erp>0.2</erp>
          </limit>
        </ode>
      </physics>
    </joint>
    <plugin name='gazebo_ros_control' filename='libgazebo_ros_control.so'>
      <robotSimType>sr_gazebo_sim/SrGazeboHWSim</robotSimType>
    </plugin>
    <static>0</static>
    <plugin name='gazebo_ros_control' filename='libgazebo_ros_control.so'>
      <robotNamespace>/hand_iiwa</robotNamespace>
    </plugin>
  </model>
</sdf>
